2018-09-18 10:01:12,991 INFO org.apache.hadoop.yarn.server.resourcemanager.ClientRMService: Allocated new applicationId: 1
2018-09-18 10:01:13,801 INFO org.apache.hadoop.yarn.server.resourcemanager.scheduler.capacity.CapacityScheduler: Application 'application_1536878829533_0001' is submitted without priority hence considering default queue/cluster priority: 0
2018-09-18 10:01:13,801 INFO org.apache.hadoop.yarn.server.resourcemanager.scheduler.capacity.CapacityScheduler: Priority '0' is acceptable in queue : default for application: application_1536878829533_0001 for the user: jason
2018-09-18 10:01:13,834 INFO org.apache.hadoop.yarn.server.resourcemanager.ClientRMService: Application with id 1 submitted by user jason
2018-09-18 10:01:13,834 INFO org.apache.hadoop.yarn.server.resourcemanager.rmapp.RMAppImpl: Storing application with id application_1536878829533_0001
2018-09-18 10:01:13,842 INFO org.apache.hadoop.yarn.server.resourcemanager.RMAuditLogger: USER=jason	IP=192.168.1.103	OPERATION=Submit Application Request	TARGET=ClientRMService	RESULT=SUCCESS	APPID=application_1536878829533_0001
2018-09-18 10:01:13,853 INFO org.apache.hadoop.yarn.server.resourcemanager.rmapp.RMAppImpl: application_1536878829533_0001 State change from NEW to NEW_SAVING on event=START
2018-09-18 10:01:13,853 INFO org.apache.hadoop.yarn.server.resourcemanager.recovery.RMStateStore: Storing info for app: application_1536878829533_0001
2018-09-18 10:01:13,854 INFO org.apache.hadoop.yarn.server.resourcemanager.rmapp.RMAppImpl: application_1536878829533_0001 State change from NEW_SAVING to SUBMITTED on event=APP_NEW_SAVED
2018-09-18 10:01:13,857 INFO org.apache.hadoop.yarn.server.resourcemanager.scheduler.capacity.ParentQueue: Application added - appId: application_1536878829533_0001 user: jason leaf-queue of parent: root #applications: 1
2018-09-18 10:01:13,858 INFO org.apache.hadoop.yarn.server.resourcemanager.scheduler.capacity.CapacityScheduler: Accepted application application_1536878829533_0001 from user: jason, in queue: default
2018-09-18 10:01:13,893 INFO org.apache.hadoop.yarn.server.resourcemanager.rmapp.RMAppImpl: application_1536878829533_0001 State change from SUBMITTED to ACCEPTED on event=APP_ACCEPTED
2018-09-18 10:01:13,932 INFO org.apache.hadoop.yarn.server.resourcemanager.ApplicationMasterService: Registering app attempt : appattempt_1536878829533_0001_000001
2018-09-18 10:01:13,934 INFO org.apache.hadoop.yarn.server.resourcemanager.rmapp.attempt.RMAppAttemptImpl: appattempt_1536878829533_0001_000001 State change from NEW to SUBMITTED
2018-09-18 10:01:13,961 WARN org.apache.hadoop.yarn.server.resourcemanager.scheduler.capacity.LeafQueue: maximum-am-resource-percent is insufficient to start a single application in queue, it is likely set too low. skipping enforcement to allow at least one application to start
2018-09-18 10:01:13,961 WARN org.apache.hadoop.yarn.server.resourcemanager.scheduler.capacity.LeafQueue: maximum-am-resource-percent is insufficient to start a single application in queue for user, it is likely set too low. skipping enforcement to allow at least one application to start
2018-09-18 10:01:13,965 INFO org.apache.hadoop.yarn.server.resourcemanager.scheduler.capacity.LeafQueue: Application application_1536878829533_0001 from user: jason activated in queue: default
2018-09-18 10:01:13,965 INFO org.apache.hadoop.yarn.server.resourcemanager.scheduler.capacity.LeafQueue: Application added - appId: application_1536878829533_0001 user: jason, leaf-queue: default #user-pending-applications: 0 #user-active-applications: 1 #queue-pending-applications: 0 #queue-active-applications: 1
2018-09-18 10:01:13,965 INFO org.apache.hadoop.yarn.server.resourcemanager.scheduler.capacity.CapacityScheduler: Added Application Attempt appattempt_1536878829533_0001_000001 to scheduler from user jason in queue default
2018-09-18 10:01:13,968 INFO org.apache.hadoop.yarn.server.resourcemanager.rmapp.attempt.RMAppAttemptImpl: appattempt_1536878829533_0001_000001 State change from SUBMITTED to SCHEDULED
2018-09-18 10:01:14,917 INFO org.apache.hadoop.yarn.server.resourcemanager.rmcontainer.RMContainerImpl: container_1536878829533_0001_01_000001 Container Transitioned from NEW to ALLOCATED
2018-09-18 10:01:14,918 INFO org.apache.hadoop.yarn.server.resourcemanager.RMAuditLogger: USER=jason	OPERATION=AM Allocated Container	TARGET=SchedulerApp	RESULT=SUCCESS	APPID=application_1536878829533_0001	CONTAINERID=container_1536878829533_0001_01_000001
2018-09-18 10:01:14,919 INFO org.apache.hadoop.yarn.server.resourcemanager.scheduler.SchedulerNode: Assigned container container_1536878829533_0001_01_000001 of capacity <memory:2048, vCores:1> on host 192.168.1.103:56395, which has 1 containers, <memory:2048, vCores:1> used and <memory:6144, vCores:7> available after allocation
2018-09-18 10:01:14,919 INFO org.apache.hadoop.yarn.server.resourcemanager.scheduler.capacity.allocator.AbstractContainerAllocator: assignedContainer application attempt=appattempt_1536878829533_0001_000001 container=container_1536878829533_0001_01_000001 queue=org.apache.hadoop.yarn.server.resourcemanager.scheduler.capacity.allocator.RegularContainerAllocator@616798c1 clusterResource=<memory:8192, vCores:8> type=OFF_SWITCH
2018-09-18 10:01:14,952 INFO org.apache.hadoop.yarn.server.resourcemanager.security.NMTokenSecretManagerInRM: Sending NMToken for nodeId : 192.168.1.103:56395 for container : container_1536878829533_0001_01_000001
2018-09-18 10:01:14,965 INFO org.apache.hadoop.yarn.server.resourcemanager.rmcontainer.RMContainerImpl: container_1536878829533_0001_01_000001 Container Transitioned from ALLOCATED to ACQUIRED
2018-09-18 10:01:14,965 INFO org.apache.hadoop.yarn.server.resourcemanager.security.NMTokenSecretManagerInRM: Clear node set for appattempt_1536878829533_0001_000001
2018-09-18 10:01:14,966 INFO org.apache.hadoop.yarn.server.resourcemanager.rmapp.attempt.RMAppAttemptImpl: Storing attempt: AppId: application_1536878829533_0001 AttemptId: appattempt_1536878829533_0001_000001 MasterContainer: Container: [ContainerId: container_1536878829533_0001_01_000001, Version: 0, NodeId: 192.168.1.103:56395, NodeHttpAddress: 192.168.1.103:8042, Resource: <memory:2048, vCores:1>, Priority: 0, Token: Token { kind: ContainerToken, service: 192.168.1.103:56395 }, ]
2018-09-18 10:01:14,966 INFO org.apache.hadoop.yarn.server.resourcemanager.scheduler.capacity.ParentQueue: Re-sorting assigned queue: root.default stats: default: capacity=1.0, absoluteCapacity=1.0, usedResources=<memory:2048, vCores:1>, usedCapacity=0.25, absoluteUsedCapacity=0.25, numApps=1, numContainers=1
2018-09-18 10:01:14,966 INFO org.apache.hadoop.yarn.server.resourcemanager.scheduler.capacity.ParentQueue: assignedContainer queue=root usedCapacity=0.25 absoluteUsedCapacity=0.25 used=<memory:2048, vCores:1> cluster=<memory:8192, vCores:8>
2018-09-18 10:01:14,977 INFO org.apache.hadoop.yarn.server.resourcemanager.rmapp.attempt.RMAppAttemptImpl: appattempt_1536878829533_0001_000001 State change from SCHEDULED to ALLOCATED_SAVING
2018-09-18 10:01:14,983 INFO org.apache.hadoop.yarn.server.resourcemanager.rmapp.attempt.RMAppAttemptImpl: appattempt_1536878829533_0001_000001 State change from ALLOCATED_SAVING to ALLOCATED
2018-09-18 10:01:14,987 INFO org.apache.hadoop.yarn.server.resourcemanager.amlauncher.AMLauncher: Launching masterappattempt_1536878829533_0001_000001
2018-09-18 10:01:15,047 INFO org.apache.hadoop.yarn.server.resourcemanager.amlauncher.AMLauncher: Setting up container Container: [ContainerId: container_1536878829533_0001_01_000001, Version: 0, NodeId: 192.168.1.103:56395, NodeHttpAddress: 192.168.1.103:8042, Resource: <memory:2048, vCores:1>, Priority: 0, Token: Token { kind: ContainerToken, service: 192.168.1.103:56395 }, ] for AM appattempt_1536878829533_0001_000001
2018-09-18 10:01:15,047 INFO org.apache.hadoop.yarn.server.resourcemanager.security.AMRMTokenSecretManager: Create AMRMToken for ApplicationAttempt: appattempt_1536878829533_0001_000001
2018-09-18 10:01:15,051 INFO org.apache.hadoop.yarn.server.resourcemanager.security.AMRMTokenSecretManager: Creating password for appattempt_1536878829533_0001_000001
2018-09-18 10:01:15,456 INFO org.apache.hadoop.yarn.server.resourcemanager.amlauncher.AMLauncher: Done launching container Container: [ContainerId: container_1536878829533_0001_01_000001, Version: 0, NodeId: 192.168.1.103:56395, NodeHttpAddress: 192.168.1.103:8042, Resource: <memory:2048, vCores:1>, Priority: 0, Token: Token { kind: ContainerToken, service: 192.168.1.103:56395 }, ] for AM appattempt_1536878829533_0001_000001
2018-09-18 10:01:15,456 INFO org.apache.hadoop.yarn.server.resourcemanager.rmapp.attempt.RMAppAttemptImpl: appattempt_1536878829533_0001_000001 State change from ALLOCATED to LAUNCHED
2018-09-18 10:01:15,890 INFO org.apache.hadoop.yarn.server.resourcemanager.rmcontainer.RMContainerImpl: container_1536878829533_0001_01_000001 Container Transitioned from ACQUIRED to RUNNING
2018-09-18 10:01:20,038 INFO SecurityLogger.org.apache.hadoop.ipc.Server: Auth successful for appattempt_1536878829533_0001_000001 (auth:SIMPLE)
2018-09-18 10:01:20,046 INFO org.apache.hadoop.yarn.server.resourcemanager.ApplicationMasterService: AM registration appattempt_1536878829533_0001_000001
2018-09-18 10:01:20,046 INFO org.apache.hadoop.yarn.server.resourcemanager.RMAuditLogger: USER=jason	IP=192.168.1.103	OPERATION=Register App Master	TARGET=ApplicationMasterService	RESULT=SUCCESS	APPID=application_1536878829533_0001	APPATTEMPTID=appattempt_1536878829533_0001_000001
2018-09-18 10:01:20,046 INFO org.apache.hadoop.yarn.server.resourcemanager.rmapp.attempt.RMAppAttemptImpl: appattempt_1536878829533_0001_000001 State change from LAUNCHED to RUNNING
2018-09-18 10:01:20,047 INFO org.apache.hadoop.yarn.server.resourcemanager.rmapp.RMAppImpl: application_1536878829533_0001 State change from ACCEPTED to RUNNING on event=ATTEMPT_REGISTERED
2018-09-18 10:01:21,909 INFO org.apache.hadoop.yarn.server.resourcemanager.rmcontainer.RMContainerImpl: container_1536878829533_0001_01_000002 Container Transitioned from NEW to ALLOCATED
2018-09-18 10:01:21,909 INFO org.apache.hadoop.yarn.server.resourcemanager.RMAuditLogger: USER=jason	OPERATION=AM Allocated Container	TARGET=SchedulerApp	RESULT=SUCCESS	APPID=application_1536878829533_0001	CONTAINERID=container_1536878829533_0001_01_000002
2018-09-18 10:01:21,909 INFO org.apache.hadoop.yarn.server.resourcemanager.scheduler.SchedulerNode: Assigned container container_1536878829533_0001_01_000002 of capacity <memory:1024, vCores:1> on host 192.168.1.103:56395, which has 2 containers, <memory:3072, vCores:2> used and <memory:5120, vCores:6> available after allocation
2018-09-18 10:01:21,909 INFO org.apache.hadoop.yarn.server.resourcemanager.scheduler.capacity.allocator.AbstractContainerAllocator: assignedContainer application attempt=appattempt_1536878829533_0001_000001 container=container_1536878829533_0001_01_000002 queue=org.apache.hadoop.yarn.server.resourcemanager.scheduler.capacity.allocator.RegularContainerAllocator@616798c1 clusterResource=<memory:8192, vCores:8> type=NODE_LOCAL
2018-09-18 10:01:21,909 INFO org.apache.hadoop.yarn.server.resourcemanager.scheduler.capacity.ParentQueue: Re-sorting assigned queue: root.default stats: default: capacity=1.0, absoluteCapacity=1.0, usedResources=<memory:3072, vCores:2>, usedCapacity=0.375, absoluteUsedCapacity=0.375, numApps=1, numContainers=2
2018-09-18 10:01:21,909 INFO org.apache.hadoop.yarn.server.resourcemanager.scheduler.capacity.ParentQueue: assignedContainer queue=root usedCapacity=0.375 absoluteUsedCapacity=0.375 used=<memory:3072, vCores:2> cluster=<memory:8192, vCores:8>
2018-09-18 10:01:22,122 INFO org.apache.hadoop.yarn.server.resourcemanager.security.NMTokenSecretManagerInRM: Sending NMToken for nodeId : 192.168.1.103:56395 for container : container_1536878829533_0001_01_000002
2018-09-18 10:01:22,123 INFO org.apache.hadoop.yarn.server.resourcemanager.rmcontainer.RMContainerImpl: container_1536878829533_0001_01_000002 Container Transitioned from ALLOCATED to ACQUIRED
2018-09-18 10:01:22,909 INFO org.apache.hadoop.yarn.server.resourcemanager.rmcontainer.RMContainerImpl: container_1536878829533_0001_01_000002 Container Transitioned from ACQUIRED to RUNNING
2018-09-18 10:01:23,142 INFO org.apache.hadoop.yarn.server.resourcemanager.scheduler.AppSchedulingInfo: checking for deactivate of application :application_1536878829533_0001
2018-09-18 10:01:24,603 INFO org.apache.hadoop.yarn.server.resourcemanager.rmcontainer.RMContainerImpl: container_1536878829533_0001_01_000002 Container Transitioned from RUNNING to COMPLETED
2018-09-18 10:01:24,603 INFO org.apache.hadoop.yarn.server.resourcemanager.RMAuditLogger: USER=jason	OPERATION=AM Released Container	TARGET=SchedulerApp	RESULT=SUCCESS	APPID=application_1536878829533_0001	CONTAINERID=container_1536878829533_0001_01_000002
2018-09-18 10:01:24,604 INFO org.apache.hadoop.yarn.server.resourcemanager.scheduler.SchedulerNode: Released container container_1536878829533_0001_01_000002 of capacity <memory:1024, vCores:1> on host 192.168.1.103:56395, which currently has 1 containers, <memory:2048, vCores:1> used and <memory:6144, vCores:7> available, release resources=true
2018-09-18 10:01:26,616 INFO org.apache.hadoop.yarn.server.resourcemanager.rmcontainer.RMContainerImpl: container_1536878829533_0001_01_000003 Container Transitioned from NEW to ALLOCATED
2018-09-18 10:01:26,616 INFO org.apache.hadoop.yarn.server.resourcemanager.RMAuditLogger: USER=jason	OPERATION=AM Allocated Container	TARGET=SchedulerApp	RESULT=SUCCESS	APPID=application_1536878829533_0001	CONTAINERID=container_1536878829533_0001_01_000003
2018-09-18 10:01:26,616 INFO org.apache.hadoop.yarn.server.resourcemanager.scheduler.SchedulerNode: Assigned container container_1536878829533_0001_01_000003 of capacity <memory:1024, vCores:1> on host 192.168.1.103:56395, which has 2 containers, <memory:3072, vCores:2> used and <memory:5120, vCores:6> available after allocation
2018-09-18 10:01:26,616 INFO org.apache.hadoop.yarn.server.resourcemanager.scheduler.capacity.allocator.AbstractContainerAllocator: assignedContainer application attempt=appattempt_1536878829533_0001_000001 container=container_1536878829533_0001_01_000003 queue=org.apache.hadoop.yarn.server.resourcemanager.scheduler.capacity.allocator.RegularContainerAllocator@616798c1 clusterResource=<memory:8192, vCores:8> type=OFF_SWITCH
2018-09-18 10:01:26,616 INFO org.apache.hadoop.yarn.server.resourcemanager.scheduler.capacity.ParentQueue: Re-sorting assigned queue: root.default stats: default: capacity=1.0, absoluteCapacity=1.0, usedResources=<memory:3072, vCores:2>, usedCapacity=0.375, absoluteUsedCapacity=0.375, numApps=1, numContainers=2
2018-09-18 10:01:26,616 INFO org.apache.hadoop.yarn.server.resourcemanager.scheduler.capacity.ParentQueue: assignedContainer queue=root usedCapacity=0.375 absoluteUsedCapacity=0.375 used=<memory:3072, vCores:2> cluster=<memory:8192, vCores:8>
2018-09-18 10:01:27,173 INFO org.apache.hadoop.yarn.server.resourcemanager.rmcontainer.RMContainerImpl: container_1536878829533_0001_01_000003 Container Transitioned from ALLOCATED to ACQUIRED
2018-09-18 10:01:27,622 INFO org.apache.hadoop.yarn.server.resourcemanager.rmcontainer.RMContainerImpl: container_1536878829533_0001_01_000003 Container Transitioned from ACQUIRED to RUNNING
2018-09-18 10:01:28,177 INFO org.apache.hadoop.yarn.server.resourcemanager.scheduler.AppSchedulingInfo: checking for deactivate of application :application_1536878829533_0001
2018-09-18 10:01:29,477 INFO org.apache.hadoop.yarn.server.resourcemanager.rmapp.attempt.RMAppAttemptImpl: Updating application attempt appattempt_1536878829533_0001_000001 with final state: FINISHING, and exit status: -1000
2018-09-18 10:01:29,478 INFO org.apache.hadoop.yarn.server.resourcemanager.rmapp.attempt.RMAppAttemptImpl: appattempt_1536878829533_0001_000001 State change from RUNNING to FINAL_SAVING
2018-09-18 10:01:29,478 INFO org.apache.hadoop.yarn.server.resourcemanager.rmapp.RMAppImpl: Updating application application_1536878829533_0001 with final state: FINISHING
2018-09-18 10:01:29,478 INFO org.apache.hadoop.yarn.server.resourcemanager.rmapp.RMAppImpl: application_1536878829533_0001 State change from RUNNING to FINAL_SAVING on event=ATTEMPT_UNREGISTERED
2018-09-18 10:01:29,478 INFO org.apache.hadoop.yarn.server.resourcemanager.recovery.RMStateStore: Updating info for app: application_1536878829533_0001
2018-09-18 10:01:29,478 INFO org.apache.hadoop.yarn.server.resourcemanager.rmapp.attempt.RMAppAttemptImpl: appattempt_1536878829533_0001_000001 State change from FINAL_SAVING to FINISHING
2018-09-18 10:01:29,478 INFO org.apache.hadoop.yarn.server.resourcemanager.rmapp.RMAppImpl: application_1536878829533_0001 State change from FINAL_SAVING to FINISHING on event=APP_UPDATE_SAVED
2018-09-18 10:01:29,488 INFO org.apache.hadoop.yarn.server.resourcemanager.rmcontainer.RMContainerImpl: container_1536878829533_0001_01_000003 Container Transitioned from RUNNING to COMPLETED
2018-09-18 10:01:29,488 INFO org.apache.hadoop.yarn.server.resourcemanager.RMAuditLogger: USER=jason	OPERATION=AM Released Container	TARGET=SchedulerApp	RESULT=SUCCESS	APPID=application_1536878829533_0001	CONTAINERID=container_1536878829533_0001_01_000003
2018-09-18 10:01:29,489 INFO org.apache.hadoop.yarn.server.resourcemanager.scheduler.SchedulerNode: Released container container_1536878829533_0001_01_000003 of capacity <memory:1024, vCores:1> on host 192.168.1.103:56395, which currently has 1 containers, <memory:2048, vCores:1> used and <memory:6144, vCores:7> available, release resources=true
2018-09-18 10:01:30,485 INFO org.apache.hadoop.yarn.server.resourcemanager.ApplicationMasterService: application_1536878829533_0001 unregistered successfully. 
2018-09-18 10:01:35,676 INFO org.apache.hadoop.yarn.server.resourcemanager.rmcontainer.RMContainerImpl: container_1536878829533_0001_01_000001 Container Transitioned from RUNNING to COMPLETED
2018-09-18 10:01:35,676 INFO org.apache.hadoop.yarn.server.resourcemanager.ApplicationMasterService: Unregistering app attempt : appattempt_1536878829533_0001_000001
2018-09-18 10:01:35,676 INFO org.apache.hadoop.yarn.server.resourcemanager.RMAuditLogger: USER=jason	OPERATION=AM Released Container	TARGET=SchedulerApp	RESULT=SUCCESS	APPID=application_1536878829533_0001	CONTAINERID=container_1536878829533_0001_01_000001
2018-09-18 10:01:35,677 INFO org.apache.hadoop.yarn.server.resourcemanager.scheduler.SchedulerNode: Released container container_1536878829533_0001_01_000001 of capacity <memory:2048, vCores:1> on host 192.168.1.103:56395, which currently has 0 containers, <memory:0, vCores:0> used and <memory:8192, vCores:8> available, release resources=true
2018-09-18 10:01:35,677 INFO org.apache.hadoop.yarn.server.resourcemanager.security.AMRMTokenSecretManager: Application finished, removing password for appattempt_1536878829533_0001_000001
2018-09-18 10:01:35,678 INFO org.apache.hadoop.yarn.server.resourcemanager.rmapp.attempt.RMAppAttemptImpl: appattempt_1536878829533_0001_000001 State change from FINISHING to FINISHED
2018-09-18 10:01:35,680 INFO org.apache.hadoop.yarn.server.resourcemanager.rmapp.RMAppImpl: application_1536878829533_0001 State change from FINISHING to FINISHED on event=ATTEMPT_FINISHED
2018-09-18 10:01:35,680 INFO org.apache.hadoop.yarn.server.resourcemanager.scheduler.capacity.CapacityScheduler: Application Attempt appattempt_1536878829533_0001_000001 is done. finalState=FINISHED
2018-09-18 10:01:35,681 INFO org.apache.hadoop.yarn.server.resourcemanager.scheduler.AppSchedulingInfo: Application application_1536878829533_0001 requests cleared
2018-09-18 10:01:35,681 INFO org.apache.hadoop.yarn.server.resourcemanager.amlauncher.AMLauncher: Cleaning master appattempt_1536878829533_0001_000001
2018-09-18 10:01:35,681 INFO org.apache.hadoop.yarn.server.resourcemanager.scheduler.capacity.LeafQueue: Application removed - appId: application_1536878829533_0001 user: jason queue: default #user-pending-applications: 0 #user-active-applications: 0 #queue-pending-applications: 0 #queue-active-applications: 0
2018-09-18 10:01:35,681 INFO org.apache.hadoop.yarn.server.resourcemanager.scheduler.capacity.ParentQueue: Application removed - appId: application_1536878829533_0001 user: jason leaf-queue of parent: root #applications: 0
2018-09-18 10:01:35,681 INFO org.apache.hadoop.yarn.server.resourcemanager.RMAuditLogger: USER=jason	OPERATION=Application Finished - Succeeded	TARGET=RMAppManager	RESULT=SUCCESS	APPID=application_1536878829533_0001
2018-09-18 10:01:35,684 INFO org.apache.hadoop.yarn.server.resourcemanager.RMAppManager$ApplicationSummary: appId=application_1536878829533_0001,name=word count,user=jason,queue=default,state=FINISHED,trackingUrl=http://Jasons-MacBook-Pro.local:8088/proxy/application_1536878829533_0001/,appMasterHost=192.168.1.103,startTime=1537282873821,finishTime=1537282889478,finalStatus=SUCCEEDED,memorySeconds=48216,vcoreSeconds=24,preemptedMemorySeconds=0,preemptedVcoreSeconds=0,preemptedAMContainers=0,preemptedNonAMContainers=0,preemptedResources=<memory:0\, vCores:0>,applicationType=MAPREDUCE
2018-09-18 10:01:37,691 INFO org.apache.hadoop.yarn.server.resourcemanager.scheduler.AbstractYarnScheduler: Container container_1536878829533_0001_01_000003 completed with event FINISHED, but corresponding RMContainer doesn't exist.
2018-09-18 20:05:53,448 INFO org.apache.hadoop.security.token.delegation.AbstractDelegationTokenSecretManager: Updating the current master key for generating delegation tokens
2018-09-18 20:05:54,060 WARN org.apache.hadoop.util.JvmPauseMonitor: Detected pause in JVM or host machine (eg GC): pause of approximately 24928ms
No GCs detected
2018-09-18 20:05:53,448 INFO org.apache.hadoop.security.token.delegation.AbstractDelegationTokenSecretManager: Updating the current master key for generating delegation tokens
2018-09-18 20:05:54,091 INFO org.apache.hadoop.yarn.server.resourcemanager.security.RMDelegationTokenSecretManager: storing master key with keyID 7
2018-09-18 20:05:54,096 INFO org.apache.hadoop.yarn.server.resourcemanager.recovery.RMStateStore: Storing RMDTMasterKey.
2018-09-18 20:06:21,104 INFO org.apache.hadoop.yarn.server.resourcemanager.ClientRMService: Allocated new applicationId: 4
2018-09-18 20:06:22,791 INFO org.apache.hadoop.yarn.server.resourcemanager.scheduler.capacity.CapacityScheduler: Application 'application_1536878829533_0004' is submitted without priority hence considering default queue/cluster priority: 0
2018-09-18 20:06:22,791 INFO org.apache.hadoop.yarn.server.resourcemanager.scheduler.capacity.CapacityScheduler: Priority '0' is acceptable in queue : default for application: application_1536878829533_0004 for the user: jason
2018-09-18 20:06:22,795 INFO org.apache.hadoop.yarn.server.resourcemanager.ClientRMService: Application with id 4 submitted by user jason
2018-09-18 20:06:22,796 INFO org.apache.hadoop.yarn.server.resourcemanager.rmapp.RMAppImpl: Storing application with id application_1536878829533_0004
2018-09-18 20:06:22,796 INFO org.apache.hadoop.yarn.server.resourcemanager.RMAuditLogger: USER=jason	IP=192.168.1.103	OPERATION=Submit Application Request	TARGET=ClientRMService	RESULT=SUCCESS	APPID=application_1536878829533_0004
2018-09-18 20:06:22,796 INFO org.apache.hadoop.yarn.server.resourcemanager.recovery.RMStateStore: Storing info for app: application_1536878829533_0004
2018-09-18 20:06:22,797 INFO org.apache.hadoop.yarn.server.resourcemanager.rmapp.RMAppImpl: application_1536878829533_0004 State change from NEW to NEW_SAVING on event=START
2018-09-18 20:06:22,798 INFO org.apache.hadoop.yarn.server.resourcemanager.rmapp.RMAppImpl: application_1536878829533_0004 State change from NEW_SAVING to SUBMITTED on event=APP_NEW_SAVED
2018-09-18 20:06:22,798 INFO org.apache.hadoop.yarn.server.resourcemanager.scheduler.capacity.ParentQueue: Application added - appId: application_1536878829533_0004 user: jason leaf-queue of parent: root #applications: 1
2018-09-18 20:06:22,798 INFO org.apache.hadoop.yarn.server.resourcemanager.scheduler.capacity.CapacityScheduler: Accepted application application_1536878829533_0004 from user: jason, in queue: default
2018-09-18 20:06:22,805 INFO org.apache.hadoop.yarn.server.resourcemanager.rmapp.RMAppImpl: application_1536878829533_0004 State change from SUBMITTED to ACCEPTED on event=APP_ACCEPTED
2018-09-18 20:06:22,821 INFO org.apache.hadoop.yarn.server.resourcemanager.ApplicationMasterService: Registering app attempt : appattempt_1536878829533_0004_000001
2018-09-18 20:06:22,821 INFO org.apache.hadoop.yarn.server.resourcemanager.rmapp.attempt.RMAppAttemptImpl: appattempt_1536878829533_0004_000001 State change from NEW to SUBMITTED
2018-09-18 20:06:22,823 WARN org.apache.hadoop.yarn.server.resourcemanager.scheduler.capacity.LeafQueue: maximum-am-resource-percent is insufficient to start a single application in queue, it is likely set too low. skipping enforcement to allow at least one application to start
2018-09-18 20:06:22,823 WARN org.apache.hadoop.yarn.server.resourcemanager.scheduler.capacity.LeafQueue: maximum-am-resource-percent is insufficient to start a single application in queue for user, it is likely set too low. skipping enforcement to allow at least one application to start
2018-09-18 20:06:22,825 INFO org.apache.hadoop.yarn.server.resourcemanager.scheduler.capacity.LeafQueue: Application application_1536878829533_0004 from user: jason activated in queue: default
2018-09-18 20:06:22,825 INFO org.apache.hadoop.yarn.server.resourcemanager.scheduler.capacity.LeafQueue: Application added - appId: application_1536878829533_0004 user: jason, leaf-queue: default #user-pending-applications: 0 #user-active-applications: 1 #queue-pending-applications: 0 #queue-active-applications: 1
2018-09-18 20:06:22,825 INFO org.apache.hadoop.yarn.server.resourcemanager.scheduler.capacity.CapacityScheduler: Added Application Attempt appattempt_1536878829533_0004_000001 to scheduler from user jason in queue default
2018-09-18 20:06:22,826 INFO org.apache.hadoop.yarn.server.resourcemanager.rmapp.attempt.RMAppAttemptImpl: appattempt_1536878829533_0004_000001 State change from SUBMITTED to SCHEDULED
2018-09-18 20:06:26,573 INFO org.apache.hadoop.yarn.server.resourcemanager.rmcontainer.RMContainerImpl: container_1536878829533_0004_01_000001 Container Transitioned from NEW to ALLOCATED
2018-09-18 20:06:26,573 INFO org.apache.hadoop.yarn.server.resourcemanager.RMAuditLogger: USER=jason	OPERATION=AM Allocated Container	TARGET=SchedulerApp	RESULT=SUCCESS	APPID=application_1536878829533_0004	CONTAINERID=container_1536878829533_0004_01_000001
2018-09-18 20:06:26,573 INFO org.apache.hadoop.yarn.server.resourcemanager.scheduler.SchedulerNode: Assigned container container_1536878829533_0004_01_000001 of capacity <memory:2048, vCores:1> on host 192.168.1.103:56395, which has 1 containers, <memory:2048, vCores:1> used and <memory:6144, vCores:7> available after allocation
2018-09-18 20:06:26,574 INFO org.apache.hadoop.yarn.server.resourcemanager.scheduler.capacity.allocator.AbstractContainerAllocator: assignedContainer application attempt=appattempt_1536878829533_0004_000001 container=container_1536878829533_0004_01_000001 queue=org.apache.hadoop.yarn.server.resourcemanager.scheduler.capacity.allocator.RegularContainerAllocator@23986f8e clusterResource=<memory:8192, vCores:8> type=OFF_SWITCH
2018-09-18 20:06:26,580 INFO org.apache.hadoop.yarn.server.resourcemanager.security.NMTokenSecretManagerInRM: Sending NMToken for nodeId : 192.168.1.103:56395 for container : container_1536878829533_0004_01_000001
2018-09-18 20:06:26,583 INFO org.apache.hadoop.yarn.server.resourcemanager.rmcontainer.RMContainerImpl: container_1536878829533_0004_01_000001 Container Transitioned from ALLOCATED to ACQUIRED
2018-09-18 20:06:26,583 INFO org.apache.hadoop.yarn.server.resourcemanager.security.NMTokenSecretManagerInRM: Clear node set for appattempt_1536878829533_0004_000001
2018-09-18 20:06:26,583 INFO org.apache.hadoop.yarn.server.resourcemanager.rmapp.attempt.RMAppAttemptImpl: Storing attempt: AppId: application_1536878829533_0004 AttemptId: appattempt_1536878829533_0004_000001 MasterContainer: Container: [ContainerId: container_1536878829533_0004_01_000001, Version: 0, NodeId: 192.168.1.103:56395, NodeHttpAddress: 192.168.1.103:8042, Resource: <memory:2048, vCores:1>, Priority: 0, Token: Token { kind: ContainerToken, service: 192.168.1.103:56395 }, ]
2018-09-18 20:06:26,583 INFO org.apache.hadoop.yarn.server.resourcemanager.scheduler.capacity.ParentQueue: Re-sorting assigned queue: root.default stats: default: capacity=1.0, absoluteCapacity=1.0, usedResources=<memory:2048, vCores:1>, usedCapacity=0.25, absoluteUsedCapacity=0.25, numApps=1, numContainers=1
2018-09-18 20:06:26,584 INFO org.apache.hadoop.yarn.server.resourcemanager.rmapp.attempt.RMAppAttemptImpl: appattempt_1536878829533_0004_000001 State change from SCHEDULED to ALLOCATED_SAVING
2018-09-18 20:06:26,584 INFO org.apache.hadoop.yarn.server.resourcemanager.scheduler.capacity.ParentQueue: assignedContainer queue=root usedCapacity=0.25 absoluteUsedCapacity=0.25 used=<memory:2048, vCores:1> cluster=<memory:8192, vCores:8>
2018-09-18 20:06:26,585 INFO org.apache.hadoop.yarn.server.resourcemanager.rmapp.attempt.RMAppAttemptImpl: appattempt_1536878829533_0004_000001 State change from ALLOCATED_SAVING to ALLOCATED
2018-09-18 20:06:26,587 INFO org.apache.hadoop.yarn.server.resourcemanager.amlauncher.AMLauncher: Launching masterappattempt_1536878829533_0004_000001
2018-09-18 20:06:26,608 INFO org.apache.hadoop.yarn.server.resourcemanager.amlauncher.AMLauncher: Setting up container Container: [ContainerId: container_1536878829533_0004_01_000001, Version: 0, NodeId: 192.168.1.103:56395, NodeHttpAddress: 192.168.1.103:8042, Resource: <memory:2048, vCores:1>, Priority: 0, Token: Token { kind: ContainerToken, service: 192.168.1.103:56395 }, ] for AM appattempt_1536878829533_0004_000001
2018-09-18 20:06:26,608 INFO org.apache.hadoop.yarn.server.resourcemanager.security.AMRMTokenSecretManager: Create AMRMToken for ApplicationAttempt: appattempt_1536878829533_0004_000001
2018-09-18 20:06:26,608 INFO org.apache.hadoop.yarn.server.resourcemanager.security.AMRMTokenSecretManager: Creating password for appattempt_1536878829533_0004_000001
2018-09-18 20:06:26,695 INFO org.apache.hadoop.yarn.server.resourcemanager.amlauncher.AMLauncher: Done launching container Container: [ContainerId: container_1536878829533_0004_01_000001, Version: 0, NodeId: 192.168.1.103:56395, NodeHttpAddress: 192.168.1.103:8042, Resource: <memory:2048, vCores:1>, Priority: 0, Token: Token { kind: ContainerToken, service: 192.168.1.103:56395 }, ] for AM appattempt_1536878829533_0004_000001
2018-09-18 20:06:26,696 INFO org.apache.hadoop.yarn.server.resourcemanager.rmapp.attempt.RMAppAttemptImpl: appattempt_1536878829533_0004_000001 State change from ALLOCATED to LAUNCHED
2018-09-18 20:06:27,581 INFO org.apache.hadoop.yarn.server.resourcemanager.rmcontainer.RMContainerImpl: container_1536878829533_0004_01_000001 Container Transitioned from ACQUIRED to RUNNING
2018-09-18 20:06:30,890 INFO SecurityLogger.org.apache.hadoop.ipc.Server: Auth successful for appattempt_1536878829533_0004_000001 (auth:SIMPLE)
2018-09-18 20:06:30,895 INFO org.apache.hadoop.yarn.server.resourcemanager.ApplicationMasterService: AM registration appattempt_1536878829533_0004_000001
2018-09-18 20:06:30,895 INFO org.apache.hadoop.yarn.server.resourcemanager.rmapp.attempt.RMAppAttemptImpl: appattempt_1536878829533_0004_000001 State change from LAUNCHED to RUNNING
2018-09-18 20:06:30,895 INFO org.apache.hadoop.yarn.server.resourcemanager.rmapp.RMAppImpl: application_1536878829533_0004 State change from ACCEPTED to RUNNING on event=ATTEMPT_REGISTERED
2018-09-18 20:06:30,896 INFO org.apache.hadoop.yarn.server.resourcemanager.RMAuditLogger: USER=jason	IP=192.168.1.103	OPERATION=Register App Master	TARGET=ApplicationMasterService	RESULT=SUCCESS	APPID=application_1536878829533_0004	APPATTEMPTID=appattempt_1536878829533_0004_000001
2018-09-18 20:06:32,605 INFO org.apache.hadoop.yarn.server.resourcemanager.rmcontainer.RMContainerImpl: container_1536878829533_0004_01_000002 Container Transitioned from NEW to ALLOCATED
2018-09-18 20:06:32,605 INFO org.apache.hadoop.yarn.server.resourcemanager.RMAuditLogger: USER=jason	OPERATION=AM Allocated Container	TARGET=SchedulerApp	RESULT=SUCCESS	APPID=application_1536878829533_0004	CONTAINERID=container_1536878829533_0004_01_000002
2018-09-18 20:06:32,605 INFO org.apache.hadoop.yarn.server.resourcemanager.scheduler.SchedulerNode: Assigned container container_1536878829533_0004_01_000002 of capacity <memory:1024, vCores:1> on host 192.168.1.103:56395, which has 2 containers, <memory:3072, vCores:2> used and <memory:5120, vCores:6> available after allocation
2018-09-18 20:06:32,605 INFO org.apache.hadoop.yarn.server.resourcemanager.scheduler.capacity.allocator.AbstractContainerAllocator: assignedContainer application attempt=appattempt_1536878829533_0004_000001 container=container_1536878829533_0004_01_000002 queue=org.apache.hadoop.yarn.server.resourcemanager.scheduler.capacity.allocator.RegularContainerAllocator@23986f8e clusterResource=<memory:8192, vCores:8> type=NODE_LOCAL
2018-09-18 20:06:32,605 INFO org.apache.hadoop.yarn.server.resourcemanager.scheduler.capacity.ParentQueue: Re-sorting assigned queue: root.default stats: default: capacity=1.0, absoluteCapacity=1.0, usedResources=<memory:3072, vCores:2>, usedCapacity=0.375, absoluteUsedCapacity=0.375, numApps=1, numContainers=2
2018-09-18 20:06:32,605 INFO org.apache.hadoop.yarn.server.resourcemanager.scheduler.capacity.ParentQueue: assignedContainer queue=root usedCapacity=0.375 absoluteUsedCapacity=0.375 used=<memory:3072, vCores:2> cluster=<memory:8192, vCores:8>
2018-09-18 20:06:32,970 INFO org.apache.hadoop.yarn.server.resourcemanager.security.NMTokenSecretManagerInRM: Sending NMToken for nodeId : 192.168.1.103:56395 for container : container_1536878829533_0004_01_000002
2018-09-18 20:06:32,971 INFO org.apache.hadoop.yarn.server.resourcemanager.rmcontainer.RMContainerImpl: container_1536878829533_0004_01_000002 Container Transitioned from ALLOCATED to ACQUIRED
2018-09-18 20:06:33,607 INFO org.apache.hadoop.yarn.server.resourcemanager.rmcontainer.RMContainerImpl: container_1536878829533_0004_01_000002 Container Transitioned from ACQUIRED to RUNNING
2018-09-18 20:06:33,996 INFO org.apache.hadoop.yarn.server.resourcemanager.scheduler.AppSchedulingInfo: checking for deactivate of application :application_1536878829533_0004
2018-09-18 20:06:35,491 INFO org.apache.hadoop.yarn.server.resourcemanager.rmcontainer.RMContainerImpl: container_1536878829533_0004_01_000002 Container Transitioned from RUNNING to COMPLETED
2018-09-18 20:06:35,491 INFO org.apache.hadoop.yarn.server.resourcemanager.RMAuditLogger: USER=jason	OPERATION=AM Released Container	TARGET=SchedulerApp	RESULT=SUCCESS	APPID=application_1536878829533_0004	CONTAINERID=container_1536878829533_0004_01_000002
2018-09-18 20:06:35,492 INFO org.apache.hadoop.yarn.server.resourcemanager.scheduler.SchedulerNode: Released container container_1536878829533_0004_01_000002 of capacity <memory:1024, vCores:1> on host 192.168.1.103:56395, which currently has 1 containers, <memory:2048, vCores:1> used and <memory:6144, vCores:7> available, release resources=true
2018-09-18 20:06:37,511 INFO org.apache.hadoop.yarn.server.resourcemanager.rmcontainer.RMContainerImpl: container_1536878829533_0004_01_000003 Container Transitioned from NEW to ALLOCATED
2018-09-18 20:06:37,511 INFO org.apache.hadoop.yarn.server.resourcemanager.RMAuditLogger: USER=jason	OPERATION=AM Allocated Container	TARGET=SchedulerApp	RESULT=SUCCESS	APPID=application_1536878829533_0004	CONTAINERID=container_1536878829533_0004_01_000003
2018-09-18 20:06:37,512 INFO org.apache.hadoop.yarn.server.resourcemanager.scheduler.SchedulerNode: Assigned container container_1536878829533_0004_01_000003 of capacity <memory:1024, vCores:1> on host 192.168.1.103:56395, which has 2 containers, <memory:3072, vCores:2> used and <memory:5120, vCores:6> available after allocation
2018-09-18 20:06:37,512 INFO org.apache.hadoop.yarn.server.resourcemanager.scheduler.capacity.allocator.AbstractContainerAllocator: assignedContainer application attempt=appattempt_1536878829533_0004_000001 container=container_1536878829533_0004_01_000003 queue=org.apache.hadoop.yarn.server.resourcemanager.scheduler.capacity.allocator.RegularContainerAllocator@23986f8e clusterResource=<memory:8192, vCores:8> type=OFF_SWITCH
2018-09-18 20:06:37,512 INFO org.apache.hadoop.yarn.server.resourcemanager.scheduler.capacity.ParentQueue: Re-sorting assigned queue: root.default stats: default: capacity=1.0, absoluteCapacity=1.0, usedResources=<memory:3072, vCores:2>, usedCapacity=0.375, absoluteUsedCapacity=0.375, numApps=1, numContainers=2
2018-09-18 20:06:37,512 INFO org.apache.hadoop.yarn.server.resourcemanager.scheduler.capacity.ParentQueue: assignedContainer queue=root usedCapacity=0.375 absoluteUsedCapacity=0.375 used=<memory:3072, vCores:2> cluster=<memory:8192, vCores:8>
2018-09-18 20:06:38,040 INFO org.apache.hadoop.yarn.server.resourcemanager.rmcontainer.RMContainerImpl: container_1536878829533_0004_01_000003 Container Transitioned from ALLOCATED to ACQUIRED
2018-09-18 20:06:38,522 INFO org.apache.hadoop.yarn.server.resourcemanager.rmcontainer.RMContainerImpl: container_1536878829533_0004_01_000003 Container Transitioned from ACQUIRED to RUNNING
2018-09-18 20:06:39,044 INFO org.apache.hadoop.yarn.server.resourcemanager.scheduler.AppSchedulingInfo: checking for deactivate of application :application_1536878829533_0004
2018-09-18 20:06:40,286 INFO org.apache.hadoop.yarn.server.resourcemanager.rmcontainer.RMContainerImpl: container_1536878829533_0004_01_000003 Container Transitioned from RUNNING to COMPLETED
2018-09-18 20:06:40,286 INFO org.apache.hadoop.yarn.server.resourcemanager.RMAuditLogger: USER=jason	OPERATION=AM Released Container	TARGET=SchedulerApp	RESULT=SUCCESS	APPID=application_1536878829533_0004	CONTAINERID=container_1536878829533_0004_01_000003
2018-09-18 20:06:40,286 INFO org.apache.hadoop.yarn.server.resourcemanager.scheduler.SchedulerNode: Released container container_1536878829533_0004_01_000003 of capacity <memory:1024, vCores:1> on host 192.168.1.103:56395, which currently has 1 containers, <memory:2048, vCores:1> used and <memory:6144, vCores:7> available, release resources=true
2018-09-18 20:06:40,602 INFO org.apache.hadoop.yarn.server.resourcemanager.rmapp.attempt.RMAppAttemptImpl: Updating application attempt appattempt_1536878829533_0004_000001 with final state: FINISHING, and exit status: -1000
2018-09-18 20:06:40,602 INFO org.apache.hadoop.yarn.server.resourcemanager.rmapp.attempt.RMAppAttemptImpl: appattempt_1536878829533_0004_000001 State change from RUNNING to FINAL_SAVING
2018-09-18 20:06:40,603 INFO org.apache.hadoop.yarn.server.resourcemanager.rmapp.RMAppImpl: Updating application application_1536878829533_0004 with final state: FINISHING
2018-09-18 20:06:40,603 INFO org.apache.hadoop.yarn.server.resourcemanager.rmapp.RMAppImpl: application_1536878829533_0004 State change from RUNNING to FINAL_SAVING on event=ATTEMPT_UNREGISTERED
2018-09-18 20:06:40,603 INFO org.apache.hadoop.yarn.server.resourcemanager.rmapp.attempt.RMAppAttemptImpl: appattempt_1536878829533_0004_000001 State change from FINAL_SAVING to FINISHING
2018-09-18 20:06:40,603 INFO org.apache.hadoop.yarn.server.resourcemanager.recovery.RMStateStore: Updating info for app: application_1536878829533_0004
2018-09-18 20:06:40,603 INFO org.apache.hadoop.yarn.server.resourcemanager.rmapp.RMAppImpl: application_1536878829533_0004 State change from FINAL_SAVING to FINISHING on event=APP_UPDATE_SAVED
2018-09-18 20:06:41,603 INFO org.apache.hadoop.yarn.server.resourcemanager.ApplicationMasterService: application_1536878829533_0004 unregistered successfully. 
2018-09-18 20:06:46,790 INFO org.apache.hadoop.yarn.server.resourcemanager.rmcontainer.RMContainerImpl: container_1536878829533_0004_01_000001 Container Transitioned from RUNNING to COMPLETED
2018-09-18 20:06:46,790 INFO org.apache.hadoop.yarn.server.resourcemanager.RMAuditLogger: USER=jason	OPERATION=AM Released Container	TARGET=SchedulerApp	RESULT=SUCCESS	APPID=application_1536878829533_0004	CONTAINERID=container_1536878829533_0004_01_000001
2018-09-18 20:06:46,790 INFO org.apache.hadoop.yarn.server.resourcemanager.ApplicationMasterService: Unregistering app attempt : appattempt_1536878829533_0004_000001
2018-09-18 20:06:46,790 INFO org.apache.hadoop.yarn.server.resourcemanager.security.AMRMTokenSecretManager: Application finished, removing password for appattempt_1536878829533_0004_000001
2018-09-18 20:06:46,791 INFO org.apache.hadoop.yarn.server.resourcemanager.rmapp.attempt.RMAppAttemptImpl: appattempt_1536878829533_0004_000001 State change from FINISHING to FINISHED
2018-09-18 20:06:46,791 INFO org.apache.hadoop.yarn.server.resourcemanager.rmapp.RMAppImpl: application_1536878829533_0004 State change from FINISHING to FINISHED on event=ATTEMPT_FINISHED
2018-09-18 20:06:46,791 INFO org.apache.hadoop.yarn.server.resourcemanager.scheduler.SchedulerNode: Released container container_1536878829533_0004_01_000001 of capacity <memory:2048, vCores:1> on host 192.168.1.103:56395, which currently has 0 containers, <memory:0, vCores:0> used and <memory:8192, vCores:8> available, release resources=true
2018-09-18 20:06:46,791 INFO org.apache.hadoop.yarn.server.resourcemanager.scheduler.capacity.CapacityScheduler: Application Attempt appattempt_1536878829533_0004_000001 is done. finalState=FINISHED
2018-09-18 20:06:46,791 INFO org.apache.hadoop.yarn.server.resourcemanager.RMAuditLogger: USER=jason	OPERATION=Application Finished - Succeeded	TARGET=RMAppManager	RESULT=SUCCESS	APPID=application_1536878829533_0004
2018-09-18 20:06:46,792 INFO org.apache.hadoop.yarn.server.resourcemanager.scheduler.AppSchedulingInfo: Application application_1536878829533_0004 requests cleared
2018-09-18 20:06:46,792 INFO org.apache.hadoop.yarn.server.resourcemanager.amlauncher.AMLauncher: Cleaning master appattempt_1536878829533_0004_000001
2018-09-18 20:06:46,792 INFO org.apache.hadoop.yarn.server.resourcemanager.scheduler.capacity.LeafQueue: Application removed - appId: application_1536878829533_0004 user: jason queue: default #user-pending-applications: 0 #user-active-applications: 0 #queue-pending-applications: 0 #queue-active-applications: 0
2018-09-18 20:06:46,792 INFO org.apache.hadoop.yarn.server.resourcemanager.scheduler.capacity.ParentQueue: Application removed - appId: application_1536878829533_0004 user: jason leaf-queue of parent: root #applications: 0
2018-09-18 20:06:46,793 INFO org.apache.hadoop.yarn.server.resourcemanager.RMAppManager$ApplicationSummary: appId=application_1536878829533_0004,name=word count,user=jason,queue=default,state=FINISHED,trackingUrl=http://Jasons-MacBook-Pro.local:8088/proxy/application_1536878829533_0004/,appMasterHost=192.168.1.103,startTime=1537319182792,finishTime=1537319200602,finalStatus=SUCCEEDED,memorySeconds=47203,vcoreSeconds=24,preemptedMemorySeconds=0,preemptedVcoreSeconds=0,preemptedAMContainers=0,preemptedNonAMContainers=0,preemptedResources=<memory:0\, vCores:0>,applicationType=MAPREDUCE
2018-09-18 20:06:48,797 INFO org.apache.hadoop.yarn.server.resourcemanager.scheduler.AbstractYarnScheduler: Container container_1536878829533_0004_01_000003 completed with event FINISHED, but corresponding RMContainer doesn't exist.
2018-09-19 11:51:35,511 INFO org.apache.hadoop.yarn.server.resourcemanager.ClientRMService: Allocated new applicationId: 5
2018-09-19 11:51:36,021 INFO org.apache.hadoop.yarn.server.resourcemanager.scheduler.capacity.CapacityScheduler: Application 'application_1536878829533_0005' is submitted without priority hence considering default queue/cluster priority: 0
2018-09-19 11:51:36,021 INFO org.apache.hadoop.yarn.server.resourcemanager.scheduler.capacity.CapacityScheduler: Priority '0' is acceptable in queue : default for application: application_1536878829533_0005 for the user: jason
2018-09-19 11:51:36,022 INFO org.apache.hadoop.yarn.server.resourcemanager.ClientRMService: Application with id 5 submitted by user jason
2018-09-19 11:51:36,022 INFO org.apache.hadoop.yarn.server.resourcemanager.RMAuditLogger: USER=jason	IP=192.168.1.103	OPERATION=Submit Application Request	TARGET=ClientRMService	RESULT=SUCCESS	APPID=application_1536878829533_0005
2018-09-19 11:51:36,022 INFO org.apache.hadoop.yarn.server.resourcemanager.rmapp.RMAppImpl: Storing application with id application_1536878829533_0005
2018-09-19 11:51:36,022 INFO org.apache.hadoop.yarn.server.resourcemanager.rmapp.RMAppImpl: application_1536878829533_0005 State change from NEW to NEW_SAVING on event=START
2018-09-19 11:51:36,022 INFO org.apache.hadoop.yarn.server.resourcemanager.recovery.RMStateStore: Storing info for app: application_1536878829533_0005
2018-09-19 11:51:36,022 INFO org.apache.hadoop.yarn.server.resourcemanager.rmapp.RMAppImpl: application_1536878829533_0005 State change from NEW_SAVING to SUBMITTED on event=APP_NEW_SAVED
2018-09-19 11:51:36,022 INFO org.apache.hadoop.yarn.server.resourcemanager.scheduler.capacity.ParentQueue: Application added - appId: application_1536878829533_0005 user: jason leaf-queue of parent: root #applications: 1
2018-09-19 11:51:36,022 INFO org.apache.hadoop.yarn.server.resourcemanager.scheduler.capacity.CapacityScheduler: Accepted application application_1536878829533_0005 from user: jason, in queue: default
2018-09-19 11:51:36,023 INFO org.apache.hadoop.yarn.server.resourcemanager.rmapp.RMAppImpl: application_1536878829533_0005 State change from SUBMITTED to ACCEPTED on event=APP_ACCEPTED
2018-09-19 11:51:36,024 INFO org.apache.hadoop.yarn.server.resourcemanager.ApplicationMasterService: Registering app attempt : appattempt_1536878829533_0005_000001
2018-09-19 11:51:36,024 INFO org.apache.hadoop.yarn.server.resourcemanager.rmapp.attempt.RMAppAttemptImpl: appattempt_1536878829533_0005_000001 State change from NEW to SUBMITTED
2018-09-19 11:51:36,024 WARN org.apache.hadoop.yarn.server.resourcemanager.scheduler.capacity.LeafQueue: maximum-am-resource-percent is insufficient to start a single application in queue, it is likely set too low. skipping enforcement to allow at least one application to start
2018-09-19 11:51:36,024 WARN org.apache.hadoop.yarn.server.resourcemanager.scheduler.capacity.LeafQueue: maximum-am-resource-percent is insufficient to start a single application in queue for user, it is likely set too low. skipping enforcement to allow at least one application to start
2018-09-19 11:51:36,024 INFO org.apache.hadoop.yarn.server.resourcemanager.scheduler.capacity.LeafQueue: Application application_1536878829533_0005 from user: jason activated in queue: default
2018-09-19 11:51:36,024 INFO org.apache.hadoop.yarn.server.resourcemanager.scheduler.capacity.LeafQueue: Application added - appId: application_1536878829533_0005 user: jason, leaf-queue: default #user-pending-applications: 0 #user-active-applications: 1 #queue-pending-applications: 0 #queue-active-applications: 1
2018-09-19 11:51:36,024 INFO org.apache.hadoop.yarn.server.resourcemanager.scheduler.capacity.CapacityScheduler: Added Application Attempt appattempt_1536878829533_0005_000001 to scheduler from user jason in queue default
2018-09-19 11:51:36,025 INFO org.apache.hadoop.yarn.server.resourcemanager.rmapp.attempt.RMAppAttemptImpl: appattempt_1536878829533_0005_000001 State change from SUBMITTED to SCHEDULED
2018-09-19 11:51:36,148 INFO org.apache.hadoop.yarn.server.resourcemanager.rmcontainer.RMContainerImpl: container_1536878829533_0005_01_000001 Container Transitioned from NEW to ALLOCATED
2018-09-19 11:51:36,148 INFO org.apache.hadoop.yarn.server.resourcemanager.RMAuditLogger: USER=jason	OPERATION=AM Allocated Container	TARGET=SchedulerApp	RESULT=SUCCESS	APPID=application_1536878829533_0005	CONTAINERID=container_1536878829533_0005_01_000001
2018-09-19 11:51:36,148 INFO org.apache.hadoop.yarn.server.resourcemanager.scheduler.SchedulerNode: Assigned container container_1536878829533_0005_01_000001 of capacity <memory:2048, vCores:1> on host 192.168.1.103:56395, which has 1 containers, <memory:2048, vCores:1> used and <memory:6144, vCores:7> available after allocation
2018-09-19 11:51:36,148 INFO org.apache.hadoop.yarn.server.resourcemanager.scheduler.capacity.allocator.AbstractContainerAllocator: assignedContainer application attempt=appattempt_1536878829533_0005_000001 container=container_1536878829533_0005_01_000001 queue=org.apache.hadoop.yarn.server.resourcemanager.scheduler.capacity.allocator.RegularContainerAllocator@66312ccb clusterResource=<memory:8192, vCores:8> type=OFF_SWITCH
2018-09-19 11:51:36,149 INFO org.apache.hadoop.yarn.server.resourcemanager.security.NMTokenSecretManagerInRM: Sending NMToken for nodeId : 192.168.1.103:56395 for container : container_1536878829533_0005_01_000001
2018-09-19 11:51:36,150 INFO org.apache.hadoop.yarn.server.resourcemanager.rmcontainer.RMContainerImpl: container_1536878829533_0005_01_000001 Container Transitioned from ALLOCATED to ACQUIRED
2018-09-19 11:51:36,150 INFO org.apache.hadoop.yarn.server.resourcemanager.security.NMTokenSecretManagerInRM: Clear node set for appattempt_1536878829533_0005_000001
2018-09-19 11:51:36,150 INFO org.apache.hadoop.yarn.server.resourcemanager.rmapp.attempt.RMAppAttemptImpl: Storing attempt: AppId: application_1536878829533_0005 AttemptId: appattempt_1536878829533_0005_000001 MasterContainer: Container: [ContainerId: container_1536878829533_0005_01_000001, Version: 0, NodeId: 192.168.1.103:56395, NodeHttpAddress: 192.168.1.103:8042, Resource: <memory:2048, vCores:1>, Priority: 0, Token: Token { kind: ContainerToken, service: 192.168.1.103:56395 }, ]
2018-09-19 11:51:36,150 INFO org.apache.hadoop.yarn.server.resourcemanager.scheduler.capacity.ParentQueue: Re-sorting assigned queue: root.default stats: default: capacity=1.0, absoluteCapacity=1.0, usedResources=<memory:2048, vCores:1>, usedCapacity=0.25, absoluteUsedCapacity=0.25, numApps=1, numContainers=1
2018-09-19 11:51:36,150 INFO org.apache.hadoop.yarn.server.resourcemanager.rmapp.attempt.RMAppAttemptImpl: appattempt_1536878829533_0005_000001 State change from SCHEDULED to ALLOCATED_SAVING
2018-09-19 11:51:36,150 INFO org.apache.hadoop.yarn.server.resourcemanager.scheduler.capacity.ParentQueue: assignedContainer queue=root usedCapacity=0.25 absoluteUsedCapacity=0.25 used=<memory:2048, vCores:1> cluster=<memory:8192, vCores:8>
2018-09-19 11:51:36,150 INFO org.apache.hadoop.yarn.server.resourcemanager.rmapp.attempt.RMAppAttemptImpl: appattempt_1536878829533_0005_000001 State change from ALLOCATED_SAVING to ALLOCATED
2018-09-19 11:51:36,150 INFO org.apache.hadoop.yarn.server.resourcemanager.amlauncher.AMLauncher: Launching masterappattempt_1536878829533_0005_000001
2018-09-19 11:51:36,163 INFO org.apache.hadoop.yarn.server.resourcemanager.amlauncher.AMLauncher: Setting up container Container: [ContainerId: container_1536878829533_0005_01_000001, Version: 0, NodeId: 192.168.1.103:56395, NodeHttpAddress: 192.168.1.103:8042, Resource: <memory:2048, vCores:1>, Priority: 0, Token: Token { kind: ContainerToken, service: 192.168.1.103:56395 }, ] for AM appattempt_1536878829533_0005_000001
2018-09-19 11:51:36,163 INFO org.apache.hadoop.yarn.server.resourcemanager.security.AMRMTokenSecretManager: Create AMRMToken for ApplicationAttempt: appattempt_1536878829533_0005_000001
2018-09-19 11:51:36,163 INFO org.apache.hadoop.yarn.server.resourcemanager.security.AMRMTokenSecretManager: Creating password for appattempt_1536878829533_0005_000001
2018-09-19 11:51:36,175 INFO org.apache.hadoop.yarn.server.resourcemanager.amlauncher.AMLauncher: Done launching container Container: [ContainerId: container_1536878829533_0005_01_000001, Version: 0, NodeId: 192.168.1.103:56395, NodeHttpAddress: 192.168.1.103:8042, Resource: <memory:2048, vCores:1>, Priority: 0, Token: Token { kind: ContainerToken, service: 192.168.1.103:56395 }, ] for AM appattempt_1536878829533_0005_000001
2018-09-19 11:51:36,175 INFO org.apache.hadoop.yarn.server.resourcemanager.rmapp.attempt.RMAppAttemptImpl: appattempt_1536878829533_0005_000001 State change from ALLOCATED to LAUNCHED
2018-09-19 11:51:37,151 INFO org.apache.hadoop.yarn.server.resourcemanager.rmcontainer.RMContainerImpl: container_1536878829533_0005_01_000001 Container Transitioned from ACQUIRED to RUNNING
2018-09-19 11:51:39,711 INFO SecurityLogger.org.apache.hadoop.ipc.Server: Auth successful for appattempt_1536878829533_0005_000001 (auth:SIMPLE)
2018-09-19 11:51:39,716 INFO org.apache.hadoop.yarn.server.resourcemanager.ApplicationMasterService: AM registration appattempt_1536878829533_0005_000001
2018-09-19 11:51:39,716 INFO org.apache.hadoop.yarn.server.resourcemanager.RMAuditLogger: USER=jason	IP=192.168.1.103	OPERATION=Register App Master	TARGET=ApplicationMasterService	RESULT=SUCCESS	APPID=application_1536878829533_0005	APPATTEMPTID=appattempt_1536878829533_0005_000001
2018-09-19 11:51:39,716 INFO org.apache.hadoop.yarn.server.resourcemanager.rmapp.attempt.RMAppAttemptImpl: appattempt_1536878829533_0005_000001 State change from LAUNCHED to RUNNING
2018-09-19 11:51:39,716 INFO org.apache.hadoop.yarn.server.resourcemanager.rmapp.RMAppImpl: application_1536878829533_0005 State change from ACCEPTED to RUNNING on event=ATTEMPT_REGISTERED
2018-09-19 11:51:41,164 INFO org.apache.hadoop.yarn.server.resourcemanager.rmcontainer.RMContainerImpl: container_1536878829533_0005_01_000002 Container Transitioned from NEW to ALLOCATED
2018-09-19 11:51:41,164 INFO org.apache.hadoop.yarn.server.resourcemanager.RMAuditLogger: USER=jason	OPERATION=AM Allocated Container	TARGET=SchedulerApp	RESULT=SUCCESS	APPID=application_1536878829533_0005	CONTAINERID=container_1536878829533_0005_01_000002
2018-09-19 11:51:41,164 INFO org.apache.hadoop.yarn.server.resourcemanager.scheduler.SchedulerNode: Assigned container container_1536878829533_0005_01_000002 of capacity <memory:1024, vCores:1> on host 192.168.1.103:56395, which has 2 containers, <memory:3072, vCores:2> used and <memory:5120, vCores:6> available after allocation
2018-09-19 11:51:41,164 INFO org.apache.hadoop.yarn.server.resourcemanager.scheduler.capacity.allocator.AbstractContainerAllocator: assignedContainer application attempt=appattempt_1536878829533_0005_000001 container=container_1536878829533_0005_01_000002 queue=org.apache.hadoop.yarn.server.resourcemanager.scheduler.capacity.allocator.RegularContainerAllocator@66312ccb clusterResource=<memory:8192, vCores:8> type=NODE_LOCAL
2018-09-19 11:51:41,165 INFO org.apache.hadoop.yarn.server.resourcemanager.scheduler.capacity.ParentQueue: Re-sorting assigned queue: root.default stats: default: capacity=1.0, absoluteCapacity=1.0, usedResources=<memory:3072, vCores:2>, usedCapacity=0.375, absoluteUsedCapacity=0.375, numApps=1, numContainers=2
2018-09-19 11:51:41,165 INFO org.apache.hadoop.yarn.server.resourcemanager.scheduler.capacity.ParentQueue: assignedContainer queue=root usedCapacity=0.375 absoluteUsedCapacity=0.375 used=<memory:3072, vCores:2> cluster=<memory:8192, vCores:8>
2018-09-19 11:51:41,165 INFO org.apache.hadoop.yarn.server.resourcemanager.rmcontainer.RMContainerImpl: container_1536878829533_0005_01_000003 Container Transitioned from NEW to ALLOCATED
2018-09-19 11:51:41,165 INFO org.apache.hadoop.yarn.server.resourcemanager.RMAuditLogger: USER=jason	OPERATION=AM Allocated Container	TARGET=SchedulerApp	RESULT=SUCCESS	APPID=application_1536878829533_0005	CONTAINERID=container_1536878829533_0005_01_000003
2018-09-19 11:51:41,165 INFO org.apache.hadoop.yarn.server.resourcemanager.scheduler.SchedulerNode: Assigned container container_1536878829533_0005_01_000003 of capacity <memory:1024, vCores:1> on host 192.168.1.103:56395, which has 3 containers, <memory:4096, vCores:3> used and <memory:4096, vCores:5> available after allocation
2018-09-19 11:51:41,165 INFO org.apache.hadoop.yarn.server.resourcemanager.scheduler.capacity.allocator.AbstractContainerAllocator: assignedContainer application attempt=appattempt_1536878829533_0005_000001 container=container_1536878829533_0005_01_000003 queue=org.apache.hadoop.yarn.server.resourcemanager.scheduler.capacity.allocator.RegularContainerAllocator@66312ccb clusterResource=<memory:8192, vCores:8> type=NODE_LOCAL
2018-09-19 11:51:41,165 INFO org.apache.hadoop.yarn.server.resourcemanager.scheduler.capacity.ParentQueue: Re-sorting assigned queue: root.default stats: default: capacity=1.0, absoluteCapacity=1.0, usedResources=<memory:4096, vCores:3>, usedCapacity=0.5, absoluteUsedCapacity=0.5, numApps=1, numContainers=3
2018-09-19 11:51:41,165 INFO org.apache.hadoop.yarn.server.resourcemanager.scheduler.capacity.ParentQueue: assignedContainer queue=root usedCapacity=0.5 absoluteUsedCapacity=0.5 used=<memory:4096, vCores:3> cluster=<memory:8192, vCores:8>
2018-09-19 11:51:41,165 INFO org.apache.hadoop.yarn.server.resourcemanager.rmcontainer.RMContainerImpl: container_1536878829533_0005_01_000004 Container Transitioned from NEW to ALLOCATED
2018-09-19 11:51:41,166 INFO org.apache.hadoop.yarn.server.resourcemanager.RMAuditLogger: USER=jason	OPERATION=AM Allocated Container	TARGET=SchedulerApp	RESULT=SUCCESS	APPID=application_1536878829533_0005	CONTAINERID=container_1536878829533_0005_01_000004
2018-09-19 11:51:41,166 INFO org.apache.hadoop.yarn.server.resourcemanager.scheduler.SchedulerNode: Assigned container container_1536878829533_0005_01_000004 of capacity <memory:1024, vCores:1> on host 192.168.1.103:56395, which has 4 containers, <memory:5120, vCores:4> used and <memory:3072, vCores:4> available after allocation
2018-09-19 11:51:41,166 INFO org.apache.hadoop.yarn.server.resourcemanager.scheduler.capacity.allocator.AbstractContainerAllocator: assignedContainer application attempt=appattempt_1536878829533_0005_000001 container=container_1536878829533_0005_01_000004 queue=org.apache.hadoop.yarn.server.resourcemanager.scheduler.capacity.allocator.RegularContainerAllocator@66312ccb clusterResource=<memory:8192, vCores:8> type=NODE_LOCAL
2018-09-19 11:51:41,166 INFO org.apache.hadoop.yarn.server.resourcemanager.scheduler.capacity.ParentQueue: Re-sorting assigned queue: root.default stats: default: capacity=1.0, absoluteCapacity=1.0, usedResources=<memory:5120, vCores:4>, usedCapacity=0.625, absoluteUsedCapacity=0.625, numApps=1, numContainers=4
2018-09-19 11:51:41,166 INFO org.apache.hadoop.yarn.server.resourcemanager.scheduler.capacity.ParentQueue: assignedContainer queue=root usedCapacity=0.625 absoluteUsedCapacity=0.625 used=<memory:5120, vCores:4> cluster=<memory:8192, vCores:8>
2018-09-19 11:51:41,172 INFO org.apache.hadoop.yarn.server.resourcemanager.rmcontainer.RMContainerImpl: container_1536878829533_0005_01_000005 Container Transitioned from NEW to ALLOCATED
2018-09-19 11:51:41,172 INFO org.apache.hadoop.yarn.server.resourcemanager.RMAuditLogger: USER=jason	OPERATION=AM Allocated Container	TARGET=SchedulerApp	RESULT=SUCCESS	APPID=application_1536878829533_0005	CONTAINERID=container_1536878829533_0005_01_000005
2018-09-19 11:51:41,172 INFO org.apache.hadoop.yarn.server.resourcemanager.scheduler.SchedulerNode: Assigned container container_1536878829533_0005_01_000005 of capacity <memory:1024, vCores:1> on host 192.168.1.103:56395, which has 5 containers, <memory:6144, vCores:5> used and <memory:2048, vCores:3> available after allocation
2018-09-19 11:51:41,173 INFO org.apache.hadoop.yarn.server.resourcemanager.scheduler.capacity.allocator.AbstractContainerAllocator: assignedContainer application attempt=appattempt_1536878829533_0005_000001 container=container_1536878829533_0005_01_000005 queue=org.apache.hadoop.yarn.server.resourcemanager.scheduler.capacity.allocator.RegularContainerAllocator@66312ccb clusterResource=<memory:8192, vCores:8> type=NODE_LOCAL
2018-09-19 11:51:41,173 INFO org.apache.hadoop.yarn.server.resourcemanager.scheduler.capacity.ParentQueue: Re-sorting assigned queue: root.default stats: default: capacity=1.0, absoluteCapacity=1.0, usedResources=<memory:6144, vCores:5>, usedCapacity=0.75, absoluteUsedCapacity=0.75, numApps=1, numContainers=5
2018-09-19 11:51:41,173 INFO org.apache.hadoop.yarn.server.resourcemanager.scheduler.capacity.ParentQueue: assignedContainer queue=root usedCapacity=0.75 absoluteUsedCapacity=0.75 used=<memory:6144, vCores:5> cluster=<memory:8192, vCores:8>
2018-09-19 11:51:41,174 INFO org.apache.hadoop.yarn.server.resourcemanager.rmcontainer.RMContainerImpl: container_1536878829533_0005_01_000006 Container Transitioned from NEW to ALLOCATED
2018-09-19 11:51:41,174 INFO org.apache.hadoop.yarn.server.resourcemanager.RMAuditLogger: USER=jason	OPERATION=AM Allocated Container	TARGET=SchedulerApp	RESULT=SUCCESS	APPID=application_1536878829533_0005	CONTAINERID=container_1536878829533_0005_01_000006
2018-09-19 11:51:41,174 INFO org.apache.hadoop.yarn.server.resourcemanager.scheduler.SchedulerNode: Assigned container container_1536878829533_0005_01_000006 of capacity <memory:1024, vCores:1> on host 192.168.1.103:56395, which has 6 containers, <memory:7168, vCores:6> used and <memory:1024, vCores:2> available after allocation
2018-09-19 11:51:41,174 INFO org.apache.hadoop.yarn.server.resourcemanager.scheduler.capacity.allocator.AbstractContainerAllocator: assignedContainer application attempt=appattempt_1536878829533_0005_000001 container=container_1536878829533_0005_01_000006 queue=org.apache.hadoop.yarn.server.resourcemanager.scheduler.capacity.allocator.RegularContainerAllocator@66312ccb clusterResource=<memory:8192, vCores:8> type=NODE_LOCAL
2018-09-19 11:51:41,174 INFO org.apache.hadoop.yarn.server.resourcemanager.scheduler.capacity.ParentQueue: Re-sorting assigned queue: root.default stats: default: capacity=1.0, absoluteCapacity=1.0, usedResources=<memory:7168, vCores:6>, usedCapacity=0.875, absoluteUsedCapacity=0.875, numApps=1, numContainers=6
2018-09-19 11:51:41,174 INFO org.apache.hadoop.yarn.server.resourcemanager.scheduler.capacity.ParentQueue: assignedContainer queue=root usedCapacity=0.875 absoluteUsedCapacity=0.875 used=<memory:7168, vCores:6> cluster=<memory:8192, vCores:8>
2018-09-19 11:51:41,175 INFO org.apache.hadoop.yarn.server.resourcemanager.rmcontainer.RMContainerImpl: container_1536878829533_0005_01_000007 Container Transitioned from NEW to ALLOCATED
2018-09-19 11:51:41,175 INFO org.apache.hadoop.yarn.server.resourcemanager.RMAuditLogger: USER=jason	OPERATION=AM Allocated Container	TARGET=SchedulerApp	RESULT=SUCCESS	APPID=application_1536878829533_0005	CONTAINERID=container_1536878829533_0005_01_000007
2018-09-19 11:51:41,175 INFO org.apache.hadoop.yarn.server.resourcemanager.scheduler.SchedulerNode: Assigned container container_1536878829533_0005_01_000007 of capacity <memory:1024, vCores:1> on host 192.168.1.103:56395, which has 7 containers, <memory:8192, vCores:7> used and <memory:0, vCores:1> available after allocation
2018-09-19 11:51:41,175 INFO org.apache.hadoop.yarn.server.resourcemanager.scheduler.capacity.allocator.AbstractContainerAllocator: assignedContainer application attempt=appattempt_1536878829533_0005_000001 container=container_1536878829533_0005_01_000007 queue=org.apache.hadoop.yarn.server.resourcemanager.scheduler.capacity.allocator.RegularContainerAllocator@66312ccb clusterResource=<memory:8192, vCores:8> type=NODE_LOCAL
2018-09-19 11:51:41,176 INFO org.apache.hadoop.yarn.server.resourcemanager.scheduler.capacity.ParentQueue: Re-sorting assigned queue: root.default stats: default: capacity=1.0, absoluteCapacity=1.0, usedResources=<memory:8192, vCores:7>, usedCapacity=1.0, absoluteUsedCapacity=1.0, numApps=1, numContainers=7
2018-09-19 11:51:41,176 INFO org.apache.hadoop.yarn.server.resourcemanager.scheduler.capacity.ParentQueue: assignedContainer queue=root usedCapacity=1.0 absoluteUsedCapacity=1.0 used=<memory:8192, vCores:7> cluster=<memory:8192, vCores:8>
2018-09-19 11:51:41,772 INFO org.apache.hadoop.yarn.server.resourcemanager.security.NMTokenSecretManagerInRM: Sending NMToken for nodeId : 192.168.1.103:56395 for container : container_1536878829533_0005_01_000002
2018-09-19 11:51:41,773 INFO org.apache.hadoop.yarn.server.resourcemanager.rmcontainer.RMContainerImpl: container_1536878829533_0005_01_000002 Container Transitioned from ALLOCATED to ACQUIRED
2018-09-19 11:51:41,774 INFO org.apache.hadoop.yarn.server.resourcemanager.rmcontainer.RMContainerImpl: container_1536878829533_0005_01_000003 Container Transitioned from ALLOCATED to ACQUIRED
2018-09-19 11:51:41,775 INFO org.apache.hadoop.yarn.server.resourcemanager.rmcontainer.RMContainerImpl: container_1536878829533_0005_01_000004 Container Transitioned from ALLOCATED to ACQUIRED
2018-09-19 11:51:41,776 INFO org.apache.hadoop.yarn.server.resourcemanager.rmcontainer.RMContainerImpl: container_1536878829533_0005_01_000005 Container Transitioned from ALLOCATED to ACQUIRED
2018-09-19 11:51:41,777 INFO org.apache.hadoop.yarn.server.resourcemanager.rmcontainer.RMContainerImpl: container_1536878829533_0005_01_000006 Container Transitioned from ALLOCATED to ACQUIRED
2018-09-19 11:51:41,778 INFO org.apache.hadoop.yarn.server.resourcemanager.rmcontainer.RMContainerImpl: container_1536878829533_0005_01_000007 Container Transitioned from ALLOCATED to ACQUIRED
2018-09-19 11:51:42,168 INFO org.apache.hadoop.yarn.server.resourcemanager.rmcontainer.RMContainerImpl: container_1536878829533_0005_01_000002 Container Transitioned from ACQUIRED to RUNNING
2018-09-19 11:51:42,169 INFO org.apache.hadoop.yarn.server.resourcemanager.rmcontainer.RMContainerImpl: container_1536878829533_0005_01_000003 Container Transitioned from ACQUIRED to RUNNING
2018-09-19 11:51:42,170 INFO org.apache.hadoop.yarn.server.resourcemanager.rmcontainer.RMContainerImpl: container_1536878829533_0005_01_000004 Container Transitioned from ACQUIRED to RUNNING
2018-09-19 11:51:42,170 INFO org.apache.hadoop.yarn.server.resourcemanager.rmcontainer.RMContainerImpl: container_1536878829533_0005_01_000005 Container Transitioned from ACQUIRED to RUNNING
2018-09-19 11:51:42,172 INFO org.apache.hadoop.yarn.server.resourcemanager.rmcontainer.RMContainerImpl: container_1536878829533_0005_01_000006 Container Transitioned from ACQUIRED to RUNNING
2018-09-19 11:51:42,172 INFO org.apache.hadoop.yarn.server.resourcemanager.rmcontainer.RMContainerImpl: container_1536878829533_0005_01_000007 Container Transitioned from ACQUIRED to RUNNING
2018-09-19 11:51:48,188 INFO org.apache.hadoop.yarn.server.resourcemanager.rmcontainer.RMContainerImpl: container_1536878829533_0005_01_000002 Container Transitioned from RUNNING to COMPLETED
2018-09-19 11:51:48,188 INFO org.apache.hadoop.yarn.server.resourcemanager.RMAuditLogger: USER=jason	OPERATION=AM Released Container	TARGET=SchedulerApp	RESULT=SUCCESS	APPID=application_1536878829533_0005	CONTAINERID=container_1536878829533_0005_01_000002
2018-09-19 11:51:48,188 INFO org.apache.hadoop.yarn.server.resourcemanager.scheduler.SchedulerNode: Released container container_1536878829533_0005_01_000002 of capacity <memory:1024, vCores:1> on host 192.168.1.103:56395, which currently has 6 containers, <memory:7168, vCores:6> used and <memory:1024, vCores:2> available, release resources=true
2018-09-19 11:51:48,189 INFO org.apache.hadoop.yarn.server.resourcemanager.rmcontainer.RMContainerImpl: container_1536878829533_0005_01_000008 Container Transitioned from NEW to ALLOCATED
2018-09-19 11:51:48,189 INFO org.apache.hadoop.yarn.server.resourcemanager.RMAuditLogger: USER=jason	OPERATION=AM Allocated Container	TARGET=SchedulerApp	RESULT=SUCCESS	APPID=application_1536878829533_0005	CONTAINERID=container_1536878829533_0005_01_000008
2018-09-19 11:51:48,189 INFO org.apache.hadoop.yarn.server.resourcemanager.scheduler.SchedulerNode: Assigned container container_1536878829533_0005_01_000008 of capacity <memory:1024, vCores:1> on host 192.168.1.103:56395, which has 7 containers, <memory:8192, vCores:7> used and <memory:0, vCores:1> available after allocation
2018-09-19 11:51:48,189 INFO org.apache.hadoop.yarn.server.resourcemanager.scheduler.capacity.allocator.AbstractContainerAllocator: assignedContainer application attempt=appattempt_1536878829533_0005_000001 container=container_1536878829533_0005_01_000008 queue=org.apache.hadoop.yarn.server.resourcemanager.scheduler.capacity.allocator.RegularContainerAllocator@66312ccb clusterResource=<memory:8192, vCores:8> type=NODE_LOCAL
2018-09-19 11:51:48,189 INFO org.apache.hadoop.yarn.server.resourcemanager.scheduler.capacity.ParentQueue: Re-sorting assigned queue: root.default stats: default: capacity=1.0, absoluteCapacity=1.0, usedResources=<memory:8192, vCores:7>, usedCapacity=1.0, absoluteUsedCapacity=1.0, numApps=1, numContainers=7
2018-09-19 11:51:48,189 INFO org.apache.hadoop.yarn.server.resourcemanager.scheduler.capacity.ParentQueue: assignedContainer queue=root usedCapacity=1.0 absoluteUsedCapacity=1.0 used=<memory:8192, vCores:7> cluster=<memory:8192, vCores:8>
2018-09-19 11:51:48,273 INFO org.apache.hadoop.yarn.server.resourcemanager.rmcontainer.RMContainerImpl: container_1536878829533_0005_01_000007 Container Transitioned from RUNNING to COMPLETED
2018-09-19 11:51:48,273 INFO org.apache.hadoop.yarn.server.resourcemanager.RMAuditLogger: USER=jason	OPERATION=AM Released Container	TARGET=SchedulerApp	RESULT=SUCCESS	APPID=application_1536878829533_0005	CONTAINERID=container_1536878829533_0005_01_000007
2018-09-19 11:51:48,274 INFO org.apache.hadoop.yarn.server.resourcemanager.scheduler.SchedulerNode: Released container container_1536878829533_0005_01_000007 of capacity <memory:1024, vCores:1> on host 192.168.1.103:56395, which currently has 6 containers, <memory:7168, vCores:6> used and <memory:1024, vCores:2> available, release resources=true
2018-09-19 11:51:48,275 INFO org.apache.hadoop.yarn.server.resourcemanager.rmcontainer.RMContainerImpl: container_1536878829533_0005_01_000009 Container Transitioned from NEW to ALLOCATED
2018-09-19 11:51:48,275 INFO org.apache.hadoop.yarn.server.resourcemanager.RMAuditLogger: USER=jason	OPERATION=AM Allocated Container	TARGET=SchedulerApp	RESULT=SUCCESS	APPID=application_1536878829533_0005	CONTAINERID=container_1536878829533_0005_01_000009
2018-09-19 11:51:48,275 INFO org.apache.hadoop.yarn.server.resourcemanager.scheduler.SchedulerNode: Assigned container container_1536878829533_0005_01_000009 of capacity <memory:1024, vCores:1> on host 192.168.1.103:56395, which has 7 containers, <memory:8192, vCores:7> used and <memory:0, vCores:1> available after allocation
2018-09-19 11:51:48,275 INFO org.apache.hadoop.yarn.server.resourcemanager.scheduler.capacity.allocator.AbstractContainerAllocator: assignedContainer application attempt=appattempt_1536878829533_0005_000001 container=container_1536878829533_0005_01_000009 queue=org.apache.hadoop.yarn.server.resourcemanager.scheduler.capacity.allocator.RegularContainerAllocator@66312ccb clusterResource=<memory:8192, vCores:8> type=NODE_LOCAL
2018-09-19 11:51:48,275 INFO org.apache.hadoop.yarn.server.resourcemanager.scheduler.capacity.ParentQueue: Re-sorting assigned queue: root.default stats: default: capacity=1.0, absoluteCapacity=1.0, usedResources=<memory:8192, vCores:7>, usedCapacity=1.0, absoluteUsedCapacity=1.0, numApps=1, numContainers=7
2018-09-19 11:51:48,275 INFO org.apache.hadoop.yarn.server.resourcemanager.scheduler.capacity.ParentQueue: assignedContainer queue=root usedCapacity=1.0 absoluteUsedCapacity=1.0 used=<memory:8192, vCores:7> cluster=<memory:8192, vCores:8>
2018-09-19 11:51:48,364 INFO org.apache.hadoop.yarn.server.resourcemanager.rmcontainer.RMContainerImpl: container_1536878829533_0005_01_000006 Container Transitioned from RUNNING to COMPLETED
2018-09-19 11:51:48,364 INFO org.apache.hadoop.yarn.server.resourcemanager.RMAuditLogger: USER=jason	OPERATION=AM Released Container	TARGET=SchedulerApp	RESULT=SUCCESS	APPID=application_1536878829533_0005	CONTAINERID=container_1536878829533_0005_01_000006
2018-09-19 11:51:48,364 INFO org.apache.hadoop.yarn.server.resourcemanager.scheduler.SchedulerNode: Released container container_1536878829533_0005_01_000006 of capacity <memory:1024, vCores:1> on host 192.168.1.103:56395, which currently has 6 containers, <memory:7168, vCores:6> used and <memory:1024, vCores:2> available, release resources=true
2018-09-19 11:51:48,365 INFO org.apache.hadoop.yarn.server.resourcemanager.rmcontainer.RMContainerImpl: container_1536878829533_0005_01_000005 Container Transitioned from RUNNING to COMPLETED
2018-09-19 11:51:48,365 INFO org.apache.hadoop.yarn.server.resourcemanager.RMAuditLogger: USER=jason	OPERATION=AM Released Container	TARGET=SchedulerApp	RESULT=SUCCESS	APPID=application_1536878829533_0005	CONTAINERID=container_1536878829533_0005_01_000005
2018-09-19 11:51:48,365 INFO org.apache.hadoop.yarn.server.resourcemanager.scheduler.SchedulerNode: Released container container_1536878829533_0005_01_000005 of capacity <memory:1024, vCores:1> on host 192.168.1.103:56395, which currently has 5 containers, <memory:6144, vCores:5> used and <memory:2048, vCores:3> available, release resources=true
2018-09-19 11:51:48,365 INFO org.apache.hadoop.yarn.server.resourcemanager.rmcontainer.RMContainerImpl: container_1536878829533_0005_01_000004 Container Transitioned from RUNNING to COMPLETED
2018-09-19 11:51:48,365 INFO org.apache.hadoop.yarn.server.resourcemanager.RMAuditLogger: USER=jason	OPERATION=AM Released Container	TARGET=SchedulerApp	RESULT=SUCCESS	APPID=application_1536878829533_0005	CONTAINERID=container_1536878829533_0005_01_000004
2018-09-19 11:51:48,365 INFO org.apache.hadoop.yarn.server.resourcemanager.scheduler.SchedulerNode: Released container container_1536878829533_0005_01_000004 of capacity <memory:1024, vCores:1> on host 192.168.1.103:56395, which currently has 4 containers, <memory:5120, vCores:4> used and <memory:3072, vCores:4> available, release resources=true
2018-09-19 11:51:48,833 INFO org.apache.hadoop.yarn.server.resourcemanager.rmcontainer.RMContainerImpl: container_1536878829533_0005_01_000008 Container Transitioned from ALLOCATED to ACQUIRED
2018-09-19 11:51:48,834 INFO org.apache.hadoop.yarn.server.resourcemanager.rmcontainer.RMContainerImpl: container_1536878829533_0005_01_000009 Container Transitioned from ALLOCATED to ACQUIRED
2018-09-19 11:51:49,369 INFO org.apache.hadoop.yarn.server.resourcemanager.rmcontainer.RMContainerImpl: container_1536878829533_0005_01_000008 Container Transitioned from ACQUIRED to RUNNING
2018-09-19 11:51:49,369 INFO org.apache.hadoop.yarn.server.resourcemanager.rmcontainer.RMContainerImpl: container_1536878829533_0005_01_000009 Container Transitioned from ACQUIRED to RUNNING
2018-09-19 11:51:49,370 INFO org.apache.hadoop.yarn.server.resourcemanager.rmcontainer.RMContainerImpl: container_1536878829533_0005_01_000003 Container Transitioned from RUNNING to COMPLETED
2018-09-19 11:51:49,370 INFO org.apache.hadoop.yarn.server.resourcemanager.RMAuditLogger: USER=jason	OPERATION=AM Released Container	TARGET=SchedulerApp	RESULT=SUCCESS	APPID=application_1536878829533_0005	CONTAINERID=container_1536878829533_0005_01_000003
2018-09-19 11:51:49,370 INFO org.apache.hadoop.yarn.server.resourcemanager.scheduler.SchedulerNode: Released container container_1536878829533_0005_01_000003 of capacity <memory:1024, vCores:1> on host 192.168.1.103:56395, which currently has 3 containers, <memory:4096, vCores:3> used and <memory:4096, vCores:5> available, release resources=true
2018-09-19 11:51:49,845 INFO org.apache.hadoop.yarn.server.resourcemanager.scheduler.AppSchedulingInfo: checking for deactivate of application :application_1536878829533_0005
2018-09-19 11:51:50,373 INFO org.apache.hadoop.yarn.server.resourcemanager.rmcontainer.RMContainerImpl: container_1536878829533_0005_01_000010 Container Transitioned from NEW to ALLOCATED
2018-09-19 11:51:50,373 INFO org.apache.hadoop.yarn.server.resourcemanager.RMAuditLogger: USER=jason	OPERATION=AM Allocated Container	TARGET=SchedulerApp	RESULT=SUCCESS	APPID=application_1536878829533_0005	CONTAINERID=container_1536878829533_0005_01_000010
2018-09-19 11:51:50,373 INFO org.apache.hadoop.yarn.server.resourcemanager.scheduler.SchedulerNode: Assigned container container_1536878829533_0005_01_000010 of capacity <memory:1024, vCores:1> on host 192.168.1.103:56395, which has 4 containers, <memory:5120, vCores:4> used and <memory:3072, vCores:4> available after allocation
2018-09-19 11:51:50,373 INFO org.apache.hadoop.yarn.server.resourcemanager.scheduler.capacity.allocator.AbstractContainerAllocator: assignedContainer application attempt=appattempt_1536878829533_0005_000001 container=container_1536878829533_0005_01_000010 queue=org.apache.hadoop.yarn.server.resourcemanager.scheduler.capacity.allocator.RegularContainerAllocator@66312ccb clusterResource=<memory:8192, vCores:8> type=OFF_SWITCH
2018-09-19 11:51:50,373 INFO org.apache.hadoop.yarn.server.resourcemanager.scheduler.capacity.ParentQueue: Re-sorting assigned queue: root.default stats: default: capacity=1.0, absoluteCapacity=1.0, usedResources=<memory:5120, vCores:4>, usedCapacity=0.625, absoluteUsedCapacity=0.625, numApps=1, numContainers=4
2018-09-19 11:51:50,373 INFO org.apache.hadoop.yarn.server.resourcemanager.scheduler.capacity.ParentQueue: assignedContainer queue=root usedCapacity=0.625 absoluteUsedCapacity=0.625 used=<memory:5120, vCores:4> cluster=<memory:8192, vCores:8>
2018-09-19 11:51:50,852 INFO org.apache.hadoop.yarn.server.resourcemanager.rmcontainer.RMContainerImpl: container_1536878829533_0005_01_000010 Container Transitioned from ALLOCATED to ACQUIRED
2018-09-19 11:51:51,375 INFO org.apache.hadoop.yarn.server.resourcemanager.rmcontainer.RMContainerImpl: container_1536878829533_0005_01_000010 Container Transitioned from ACQUIRED to RUNNING
2018-09-19 11:51:51,530 INFO org.apache.hadoop.yarn.server.resourcemanager.rmcontainer.RMContainerImpl: container_1536878829533_0005_01_000008 Container Transitioned from RUNNING to COMPLETED
2018-09-19 11:51:51,530 INFO org.apache.hadoop.yarn.server.resourcemanager.RMAuditLogger: USER=jason	OPERATION=AM Released Container	TARGET=SchedulerApp	RESULT=SUCCESS	APPID=application_1536878829533_0005	CONTAINERID=container_1536878829533_0005_01_000008
2018-09-19 11:51:51,530 INFO org.apache.hadoop.yarn.server.resourcemanager.scheduler.SchedulerNode: Released container container_1536878829533_0005_01_000008 of capacity <memory:1024, vCores:1> on host 192.168.1.103:56395, which currently has 3 containers, <memory:4096, vCores:3> used and <memory:4096, vCores:5> available, release resources=true
2018-09-19 11:51:51,577 INFO org.apache.hadoop.yarn.server.resourcemanager.rmcontainer.RMContainerImpl: container_1536878829533_0005_01_000009 Container Transitioned from RUNNING to COMPLETED
2018-09-19 11:51:51,577 INFO org.apache.hadoop.yarn.server.resourcemanager.RMAuditLogger: USER=jason	OPERATION=AM Released Container	TARGET=SchedulerApp	RESULT=SUCCESS	APPID=application_1536878829533_0005	CONTAINERID=container_1536878829533_0005_01_000009
2018-09-19 11:51:51,577 INFO org.apache.hadoop.yarn.server.resourcemanager.scheduler.SchedulerNode: Released container container_1536878829533_0005_01_000009 of capacity <memory:1024, vCores:1> on host 192.168.1.103:56395, which currently has 2 containers, <memory:3072, vCores:2> used and <memory:5120, vCores:6> available, release resources=true
2018-09-19 11:51:51,854 INFO org.apache.hadoop.yarn.server.resourcemanager.scheduler.AppSchedulingInfo: checking for deactivate of application :application_1536878829533_0005
2018-09-19 11:51:53,312 INFO org.apache.hadoop.yarn.server.resourcemanager.rmcontainer.RMContainerImpl: container_1536878829533_0005_01_000010 Container Transitioned from RUNNING to COMPLETED
2018-09-19 11:51:53,312 INFO org.apache.hadoop.yarn.server.resourcemanager.RMAuditLogger: USER=jason	OPERATION=AM Released Container	TARGET=SchedulerApp	RESULT=SUCCESS	APPID=application_1536878829533_0005	CONTAINERID=container_1536878829533_0005_01_000010
2018-09-19 11:51:53,312 INFO org.apache.hadoop.yarn.server.resourcemanager.scheduler.SchedulerNode: Released container container_1536878829533_0005_01_000010 of capacity <memory:1024, vCores:1> on host 192.168.1.103:56395, which currently has 1 containers, <memory:2048, vCores:1> used and <memory:6144, vCores:7> available, release resources=true
2018-09-19 11:51:53,575 INFO org.apache.hadoop.yarn.server.resourcemanager.rmapp.attempt.RMAppAttemptImpl: Updating application attempt appattempt_1536878829533_0005_000001 with final state: FINISHING, and exit status: -1000
2018-09-19 11:51:53,575 INFO org.apache.hadoop.yarn.server.resourcemanager.rmapp.attempt.RMAppAttemptImpl: appattempt_1536878829533_0005_000001 State change from RUNNING to FINAL_SAVING
2018-09-19 11:51:53,575 INFO org.apache.hadoop.yarn.server.resourcemanager.rmapp.RMAppImpl: Updating application application_1536878829533_0005 with final state: FINISHING
2018-09-19 11:51:53,575 INFO org.apache.hadoop.yarn.server.resourcemanager.rmapp.RMAppImpl: application_1536878829533_0005 State change from RUNNING to FINAL_SAVING on event=ATTEMPT_UNREGISTERED
2018-09-19 11:51:53,575 INFO org.apache.hadoop.yarn.server.resourcemanager.recovery.RMStateStore: Updating info for app: application_1536878829533_0005
2018-09-19 11:51:53,575 INFO org.apache.hadoop.yarn.server.resourcemanager.rmapp.attempt.RMAppAttemptImpl: appattempt_1536878829533_0005_000001 State change from FINAL_SAVING to FINISHING
2018-09-19 11:51:53,575 INFO org.apache.hadoop.yarn.server.resourcemanager.rmapp.RMAppImpl: application_1536878829533_0005 State change from FINAL_SAVING to FINISHING on event=APP_UPDATE_SAVED
2018-09-19 11:51:54,577 INFO org.apache.hadoop.yarn.server.resourcemanager.ApplicationMasterService: application_1536878829533_0005 unregistered successfully. 
2018-09-19 11:51:59,760 INFO org.apache.hadoop.yarn.server.resourcemanager.rmcontainer.RMContainerImpl: container_1536878829533_0005_01_000001 Container Transitioned from RUNNING to COMPLETED
2018-09-19 11:51:59,760 INFO org.apache.hadoop.yarn.server.resourcemanager.ApplicationMasterService: Unregistering app attempt : appattempt_1536878829533_0005_000001
2018-09-19 11:51:59,760 INFO org.apache.hadoop.yarn.server.resourcemanager.RMAuditLogger: USER=jason	OPERATION=AM Released Container	TARGET=SchedulerApp	RESULT=SUCCESS	APPID=application_1536878829533_0005	CONTAINERID=container_1536878829533_0005_01_000001
2018-09-19 11:51:59,760 INFO org.apache.hadoop.yarn.server.resourcemanager.security.AMRMTokenSecretManager: Application finished, removing password for appattempt_1536878829533_0005_000001
2018-09-19 11:51:59,760 INFO org.apache.hadoop.yarn.server.resourcemanager.rmapp.attempt.RMAppAttemptImpl: appattempt_1536878829533_0005_000001 State change from FINISHING to FINISHED
2018-09-19 11:51:59,760 INFO org.apache.hadoop.yarn.server.resourcemanager.rmapp.RMAppImpl: application_1536878829533_0005 State change from FINISHING to FINISHED on event=ATTEMPT_FINISHED
2018-09-19 11:51:59,761 INFO org.apache.hadoop.yarn.server.resourcemanager.scheduler.SchedulerNode: Released container container_1536878829533_0005_01_000001 of capacity <memory:2048, vCores:1> on host 192.168.1.103:56395, which currently has 0 containers, <memory:0, vCores:0> used and <memory:8192, vCores:8> available, release resources=true
2018-09-19 11:51:59,761 INFO org.apache.hadoop.yarn.server.resourcemanager.RMAuditLogger: USER=jason	OPERATION=Application Finished - Succeeded	TARGET=RMAppManager	RESULT=SUCCESS	APPID=application_1536878829533_0005
2018-09-19 11:51:59,761 INFO org.apache.hadoop.yarn.server.resourcemanager.scheduler.capacity.CapacityScheduler: Application Attempt appattempt_1536878829533_0005_000001 is done. finalState=FINISHED
2018-09-19 11:51:59,761 INFO org.apache.hadoop.yarn.server.resourcemanager.RMAppManager$ApplicationSummary: appId=application_1536878829533_0005,name=word count,user=jason,queue=default,state=FINISHED,trackingUrl=http://Jasons-MacBook-Pro.local:8088/proxy/application_1536878829533_0005/,appMasterHost=192.168.1.103,startTime=1537375896021,finishTime=1537375913575,finalStatus=SUCCEEDED,memorySeconds=103129,vcoreSeconds=74,preemptedMemorySeconds=0,preemptedVcoreSeconds=0,preemptedAMContainers=0,preemptedNonAMContainers=0,preemptedResources=<memory:0\, vCores:0>,applicationType=MAPREDUCE
2018-09-19 11:51:59,762 INFO org.apache.hadoop.yarn.server.resourcemanager.scheduler.AppSchedulingInfo: Application application_1536878829533_0005 requests cleared
2018-09-19 11:51:59,762 INFO org.apache.hadoop.yarn.server.resourcemanager.amlauncher.AMLauncher: Cleaning master appattempt_1536878829533_0005_000001
2018-09-19 11:51:59,762 INFO org.apache.hadoop.yarn.server.resourcemanager.scheduler.capacity.LeafQueue: Application removed - appId: application_1536878829533_0005 user: jason queue: default #user-pending-applications: 0 #user-active-applications: 0 #queue-pending-applications: 0 #queue-active-applications: 0
2018-09-19 11:51:59,762 INFO org.apache.hadoop.yarn.server.resourcemanager.scheduler.capacity.ParentQueue: Application removed - appId: application_1536878829533_0005 user: jason leaf-queue of parent: root #applications: 0
2018-09-19 11:52:01,768 INFO org.apache.hadoop.yarn.server.resourcemanager.scheduler.AbstractYarnScheduler: Container container_1536878829533_0005_01_000010 completed with event FINISHED, but corresponding RMContainer doesn't exist.
2018-09-19 11:59:35,328 INFO org.apache.hadoop.yarn.server.resourcemanager.ClientRMService: Allocated new applicationId: 6
2018-09-19 11:59:35,829 INFO org.apache.hadoop.yarn.server.resourcemanager.scheduler.capacity.CapacityScheduler: Application 'application_1536878829533_0006' is submitted without priority hence considering default queue/cluster priority: 0
2018-09-19 11:59:35,829 INFO org.apache.hadoop.yarn.server.resourcemanager.scheduler.capacity.CapacityScheduler: Priority '0' is acceptable in queue : default for application: application_1536878829533_0006 for the user: jason
2018-09-19 11:59:35,830 INFO org.apache.hadoop.yarn.server.resourcemanager.ClientRMService: Application with id 6 submitted by user jason
2018-09-19 11:59:35,830 INFO org.apache.hadoop.yarn.server.resourcemanager.RMAuditLogger: USER=jason	IP=192.168.1.103	OPERATION=Submit Application Request	TARGET=ClientRMService	RESULT=SUCCESS	APPID=application_1536878829533_0006
2018-09-19 11:59:35,830 INFO org.apache.hadoop.yarn.server.resourcemanager.rmapp.RMAppImpl: Storing application with id application_1536878829533_0006
2018-09-19 11:59:35,830 INFO org.apache.hadoop.yarn.server.resourcemanager.recovery.RMStateStore: Storing info for app: application_1536878829533_0006
2018-09-19 11:59:35,830 INFO org.apache.hadoop.yarn.server.resourcemanager.rmapp.RMAppImpl: application_1536878829533_0006 State change from NEW to NEW_SAVING on event=START
2018-09-19 11:59:35,830 INFO org.apache.hadoop.yarn.server.resourcemanager.rmapp.RMAppImpl: application_1536878829533_0006 State change from NEW_SAVING to SUBMITTED on event=APP_NEW_SAVED
2018-09-19 11:59:35,831 INFO org.apache.hadoop.yarn.server.resourcemanager.scheduler.capacity.ParentQueue: Application added - appId: application_1536878829533_0006 user: jason leaf-queue of parent: root #applications: 1
2018-09-19 11:59:35,831 INFO org.apache.hadoop.yarn.server.resourcemanager.scheduler.capacity.CapacityScheduler: Accepted application application_1536878829533_0006 from user: jason, in queue: default
2018-09-19 11:59:35,831 INFO org.apache.hadoop.yarn.server.resourcemanager.rmapp.RMAppImpl: application_1536878829533_0006 State change from SUBMITTED to ACCEPTED on event=APP_ACCEPTED
2018-09-19 11:59:35,831 INFO org.apache.hadoop.yarn.server.resourcemanager.ApplicationMasterService: Registering app attempt : appattempt_1536878829533_0006_000001
2018-09-19 11:59:35,831 INFO org.apache.hadoop.yarn.server.resourcemanager.rmapp.attempt.RMAppAttemptImpl: appattempt_1536878829533_0006_000001 State change from NEW to SUBMITTED
2018-09-19 11:59:35,832 WARN org.apache.hadoop.yarn.server.resourcemanager.scheduler.capacity.LeafQueue: maximum-am-resource-percent is insufficient to start a single application in queue, it is likely set too low. skipping enforcement to allow at least one application to start
2018-09-19 11:59:35,832 WARN org.apache.hadoop.yarn.server.resourcemanager.scheduler.capacity.LeafQueue: maximum-am-resource-percent is insufficient to start a single application in queue for user, it is likely set too low. skipping enforcement to allow at least one application to start
2018-09-19 11:59:35,832 INFO org.apache.hadoop.yarn.server.resourcemanager.scheduler.capacity.LeafQueue: Application application_1536878829533_0006 from user: jason activated in queue: default
2018-09-19 11:59:35,832 INFO org.apache.hadoop.yarn.server.resourcemanager.scheduler.capacity.LeafQueue: Application added - appId: application_1536878829533_0006 user: jason, leaf-queue: default #user-pending-applications: 0 #user-active-applications: 1 #queue-pending-applications: 0 #queue-active-applications: 1
2018-09-19 11:59:35,832 INFO org.apache.hadoop.yarn.server.resourcemanager.scheduler.capacity.CapacityScheduler: Added Application Attempt appattempt_1536878829533_0006_000001 to scheduler from user jason in queue default
2018-09-19 11:59:35,833 INFO org.apache.hadoop.yarn.server.resourcemanager.rmapp.attempt.RMAppAttemptImpl: appattempt_1536878829533_0006_000001 State change from SUBMITTED to SCHEDULED
2018-09-19 11:59:35,957 INFO org.apache.hadoop.yarn.server.resourcemanager.rmcontainer.RMContainerImpl: container_1536878829533_0006_01_000001 Container Transitioned from NEW to ALLOCATED
2018-09-19 11:59:35,957 INFO org.apache.hadoop.yarn.server.resourcemanager.RMAuditLogger: USER=jason	OPERATION=AM Allocated Container	TARGET=SchedulerApp	RESULT=SUCCESS	APPID=application_1536878829533_0006	CONTAINERID=container_1536878829533_0006_01_000001
2018-09-19 11:59:35,957 INFO org.apache.hadoop.yarn.server.resourcemanager.scheduler.SchedulerNode: Assigned container container_1536878829533_0006_01_000001 of capacity <memory:2048, vCores:1> on host 192.168.1.103:56395, which has 1 containers, <memory:2048, vCores:1> used and <memory:6144, vCores:7> available after allocation
2018-09-19 11:59:35,957 INFO org.apache.hadoop.yarn.server.resourcemanager.scheduler.capacity.allocator.AbstractContainerAllocator: assignedContainer application attempt=appattempt_1536878829533_0006_000001 container=container_1536878829533_0006_01_000001 queue=org.apache.hadoop.yarn.server.resourcemanager.scheduler.capacity.allocator.RegularContainerAllocator@a99f42b clusterResource=<memory:8192, vCores:8> type=OFF_SWITCH
2018-09-19 11:59:35,957 INFO org.apache.hadoop.yarn.server.resourcemanager.security.NMTokenSecretManagerInRM: Sending NMToken for nodeId : 192.168.1.103:56395 for container : container_1536878829533_0006_01_000001
2018-09-19 11:59:35,958 INFO org.apache.hadoop.yarn.server.resourcemanager.rmcontainer.RMContainerImpl: container_1536878829533_0006_01_000001 Container Transitioned from ALLOCATED to ACQUIRED
2018-09-19 11:59:35,958 INFO org.apache.hadoop.yarn.server.resourcemanager.security.NMTokenSecretManagerInRM: Clear node set for appattempt_1536878829533_0006_000001
2018-09-19 11:59:35,958 INFO org.apache.hadoop.yarn.server.resourcemanager.rmapp.attempt.RMAppAttemptImpl: Storing attempt: AppId: application_1536878829533_0006 AttemptId: appattempt_1536878829533_0006_000001 MasterContainer: Container: [ContainerId: container_1536878829533_0006_01_000001, Version: 0, NodeId: 192.168.1.103:56395, NodeHttpAddress: 192.168.1.103:8042, Resource: <memory:2048, vCores:1>, Priority: 0, Token: Token { kind: ContainerToken, service: 192.168.1.103:56395 }, ]
2018-09-19 11:59:35,958 INFO org.apache.hadoop.yarn.server.resourcemanager.scheduler.capacity.ParentQueue: Re-sorting assigned queue: root.default stats: default: capacity=1.0, absoluteCapacity=1.0, usedResources=<memory:2048, vCores:1>, usedCapacity=0.25, absoluteUsedCapacity=0.25, numApps=1, numContainers=1
2018-09-19 11:59:35,958 INFO org.apache.hadoop.yarn.server.resourcemanager.rmapp.attempt.RMAppAttemptImpl: appattempt_1536878829533_0006_000001 State change from SCHEDULED to ALLOCATED_SAVING
2018-09-19 11:59:35,958 INFO org.apache.hadoop.yarn.server.resourcemanager.scheduler.capacity.ParentQueue: assignedContainer queue=root usedCapacity=0.25 absoluteUsedCapacity=0.25 used=<memory:2048, vCores:1> cluster=<memory:8192, vCores:8>
2018-09-19 11:59:35,958 INFO org.apache.hadoop.yarn.server.resourcemanager.rmapp.attempt.RMAppAttemptImpl: appattempt_1536878829533_0006_000001 State change from ALLOCATED_SAVING to ALLOCATED
2018-09-19 11:59:35,959 INFO org.apache.hadoop.yarn.server.resourcemanager.amlauncher.AMLauncher: Launching masterappattempt_1536878829533_0006_000001
2018-09-19 11:59:35,960 INFO org.apache.hadoop.yarn.server.resourcemanager.amlauncher.AMLauncher: Setting up container Container: [ContainerId: container_1536878829533_0006_01_000001, Version: 0, NodeId: 192.168.1.103:56395, NodeHttpAddress: 192.168.1.103:8042, Resource: <memory:2048, vCores:1>, Priority: 0, Token: Token { kind: ContainerToken, service: 192.168.1.103:56395 }, ] for AM appattempt_1536878829533_0006_000001
2018-09-19 11:59:35,960 INFO org.apache.hadoop.yarn.server.resourcemanager.security.AMRMTokenSecretManager: Create AMRMToken for ApplicationAttempt: appattempt_1536878829533_0006_000001
2018-09-19 11:59:35,960 INFO org.apache.hadoop.yarn.server.resourcemanager.security.AMRMTokenSecretManager: Creating password for appattempt_1536878829533_0006_000001
2018-09-19 11:59:35,973 INFO org.apache.hadoop.yarn.server.resourcemanager.amlauncher.AMLauncher: Done launching container Container: [ContainerId: container_1536878829533_0006_01_000001, Version: 0, NodeId: 192.168.1.103:56395, NodeHttpAddress: 192.168.1.103:8042, Resource: <memory:2048, vCores:1>, Priority: 0, Token: Token { kind: ContainerToken, service: 192.168.1.103:56395 }, ] for AM appattempt_1536878829533_0006_000001
2018-09-19 11:59:35,973 INFO org.apache.hadoop.yarn.server.resourcemanager.rmapp.attempt.RMAppAttemptImpl: appattempt_1536878829533_0006_000001 State change from ALLOCATED to LAUNCHED
2018-09-19 11:59:36,957 INFO org.apache.hadoop.yarn.server.resourcemanager.rmcontainer.RMContainerImpl: container_1536878829533_0006_01_000001 Container Transitioned from ACQUIRED to RUNNING
2018-09-19 11:59:39,409 INFO SecurityLogger.org.apache.hadoop.ipc.Server: Auth successful for appattempt_1536878829533_0006_000001 (auth:SIMPLE)
2018-09-19 11:59:39,411 INFO org.apache.hadoop.yarn.server.resourcemanager.ApplicationMasterService: AM registration appattempt_1536878829533_0006_000001
2018-09-19 11:59:39,411 INFO org.apache.hadoop.yarn.server.resourcemanager.RMAuditLogger: USER=jason	IP=192.168.1.103	OPERATION=Register App Master	TARGET=ApplicationMasterService	RESULT=SUCCESS	APPID=application_1536878829533_0006	APPATTEMPTID=appattempt_1536878829533_0006_000001
2018-09-19 11:59:39,411 INFO org.apache.hadoop.yarn.server.resourcemanager.rmapp.attempt.RMAppAttemptImpl: appattempt_1536878829533_0006_000001 State change from LAUNCHED to RUNNING
2018-09-19 11:59:39,411 INFO org.apache.hadoop.yarn.server.resourcemanager.rmapp.RMAppImpl: application_1536878829533_0006 State change from ACCEPTED to RUNNING on event=ATTEMPT_REGISTERED
2018-09-19 11:59:40,970 INFO org.apache.hadoop.yarn.server.resourcemanager.rmcontainer.RMContainerImpl: container_1536878829533_0006_01_000002 Container Transitioned from NEW to ALLOCATED
2018-09-19 11:59:40,970 INFO org.apache.hadoop.yarn.server.resourcemanager.RMAuditLogger: USER=jason	OPERATION=AM Allocated Container	TARGET=SchedulerApp	RESULT=SUCCESS	APPID=application_1536878829533_0006	CONTAINERID=container_1536878829533_0006_01_000002
2018-09-19 11:59:40,970 INFO org.apache.hadoop.yarn.server.resourcemanager.scheduler.SchedulerNode: Assigned container container_1536878829533_0006_01_000002 of capacity <memory:1024, vCores:1> on host 192.168.1.103:56395, which has 2 containers, <memory:3072, vCores:2> used and <memory:5120, vCores:6> available after allocation
2018-09-19 11:59:40,970 INFO org.apache.hadoop.yarn.server.resourcemanager.scheduler.capacity.allocator.AbstractContainerAllocator: assignedContainer application attempt=appattempt_1536878829533_0006_000001 container=container_1536878829533_0006_01_000002 queue=org.apache.hadoop.yarn.server.resourcemanager.scheduler.capacity.allocator.RegularContainerAllocator@a99f42b clusterResource=<memory:8192, vCores:8> type=NODE_LOCAL
2018-09-19 11:59:40,970 INFO org.apache.hadoop.yarn.server.resourcemanager.scheduler.capacity.ParentQueue: Re-sorting assigned queue: root.default stats: default: capacity=1.0, absoluteCapacity=1.0, usedResources=<memory:3072, vCores:2>, usedCapacity=0.375, absoluteUsedCapacity=0.375, numApps=1, numContainers=2
2018-09-19 11:59:40,970 INFO org.apache.hadoop.yarn.server.resourcemanager.scheduler.capacity.ParentQueue: assignedContainer queue=root usedCapacity=0.375 absoluteUsedCapacity=0.375 used=<memory:3072, vCores:2> cluster=<memory:8192, vCores:8>
2018-09-19 11:59:40,970 INFO org.apache.hadoop.yarn.server.resourcemanager.rmcontainer.RMContainerImpl: container_1536878829533_0006_01_000003 Container Transitioned from NEW to ALLOCATED
2018-09-19 11:59:40,970 INFO org.apache.hadoop.yarn.server.resourcemanager.RMAuditLogger: USER=jason	OPERATION=AM Allocated Container	TARGET=SchedulerApp	RESULT=SUCCESS	APPID=application_1536878829533_0006	CONTAINERID=container_1536878829533_0006_01_000003
2018-09-19 11:59:40,970 INFO org.apache.hadoop.yarn.server.resourcemanager.scheduler.SchedulerNode: Assigned container container_1536878829533_0006_01_000003 of capacity <memory:1024, vCores:1> on host 192.168.1.103:56395, which has 3 containers, <memory:4096, vCores:3> used and <memory:4096, vCores:5> available after allocation
2018-09-19 11:59:40,971 INFO org.apache.hadoop.yarn.server.resourcemanager.scheduler.capacity.allocator.AbstractContainerAllocator: assignedContainer application attempt=appattempt_1536878829533_0006_000001 container=container_1536878829533_0006_01_000003 queue=org.apache.hadoop.yarn.server.resourcemanager.scheduler.capacity.allocator.RegularContainerAllocator@a99f42b clusterResource=<memory:8192, vCores:8> type=NODE_LOCAL
2018-09-19 11:59:40,971 INFO org.apache.hadoop.yarn.server.resourcemanager.scheduler.capacity.ParentQueue: Re-sorting assigned queue: root.default stats: default: capacity=1.0, absoluteCapacity=1.0, usedResources=<memory:4096, vCores:3>, usedCapacity=0.5, absoluteUsedCapacity=0.5, numApps=1, numContainers=3
2018-09-19 11:59:40,971 INFO org.apache.hadoop.yarn.server.resourcemanager.scheduler.capacity.ParentQueue: assignedContainer queue=root usedCapacity=0.5 absoluteUsedCapacity=0.5 used=<memory:4096, vCores:3> cluster=<memory:8192, vCores:8>
2018-09-19 11:59:40,971 INFO org.apache.hadoop.yarn.server.resourcemanager.rmcontainer.RMContainerImpl: container_1536878829533_0006_01_000004 Container Transitioned from NEW to ALLOCATED
2018-09-19 11:59:40,971 INFO org.apache.hadoop.yarn.server.resourcemanager.RMAuditLogger: USER=jason	OPERATION=AM Allocated Container	TARGET=SchedulerApp	RESULT=SUCCESS	APPID=application_1536878829533_0006	CONTAINERID=container_1536878829533_0006_01_000004
2018-09-19 11:59:40,971 INFO org.apache.hadoop.yarn.server.resourcemanager.scheduler.SchedulerNode: Assigned container container_1536878829533_0006_01_000004 of capacity <memory:1024, vCores:1> on host 192.168.1.103:56395, which has 4 containers, <memory:5120, vCores:4> used and <memory:3072, vCores:4> available after allocation
2018-09-19 11:59:40,971 INFO org.apache.hadoop.yarn.server.resourcemanager.scheduler.capacity.allocator.AbstractContainerAllocator: assignedContainer application attempt=appattempt_1536878829533_0006_000001 container=container_1536878829533_0006_01_000004 queue=org.apache.hadoop.yarn.server.resourcemanager.scheduler.capacity.allocator.RegularContainerAllocator@a99f42b clusterResource=<memory:8192, vCores:8> type=NODE_LOCAL
2018-09-19 11:59:40,971 INFO org.apache.hadoop.yarn.server.resourcemanager.scheduler.capacity.ParentQueue: Re-sorting assigned queue: root.default stats: default: capacity=1.0, absoluteCapacity=1.0, usedResources=<memory:5120, vCores:4>, usedCapacity=0.625, absoluteUsedCapacity=0.625, numApps=1, numContainers=4
2018-09-19 11:59:40,971 INFO org.apache.hadoop.yarn.server.resourcemanager.scheduler.capacity.ParentQueue: assignedContainer queue=root usedCapacity=0.625 absoluteUsedCapacity=0.625 used=<memory:5120, vCores:4> cluster=<memory:8192, vCores:8>
2018-09-19 11:59:40,972 INFO org.apache.hadoop.yarn.server.resourcemanager.rmcontainer.RMContainerImpl: container_1536878829533_0006_01_000005 Container Transitioned from NEW to ALLOCATED
2018-09-19 11:59:40,972 INFO org.apache.hadoop.yarn.server.resourcemanager.RMAuditLogger: USER=jason	OPERATION=AM Allocated Container	TARGET=SchedulerApp	RESULT=SUCCESS	APPID=application_1536878829533_0006	CONTAINERID=container_1536878829533_0006_01_000005
2018-09-19 11:59:40,972 INFO org.apache.hadoop.yarn.server.resourcemanager.scheduler.SchedulerNode: Assigned container container_1536878829533_0006_01_000005 of capacity <memory:1024, vCores:1> on host 192.168.1.103:56395, which has 5 containers, <memory:6144, vCores:5> used and <memory:2048, vCores:3> available after allocation
2018-09-19 11:59:40,972 INFO org.apache.hadoop.yarn.server.resourcemanager.scheduler.capacity.allocator.AbstractContainerAllocator: assignedContainer application attempt=appattempt_1536878829533_0006_000001 container=container_1536878829533_0006_01_000005 queue=org.apache.hadoop.yarn.server.resourcemanager.scheduler.capacity.allocator.RegularContainerAllocator@a99f42b clusterResource=<memory:8192, vCores:8> type=NODE_LOCAL
2018-09-19 11:59:40,972 INFO org.apache.hadoop.yarn.server.resourcemanager.scheduler.capacity.ParentQueue: Re-sorting assigned queue: root.default stats: default: capacity=1.0, absoluteCapacity=1.0, usedResources=<memory:6144, vCores:5>, usedCapacity=0.75, absoluteUsedCapacity=0.75, numApps=1, numContainers=5
2018-09-19 11:59:40,972 INFO org.apache.hadoop.yarn.server.resourcemanager.scheduler.capacity.ParentQueue: assignedContainer queue=root usedCapacity=0.75 absoluteUsedCapacity=0.75 used=<memory:6144, vCores:5> cluster=<memory:8192, vCores:8>
2018-09-19 11:59:40,972 INFO org.apache.hadoop.yarn.server.resourcemanager.rmcontainer.RMContainerImpl: container_1536878829533_0006_01_000006 Container Transitioned from NEW to ALLOCATED
2018-09-19 11:59:40,972 INFO org.apache.hadoop.yarn.server.resourcemanager.RMAuditLogger: USER=jason	OPERATION=AM Allocated Container	TARGET=SchedulerApp	RESULT=SUCCESS	APPID=application_1536878829533_0006	CONTAINERID=container_1536878829533_0006_01_000006
2018-09-19 11:59:40,972 INFO org.apache.hadoop.yarn.server.resourcemanager.scheduler.SchedulerNode: Assigned container container_1536878829533_0006_01_000006 of capacity <memory:1024, vCores:1> on host 192.168.1.103:56395, which has 6 containers, <memory:7168, vCores:6> used and <memory:1024, vCores:2> available after allocation
2018-09-19 11:59:40,972 INFO org.apache.hadoop.yarn.server.resourcemanager.scheduler.capacity.allocator.AbstractContainerAllocator: assignedContainer application attempt=appattempt_1536878829533_0006_000001 container=container_1536878829533_0006_01_000006 queue=org.apache.hadoop.yarn.server.resourcemanager.scheduler.capacity.allocator.RegularContainerAllocator@a99f42b clusterResource=<memory:8192, vCores:8> type=NODE_LOCAL
2018-09-19 11:59:40,972 INFO org.apache.hadoop.yarn.server.resourcemanager.scheduler.capacity.ParentQueue: Re-sorting assigned queue: root.default stats: default: capacity=1.0, absoluteCapacity=1.0, usedResources=<memory:7168, vCores:6>, usedCapacity=0.875, absoluteUsedCapacity=0.875, numApps=1, numContainers=6
2018-09-19 11:59:40,973 INFO org.apache.hadoop.yarn.server.resourcemanager.scheduler.capacity.ParentQueue: assignedContainer queue=root usedCapacity=0.875 absoluteUsedCapacity=0.875 used=<memory:7168, vCores:6> cluster=<memory:8192, vCores:8>
2018-09-19 11:59:40,973 INFO org.apache.hadoop.yarn.server.resourcemanager.rmcontainer.RMContainerImpl: container_1536878829533_0006_01_000007 Container Transitioned from NEW to ALLOCATED
2018-09-19 11:59:40,973 INFO org.apache.hadoop.yarn.server.resourcemanager.RMAuditLogger: USER=jason	OPERATION=AM Allocated Container	TARGET=SchedulerApp	RESULT=SUCCESS	APPID=application_1536878829533_0006	CONTAINERID=container_1536878829533_0006_01_000007
2018-09-19 11:59:40,973 INFO org.apache.hadoop.yarn.server.resourcemanager.scheduler.SchedulerNode: Assigned container container_1536878829533_0006_01_000007 of capacity <memory:1024, vCores:1> on host 192.168.1.103:56395, which has 7 containers, <memory:8192, vCores:7> used and <memory:0, vCores:1> available after allocation
2018-09-19 11:59:40,973 INFO org.apache.hadoop.yarn.server.resourcemanager.scheduler.capacity.allocator.AbstractContainerAllocator: assignedContainer application attempt=appattempt_1536878829533_0006_000001 container=container_1536878829533_0006_01_000007 queue=org.apache.hadoop.yarn.server.resourcemanager.scheduler.capacity.allocator.RegularContainerAllocator@a99f42b clusterResource=<memory:8192, vCores:8> type=NODE_LOCAL
2018-09-19 11:59:40,973 INFO org.apache.hadoop.yarn.server.resourcemanager.scheduler.capacity.ParentQueue: Re-sorting assigned queue: root.default stats: default: capacity=1.0, absoluteCapacity=1.0, usedResources=<memory:8192, vCores:7>, usedCapacity=1.0, absoluteUsedCapacity=1.0, numApps=1, numContainers=7
2018-09-19 11:59:40,973 INFO org.apache.hadoop.yarn.server.resourcemanager.scheduler.capacity.ParentQueue: assignedContainer queue=root usedCapacity=1.0 absoluteUsedCapacity=1.0 used=<memory:8192, vCores:7> cluster=<memory:8192, vCores:8>
2018-09-19 11:59:41,457 INFO org.apache.hadoop.yarn.server.resourcemanager.security.NMTokenSecretManagerInRM: Sending NMToken for nodeId : 192.168.1.103:56395 for container : container_1536878829533_0006_01_000002
2018-09-19 11:59:41,458 INFO org.apache.hadoop.yarn.server.resourcemanager.rmcontainer.RMContainerImpl: container_1536878829533_0006_01_000002 Container Transitioned from ALLOCATED to ACQUIRED
2018-09-19 11:59:41,459 INFO org.apache.hadoop.yarn.server.resourcemanager.rmcontainer.RMContainerImpl: container_1536878829533_0006_01_000003 Container Transitioned from ALLOCATED to ACQUIRED
2018-09-19 11:59:41,459 INFO org.apache.hadoop.yarn.server.resourcemanager.rmcontainer.RMContainerImpl: container_1536878829533_0006_01_000004 Container Transitioned from ALLOCATED to ACQUIRED
2018-09-19 11:59:41,460 INFO org.apache.hadoop.yarn.server.resourcemanager.rmcontainer.RMContainerImpl: container_1536878829533_0006_01_000005 Container Transitioned from ALLOCATED to ACQUIRED
2018-09-19 11:59:41,461 INFO org.apache.hadoop.yarn.server.resourcemanager.rmcontainer.RMContainerImpl: container_1536878829533_0006_01_000006 Container Transitioned from ALLOCATED to ACQUIRED
2018-09-19 11:59:41,462 INFO org.apache.hadoop.yarn.server.resourcemanager.rmcontainer.RMContainerImpl: container_1536878829533_0006_01_000007 Container Transitioned from ALLOCATED to ACQUIRED
2018-09-19 11:59:41,969 INFO org.apache.hadoop.yarn.server.resourcemanager.rmcontainer.RMContainerImpl: container_1536878829533_0006_01_000002 Container Transitioned from ACQUIRED to RUNNING
2018-09-19 11:59:41,970 INFO org.apache.hadoop.yarn.server.resourcemanager.rmcontainer.RMContainerImpl: container_1536878829533_0006_01_000003 Container Transitioned from ACQUIRED to RUNNING
2018-09-19 11:59:41,970 INFO org.apache.hadoop.yarn.server.resourcemanager.rmcontainer.RMContainerImpl: container_1536878829533_0006_01_000004 Container Transitioned from ACQUIRED to RUNNING
2018-09-19 11:59:41,970 INFO org.apache.hadoop.yarn.server.resourcemanager.rmcontainer.RMContainerImpl: container_1536878829533_0006_01_000005 Container Transitioned from ACQUIRED to RUNNING
2018-09-19 11:59:41,971 INFO org.apache.hadoop.yarn.server.resourcemanager.rmcontainer.RMContainerImpl: container_1536878829533_0006_01_000006 Container Transitioned from ACQUIRED to RUNNING
2018-09-19 11:59:41,972 INFO org.apache.hadoop.yarn.server.resourcemanager.rmcontainer.RMContainerImpl: container_1536878829533_0006_01_000007 Container Transitioned from ACQUIRED to RUNNING
2018-09-19 11:59:47,628 INFO org.apache.hadoop.yarn.server.resourcemanager.rmcontainer.RMContainerImpl: container_1536878829533_0006_01_000006 Container Transitioned from RUNNING to COMPLETED
2018-09-19 11:59:47,629 INFO org.apache.hadoop.yarn.server.resourcemanager.RMAuditLogger: USER=jason	OPERATION=AM Released Container	TARGET=SchedulerApp	RESULT=SUCCESS	APPID=application_1536878829533_0006	CONTAINERID=container_1536878829533_0006_01_000006
2018-09-19 11:59:47,629 INFO org.apache.hadoop.yarn.server.resourcemanager.scheduler.SchedulerNode: Released container container_1536878829533_0006_01_000006 of capacity <memory:1024, vCores:1> on host 192.168.1.103:56395, which currently has 6 containers, <memory:7168, vCores:6> used and <memory:1024, vCores:2> available, release resources=true
2018-09-19 11:59:47,630 INFO org.apache.hadoop.yarn.server.resourcemanager.rmcontainer.RMContainerImpl: container_1536878829533_0006_01_000008 Container Transitioned from NEW to ALLOCATED
2018-09-19 11:59:47,630 INFO org.apache.hadoop.yarn.server.resourcemanager.RMAuditLogger: USER=jason	OPERATION=AM Allocated Container	TARGET=SchedulerApp	RESULT=SUCCESS	APPID=application_1536878829533_0006	CONTAINERID=container_1536878829533_0006_01_000008
2018-09-19 11:59:47,630 INFO org.apache.hadoop.yarn.server.resourcemanager.scheduler.SchedulerNode: Assigned container container_1536878829533_0006_01_000008 of capacity <memory:1024, vCores:1> on host 192.168.1.103:56395, which has 7 containers, <memory:8192, vCores:7> used and <memory:0, vCores:1> available after allocation
2018-09-19 11:59:47,630 INFO org.apache.hadoop.yarn.server.resourcemanager.scheduler.capacity.allocator.AbstractContainerAllocator: assignedContainer application attempt=appattempt_1536878829533_0006_000001 container=container_1536878829533_0006_01_000008 queue=org.apache.hadoop.yarn.server.resourcemanager.scheduler.capacity.allocator.RegularContainerAllocator@a99f42b clusterResource=<memory:8192, vCores:8> type=NODE_LOCAL
2018-09-19 11:59:47,630 INFO org.apache.hadoop.yarn.server.resourcemanager.scheduler.capacity.ParentQueue: Re-sorting assigned queue: root.default stats: default: capacity=1.0, absoluteCapacity=1.0, usedResources=<memory:8192, vCores:7>, usedCapacity=1.0, absoluteUsedCapacity=1.0, numApps=1, numContainers=7
2018-09-19 11:59:47,630 INFO org.apache.hadoop.yarn.server.resourcemanager.scheduler.capacity.ParentQueue: assignedContainer queue=root usedCapacity=1.0 absoluteUsedCapacity=1.0 used=<memory:8192, vCores:7> cluster=<memory:8192, vCores:8>
2018-09-19 11:59:47,679 INFO org.apache.hadoop.yarn.server.resourcemanager.rmcontainer.RMContainerImpl: container_1536878829533_0006_01_000007 Container Transitioned from RUNNING to COMPLETED
2018-09-19 11:59:47,679 INFO org.apache.hadoop.yarn.server.resourcemanager.RMAuditLogger: USER=jason	OPERATION=AM Released Container	TARGET=SchedulerApp	RESULT=SUCCESS	APPID=application_1536878829533_0006	CONTAINERID=container_1536878829533_0006_01_000007
2018-09-19 11:59:47,680 INFO org.apache.hadoop.yarn.server.resourcemanager.scheduler.SchedulerNode: Released container container_1536878829533_0006_01_000007 of capacity <memory:1024, vCores:1> on host 192.168.1.103:56395, which currently has 6 containers, <memory:7168, vCores:6> used and <memory:1024, vCores:2> available, release resources=true
2018-09-19 11:59:47,680 INFO org.apache.hadoop.yarn.server.resourcemanager.rmcontainer.RMContainerImpl: container_1536878829533_0006_01_000004 Container Transitioned from RUNNING to COMPLETED
2018-09-19 11:59:47,680 INFO org.apache.hadoop.yarn.server.resourcemanager.RMAuditLogger: USER=jason	OPERATION=AM Released Container	TARGET=SchedulerApp	RESULT=SUCCESS	APPID=application_1536878829533_0006	CONTAINERID=container_1536878829533_0006_01_000004
2018-09-19 11:59:47,680 INFO org.apache.hadoop.yarn.server.resourcemanager.scheduler.SchedulerNode: Released container container_1536878829533_0006_01_000004 of capacity <memory:1024, vCores:1> on host 192.168.1.103:56395, which currently has 5 containers, <memory:6144, vCores:5> used and <memory:2048, vCores:3> available, release resources=true
2018-09-19 11:59:47,681 INFO org.apache.hadoop.yarn.server.resourcemanager.rmcontainer.RMContainerImpl: container_1536878829533_0006_01_000005 Container Transitioned from RUNNING to COMPLETED
2018-09-19 11:59:47,681 INFO org.apache.hadoop.yarn.server.resourcemanager.RMAuditLogger: USER=jason	OPERATION=AM Released Container	TARGET=SchedulerApp	RESULT=SUCCESS	APPID=application_1536878829533_0006	CONTAINERID=container_1536878829533_0006_01_000005
2018-09-19 11:59:47,681 INFO org.apache.hadoop.yarn.server.resourcemanager.scheduler.SchedulerNode: Released container container_1536878829533_0006_01_000005 of capacity <memory:1024, vCores:1> on host 192.168.1.103:56395, which currently has 4 containers, <memory:5120, vCores:4> used and <memory:3072, vCores:4> available, release resources=true
2018-09-19 11:59:47,682 INFO org.apache.hadoop.yarn.server.resourcemanager.rmcontainer.RMContainerImpl: container_1536878829533_0006_01_000009 Container Transitioned from NEW to ALLOCATED
2018-09-19 11:59:47,682 INFO org.apache.hadoop.yarn.server.resourcemanager.RMAuditLogger: USER=jason	OPERATION=AM Allocated Container	TARGET=SchedulerApp	RESULT=SUCCESS	APPID=application_1536878829533_0006	CONTAINERID=container_1536878829533_0006_01_000009
2018-09-19 11:59:47,682 INFO org.apache.hadoop.yarn.server.resourcemanager.scheduler.SchedulerNode: Assigned container container_1536878829533_0006_01_000009 of capacity <memory:1024, vCores:1> on host 192.168.1.103:56395, which has 5 containers, <memory:6144, vCores:5> used and <memory:2048, vCores:3> available after allocation
2018-09-19 11:59:47,682 INFO org.apache.hadoop.yarn.server.resourcemanager.scheduler.capacity.allocator.AbstractContainerAllocator: assignedContainer application attempt=appattempt_1536878829533_0006_000001 container=container_1536878829533_0006_01_000009 queue=org.apache.hadoop.yarn.server.resourcemanager.scheduler.capacity.allocator.RegularContainerAllocator@a99f42b clusterResource=<memory:8192, vCores:8> type=NODE_LOCAL
2018-09-19 11:59:47,682 INFO org.apache.hadoop.yarn.server.resourcemanager.scheduler.capacity.ParentQueue: Re-sorting assigned queue: root.default stats: default: capacity=1.0, absoluteCapacity=1.0, usedResources=<memory:6144, vCores:5>, usedCapacity=0.75, absoluteUsedCapacity=0.75, numApps=1, numContainers=5
2018-09-19 11:59:47,682 INFO org.apache.hadoop.yarn.server.resourcemanager.scheduler.capacity.ParentQueue: assignedContainer queue=root usedCapacity=0.75 absoluteUsedCapacity=0.75 used=<memory:6144, vCores:5> cluster=<memory:8192, vCores:8>
2018-09-19 11:59:47,713 INFO org.apache.hadoop.yarn.server.resourcemanager.rmcontainer.RMContainerImpl: container_1536878829533_0006_01_000002 Container Transitioned from RUNNING to COMPLETED
2018-09-19 11:59:47,713 INFO org.apache.hadoop.yarn.server.resourcemanager.RMAuditLogger: USER=jason	OPERATION=AM Released Container	TARGET=SchedulerApp	RESULT=SUCCESS	APPID=application_1536878829533_0006	CONTAINERID=container_1536878829533_0006_01_000002
2018-09-19 11:59:47,713 INFO org.apache.hadoop.yarn.server.resourcemanager.scheduler.SchedulerNode: Released container container_1536878829533_0006_01_000002 of capacity <memory:1024, vCores:1> on host 192.168.1.103:56395, which currently has 4 containers, <memory:5120, vCores:4> used and <memory:3072, vCores:4> available, release resources=true
2018-09-19 11:59:47,714 INFO org.apache.hadoop.yarn.server.resourcemanager.rmcontainer.RMContainerImpl: container_1536878829533_0006_01_000003 Container Transitioned from RUNNING to COMPLETED
2018-09-19 11:59:47,714 INFO org.apache.hadoop.yarn.server.resourcemanager.RMAuditLogger: USER=jason	OPERATION=AM Released Container	TARGET=SchedulerApp	RESULT=SUCCESS	APPID=application_1536878829533_0006	CONTAINERID=container_1536878829533_0006_01_000003
2018-09-19 11:59:47,714 INFO org.apache.hadoop.yarn.server.resourcemanager.scheduler.SchedulerNode: Released container container_1536878829533_0006_01_000003 of capacity <memory:1024, vCores:1> on host 192.168.1.103:56395, which currently has 3 containers, <memory:4096, vCores:3> used and <memory:4096, vCores:5> available, release resources=true
2018-09-19 11:59:48,505 INFO org.apache.hadoop.yarn.server.resourcemanager.rmcontainer.RMContainerImpl: container_1536878829533_0006_01_000008 Container Transitioned from ALLOCATED to ACQUIRED
2018-09-19 11:59:48,506 INFO org.apache.hadoop.yarn.server.resourcemanager.rmcontainer.RMContainerImpl: container_1536878829533_0006_01_000009 Container Transitioned from ALLOCATED to ACQUIRED
2018-09-19 11:59:48,714 INFO org.apache.hadoop.yarn.server.resourcemanager.rmcontainer.RMContainerImpl: container_1536878829533_0006_01_000008 Container Transitioned from ACQUIRED to RUNNING
2018-09-19 11:59:48,714 INFO org.apache.hadoop.yarn.server.resourcemanager.rmcontainer.RMContainerImpl: container_1536878829533_0006_01_000009 Container Transitioned from ACQUIRED to RUNNING
2018-09-19 11:59:48,715 INFO org.apache.hadoop.yarn.server.resourcemanager.rmcontainer.RMContainerImpl: container_1536878829533_0006_01_000010 Container Transitioned from NEW to ALLOCATED
2018-09-19 11:59:48,715 INFO org.apache.hadoop.yarn.server.resourcemanager.RMAuditLogger: USER=jason	OPERATION=AM Allocated Container	TARGET=SchedulerApp	RESULT=SUCCESS	APPID=application_1536878829533_0006	CONTAINERID=container_1536878829533_0006_01_000010
2018-09-19 11:59:48,715 INFO org.apache.hadoop.yarn.server.resourcemanager.scheduler.SchedulerNode: Assigned container container_1536878829533_0006_01_000010 of capacity <memory:1024, vCores:1> on host 192.168.1.103:56395, which has 4 containers, <memory:5120, vCores:4> used and <memory:3072, vCores:4> available after allocation
2018-09-19 11:59:48,715 INFO org.apache.hadoop.yarn.server.resourcemanager.scheduler.capacity.allocator.AbstractContainerAllocator: assignedContainer application attempt=appattempt_1536878829533_0006_000001 container=container_1536878829533_0006_01_000010 queue=org.apache.hadoop.yarn.server.resourcemanager.scheduler.capacity.allocator.RegularContainerAllocator@a99f42b clusterResource=<memory:8192, vCores:8> type=OFF_SWITCH
2018-09-19 11:59:48,715 INFO org.apache.hadoop.yarn.server.resourcemanager.scheduler.capacity.ParentQueue: Re-sorting assigned queue: root.default stats: default: capacity=1.0, absoluteCapacity=1.0, usedResources=<memory:5120, vCores:4>, usedCapacity=0.625, absoluteUsedCapacity=0.625, numApps=1, numContainers=4
2018-09-19 11:59:48,715 INFO org.apache.hadoop.yarn.server.resourcemanager.scheduler.capacity.ParentQueue: assignedContainer queue=root usedCapacity=0.625 absoluteUsedCapacity=0.625 used=<memory:5120, vCores:4> cluster=<memory:8192, vCores:8>
2018-09-19 11:59:49,518 INFO org.apache.hadoop.yarn.server.resourcemanager.scheduler.AppSchedulingInfo: checking for deactivate of application :application_1536878829533_0006
2018-09-19 11:59:49,520 INFO org.apache.hadoop.yarn.server.resourcemanager.rmcontainer.RMContainerImpl: container_1536878829533_0006_01_000010 Container Transitioned from ALLOCATED to ACQUIRED
2018-09-19 11:59:49,717 INFO org.apache.hadoop.yarn.server.resourcemanager.rmcontainer.RMContainerImpl: container_1536878829533_0006_01_000010 Container Transitioned from ACQUIRED to RUNNING
2018-09-19 11:59:50,525 INFO org.apache.hadoop.yarn.server.resourcemanager.scheduler.AppSchedulingInfo: checking for deactivate of application :application_1536878829533_0006
2018-09-19 11:59:51,529 INFO org.apache.hadoop.yarn.server.resourcemanager.scheduler.AppSchedulingInfo: checking for deactivate of application :application_1536878829533_0006
2018-09-19 11:59:51,631 INFO org.apache.hadoop.yarn.server.resourcemanager.rmcontainer.RMContainerImpl: container_1536878829533_0006_01_000009 Container Transitioned from RUNNING to COMPLETED
2018-09-19 11:59:51,632 INFO org.apache.hadoop.yarn.server.resourcemanager.RMAuditLogger: USER=jason	OPERATION=AM Released Container	TARGET=SchedulerApp	RESULT=SUCCESS	APPID=application_1536878829533_0006	CONTAINERID=container_1536878829533_0006_01_000009
2018-09-19 11:59:51,632 INFO org.apache.hadoop.yarn.server.resourcemanager.scheduler.SchedulerNode: Released container container_1536878829533_0006_01_000009 of capacity <memory:1024, vCores:1> on host 192.168.1.103:56395, which currently has 3 containers, <memory:4096, vCores:3> used and <memory:4096, vCores:5> available, release resources=true
2018-09-19 11:59:51,654 INFO org.apache.hadoop.yarn.server.resourcemanager.rmcontainer.RMContainerImpl: container_1536878829533_0006_01_000008 Container Transitioned from RUNNING to COMPLETED
2018-09-19 11:59:51,654 INFO org.apache.hadoop.yarn.server.resourcemanager.RMAuditLogger: USER=jason	OPERATION=AM Released Container	TARGET=SchedulerApp	RESULT=SUCCESS	APPID=application_1536878829533_0006	CONTAINERID=container_1536878829533_0006_01_000008
2018-09-19 11:59:51,655 INFO org.apache.hadoop.yarn.server.resourcemanager.scheduler.SchedulerNode: Released container container_1536878829533_0006_01_000008 of capacity <memory:1024, vCores:1> on host 192.168.1.103:56395, which currently has 2 containers, <memory:3072, vCores:2> used and <memory:5120, vCores:6> available, release resources=true
2018-09-19 11:59:52,384 INFO org.apache.hadoop.yarn.server.resourcemanager.rmapp.attempt.RMAppAttemptImpl: Updating application attempt appattempt_1536878829533_0006_000001 with final state: FINISHING, and exit status: -1000
2018-09-19 11:59:52,384 INFO org.apache.hadoop.yarn.server.resourcemanager.rmapp.attempt.RMAppAttemptImpl: appattempt_1536878829533_0006_000001 State change from RUNNING to FINAL_SAVING
2018-09-19 11:59:52,384 INFO org.apache.hadoop.yarn.server.resourcemanager.rmapp.RMAppImpl: Updating application application_1536878829533_0006 with final state: FINISHING
2018-09-19 11:59:52,384 INFO org.apache.hadoop.yarn.server.resourcemanager.rmapp.RMAppImpl: application_1536878829533_0006 State change from RUNNING to FINAL_SAVING on event=ATTEMPT_UNREGISTERED
2018-09-19 11:59:52,384 INFO org.apache.hadoop.yarn.server.resourcemanager.recovery.RMStateStore: Updating info for app: application_1536878829533_0006
2018-09-19 11:59:52,384 INFO org.apache.hadoop.yarn.server.resourcemanager.rmapp.attempt.RMAppAttemptImpl: appattempt_1536878829533_0006_000001 State change from FINAL_SAVING to FINISHING
2018-09-19 11:59:52,384 INFO org.apache.hadoop.yarn.server.resourcemanager.rmapp.RMAppImpl: application_1536878829533_0006 State change from FINAL_SAVING to FINISHING on event=APP_UPDATE_SAVED
2018-09-19 11:59:52,386 INFO org.apache.hadoop.yarn.server.resourcemanager.rmcontainer.RMContainerImpl: container_1536878829533_0006_01_000010 Container Transitioned from RUNNING to COMPLETED
2018-09-19 11:59:52,386 INFO org.apache.hadoop.yarn.server.resourcemanager.RMAuditLogger: USER=jason	OPERATION=AM Released Container	TARGET=SchedulerApp	RESULT=SUCCESS	APPID=application_1536878829533_0006	CONTAINERID=container_1536878829533_0006_01_000010
2018-09-19 11:59:52,387 INFO org.apache.hadoop.yarn.server.resourcemanager.scheduler.SchedulerNode: Released container container_1536878829533_0006_01_000010 of capacity <memory:1024, vCores:1> on host 192.168.1.103:56395, which currently has 1 containers, <memory:2048, vCores:1> used and <memory:6144, vCores:7> available, release resources=true
2018-09-19 11:59:53,390 INFO org.apache.hadoop.yarn.server.resourcemanager.ApplicationMasterService: application_1536878829533_0006 unregistered successfully. 
2018-09-19 11:59:58,572 INFO org.apache.hadoop.yarn.server.resourcemanager.rmcontainer.RMContainerImpl: container_1536878829533_0006_01_000001 Container Transitioned from RUNNING to COMPLETED
2018-09-19 11:59:58,572 INFO org.apache.hadoop.yarn.server.resourcemanager.RMAuditLogger: USER=jason	OPERATION=AM Released Container	TARGET=SchedulerApp	RESULT=SUCCESS	APPID=application_1536878829533_0006	CONTAINERID=container_1536878829533_0006_01_000001
2018-09-19 11:59:58,573 INFO org.apache.hadoop.yarn.server.resourcemanager.ApplicationMasterService: Unregistering app attempt : appattempt_1536878829533_0006_000001
2018-09-19 11:59:58,573 INFO org.apache.hadoop.yarn.server.resourcemanager.security.AMRMTokenSecretManager: Application finished, removing password for appattempt_1536878829533_0006_000001
2018-09-19 11:59:58,573 INFO org.apache.hadoop.yarn.server.resourcemanager.rmapp.attempt.RMAppAttemptImpl: appattempt_1536878829533_0006_000001 State change from FINISHING to FINISHED
2018-09-19 11:59:58,573 INFO org.apache.hadoop.yarn.server.resourcemanager.scheduler.SchedulerNode: Released container container_1536878829533_0006_01_000001 of capacity <memory:2048, vCores:1> on host 192.168.1.103:56395, which currently has 0 containers, <memory:0, vCores:0> used and <memory:8192, vCores:8> available, release resources=true
2018-09-19 11:59:58,573 INFO org.apache.hadoop.yarn.server.resourcemanager.rmapp.RMAppImpl: application_1536878829533_0006 State change from FINISHING to FINISHED on event=ATTEMPT_FINISHED
2018-09-19 11:59:58,573 INFO org.apache.hadoop.yarn.server.resourcemanager.scheduler.capacity.CapacityScheduler: Application Attempt appattempt_1536878829533_0006_000001 is done. finalState=FINISHED
2018-09-19 11:59:58,573 INFO org.apache.hadoop.yarn.server.resourcemanager.RMAuditLogger: USER=jason	OPERATION=Application Finished - Succeeded	TARGET=RMAppManager	RESULT=SUCCESS	APPID=application_1536878829533_0006
2018-09-19 11:59:58,573 INFO org.apache.hadoop.yarn.server.resourcemanager.scheduler.AppSchedulingInfo: Application application_1536878829533_0006 requests cleared
2018-09-19 11:59:58,574 INFO org.apache.hadoop.yarn.server.resourcemanager.scheduler.capacity.LeafQueue: Application removed - appId: application_1536878829533_0006 user: jason queue: default #user-pending-applications: 0 #user-active-applications: 0 #queue-pending-applications: 0 #queue-active-applications: 0
2018-09-19 11:59:58,574 INFO org.apache.hadoop.yarn.server.resourcemanager.scheduler.capacity.ParentQueue: Application removed - appId: application_1536878829533_0006 user: jason leaf-queue of parent: root #applications: 0
2018-09-19 11:59:58,574 INFO org.apache.hadoop.yarn.server.resourcemanager.RMAppManager$ApplicationSummary: appId=application_1536878829533_0006,name=word count,user=jason,queue=default,state=FINISHED,trackingUrl=http://Jasons-MacBook-Pro.local:8088/proxy/application_1536878829533_0006/,appMasterHost=192.168.1.103,startTime=1537376375829,finishTime=1537376392384,finalStatus=SUCCEEDED,memorySeconds=99471,vcoreSeconds=68,preemptedMemorySeconds=0,preemptedVcoreSeconds=0,preemptedAMContainers=0,preemptedNonAMContainers=0,preemptedResources=<memory:0\, vCores:0>,applicationType=MAPREDUCE
2018-09-19 11:59:58,574 INFO org.apache.hadoop.yarn.server.resourcemanager.amlauncher.AMLauncher: Cleaning master appattempt_1536878829533_0006_000001
2018-09-19 12:00:00,575 INFO org.apache.hadoop.yarn.server.resourcemanager.scheduler.AbstractYarnScheduler: Container container_1536878829533_0006_01_000010 completed with event FINISHED, but corresponding RMContainer doesn't exist.
2018-09-19 12:00:00,576 INFO org.apache.hadoop.yarn.server.resourcemanager.scheduler.AbstractYarnScheduler: Container container_1536878829533_0006_01_000008 completed with event FINISHED, but corresponding RMContainer doesn't exist.
2018-09-19 12:00:00,576 INFO org.apache.hadoop.yarn.server.resourcemanager.scheduler.AbstractYarnScheduler: Container container_1536878829533_0006_01_000009 completed with event FINISHED, but corresponding RMContainer doesn't exist.