2018-09-06 20:27:41,537 INFO org.apache.hadoop.yarn.server.resourcemanager.ResourceManager: STARTUP_MSG: 
/************************************************************
STARTUP_MSG: Starting ResourceManager
STARTUP_MSG:   user = jason
STARTUP_MSG:   host = Jasons-MacBook-Pro.local/192.168.1.103
STARTUP_MSG:   args = []
STARTUP_MSG:   version = 2.8.1
STARTUP_MSG:   build = https://git-wip-us.apache.org/repos/asf/hadoop.git -r 20fe5304904fc2f5a18053c389e43cd26f7a70fe; compiled by 'vinodkv' on 2017-06-02T06:14Z
STARTUP_MSG:   java = 10.0.2
************************************************************/
2018-09-06 20:27:41,548 INFO org.apache.hadoop.yarn.server.resourcemanager.ResourceManager: registered UNIX signal handlers for [TERM, HUP, INT]
2018-09-06 20:27:41,869 INFO org.apache.hadoop.conf.Configuration: found resource core-site.xml at file:/Users/jason/hadoop-2.8.1/etc/hadoop/core-site.xml
2018-09-06 20:27:41,913 WARN org.apache.hadoop.util.NativeCodeLoader: Unable to load native-hadoop library for your platform... using builtin-java classes where applicable
2018-09-06 20:27:41,938 INFO org.apache.hadoop.security.Groups: clearing userToGroupsMap cache
2018-09-06 20:27:42,010 INFO org.apache.hadoop.conf.Configuration: found resource yarn-site.xml at file:/Users/jason/hadoop-2.8.1/etc/hadoop/yarn-site.xml
2018-09-06 20:27:42,240 INFO org.apache.hadoop.yarn.event.AsyncDispatcher: Registering class org.apache.hadoop.yarn.server.resourcemanager.RMFatalEventType for class org.apache.hadoop.yarn.server.resourcemanager.ResourceManager$RMFatalEventDispatcher
2018-09-06 20:27:42,300 INFO org.apache.hadoop.yarn.server.resourcemanager.security.NMTokenSecretManagerInRM: NMTokenKeyRollingInterval: 86400000ms and NMTokenKeyActivationDelay: 900000ms
2018-09-06 20:27:42,306 INFO org.apache.hadoop.yarn.server.resourcemanager.security.RMContainerTokenSecretManager: ContainerTokenKeyRollingInterval: 86400000ms and ContainerTokenKeyActivationDelay: 900000ms
2018-09-06 20:27:42,311 INFO org.apache.hadoop.yarn.server.resourcemanager.security.AMRMTokenSecretManager: AMRMTokenKeyRollingInterval: 86400000ms and AMRMTokenKeyActivationDelay: 900000 ms
2018-09-06 20:27:42,346 INFO org.apache.hadoop.yarn.event.AsyncDispatcher: Registering class org.apache.hadoop.yarn.server.resourcemanager.recovery.RMStateStoreEventType for class org.apache.hadoop.yarn.server.resourcemanager.recovery.RMStateStore$ForwardingEventHandler
2018-09-06 20:27:42,349 INFO org.apache.hadoop.yarn.event.AsyncDispatcher: Registering class org.apache.hadoop.yarn.server.resourcemanager.NodesListManagerEventType for class org.apache.hadoop.yarn.server.resourcemanager.NodesListManager
2018-09-06 20:27:42,349 INFO org.apache.hadoop.yarn.server.resourcemanager.ResourceManager: Using Scheduler: org.apache.hadoop.yarn.server.resourcemanager.scheduler.capacity.CapacityScheduler
2018-09-06 20:27:42,378 INFO org.apache.hadoop.yarn.event.AsyncDispatcher: Registering class org.apache.hadoop.yarn.server.resourcemanager.scheduler.event.SchedulerEventType for class org.apache.hadoop.yarn.server.resourcemanager.ResourceManager$SchedulerEventDispatcher
2018-09-06 20:27:42,380 INFO org.apache.hadoop.yarn.event.AsyncDispatcher: Registering class org.apache.hadoop.yarn.server.resourcemanager.rmapp.RMAppEventType for class org.apache.hadoop.yarn.server.resourcemanager.ResourceManager$ApplicationEventDispatcher
2018-09-06 20:27:42,380 INFO org.apache.hadoop.yarn.event.AsyncDispatcher: Registering class org.apache.hadoop.yarn.server.resourcemanager.rmapp.attempt.RMAppAttemptEventType for class org.apache.hadoop.yarn.server.resourcemanager.ResourceManager$ApplicationAttemptEventDispatcher
2018-09-06 20:27:42,382 INFO org.apache.hadoop.yarn.event.AsyncDispatcher: Registering class org.apache.hadoop.yarn.server.resourcemanager.rmnode.RMNodeEventType for class org.apache.hadoop.yarn.server.resourcemanager.ResourceManager$NodeEventDispatcher
2018-09-06 20:27:42,446 INFO org.apache.hadoop.metrics2.impl.MetricsConfig: loaded properties from hadoop-metrics2.properties
2018-09-06 20:27:42,578 INFO org.apache.hadoop.metrics2.impl.MetricsSystemImpl: Scheduled Metric snapshot period at 10 second(s).
2018-09-06 20:27:42,578 INFO org.apache.hadoop.metrics2.impl.MetricsSystemImpl: ResourceManager metrics system started
2018-09-06 20:27:42,600 INFO org.apache.hadoop.yarn.event.AsyncDispatcher: Registering class org.apache.hadoop.yarn.server.resourcemanager.RMAppManagerEventType for class org.apache.hadoop.yarn.server.resourcemanager.RMAppManager
2018-09-06 20:27:42,609 INFO org.apache.hadoop.yarn.event.AsyncDispatcher: Registering class org.apache.hadoop.yarn.server.resourcemanager.amlauncher.AMLauncherEventType for class org.apache.hadoop.yarn.server.resourcemanager.amlauncher.ApplicationMasterLauncher
2018-09-06 20:27:42,612 INFO org.apache.hadoop.yarn.server.resourcemanager.RMNMInfo: Registered RMNMInfo MBean
2018-09-06 20:27:42,620 INFO org.apache.hadoop.yarn.security.YarnAuthorizationProvider: org.apache.hadoop.yarn.security.ConfiguredYarnAuthorizer is instiantiated.
2018-09-06 20:27:42,621 INFO org.apache.hadoop.util.HostsFileReader: Refreshing hosts (include/exclude) list
2018-09-06 20:27:42,628 INFO org.apache.hadoop.conf.Configuration: found resource capacity-scheduler.xml at file:/Users/jason/hadoop-2.8.1/etc/hadoop/capacity-scheduler.xml
2018-09-06 20:27:42,677 INFO org.apache.hadoop.yarn.server.resourcemanager.scheduler.capacity.CapacitySchedulerConfiguration: max alloc mb per queue for root is undefined
2018-09-06 20:27:42,677 INFO org.apache.hadoop.yarn.server.resourcemanager.scheduler.capacity.CapacitySchedulerConfiguration: max alloc vcore per queue for root is undefined
2018-09-06 20:27:42,687 INFO org.apache.hadoop.yarn.server.resourcemanager.scheduler.capacity.ParentQueue: root, capacity=1.0, asboluteCapacity=1.0, maxCapacity=1.0, asboluteMaxCapacity=1.0, state=RUNNING, acls=SUBMIT_APP:*ADMINISTER_QUEUE:*, labels=*,, offswitchPerHeartbeatLimit = 1, reservationsContinueLooking=true
2018-09-06 20:27:42,687 INFO org.apache.hadoop.yarn.server.resourcemanager.scheduler.capacity.ParentQueue: Initialized parent-queue root name=root, fullname=root
2018-09-06 20:27:42,701 INFO org.apache.hadoop.yarn.server.resourcemanager.scheduler.capacity.CapacitySchedulerConfiguration: max alloc mb per queue for root.default is undefined
2018-09-06 20:27:42,701 INFO org.apache.hadoop.yarn.server.resourcemanager.scheduler.capacity.CapacitySchedulerConfiguration: max alloc vcore per queue for root.default is undefined
2018-09-06 20:27:42,703 INFO org.apache.hadoop.yarn.server.resourcemanager.scheduler.capacity.LeafQueue: Initializing default
capacity = 1.0 [= (float) configuredCapacity / 100 ]
asboluteCapacity = 1.0 [= parentAbsoluteCapacity * capacity ]
maxCapacity = 1.0 [= configuredMaxCapacity ]
absoluteMaxCapacity = 1.0 [= 1.0 maximumCapacity undefined, (parentAbsoluteMaxCapacity * maximumCapacity) / 100 otherwise ]
userLimit = 100 [= configuredUserLimit ]
userLimitFactor = 1.0 [= configuredUserLimitFactor ]
maxApplications = 10000 [= configuredMaximumSystemApplicationsPerQueue or (int)(configuredMaximumSystemApplications * absoluteCapacity)]
maxApplicationsPerUser = 10000 [= (int)(maxApplications * (userLimit / 100.0f) * userLimitFactor) ]
usedCapacity = 0.0 [= usedResourcesMemory / (clusterResourceMemory * absoluteCapacity)]
absoluteUsedCapacity = 0.0 [= usedResourcesMemory / clusterResourceMemory]
maxAMResourcePerQueuePercent = 0.1 [= configuredMaximumAMResourcePercent ]
minimumAllocationFactor = 0.875 [= (float)(maximumAllocationMemory - minimumAllocationMemory) / maximumAllocationMemory ]
maximumAllocation = <memory:8192, vCores:4> [= configuredMaxAllocation ]
numContainers = 0 [= currentNumContainers ]
state = RUNNING [= configuredState ]
acls = SUBMIT_APP:*ADMINISTER_QUEUE:* [= configuredAcls ]
nodeLocalityDelay = 40
labels=*,
reservationsContinueLooking = true
preemptionDisabled = true
defaultAppPriorityPerQueue = 0
2018-09-06 20:27:42,703 INFO org.apache.hadoop.yarn.server.resourcemanager.scheduler.capacity.CapacityScheduler: Initialized queue: default: capacity=1.0, absoluteCapacity=1.0, usedResources=<memory:0, vCores:0>, usedCapacity=0.0, absoluteUsedCapacity=0.0, numApps=0, numContainers=0
2018-09-06 20:27:42,703 INFO org.apache.hadoop.yarn.server.resourcemanager.scheduler.capacity.CapacityScheduler: Initialized queue: root: numChildQueue= 1, capacity=1.0, absoluteCapacity=1.0, usedResources=<memory:0, vCores:0>usedCapacity=0.0, numApps=0, numContainers=0
2018-09-06 20:27:42,703 INFO org.apache.hadoop.yarn.server.resourcemanager.scheduler.capacity.CapacityScheduler: Initialized root queue root: numChildQueue= 1, capacity=1.0, absoluteCapacity=1.0, usedResources=<memory:0, vCores:0>usedCapacity=0.0, numApps=0, numContainers=0
2018-09-06 20:27:42,704 INFO org.apache.hadoop.yarn.server.resourcemanager.scheduler.capacity.CapacityScheduler: Initialized queue mappings, override: false
2018-09-06 20:27:42,705 INFO org.apache.hadoop.yarn.server.resourcemanager.scheduler.capacity.CapacityScheduler: Initialized CapacityScheduler with calculator=class org.apache.hadoop.yarn.util.resource.DefaultResourceCalculator, minimumAllocation=<<memory:1024, vCores:1>>, maximumAllocation=<<memory:8192, vCores:4>>, asynchronousScheduling=false, asyncScheduleInterval=5ms
2018-09-06 20:27:42,708 INFO org.apache.hadoop.conf.Configuration: dynamic-resources.xml not found
2018-09-06 20:27:42,718 INFO org.apache.hadoop.yarn.server.resourcemanager.metrics.SystemMetricsPublisher: YARN system metrics publishing service is not enabled
2018-09-06 20:27:42,719 INFO org.apache.hadoop.yarn.server.resourcemanager.ResourceManager: Transitioning to active state
2018-09-06 20:27:42,729 INFO org.apache.hadoop.util.JvmPauseMonitor: Starting JVM pause monitor
2018-09-06 20:27:42,744 INFO org.apache.hadoop.yarn.server.resourcemanager.recovery.RMStateStore: Updating AMRMToken
2018-09-06 20:27:42,744 INFO org.apache.hadoop.yarn.server.resourcemanager.security.RMContainerTokenSecretManager: Rolling master-key for container-tokens
2018-09-06 20:27:42,744 INFO org.apache.hadoop.yarn.server.resourcemanager.security.NMTokenSecretManagerInRM: Rolling master-key for nm-tokens
2018-09-06 20:27:42,745 INFO org.apache.hadoop.security.token.delegation.AbstractDelegationTokenSecretManager: Updating the current master key for generating delegation tokens
2018-09-06 20:27:42,747 INFO org.apache.hadoop.yarn.server.resourcemanager.security.RMDelegationTokenSecretManager: storing master key with keyID 1
2018-09-06 20:27:42,747 INFO org.apache.hadoop.yarn.server.resourcemanager.recovery.RMStateStore: Storing RMDTMasterKey.
2018-09-06 20:27:42,747 INFO org.apache.hadoop.security.token.delegation.AbstractDelegationTokenSecretManager: Starting expired delegation token remover thread, tokenRemoverScanInterval=60 min(s)
2018-09-06 20:27:42,748 INFO org.apache.hadoop.security.token.delegation.AbstractDelegationTokenSecretManager: Updating the current master key for generating delegation tokens
2018-09-06 20:27:42,749 INFO org.apache.hadoop.yarn.server.resourcemanager.security.RMDelegationTokenSecretManager: storing master key with keyID 2
2018-09-06 20:27:42,749 INFO org.apache.hadoop.yarn.server.resourcemanager.recovery.RMStateStore: Storing RMDTMasterKey.
2018-09-06 20:27:42,751 INFO org.apache.hadoop.yarn.event.AsyncDispatcher: Registering class org.apache.hadoop.yarn.nodelabels.event.NodeLabelsStoreEventType for class org.apache.hadoop.yarn.nodelabels.CommonNodeLabelsManager$ForwardingEventHandler
2018-09-06 20:27:42,792 INFO org.apache.hadoop.ipc.CallQueueManager: Using callQueue: class java.util.concurrent.LinkedBlockingQueue queueCapacity: 5000 scheduler: class org.apache.hadoop.ipc.DefaultRpcScheduler
2018-09-06 20:27:42,822 INFO org.apache.hadoop.ipc.Server: Starting Socket Reader #1 for port 8031
2018-09-06 20:27:43,028 INFO org.apache.hadoop.yarn.factories.impl.pb.RpcServerFactoryPBImpl: Adding protocol org.apache.hadoop.yarn.server.api.ResourceTrackerPB to the server
2018-09-06 20:27:43,028 INFO org.apache.hadoop.ipc.Server: IPC Server Responder: starting
2018-09-06 20:27:43,028 INFO org.apache.hadoop.ipc.Server: IPC Server listener on 8031: starting
2018-09-06 20:27:43,054 INFO org.apache.hadoop.ipc.CallQueueManager: Using callQueue: class java.util.concurrent.LinkedBlockingQueue queueCapacity: 5000 scheduler: class org.apache.hadoop.ipc.DefaultRpcScheduler
2018-09-06 20:27:43,060 INFO org.apache.hadoop.ipc.Server: Starting Socket Reader #1 for port 8030
2018-09-06 20:27:43,082 INFO org.apache.hadoop.yarn.factories.impl.pb.RpcServerFactoryPBImpl: Adding protocol org.apache.hadoop.yarn.api.ApplicationMasterProtocolPB to the server
2018-09-06 20:27:43,082 INFO org.apache.hadoop.ipc.Server: IPC Server Responder: starting
2018-09-06 20:27:43,082 INFO org.apache.hadoop.ipc.Server: IPC Server listener on 8030: starting
2018-09-06 20:27:43,161 INFO org.apache.hadoop.ipc.CallQueueManager: Using callQueue: class java.util.concurrent.LinkedBlockingQueue queueCapacity: 5000 scheduler: class org.apache.hadoop.ipc.DefaultRpcScheduler
2018-09-06 20:27:43,161 INFO org.apache.hadoop.ipc.Server: Starting Socket Reader #1 for port 8032
2018-09-06 20:27:43,165 INFO org.apache.hadoop.yarn.factories.impl.pb.RpcServerFactoryPBImpl: Adding protocol org.apache.hadoop.yarn.api.ApplicationClientProtocolPB to the server
2018-09-06 20:27:43,165 INFO org.apache.hadoop.ipc.Server: IPC Server Responder: starting
2018-09-06 20:27:43,165 INFO org.apache.hadoop.ipc.Server: IPC Server listener on 8032: starting
2018-09-06 20:27:43,172 INFO org.apache.hadoop.yarn.server.resourcemanager.ResourceManager: Transitioned to active state
2018-09-06 20:27:43,274 INFO org.mortbay.log: Logging to org.slf4j.impl.Log4jLoggerAdapter(org.mortbay.log) via org.mortbay.log.Slf4jLog
2018-09-06 20:27:43,282 INFO org.apache.hadoop.security.authentication.server.AuthenticationFilter: Unable to initialize FileSignerSecretProvider, falling back to use random secrets.
2018-09-06 20:27:43,288 INFO org.apache.hadoop.http.HttpRequestLog: Http request log for http.requests.resourcemanager is not defined
2018-09-06 20:27:43,297 INFO org.apache.hadoop.http.HttpServer2: Added global filter 'safety' (class=org.apache.hadoop.http.HttpServer2$QuotingInputFilter)
2018-09-06 20:27:43,300 INFO org.apache.hadoop.http.HttpServer2: Added filter RMAuthenticationFilter (class=org.apache.hadoop.yarn.server.security.http.RMAuthenticationFilter) to context cluster
2018-09-06 20:27:43,300 INFO org.apache.hadoop.http.HttpServer2: Added filter RMAuthenticationFilter (class=org.apache.hadoop.yarn.server.security.http.RMAuthenticationFilter) to context static
2018-09-06 20:27:43,300 INFO org.apache.hadoop.http.HttpServer2: Added filter RMAuthenticationFilter (class=org.apache.hadoop.yarn.server.security.http.RMAuthenticationFilter) to context logs
2018-09-06 20:27:43,300 INFO org.apache.hadoop.http.HttpServer2: Added filter static_user_filter (class=org.apache.hadoop.http.lib.StaticUserWebFilter$StaticUserFilter) to context cluster
2018-09-06 20:27:43,300 INFO org.apache.hadoop.http.HttpServer2: Added filter static_user_filter (class=org.apache.hadoop.http.lib.StaticUserWebFilter$StaticUserFilter) to context static
2018-09-06 20:27:43,301 INFO org.apache.hadoop.http.HttpServer2: Added filter static_user_filter (class=org.apache.hadoop.http.lib.StaticUserWebFilter$StaticUserFilter) to context logs
2018-09-06 20:27:43,305 INFO org.apache.hadoop.http.HttpServer2: adding path spec: /cluster/*
2018-09-06 20:27:43,305 INFO org.apache.hadoop.http.HttpServer2: adding path spec: /ws/*
2018-09-06 20:27:43,650 INFO org.apache.hadoop.yarn.webapp.WebApps: Registered webapp guice modules
2018-09-06 20:27:43,654 INFO org.apache.hadoop.http.HttpServer2: Jetty bound to port 8088
2018-09-06 20:27:43,654 INFO org.mortbay.log: jetty-6.1.26
2018-09-06 20:27:43,689 INFO org.mortbay.log: Extract jar:file:/Users/jason/hadoop-2.8.1/share/hadoop/yarn/hadoop-yarn-common-2.8.1.jar!/webapps/cluster to /var/folders/7r/3c0pxtpd0rg5hjs32v2rrz_00000gn/T/Jetty_0_0_0_0_8088_cluster____u0rgz3/webapp
2018-09-06 20:27:43,791 INFO org.apache.hadoop.security.token.delegation.AbstractDelegationTokenSecretManager: Updating the current master key for generating delegation tokens
2018-09-06 20:27:43,791 INFO org.apache.hadoop.security.token.delegation.AbstractDelegationTokenSecretManager: Starting expired delegation token remover thread, tokenRemoverScanInterval=60 min(s)
2018-09-06 20:27:43,792 INFO org.apache.hadoop.security.token.delegation.AbstractDelegationTokenSecretManager: Updating the current master key for generating delegation tokens
2018-09-06 20:27:44,726 INFO org.mortbay.log: Started HttpServer2$SelectChannelConnectorWithSafeStartup@0.0.0.0:8088
2018-09-06 20:27:44,726 INFO org.apache.hadoop.yarn.webapp.WebApps: Web app cluster started at 8088
2018-09-06 20:27:44,768 INFO org.apache.hadoop.ipc.CallQueueManager: Using callQueue: class java.util.concurrent.LinkedBlockingQueue queueCapacity: 100 scheduler: class org.apache.hadoop.ipc.DefaultRpcScheduler
2018-09-06 20:27:44,768 INFO org.apache.hadoop.ipc.Server: Starting Socket Reader #1 for port 8033
2018-09-06 20:27:44,771 INFO org.apache.hadoop.yarn.factories.impl.pb.RpcServerFactoryPBImpl: Adding protocol org.apache.hadoop.yarn.server.api.ResourceManagerAdministrationProtocolPB to the server
2018-09-06 20:27:44,772 INFO org.apache.hadoop.ipc.Server: IPC Server Responder: starting
2018-09-06 20:27:44,772 INFO org.apache.hadoop.ipc.Server: IPC Server listener on 8033: starting
2018-09-06 20:31:29,324 INFO org.apache.hadoop.yarn.server.resourcemanager.ResourceTrackerService: NodeManager from node 192.168.1.103(cmPort: 59206 httpPort: 8042) registered with capability: <memory:8192, vCores:8>, assigned nodeId 192.168.1.103:59206
2018-09-06 20:31:29,333 INFO org.apache.hadoop.yarn.server.resourcemanager.rmnode.RMNodeImpl: 192.168.1.103:59206 Node Transitioned from NEW to RUNNING
2018-09-06 20:31:29,340 INFO org.apache.hadoop.yarn.server.resourcemanager.scheduler.capacity.CapacityScheduler: Added node 192.168.1.103:59206 clusterResource: <memory:8192, vCores:8>
2018-09-06 20:37:42,630 INFO org.apache.hadoop.yarn.server.resourcemanager.scheduler.AbstractYarnScheduler: Release request cache is cleaned up
2018-09-06 20:53:07,095 INFO org.apache.hadoop.yarn.server.resourcemanager.ClientRMService: Allocated new applicationId: 1
2018-09-06 20:53:07,931 INFO org.apache.hadoop.yarn.server.resourcemanager.scheduler.capacity.CapacityScheduler: Application 'application_1536283662720_0001' is submitted without priority hence considering default queue/cluster priority: 0
2018-09-06 20:53:07,931 INFO org.apache.hadoop.yarn.server.resourcemanager.scheduler.capacity.CapacityScheduler: Priority '0' is acceptable in queue : default for application: application_1536283662720_0001 for the user: jason
2018-09-06 20:53:07,948 INFO org.apache.hadoop.yarn.server.resourcemanager.ClientRMService: Application with id 1 submitted by user jason
2018-09-06 20:53:07,948 INFO org.apache.hadoop.yarn.server.resourcemanager.rmapp.RMAppImpl: Storing application with id application_1536283662720_0001
2018-09-06 20:53:07,950 INFO org.apache.hadoop.yarn.server.resourcemanager.RMAuditLogger: USER=jason	IP=192.168.1.103	OPERATION=Submit Application Request	TARGET=ClientRMService	RESULT=SUCCESS	APPID=application_1536283662720_0001
2018-09-06 20:53:07,958 INFO org.apache.hadoop.yarn.server.resourcemanager.rmapp.RMAppImpl: application_1536283662720_0001 State change from NEW to NEW_SAVING on event=START
2018-09-06 20:53:07,958 INFO org.apache.hadoop.yarn.server.resourcemanager.recovery.RMStateStore: Storing info for app: application_1536283662720_0001
2018-09-06 20:53:07,960 INFO org.apache.hadoop.yarn.server.resourcemanager.rmapp.RMAppImpl: application_1536283662720_0001 State change from NEW_SAVING to SUBMITTED on event=APP_NEW_SAVED
2018-09-06 20:53:07,963 INFO org.apache.hadoop.yarn.server.resourcemanager.scheduler.capacity.ParentQueue: Application added - appId: application_1536283662720_0001 user: jason leaf-queue of parent: root #applications: 1
2018-09-06 20:53:07,964 INFO org.apache.hadoop.yarn.server.resourcemanager.scheduler.capacity.CapacityScheduler: Accepted application application_1536283662720_0001 from user: jason, in queue: default
2018-09-06 20:53:07,990 INFO org.apache.hadoop.yarn.server.resourcemanager.rmapp.RMAppImpl: application_1536283662720_0001 State change from SUBMITTED to ACCEPTED on event=APP_ACCEPTED
2018-09-06 20:53:08,023 INFO org.apache.hadoop.yarn.server.resourcemanager.ApplicationMasterService: Registering app attempt : appattempt_1536283662720_0001_000001
2018-09-06 20:53:08,024 INFO org.apache.hadoop.yarn.server.resourcemanager.rmapp.attempt.RMAppAttemptImpl: appattempt_1536283662720_0001_000001 State change from NEW to SUBMITTED
2018-09-06 20:53:08,043 WARN org.apache.hadoop.yarn.server.resourcemanager.scheduler.capacity.LeafQueue: maximum-am-resource-percent is insufficient to start a single application in queue, it is likely set too low. skipping enforcement to allow at least one application to start
2018-09-06 20:53:08,043 WARN org.apache.hadoop.yarn.server.resourcemanager.scheduler.capacity.LeafQueue: maximum-am-resource-percent is insufficient to start a single application in queue for user, it is likely set too low. skipping enforcement to allow at least one application to start
2018-09-06 20:53:08,046 INFO org.apache.hadoop.yarn.server.resourcemanager.scheduler.capacity.LeafQueue: Application application_1536283662720_0001 from user: jason activated in queue: default
2018-09-06 20:53:08,046 INFO org.apache.hadoop.yarn.server.resourcemanager.scheduler.capacity.LeafQueue: Application added - appId: application_1536283662720_0001 user: jason, leaf-queue: default #user-pending-applications: 0 #user-active-applications: 1 #queue-pending-applications: 0 #queue-active-applications: 1
2018-09-06 20:53:08,047 INFO org.apache.hadoop.yarn.server.resourcemanager.scheduler.capacity.CapacityScheduler: Added Application Attempt appattempt_1536283662720_0001_000001 to scheduler from user jason in queue default
2018-09-06 20:53:08,048 INFO org.apache.hadoop.yarn.server.resourcemanager.rmapp.attempt.RMAppAttemptImpl: appattempt_1536283662720_0001_000001 State change from SUBMITTED to SCHEDULED
2018-09-06 20:53:08,513 INFO org.apache.hadoop.yarn.server.resourcemanager.rmcontainer.RMContainerImpl: container_1536283662720_0001_01_000001 Container Transitioned from NEW to ALLOCATED
2018-09-06 20:53:08,513 INFO org.apache.hadoop.yarn.server.resourcemanager.RMAuditLogger: USER=jason	OPERATION=AM Allocated Container	TARGET=SchedulerApp	RESULT=SUCCESS	APPID=application_1536283662720_0001	CONTAINERID=container_1536283662720_0001_01_000001
2018-09-06 20:53:08,514 INFO org.apache.hadoop.yarn.server.resourcemanager.scheduler.SchedulerNode: Assigned container container_1536283662720_0001_01_000001 of capacity <memory:2048, vCores:1> on host 192.168.1.103:59206, which has 1 containers, <memory:2048, vCores:1> used and <memory:6144, vCores:7> available after allocation
2018-09-06 20:53:08,514 INFO org.apache.hadoop.yarn.server.resourcemanager.scheduler.capacity.allocator.AbstractContainerAllocator: assignedContainer application attempt=appattempt_1536283662720_0001_000001 container=container_1536283662720_0001_01_000001 queue=org.apache.hadoop.yarn.server.resourcemanager.scheduler.capacity.allocator.RegularContainerAllocator@265609d0 clusterResource=<memory:8192, vCores:8> type=OFF_SWITCH
2018-09-06 20:53:08,533 INFO org.apache.hadoop.yarn.server.resourcemanager.security.NMTokenSecretManagerInRM: Sending NMToken for nodeId : 192.168.1.103:59206 for container : container_1536283662720_0001_01_000001
2018-09-06 20:53:08,541 INFO org.apache.hadoop.yarn.server.resourcemanager.rmcontainer.RMContainerImpl: container_1536283662720_0001_01_000001 Container Transitioned from ALLOCATED to ACQUIRED
2018-09-06 20:53:08,541 INFO org.apache.hadoop.yarn.server.resourcemanager.security.NMTokenSecretManagerInRM: Clear node set for appattempt_1536283662720_0001_000001
2018-09-06 20:53:08,541 INFO org.apache.hadoop.yarn.server.resourcemanager.scheduler.capacity.ParentQueue: Re-sorting assigned queue: root.default stats: default: capacity=1.0, absoluteCapacity=1.0, usedResources=<memory:2048, vCores:1>, usedCapacity=0.25, absoluteUsedCapacity=0.25, numApps=1, numContainers=1
2018-09-06 20:53:08,542 INFO org.apache.hadoop.yarn.server.resourcemanager.rmapp.attempt.RMAppAttemptImpl: Storing attempt: AppId: application_1536283662720_0001 AttemptId: appattempt_1536283662720_0001_000001 MasterContainer: Container: [ContainerId: container_1536283662720_0001_01_000001, Version: 0, NodeId: 192.168.1.103:59206, NodeHttpAddress: 192.168.1.103:8042, Resource: <memory:2048, vCores:1>, Priority: 0, Token: Token { kind: ContainerToken, service: 192.168.1.103:59206 }, ]
2018-09-06 20:53:08,542 INFO org.apache.hadoop.yarn.server.resourcemanager.scheduler.capacity.ParentQueue: assignedContainer queue=root usedCapacity=0.25 absoluteUsedCapacity=0.25 used=<memory:2048, vCores:1> cluster=<memory:8192, vCores:8>
2018-09-06 20:53:08,551 INFO org.apache.hadoop.yarn.server.resourcemanager.rmapp.attempt.RMAppAttemptImpl: appattempt_1536283662720_0001_000001 State change from SCHEDULED to ALLOCATED_SAVING
2018-09-06 20:53:08,555 INFO org.apache.hadoop.yarn.server.resourcemanager.rmapp.attempt.RMAppAttemptImpl: appattempt_1536283662720_0001_000001 State change from ALLOCATED_SAVING to ALLOCATED
2018-09-06 20:53:08,558 INFO org.apache.hadoop.yarn.server.resourcemanager.amlauncher.AMLauncher: Launching masterappattempt_1536283662720_0001_000001
2018-09-06 20:53:08,604 INFO org.apache.hadoop.yarn.server.resourcemanager.amlauncher.AMLauncher: Setting up container Container: [ContainerId: container_1536283662720_0001_01_000001, Version: 0, NodeId: 192.168.1.103:59206, NodeHttpAddress: 192.168.1.103:8042, Resource: <memory:2048, vCores:1>, Priority: 0, Token: Token { kind: ContainerToken, service: 192.168.1.103:59206 }, ] for AM appattempt_1536283662720_0001_000001
2018-09-06 20:53:08,604 INFO org.apache.hadoop.yarn.server.resourcemanager.security.AMRMTokenSecretManager: Create AMRMToken for ApplicationAttempt: appattempt_1536283662720_0001_000001
2018-09-06 20:53:08,606 INFO org.apache.hadoop.yarn.server.resourcemanager.security.AMRMTokenSecretManager: Creating password for appattempt_1536283662720_0001_000001
2018-09-06 20:53:08,852 INFO org.apache.hadoop.yarn.server.resourcemanager.amlauncher.AMLauncher: Done launching container Container: [ContainerId: container_1536283662720_0001_01_000001, Version: 0, NodeId: 192.168.1.103:59206, NodeHttpAddress: 192.168.1.103:8042, Resource: <memory:2048, vCores:1>, Priority: 0, Token: Token { kind: ContainerToken, service: 192.168.1.103:59206 }, ] for AM appattempt_1536283662720_0001_000001
2018-09-06 20:53:08,852 INFO org.apache.hadoop.yarn.server.resourcemanager.rmapp.attempt.RMAppAttemptImpl: appattempt_1536283662720_0001_000001 State change from ALLOCATED to LAUNCHED
2018-09-06 20:53:09,500 INFO org.apache.hadoop.yarn.server.resourcemanager.rmcontainer.RMContainerImpl: container_1536283662720_0001_01_000001 Container Transitioned from ACQUIRED to RUNNING
2018-09-06 20:53:13,749 INFO SecurityLogger.org.apache.hadoop.ipc.Server: Auth successful for appattempt_1536283662720_0001_000001 (auth:SIMPLE)
2018-09-06 20:53:13,758 INFO org.apache.hadoop.yarn.server.resourcemanager.ApplicationMasterService: AM registration appattempt_1536283662720_0001_000001
2018-09-06 20:53:13,759 INFO org.apache.hadoop.yarn.server.resourcemanager.RMAuditLogger: USER=jason	IP=192.168.1.103	OPERATION=Register App Master	TARGET=ApplicationMasterService	RESULT=SUCCESS	APPID=application_1536283662720_0001	APPATTEMPTID=appattempt_1536283662720_0001_000001
2018-09-06 20:53:13,759 INFO org.apache.hadoop.yarn.server.resourcemanager.rmapp.attempt.RMAppAttemptImpl: appattempt_1536283662720_0001_000001 State change from LAUNCHED to RUNNING
2018-09-06 20:53:13,759 INFO org.apache.hadoop.yarn.server.resourcemanager.rmapp.RMAppImpl: application_1536283662720_0001 State change from ACCEPTED to RUNNING on event=ATTEMPT_REGISTERED
2018-09-06 20:53:15,515 INFO org.apache.hadoop.yarn.server.resourcemanager.rmcontainer.RMContainerImpl: container_1536283662720_0001_01_000002 Container Transitioned from NEW to ALLOCATED
2018-09-06 20:53:15,515 INFO org.apache.hadoop.yarn.server.resourcemanager.RMAuditLogger: USER=jason	OPERATION=AM Allocated Container	TARGET=SchedulerApp	RESULT=SUCCESS	APPID=application_1536283662720_0001	CONTAINERID=container_1536283662720_0001_01_000002
2018-09-06 20:53:15,515 INFO org.apache.hadoop.yarn.server.resourcemanager.scheduler.SchedulerNode: Assigned container container_1536283662720_0001_01_000002 of capacity <memory:1024, vCores:1> on host 192.168.1.103:59206, which has 2 containers, <memory:3072, vCores:2> used and <memory:5120, vCores:6> available after allocation
2018-09-06 20:53:15,515 INFO org.apache.hadoop.yarn.server.resourcemanager.scheduler.capacity.allocator.AbstractContainerAllocator: assignedContainer application attempt=appattempt_1536283662720_0001_000001 container=container_1536283662720_0001_01_000002 queue=org.apache.hadoop.yarn.server.resourcemanager.scheduler.capacity.allocator.RegularContainerAllocator@265609d0 clusterResource=<memory:8192, vCores:8> type=NODE_LOCAL
2018-09-06 20:53:15,516 INFO org.apache.hadoop.yarn.server.resourcemanager.scheduler.capacity.ParentQueue: Re-sorting assigned queue: root.default stats: default: capacity=1.0, absoluteCapacity=1.0, usedResources=<memory:3072, vCores:2>, usedCapacity=0.375, absoluteUsedCapacity=0.375, numApps=1, numContainers=2
2018-09-06 20:53:15,516 INFO org.apache.hadoop.yarn.server.resourcemanager.scheduler.capacity.ParentQueue: assignedContainer queue=root usedCapacity=0.375 absoluteUsedCapacity=0.375 used=<memory:3072, vCores:2> cluster=<memory:8192, vCores:8>
2018-09-06 20:53:15,830 INFO org.apache.hadoop.yarn.server.resourcemanager.security.NMTokenSecretManagerInRM: Sending NMToken for nodeId : 192.168.1.103:59206 for container : container_1536283662720_0001_01_000002
2018-09-06 20:53:15,831 INFO org.apache.hadoop.yarn.server.resourcemanager.rmcontainer.RMContainerImpl: container_1536283662720_0001_01_000002 Container Transitioned from ALLOCATED to ACQUIRED
2018-09-06 20:53:16,518 INFO org.apache.hadoop.yarn.server.resourcemanager.rmcontainer.RMContainerImpl: container_1536283662720_0001_01_000002 Container Transitioned from ACQUIRED to RUNNING
2018-09-06 20:53:16,849 INFO org.apache.hadoop.yarn.server.resourcemanager.scheduler.AppSchedulingInfo: checking for deactivate of application :application_1536283662720_0001
2018-09-06 20:53:19,753 INFO org.apache.hadoop.yarn.server.resourcemanager.rmcontainer.RMContainerImpl: container_1536283662720_0001_01_000002 Container Transitioned from RUNNING to COMPLETED
2018-09-06 20:53:19,753 INFO org.apache.hadoop.yarn.server.resourcemanager.RMAuditLogger: USER=jason	OPERATION=AM Released Container	TARGET=SchedulerApp	RESULT=SUCCESS	APPID=application_1536283662720_0001	CONTAINERID=container_1536283662720_0001_01_000002
2018-09-06 20:53:19,755 INFO org.apache.hadoop.yarn.server.resourcemanager.scheduler.SchedulerNode: Released container container_1536283662720_0001_01_000002 of capacity <memory:1024, vCores:1> on host 192.168.1.103:59206, which currently has 1 containers, <memory:2048, vCores:1> used and <memory:6144, vCores:7> available, release resources=true
2018-09-06 20:53:21,762 INFO org.apache.hadoop.yarn.server.resourcemanager.rmcontainer.RMContainerImpl: container_1536283662720_0001_01_000003 Container Transitioned from NEW to ALLOCATED
2018-09-06 20:53:21,763 INFO org.apache.hadoop.yarn.server.resourcemanager.RMAuditLogger: USER=jason	OPERATION=AM Allocated Container	TARGET=SchedulerApp	RESULT=SUCCESS	APPID=application_1536283662720_0001	CONTAINERID=container_1536283662720_0001_01_000003
2018-09-06 20:53:21,763 INFO org.apache.hadoop.yarn.server.resourcemanager.scheduler.SchedulerNode: Assigned container container_1536283662720_0001_01_000003 of capacity <memory:1024, vCores:1> on host 192.168.1.103:59206, which has 2 containers, <memory:3072, vCores:2> used and <memory:5120, vCores:6> available after allocation
2018-09-06 20:53:21,763 INFO org.apache.hadoop.yarn.server.resourcemanager.scheduler.capacity.allocator.AbstractContainerAllocator: assignedContainer application attempt=appattempt_1536283662720_0001_000001 container=container_1536283662720_0001_01_000003 queue=org.apache.hadoop.yarn.server.resourcemanager.scheduler.capacity.allocator.RegularContainerAllocator@265609d0 clusterResource=<memory:8192, vCores:8> type=OFF_SWITCH
2018-09-06 20:53:21,763 INFO org.apache.hadoop.yarn.server.resourcemanager.scheduler.capacity.ParentQueue: Re-sorting assigned queue: root.default stats: default: capacity=1.0, absoluteCapacity=1.0, usedResources=<memory:3072, vCores:2>, usedCapacity=0.375, absoluteUsedCapacity=0.375, numApps=1, numContainers=2
2018-09-06 20:53:21,763 INFO org.apache.hadoop.yarn.server.resourcemanager.scheduler.capacity.ParentQueue: assignedContainer queue=root usedCapacity=0.375 absoluteUsedCapacity=0.375 used=<memory:3072, vCores:2> cluster=<memory:8192, vCores:8>
2018-09-06 20:53:21,893 INFO org.apache.hadoop.yarn.server.resourcemanager.rmcontainer.RMContainerImpl: container_1536283662720_0001_01_000003 Container Transitioned from ALLOCATED to ACQUIRED
2018-09-06 20:53:22,765 INFO org.apache.hadoop.yarn.server.resourcemanager.rmcontainer.RMContainerImpl: container_1536283662720_0001_01_000003 Container Transitioned from ACQUIRED to RUNNING
2018-09-06 20:53:22,897 INFO org.apache.hadoop.yarn.server.resourcemanager.scheduler.AppSchedulingInfo: checking for deactivate of application :application_1536283662720_0001
2018-09-06 20:53:25,262 INFO org.apache.hadoop.yarn.server.resourcemanager.rmcontainer.RMContainerImpl: container_1536283662720_0001_01_000003 Container Transitioned from RUNNING to COMPLETED
2018-09-06 20:53:25,262 INFO org.apache.hadoop.yarn.server.resourcemanager.RMAuditLogger: USER=jason	OPERATION=AM Released Container	TARGET=SchedulerApp	RESULT=SUCCESS	APPID=application_1536283662720_0001	CONTAINERID=container_1536283662720_0001_01_000003
2018-09-06 20:53:25,262 INFO org.apache.hadoop.yarn.server.resourcemanager.scheduler.SchedulerNode: Released container container_1536283662720_0001_01_000003 of capacity <memory:1024, vCores:1> on host 192.168.1.103:59206, which currently has 1 containers, <memory:2048, vCores:1> used and <memory:6144, vCores:7> available, release resources=true
2018-09-06 20:53:25,306 INFO org.apache.hadoop.yarn.server.resourcemanager.rmapp.attempt.RMAppAttemptImpl: Updating application attempt appattempt_1536283662720_0001_000001 with final state: FINISHING, and exit status: -1000
2018-09-06 20:53:25,306 INFO org.apache.hadoop.yarn.server.resourcemanager.rmapp.attempt.RMAppAttemptImpl: appattempt_1536283662720_0001_000001 State change from RUNNING to FINAL_SAVING
2018-09-06 20:53:25,307 INFO org.apache.hadoop.yarn.server.resourcemanager.rmapp.RMAppImpl: Updating application application_1536283662720_0001 with final state: FINISHING
2018-09-06 20:53:25,307 INFO org.apache.hadoop.yarn.server.resourcemanager.rmapp.RMAppImpl: application_1536283662720_0001 State change from RUNNING to FINAL_SAVING on event=ATTEMPT_UNREGISTERED
2018-09-06 20:53:25,307 INFO org.apache.hadoop.yarn.server.resourcemanager.recovery.RMStateStore: Updating info for app: application_1536283662720_0001
2018-09-06 20:53:25,307 INFO org.apache.hadoop.yarn.server.resourcemanager.rmapp.attempt.RMAppAttemptImpl: appattempt_1536283662720_0001_000001 State change from FINAL_SAVING to FINISHING
2018-09-06 20:53:25,307 INFO org.apache.hadoop.yarn.server.resourcemanager.rmapp.RMAppImpl: application_1536283662720_0001 State change from FINAL_SAVING to FINISHING on event=APP_UPDATE_SAVED
2018-09-06 20:53:26,311 INFO org.apache.hadoop.yarn.server.resourcemanager.ApplicationMasterService: application_1536283662720_0001 unregistered successfully. 
2018-09-06 20:53:31,515 INFO org.apache.hadoop.yarn.server.resourcemanager.rmcontainer.RMContainerImpl: container_1536283662720_0001_01_000001 Container Transitioned from RUNNING to COMPLETED
2018-09-06 20:53:31,515 INFO org.apache.hadoop.yarn.server.resourcemanager.ApplicationMasterService: Unregistering app attempt : appattempt_1536283662720_0001_000001
2018-09-06 20:53:31,515 INFO org.apache.hadoop.yarn.server.resourcemanager.RMAuditLogger: USER=jason	OPERATION=AM Released Container	TARGET=SchedulerApp	RESULT=SUCCESS	APPID=application_1536283662720_0001	CONTAINERID=container_1536283662720_0001_01_000001
2018-09-06 20:53:31,516 INFO org.apache.hadoop.yarn.server.resourcemanager.scheduler.SchedulerNode: Released container container_1536283662720_0001_01_000001 of capacity <memory:2048, vCores:1> on host 192.168.1.103:59206, which currently has 0 containers, <memory:0, vCores:0> used and <memory:8192, vCores:8> available, release resources=true
2018-09-06 20:53:31,516 INFO org.apache.hadoop.yarn.server.resourcemanager.security.AMRMTokenSecretManager: Application finished, removing password for appattempt_1536283662720_0001_000001
2018-09-06 20:53:31,517 INFO org.apache.hadoop.yarn.server.resourcemanager.rmapp.attempt.RMAppAttemptImpl: appattempt_1536283662720_0001_000001 State change from FINISHING to FINISHED
2018-09-06 20:53:31,519 INFO org.apache.hadoop.yarn.server.resourcemanager.rmapp.RMAppImpl: application_1536283662720_0001 State change from FINISHING to FINISHED on event=ATTEMPT_FINISHED
2018-09-06 20:53:31,519 INFO org.apache.hadoop.yarn.server.resourcemanager.scheduler.capacity.CapacityScheduler: Application Attempt appattempt_1536283662720_0001_000001 is done. finalState=FINISHED
2018-09-06 20:53:31,520 INFO org.apache.hadoop.yarn.server.resourcemanager.scheduler.AppSchedulingInfo: Application application_1536283662720_0001 requests cleared
2018-09-06 20:53:31,520 INFO org.apache.hadoop.yarn.server.resourcemanager.amlauncher.AMLauncher: Cleaning master appattempt_1536283662720_0001_000001
2018-09-06 20:53:31,520 INFO org.apache.hadoop.yarn.server.resourcemanager.scheduler.capacity.LeafQueue: Application removed - appId: application_1536283662720_0001 user: jason queue: default #user-pending-applications: 0 #user-active-applications: 0 #queue-pending-applications: 0 #queue-active-applications: 0
2018-09-06 20:53:31,520 INFO org.apache.hadoop.yarn.server.resourcemanager.scheduler.capacity.ParentQueue: Application removed - appId: application_1536283662720_0001 user: jason leaf-queue of parent: root #applications: 0
2018-09-06 20:53:31,521 INFO org.apache.hadoop.yarn.server.resourcemanager.RMAuditLogger: USER=jason	OPERATION=Application Finished - Succeeded	TARGET=RMAppManager	RESULT=SUCCESS	APPID=application_1536283662720_0001
2018-09-06 20:53:31,523 INFO org.apache.hadoop.yarn.server.resourcemanager.RMAppManager$ApplicationSummary: appId=application_1536283662720_0001,name=word count,user=jason,queue=default,state=FINISHED,trackingUrl=http://Jasons-MacBook-Pro.local:8088/proxy/application_1536283662720_0001/,appMasterHost=192.168.1.103,startTime=1536285187944,finishTime=1536285205307,finalStatus=SUCCEEDED,memorySeconds=55033,vcoreSeconds=30,preemptedMemorySeconds=0,preemptedVcoreSeconds=0,preemptedAMContainers=0,preemptedNonAMContainers=0,preemptedResources=<memory:0\, vCores:0>,applicationType=MAPREDUCE
2018-09-06 20:53:33,529 INFO org.apache.hadoop.yarn.server.resourcemanager.scheduler.AbstractYarnScheduler: Container container_1536283662720_0001_01_000003 completed with event FINISHED, but corresponding RMContainer doesn't exist.
2018-09-06 21:18:10,852 ERROR org.apache.hadoop.yarn.server.resourcemanager.ResourceManager: RECEIVED SIGNAL 15: SIGTERM
2018-09-06 21:18:10,865 ERROR org.apache.hadoop.security.token.delegation.AbstractDelegationTokenSecretManager: ExpiredTokenRemover received java.lang.InterruptedException: sleep interrupted
2018-09-06 21:18:10,868 INFO org.mortbay.log: Stopped HttpServer2$SelectChannelConnectorWithSafeStartup@0.0.0.0:8088
2018-09-06 21:18:10,972 INFO org.apache.hadoop.ipc.Server: Stopping server on 8032
2018-09-06 21:18:10,979 INFO org.apache.hadoop.ipc.Server: Stopping IPC Server listener on 8032
2018-09-06 21:18:10,980 INFO org.apache.hadoop.ipc.Server: Stopping IPC Server Responder
2018-09-06 21:18:10,983 INFO org.apache.hadoop.ipc.Server: Stopping server on 8033
2018-09-06 21:18:10,984 INFO org.apache.hadoop.ipc.Server: Stopping IPC Server listener on 8033
2018-09-06 21:18:10,984 INFO org.apache.hadoop.ipc.Server: Stopping IPC Server Responder
2018-09-06 21:18:10,985 INFO org.apache.hadoop.yarn.server.resourcemanager.ResourceManager: Transitioning to standby state
2018-09-06 21:18:10,986 WARN org.apache.hadoop.yarn.server.resourcemanager.amlauncher.ApplicationMasterLauncher: org.apache.hadoop.yarn.server.resourcemanager.amlauncher.ApplicationMasterLauncher$LauncherThread interrupted. Returning.
2018-09-06 21:18:10,986 INFO org.apache.hadoop.ipc.Server: Stopping server on 8030
2018-09-06 21:18:10,989 INFO org.apache.hadoop.ipc.Server: Stopping IPC Server listener on 8030
2018-09-06 21:18:10,990 INFO org.apache.hadoop.ipc.Server: Stopping server on 8031
2018-09-06 21:18:10,989 INFO org.apache.hadoop.ipc.Server: Stopping IPC Server Responder
2018-09-06 21:18:10,993 INFO org.apache.hadoop.ipc.Server: Stopping IPC Server listener on 8031
2018-09-06 21:18:10,993 INFO org.apache.hadoop.ipc.Server: Stopping IPC Server Responder
2018-09-06 21:18:10,993 INFO org.apache.hadoop.yarn.util.AbstractLivelinessMonitor: NMLivelinessMonitor thread interrupted
2018-09-06 21:18:10,993 ERROR org.apache.hadoop.yarn.server.resourcemanager.ResourceManager: Returning, interrupted : java.lang.InterruptedException
2018-09-06 21:18:10,994 INFO org.apache.hadoop.yarn.event.AsyncDispatcher: AsyncDispatcher is draining to stop, igonring any new events.
2018-09-06 21:18:10,994 INFO org.apache.hadoop.yarn.util.AbstractLivelinessMonitor: AMLivelinessMonitor thread interrupted
2018-09-06 21:18:10,994 INFO org.apache.hadoop.yarn.util.AbstractLivelinessMonitor: AMLivelinessMonitor thread interrupted
2018-09-06 21:18:10,995 INFO org.apache.hadoop.yarn.util.AbstractLivelinessMonitor: org.apache.hadoop.yarn.server.resourcemanager.rmcontainer.ContainerAllocationExpirer thread interrupted
2018-09-06 21:18:10,995 ERROR org.apache.hadoop.security.token.delegation.AbstractDelegationTokenSecretManager: ExpiredTokenRemover received java.lang.InterruptedException: sleep interrupted
2018-09-06 21:18:10,995 INFO org.apache.hadoop.metrics2.impl.MetricsSystemImpl: Stopping ResourceManager metrics system...
2018-09-06 21:18:10,997 INFO org.apache.hadoop.metrics2.impl.MetricsSystemImpl: ResourceManager metrics system stopped.
2018-09-06 21:18:10,997 INFO org.apache.hadoop.metrics2.impl.MetricsSystemImpl: ResourceManager metrics system shutdown complete.
2018-09-06 21:18:10,997 INFO org.apache.hadoop.yarn.event.AsyncDispatcher: AsyncDispatcher is draining to stop, igonring any new events.
2018-09-06 21:18:10,997 INFO org.apache.hadoop.yarn.server.resourcemanager.ResourceManager: Transitioned to standby state
2018-09-06 21:18:10,997 INFO org.apache.hadoop.yarn.server.resourcemanager.ResourceManager: SHUTDOWN_MSG: 
/************************************************************
SHUTDOWN_MSG: Shutting down ResourceManager at Jasons-MacBook-Pro.local/192.168.1.103
************************************************************/
2018-09-06 21:31:40,578 INFO org.apache.hadoop.yarn.server.resourcemanager.ResourceManager: STARTUP_MSG: 
/************************************************************
STARTUP_MSG: Starting ResourceManager
STARTUP_MSG:   user = jason
STARTUP_MSG:   host = Jasons-MacBook-Pro.local/192.168.1.103
STARTUP_MSG:   args = []
STARTUP_MSG:   version = 2.8.1
STARTUP_MSG:   build = https://git-wip-us.apache.org/repos/asf/hadoop.git -r 20fe5304904fc2f5a18053c389e43cd26f7a70fe; compiled by 'vinodkv' on 2017-06-02T06:14Z
STARTUP_MSG:   java = 10.0.2
************************************************************/
2018-09-06 21:31:40,590 INFO org.apache.hadoop.yarn.server.resourcemanager.ResourceManager: registered UNIX signal handlers for [TERM, HUP, INT]
2018-09-06 21:31:40,885 INFO org.apache.hadoop.conf.Configuration: found resource core-site.xml at file:/Users/jason/hadoop-2.8.1/etc/hadoop/core-site.xml
2018-09-06 21:31:40,920 WARN org.apache.hadoop.util.NativeCodeLoader: Unable to load native-hadoop library for your platform... using builtin-java classes where applicable
2018-09-06 21:31:40,943 INFO org.apache.hadoop.security.Groups: clearing userToGroupsMap cache
2018-09-06 21:31:41,011 INFO org.apache.hadoop.conf.Configuration: found resource yarn-site.xml at file:/Users/jason/hadoop-2.8.1/etc/hadoop/yarn-site.xml
2018-09-06 21:31:41,238 INFO org.apache.hadoop.yarn.event.AsyncDispatcher: Registering class org.apache.hadoop.yarn.server.resourcemanager.RMFatalEventType for class org.apache.hadoop.yarn.server.resourcemanager.ResourceManager$RMFatalEventDispatcher
2018-09-06 21:31:41,289 INFO org.apache.hadoop.yarn.server.resourcemanager.security.NMTokenSecretManagerInRM: NMTokenKeyRollingInterval: 86400000ms and NMTokenKeyActivationDelay: 900000ms
2018-09-06 21:31:41,294 INFO org.apache.hadoop.yarn.server.resourcemanager.security.RMContainerTokenSecretManager: ContainerTokenKeyRollingInterval: 86400000ms and ContainerTokenKeyActivationDelay: 900000ms
2018-09-06 21:31:41,297 INFO org.apache.hadoop.yarn.server.resourcemanager.security.AMRMTokenSecretManager: AMRMTokenKeyRollingInterval: 86400000ms and AMRMTokenKeyActivationDelay: 900000 ms
2018-09-06 21:31:41,324 INFO org.apache.hadoop.yarn.event.AsyncDispatcher: Registering class org.apache.hadoop.yarn.server.resourcemanager.recovery.RMStateStoreEventType for class org.apache.hadoop.yarn.server.resourcemanager.recovery.RMStateStore$ForwardingEventHandler
2018-09-06 21:31:41,326 INFO org.apache.hadoop.yarn.event.AsyncDispatcher: Registering class org.apache.hadoop.yarn.server.resourcemanager.NodesListManagerEventType for class org.apache.hadoop.yarn.server.resourcemanager.NodesListManager
2018-09-06 21:31:41,326 INFO org.apache.hadoop.yarn.server.resourcemanager.ResourceManager: Using Scheduler: org.apache.hadoop.yarn.server.resourcemanager.scheduler.capacity.CapacityScheduler
2018-09-06 21:31:41,351 INFO org.apache.hadoop.yarn.event.AsyncDispatcher: Registering class org.apache.hadoop.yarn.server.resourcemanager.scheduler.event.SchedulerEventType for class org.apache.hadoop.yarn.server.resourcemanager.ResourceManager$SchedulerEventDispatcher
2018-09-06 21:31:41,352 INFO org.apache.hadoop.yarn.event.AsyncDispatcher: Registering class org.apache.hadoop.yarn.server.resourcemanager.rmapp.RMAppEventType for class org.apache.hadoop.yarn.server.resourcemanager.ResourceManager$ApplicationEventDispatcher
2018-09-06 21:31:41,353 INFO org.apache.hadoop.yarn.event.AsyncDispatcher: Registering class org.apache.hadoop.yarn.server.resourcemanager.rmapp.attempt.RMAppAttemptEventType for class org.apache.hadoop.yarn.server.resourcemanager.ResourceManager$ApplicationAttemptEventDispatcher
2018-09-06 21:31:41,354 INFO org.apache.hadoop.yarn.event.AsyncDispatcher: Registering class org.apache.hadoop.yarn.server.resourcemanager.rmnode.RMNodeEventType for class org.apache.hadoop.yarn.server.resourcemanager.ResourceManager$NodeEventDispatcher
2018-09-06 21:31:41,400 INFO org.apache.hadoop.metrics2.impl.MetricsConfig: loaded properties from hadoop-metrics2.properties
2018-09-06 21:31:41,497 INFO org.apache.hadoop.metrics2.impl.MetricsSystemImpl: Scheduled Metric snapshot period at 10 second(s).
2018-09-06 21:31:41,497 INFO org.apache.hadoop.metrics2.impl.MetricsSystemImpl: ResourceManager metrics system started
2018-09-06 21:31:41,526 INFO org.apache.hadoop.yarn.event.AsyncDispatcher: Registering class org.apache.hadoop.yarn.server.resourcemanager.RMAppManagerEventType for class org.apache.hadoop.yarn.server.resourcemanager.RMAppManager
2018-09-06 21:31:41,532 INFO org.apache.hadoop.yarn.event.AsyncDispatcher: Registering class org.apache.hadoop.yarn.server.resourcemanager.amlauncher.AMLauncherEventType for class org.apache.hadoop.yarn.server.resourcemanager.amlauncher.ApplicationMasterLauncher
2018-09-06 21:31:41,534 INFO org.apache.hadoop.yarn.server.resourcemanager.RMNMInfo: Registered RMNMInfo MBean
2018-09-06 21:31:41,538 INFO org.apache.hadoop.yarn.security.YarnAuthorizationProvider: org.apache.hadoop.yarn.security.ConfiguredYarnAuthorizer is instiantiated.
2018-09-06 21:31:41,539 INFO org.apache.hadoop.util.HostsFileReader: Refreshing hosts (include/exclude) list
2018-09-06 21:31:41,544 INFO org.apache.hadoop.conf.Configuration: found resource capacity-scheduler.xml at file:/Users/jason/hadoop-2.8.1/etc/hadoop/capacity-scheduler.xml
2018-09-06 21:31:41,586 INFO org.apache.hadoop.yarn.server.resourcemanager.scheduler.capacity.CapacitySchedulerConfiguration: max alloc mb per queue for root is undefined
2018-09-06 21:31:41,586 INFO org.apache.hadoop.yarn.server.resourcemanager.scheduler.capacity.CapacitySchedulerConfiguration: max alloc vcore per queue for root is undefined
2018-09-06 21:31:41,592 INFO org.apache.hadoop.yarn.server.resourcemanager.scheduler.capacity.ParentQueue: root, capacity=1.0, asboluteCapacity=1.0, maxCapacity=1.0, asboluteMaxCapacity=1.0, state=RUNNING, acls=ADMINISTER_QUEUE:*SUBMIT_APP:*, labels=*,, offswitchPerHeartbeatLimit = 1, reservationsContinueLooking=true
2018-09-06 21:31:41,592 INFO org.apache.hadoop.yarn.server.resourcemanager.scheduler.capacity.ParentQueue: Initialized parent-queue root name=root, fullname=root
2018-09-06 21:31:41,602 INFO org.apache.hadoop.yarn.server.resourcemanager.scheduler.capacity.CapacitySchedulerConfiguration: max alloc mb per queue for root.default is undefined
2018-09-06 21:31:41,602 INFO org.apache.hadoop.yarn.server.resourcemanager.scheduler.capacity.CapacitySchedulerConfiguration: max alloc vcore per queue for root.default is undefined
2018-09-06 21:31:41,603 INFO org.apache.hadoop.yarn.server.resourcemanager.scheduler.capacity.LeafQueue: Initializing default
capacity = 1.0 [= (float) configuredCapacity / 100 ]
asboluteCapacity = 1.0 [= parentAbsoluteCapacity * capacity ]
maxCapacity = 1.0 [= configuredMaxCapacity ]
absoluteMaxCapacity = 1.0 [= 1.0 maximumCapacity undefined, (parentAbsoluteMaxCapacity * maximumCapacity) / 100 otherwise ]
userLimit = 100 [= configuredUserLimit ]
userLimitFactor = 1.0 [= configuredUserLimitFactor ]
maxApplications = 10000 [= configuredMaximumSystemApplicationsPerQueue or (int)(configuredMaximumSystemApplications * absoluteCapacity)]
maxApplicationsPerUser = 10000 [= (int)(maxApplications * (userLimit / 100.0f) * userLimitFactor) ]
usedCapacity = 0.0 [= usedResourcesMemory / (clusterResourceMemory * absoluteCapacity)]
absoluteUsedCapacity = 0.0 [= usedResourcesMemory / clusterResourceMemory]
maxAMResourcePerQueuePercent = 0.1 [= configuredMaximumAMResourcePercent ]
minimumAllocationFactor = 0.875 [= (float)(maximumAllocationMemory - minimumAllocationMemory) / maximumAllocationMemory ]
maximumAllocation = <memory:8192, vCores:4> [= configuredMaxAllocation ]
numContainers = 0 [= currentNumContainers ]
state = RUNNING [= configuredState ]
acls = ADMINISTER_QUEUE:*SUBMIT_APP:* [= configuredAcls ]
nodeLocalityDelay = 40
labels=*,
reservationsContinueLooking = true
preemptionDisabled = true
defaultAppPriorityPerQueue = 0
2018-09-06 21:31:41,604 INFO org.apache.hadoop.yarn.server.resourcemanager.scheduler.capacity.CapacityScheduler: Initialized queue: default: capacity=1.0, absoluteCapacity=1.0, usedResources=<memory:0, vCores:0>, usedCapacity=0.0, absoluteUsedCapacity=0.0, numApps=0, numContainers=0
2018-09-06 21:31:41,604 INFO org.apache.hadoop.yarn.server.resourcemanager.scheduler.capacity.CapacityScheduler: Initialized queue: root: numChildQueue= 1, capacity=1.0, absoluteCapacity=1.0, usedResources=<memory:0, vCores:0>usedCapacity=0.0, numApps=0, numContainers=0
2018-09-06 21:31:41,604 INFO org.apache.hadoop.yarn.server.resourcemanager.scheduler.capacity.CapacityScheduler: Initialized root queue root: numChildQueue= 1, capacity=1.0, absoluteCapacity=1.0, usedResources=<memory:0, vCores:0>usedCapacity=0.0, numApps=0, numContainers=0
2018-09-06 21:31:41,604 INFO org.apache.hadoop.yarn.server.resourcemanager.scheduler.capacity.CapacityScheduler: Initialized queue mappings, override: false
2018-09-06 21:31:41,605 INFO org.apache.hadoop.yarn.server.resourcemanager.scheduler.capacity.CapacityScheduler: Initialized CapacityScheduler with calculator=class org.apache.hadoop.yarn.util.resource.DefaultResourceCalculator, minimumAllocation=<<memory:1024, vCores:1>>, maximumAllocation=<<memory:8192, vCores:4>>, asynchronousScheduling=false, asyncScheduleInterval=5ms
2018-09-06 21:31:41,608 INFO org.apache.hadoop.conf.Configuration: dynamic-resources.xml not found
2018-09-06 21:31:41,619 INFO org.apache.hadoop.yarn.server.resourcemanager.metrics.SystemMetricsPublisher: YARN system metrics publishing service is not enabled
2018-09-06 21:31:41,619 INFO org.apache.hadoop.yarn.server.resourcemanager.ResourceManager: Transitioning to active state
2018-09-06 21:31:41,628 INFO org.apache.hadoop.util.JvmPauseMonitor: Starting JVM pause monitor
2018-09-06 21:31:41,642 INFO org.apache.hadoop.yarn.server.resourcemanager.recovery.RMStateStore: Updating AMRMToken
2018-09-06 21:31:41,642 INFO org.apache.hadoop.yarn.server.resourcemanager.security.RMContainerTokenSecretManager: Rolling master-key for container-tokens
2018-09-06 21:31:41,643 INFO org.apache.hadoop.yarn.server.resourcemanager.security.NMTokenSecretManagerInRM: Rolling master-key for nm-tokens
2018-09-06 21:31:41,643 INFO org.apache.hadoop.security.token.delegation.AbstractDelegationTokenSecretManager: Updating the current master key for generating delegation tokens
2018-09-06 21:31:41,643 INFO org.apache.hadoop.yarn.server.resourcemanager.security.RMDelegationTokenSecretManager: storing master key with keyID 1
2018-09-06 21:31:41,644 INFO org.apache.hadoop.yarn.server.resourcemanager.recovery.RMStateStore: Storing RMDTMasterKey.
2018-09-06 21:31:41,644 INFO org.apache.hadoop.security.token.delegation.AbstractDelegationTokenSecretManager: Starting expired delegation token remover thread, tokenRemoverScanInterval=60 min(s)
2018-09-06 21:31:41,645 INFO org.apache.hadoop.security.token.delegation.AbstractDelegationTokenSecretManager: Updating the current master key for generating delegation tokens
2018-09-06 21:31:41,647 INFO org.apache.hadoop.yarn.server.resourcemanager.security.RMDelegationTokenSecretManager: storing master key with keyID 2
2018-09-06 21:31:41,647 INFO org.apache.hadoop.yarn.server.resourcemanager.recovery.RMStateStore: Storing RMDTMasterKey.
2018-09-06 21:31:41,648 INFO org.apache.hadoop.yarn.event.AsyncDispatcher: Registering class org.apache.hadoop.yarn.nodelabels.event.NodeLabelsStoreEventType for class org.apache.hadoop.yarn.nodelabels.CommonNodeLabelsManager$ForwardingEventHandler
2018-09-06 21:31:41,674 INFO org.apache.hadoop.ipc.CallQueueManager: Using callQueue: class java.util.concurrent.LinkedBlockingQueue queueCapacity: 5000 scheduler: class org.apache.hadoop.ipc.DefaultRpcScheduler
2018-09-06 21:31:41,688 INFO org.apache.hadoop.ipc.Server: Starting Socket Reader #1 for port 8031
2018-09-06 21:31:41,824 INFO org.apache.hadoop.yarn.factories.impl.pb.RpcServerFactoryPBImpl: Adding protocol org.apache.hadoop.yarn.server.api.ResourceTrackerPB to the server
2018-09-06 21:31:41,825 INFO org.apache.hadoop.ipc.Server: IPC Server Responder: starting
2018-09-06 21:31:41,825 INFO org.apache.hadoop.ipc.Server: IPC Server listener on 8031: starting
2018-09-06 21:31:41,849 INFO org.apache.hadoop.ipc.CallQueueManager: Using callQueue: class java.util.concurrent.LinkedBlockingQueue queueCapacity: 5000 scheduler: class org.apache.hadoop.ipc.DefaultRpcScheduler
2018-09-06 21:31:41,853 INFO org.apache.hadoop.ipc.Server: Starting Socket Reader #1 for port 8030
2018-09-06 21:31:41,863 INFO org.apache.hadoop.yarn.factories.impl.pb.RpcServerFactoryPBImpl: Adding protocol org.apache.hadoop.yarn.api.ApplicationMasterProtocolPB to the server
2018-09-06 21:31:41,863 INFO org.apache.hadoop.ipc.Server: IPC Server Responder: starting
2018-09-06 21:31:41,864 INFO org.apache.hadoop.ipc.Server: IPC Server listener on 8030: starting
2018-09-06 21:31:41,918 INFO org.apache.hadoop.ipc.CallQueueManager: Using callQueue: class java.util.concurrent.LinkedBlockingQueue queueCapacity: 5000 scheduler: class org.apache.hadoop.ipc.DefaultRpcScheduler
2018-09-06 21:31:41,919 INFO org.apache.hadoop.ipc.Server: Starting Socket Reader #1 for port 8032
2018-09-06 21:31:41,923 INFO org.apache.hadoop.yarn.factories.impl.pb.RpcServerFactoryPBImpl: Adding protocol org.apache.hadoop.yarn.api.ApplicationClientProtocolPB to the server
2018-09-06 21:31:41,923 INFO org.apache.hadoop.ipc.Server: IPC Server Responder: starting
2018-09-06 21:31:41,924 INFO org.apache.hadoop.ipc.Server: IPC Server listener on 8032: starting
2018-09-06 21:31:41,930 INFO org.apache.hadoop.yarn.server.resourcemanager.ResourceManager: Transitioned to active state
2018-09-06 21:31:42,013 INFO org.mortbay.log: Logging to org.slf4j.impl.Log4jLoggerAdapter(org.mortbay.log) via org.mortbay.log.Slf4jLog
2018-09-06 21:31:42,019 INFO org.apache.hadoop.security.authentication.server.AuthenticationFilter: Unable to initialize FileSignerSecretProvider, falling back to use random secrets.
2018-09-06 21:31:42,026 INFO org.apache.hadoop.http.HttpRequestLog: Http request log for http.requests.resourcemanager is not defined
2018-09-06 21:31:42,034 INFO org.apache.hadoop.http.HttpServer2: Added global filter 'safety' (class=org.apache.hadoop.http.HttpServer2$QuotingInputFilter)
2018-09-06 21:31:42,036 INFO org.apache.hadoop.http.HttpServer2: Added filter RMAuthenticationFilter (class=org.apache.hadoop.yarn.server.security.http.RMAuthenticationFilter) to context cluster
2018-09-06 21:31:42,036 INFO org.apache.hadoop.http.HttpServer2: Added filter RMAuthenticationFilter (class=org.apache.hadoop.yarn.server.security.http.RMAuthenticationFilter) to context static
2018-09-06 21:31:42,036 INFO org.apache.hadoop.http.HttpServer2: Added filter RMAuthenticationFilter (class=org.apache.hadoop.yarn.server.security.http.RMAuthenticationFilter) to context logs
2018-09-06 21:31:42,037 INFO org.apache.hadoop.http.HttpServer2: Added filter static_user_filter (class=org.apache.hadoop.http.lib.StaticUserWebFilter$StaticUserFilter) to context cluster
2018-09-06 21:31:42,037 INFO org.apache.hadoop.http.HttpServer2: Added filter static_user_filter (class=org.apache.hadoop.http.lib.StaticUserWebFilter$StaticUserFilter) to context static
2018-09-06 21:31:42,037 INFO org.apache.hadoop.http.HttpServer2: Added filter static_user_filter (class=org.apache.hadoop.http.lib.StaticUserWebFilter$StaticUserFilter) to context logs
2018-09-06 21:31:42,039 INFO org.apache.hadoop.http.HttpServer2: adding path spec: /cluster/*
2018-09-06 21:31:42,039 INFO org.apache.hadoop.http.HttpServer2: adding path spec: /ws/*
2018-09-06 21:31:42,310 INFO org.apache.hadoop.yarn.webapp.WebApps: Registered webapp guice modules
2018-09-06 21:31:42,312 INFO org.apache.hadoop.http.HttpServer2: Jetty bound to port 8088
2018-09-06 21:31:42,312 INFO org.mortbay.log: jetty-6.1.26
2018-09-06 21:31:42,340 INFO org.mortbay.log: Extract jar:file:/Users/jason/hadoop-2.8.1/share/hadoop/yarn/hadoop-yarn-common-2.8.1.jar!/webapps/cluster to /var/folders/7r/3c0pxtpd0rg5hjs32v2rrz_00000gn/T/Jetty_0_0_0_0_8088_cluster____u0rgz3/webapp
2018-09-06 21:31:42,430 INFO org.apache.hadoop.security.token.delegation.AbstractDelegationTokenSecretManager: Updating the current master key for generating delegation tokens
2018-09-06 21:31:42,430 INFO org.apache.hadoop.security.token.delegation.AbstractDelegationTokenSecretManager: Starting expired delegation token remover thread, tokenRemoverScanInterval=60 min(s)
2018-09-06 21:31:42,431 INFO org.apache.hadoop.security.token.delegation.AbstractDelegationTokenSecretManager: Updating the current master key for generating delegation tokens
2018-09-06 21:31:43,215 INFO org.mortbay.log: Started HttpServer2$SelectChannelConnectorWithSafeStartup@0.0.0.0:8088
2018-09-06 21:31:43,217 INFO org.apache.hadoop.yarn.webapp.WebApps: Web app cluster started at 8088
2018-09-06 21:31:43,257 INFO org.apache.hadoop.ipc.CallQueueManager: Using callQueue: class java.util.concurrent.LinkedBlockingQueue queueCapacity: 100 scheduler: class org.apache.hadoop.ipc.DefaultRpcScheduler
2018-09-06 21:31:43,258 INFO org.apache.hadoop.ipc.Server: Starting Socket Reader #1 for port 8033
2018-09-06 21:31:43,261 INFO org.apache.hadoop.yarn.factories.impl.pb.RpcServerFactoryPBImpl: Adding protocol org.apache.hadoop.yarn.server.api.ResourceManagerAdministrationProtocolPB to the server
2018-09-06 21:31:43,261 INFO org.apache.hadoop.ipc.Server: IPC Server Responder: starting
2018-09-06 21:31:43,261 INFO org.apache.hadoop.ipc.Server: IPC Server listener on 8033: starting
2018-09-06 21:31:52,177 INFO org.apache.hadoop.yarn.server.resourcemanager.ResourceTrackerService: NodeManager from node 192.168.1.103(cmPort: 59669 httpPort: 8042) registered with capability: <memory:8192, vCores:8>, assigned nodeId 192.168.1.103:59669
2018-09-06 21:31:52,186 INFO org.apache.hadoop.yarn.server.resourcemanager.rmnode.RMNodeImpl: 192.168.1.103:59669 Node Transitioned from NEW to RUNNING
2018-09-06 21:31:52,195 INFO org.apache.hadoop.yarn.server.resourcemanager.scheduler.capacity.CapacityScheduler: Added node 192.168.1.103:59669 clusterResource: <memory:8192, vCores:8>
2018-09-06 21:41:41,547 INFO org.apache.hadoop.yarn.server.resourcemanager.scheduler.AbstractYarnScheduler: Release request cache is cleaned up
2018-09-06 23:18:57,187 ERROR org.apache.hadoop.yarn.server.resourcemanager.ResourceManager: RECEIVED SIGNAL 15: SIGTERM
2018-09-06 23:18:57,195 ERROR org.apache.hadoop.security.token.delegation.AbstractDelegationTokenSecretManager: ExpiredTokenRemover received java.lang.InterruptedException: sleep interrupted
2018-09-06 23:18:57,198 INFO org.mortbay.log: Stopped HttpServer2$SelectChannelConnectorWithSafeStartup@0.0.0.0:8088
2018-09-06 23:18:57,308 INFO org.apache.hadoop.ipc.Server: Stopping server on 8032
2018-09-06 23:18:57,315 INFO org.apache.hadoop.ipc.Server: Stopping IPC Server listener on 8032
2018-09-06 23:18:57,315 INFO org.apache.hadoop.ipc.Server: Stopping IPC Server Responder
2018-09-06 23:18:57,319 INFO org.apache.hadoop.ipc.Server: Stopping server on 8033
2018-09-06 23:18:57,320 INFO org.apache.hadoop.ipc.Server: Stopping IPC Server listener on 8033
2018-09-06 23:18:57,321 INFO org.apache.hadoop.ipc.Server: Stopping IPC Server Responder
2018-09-06 23:18:57,322 INFO org.apache.hadoop.yarn.server.resourcemanager.ResourceManager: Transitioning to standby state
2018-09-06 23:18:57,323 WARN org.apache.hadoop.yarn.server.resourcemanager.amlauncher.ApplicationMasterLauncher: org.apache.hadoop.yarn.server.resourcemanager.amlauncher.ApplicationMasterLauncher$LauncherThread interrupted. Returning.
2018-09-06 23:18:57,323 INFO org.apache.hadoop.ipc.Server: Stopping server on 8030
2018-09-06 23:18:57,327 INFO org.apache.hadoop.ipc.Server: Stopping server on 8031
2018-09-06 23:18:57,327 INFO org.apache.hadoop.ipc.Server: Stopping IPC Server listener on 8030
2018-09-06 23:18:57,328 INFO org.apache.hadoop.ipc.Server: Stopping IPC Server Responder
2018-09-06 23:18:57,331 INFO org.apache.hadoop.ipc.Server: Stopping IPC Server listener on 8031
2018-09-06 23:18:57,331 INFO org.apache.hadoop.ipc.Server: Stopping IPC Server Responder
2018-09-06 23:18:57,331 INFO org.apache.hadoop.yarn.util.AbstractLivelinessMonitor: NMLivelinessMonitor thread interrupted
2018-09-06 23:18:57,332 ERROR org.apache.hadoop.yarn.server.resourcemanager.ResourceManager: Returning, interrupted : java.lang.InterruptedException
2018-09-06 23:18:57,333 INFO org.apache.hadoop.yarn.event.AsyncDispatcher: AsyncDispatcher is draining to stop, igonring any new events.
2018-09-06 23:18:57,333 INFO org.apache.hadoop.yarn.util.AbstractLivelinessMonitor: AMLivelinessMonitor thread interrupted
2018-09-06 23:18:57,334 INFO org.apache.hadoop.yarn.util.AbstractLivelinessMonitor: AMLivelinessMonitor thread interrupted
2018-09-06 23:18:57,334 INFO org.apache.hadoop.yarn.util.AbstractLivelinessMonitor: org.apache.hadoop.yarn.server.resourcemanager.rmcontainer.ContainerAllocationExpirer thread interrupted
2018-09-06 23:18:57,334 ERROR org.apache.hadoop.security.token.delegation.AbstractDelegationTokenSecretManager: ExpiredTokenRemover received java.lang.InterruptedException: sleep interrupted
2018-09-06 23:18:57,335 INFO org.apache.hadoop.metrics2.impl.MetricsSystemImpl: Stopping ResourceManager metrics system...
2018-09-06 23:18:57,337 INFO org.apache.hadoop.metrics2.impl.MetricsSystemImpl: ResourceManager metrics system stopped.
2018-09-06 23:18:57,337 INFO org.apache.hadoop.metrics2.impl.MetricsSystemImpl: ResourceManager metrics system shutdown complete.
2018-09-06 23:18:57,337 INFO org.apache.hadoop.yarn.event.AsyncDispatcher: AsyncDispatcher is draining to stop, igonring any new events.
2018-09-06 23:18:57,338 INFO org.apache.hadoop.yarn.server.resourcemanager.ResourceManager: Transitioned to standby state
2018-09-06 23:18:57,338 INFO org.apache.hadoop.yarn.server.resourcemanager.ResourceManager: SHUTDOWN_MSG: 
/************************************************************
SHUTDOWN_MSG: Shutting down ResourceManager at Jasons-MacBook-Pro.local/192.168.1.103
************************************************************/
2018-09-06 23:48:55,709 INFO org.apache.hadoop.yarn.server.resourcemanager.ResourceManager: STARTUP_MSG: 
/************************************************************
STARTUP_MSG: Starting ResourceManager
STARTUP_MSG:   user = jason
STARTUP_MSG:   host = Jasons-MacBook-Pro.local/192.168.1.103
STARTUP_MSG:   args = []
STARTUP_MSG:   version = 2.8.1
STARTUP_MSG:   build = https://git-wip-us.apache.org/repos/asf/hadoop.git -r 20fe5304904fc2f5a18053c389e43cd26f7a70fe; compiled by 'vinodkv' on 2017-06-02T06:14Z
STARTUP_MSG:   java = 10.0.2
************************************************************/
2018-09-06 23:48:55,719 INFO org.apache.hadoop.yarn.server.resourcemanager.ResourceManager: registered UNIX signal handlers for [TERM, HUP, INT]
2018-09-06 23:48:56,011 INFO org.apache.hadoop.conf.Configuration: found resource core-site.xml at file:/Users/jason/hadoop-2.8.1/etc/hadoop/core-site.xml
2018-09-06 23:48:56,048 WARN org.apache.hadoop.util.NativeCodeLoader: Unable to load native-hadoop library for your platform... using builtin-java classes where applicable
2018-09-06 23:48:56,070 INFO org.apache.hadoop.security.Groups: clearing userToGroupsMap cache
2018-09-06 23:48:56,136 INFO org.apache.hadoop.conf.Configuration: found resource yarn-site.xml at file:/Users/jason/hadoop-2.8.1/etc/hadoop/yarn-site.xml
2018-09-06 23:48:56,355 INFO org.apache.hadoop.yarn.event.AsyncDispatcher: Registering class org.apache.hadoop.yarn.server.resourcemanager.RMFatalEventType for class org.apache.hadoop.yarn.server.resourcemanager.ResourceManager$RMFatalEventDispatcher
2018-09-06 23:48:56,416 INFO org.apache.hadoop.yarn.server.resourcemanager.security.NMTokenSecretManagerInRM: NMTokenKeyRollingInterval: 86400000ms and NMTokenKeyActivationDelay: 900000ms
2018-09-06 23:48:56,421 INFO org.apache.hadoop.yarn.server.resourcemanager.security.RMContainerTokenSecretManager: ContainerTokenKeyRollingInterval: 86400000ms and ContainerTokenKeyActivationDelay: 900000ms
2018-09-06 23:48:56,426 INFO org.apache.hadoop.yarn.server.resourcemanager.security.AMRMTokenSecretManager: AMRMTokenKeyRollingInterval: 86400000ms and AMRMTokenKeyActivationDelay: 900000 ms
2018-09-06 23:48:56,457 INFO org.apache.hadoop.yarn.event.AsyncDispatcher: Registering class org.apache.hadoop.yarn.server.resourcemanager.recovery.RMStateStoreEventType for class org.apache.hadoop.yarn.server.resourcemanager.recovery.RMStateStore$ForwardingEventHandler
2018-09-06 23:48:56,460 INFO org.apache.hadoop.yarn.event.AsyncDispatcher: Registering class org.apache.hadoop.yarn.server.resourcemanager.NodesListManagerEventType for class org.apache.hadoop.yarn.server.resourcemanager.NodesListManager
2018-09-06 23:48:56,460 INFO org.apache.hadoop.yarn.server.resourcemanager.ResourceManager: Using Scheduler: org.apache.hadoop.yarn.server.resourcemanager.scheduler.capacity.CapacityScheduler
2018-09-06 23:48:56,485 INFO org.apache.hadoop.yarn.event.AsyncDispatcher: Registering class org.apache.hadoop.yarn.server.resourcemanager.scheduler.event.SchedulerEventType for class org.apache.hadoop.yarn.server.resourcemanager.ResourceManager$SchedulerEventDispatcher
2018-09-06 23:48:56,486 INFO org.apache.hadoop.yarn.event.AsyncDispatcher: Registering class org.apache.hadoop.yarn.server.resourcemanager.rmapp.RMAppEventType for class org.apache.hadoop.yarn.server.resourcemanager.ResourceManager$ApplicationEventDispatcher
2018-09-06 23:48:56,487 INFO org.apache.hadoop.yarn.event.AsyncDispatcher: Registering class org.apache.hadoop.yarn.server.resourcemanager.rmapp.attempt.RMAppAttemptEventType for class org.apache.hadoop.yarn.server.resourcemanager.ResourceManager$ApplicationAttemptEventDispatcher
2018-09-06 23:48:56,488 INFO org.apache.hadoop.yarn.event.AsyncDispatcher: Registering class org.apache.hadoop.yarn.server.resourcemanager.rmnode.RMNodeEventType for class org.apache.hadoop.yarn.server.resourcemanager.ResourceManager$NodeEventDispatcher
2018-09-06 23:48:56,533 INFO org.apache.hadoop.metrics2.impl.MetricsConfig: loaded properties from hadoop-metrics2.properties
2018-09-06 23:48:56,619 INFO org.apache.hadoop.metrics2.impl.MetricsSystemImpl: Scheduled Metric snapshot period at 10 second(s).
2018-09-06 23:48:56,619 INFO org.apache.hadoop.metrics2.impl.MetricsSystemImpl: ResourceManager metrics system started
2018-09-06 23:48:56,643 INFO org.apache.hadoop.yarn.event.AsyncDispatcher: Registering class org.apache.hadoop.yarn.server.resourcemanager.RMAppManagerEventType for class org.apache.hadoop.yarn.server.resourcemanager.RMAppManager
2018-09-06 23:48:56,649 INFO org.apache.hadoop.yarn.event.AsyncDispatcher: Registering class org.apache.hadoop.yarn.server.resourcemanager.amlauncher.AMLauncherEventType for class org.apache.hadoop.yarn.server.resourcemanager.amlauncher.ApplicationMasterLauncher
2018-09-06 23:48:56,652 INFO org.apache.hadoop.yarn.server.resourcemanager.RMNMInfo: Registered RMNMInfo MBean
2018-09-06 23:48:56,658 INFO org.apache.hadoop.yarn.security.YarnAuthorizationProvider: org.apache.hadoop.yarn.security.ConfiguredYarnAuthorizer is instiantiated.
2018-09-06 23:48:56,659 INFO org.apache.hadoop.util.HostsFileReader: Refreshing hosts (include/exclude) list
2018-09-06 23:48:56,665 INFO org.apache.hadoop.conf.Configuration: found resource capacity-scheduler.xml at file:/Users/jason/hadoop-2.8.1/etc/hadoop/capacity-scheduler.xml
2018-09-06 23:48:56,705 INFO org.apache.hadoop.yarn.server.resourcemanager.scheduler.capacity.CapacitySchedulerConfiguration: max alloc mb per queue for root is undefined
2018-09-06 23:48:56,705 INFO org.apache.hadoop.yarn.server.resourcemanager.scheduler.capacity.CapacitySchedulerConfiguration: max alloc vcore per queue for root is undefined
2018-09-06 23:48:56,713 INFO org.apache.hadoop.yarn.server.resourcemanager.scheduler.capacity.ParentQueue: root, capacity=1.0, asboluteCapacity=1.0, maxCapacity=1.0, asboluteMaxCapacity=1.0, state=RUNNING, acls=SUBMIT_APP:*ADMINISTER_QUEUE:*, labels=*,, offswitchPerHeartbeatLimit = 1, reservationsContinueLooking=true
2018-09-06 23:48:56,714 INFO org.apache.hadoop.yarn.server.resourcemanager.scheduler.capacity.ParentQueue: Initialized parent-queue root name=root, fullname=root
2018-09-06 23:48:56,723 INFO org.apache.hadoop.yarn.server.resourcemanager.scheduler.capacity.CapacitySchedulerConfiguration: max alloc mb per queue for root.default is undefined
2018-09-06 23:48:56,723 INFO org.apache.hadoop.yarn.server.resourcemanager.scheduler.capacity.CapacitySchedulerConfiguration: max alloc vcore per queue for root.default is undefined
2018-09-06 23:48:56,725 INFO org.apache.hadoop.yarn.server.resourcemanager.scheduler.capacity.LeafQueue: Initializing default
capacity = 1.0 [= (float) configuredCapacity / 100 ]
asboluteCapacity = 1.0 [= parentAbsoluteCapacity * capacity ]
maxCapacity = 1.0 [= configuredMaxCapacity ]
absoluteMaxCapacity = 1.0 [= 1.0 maximumCapacity undefined, (parentAbsoluteMaxCapacity * maximumCapacity) / 100 otherwise ]
userLimit = 100 [= configuredUserLimit ]
userLimitFactor = 1.0 [= configuredUserLimitFactor ]
maxApplications = 10000 [= configuredMaximumSystemApplicationsPerQueue or (int)(configuredMaximumSystemApplications * absoluteCapacity)]
maxApplicationsPerUser = 10000 [= (int)(maxApplications * (userLimit / 100.0f) * userLimitFactor) ]
usedCapacity = 0.0 [= usedResourcesMemory / (clusterResourceMemory * absoluteCapacity)]
absoluteUsedCapacity = 0.0 [= usedResourcesMemory / clusterResourceMemory]
maxAMResourcePerQueuePercent = 0.1 [= configuredMaximumAMResourcePercent ]
minimumAllocationFactor = 0.875 [= (float)(maximumAllocationMemory - minimumAllocationMemory) / maximumAllocationMemory ]
maximumAllocation = <memory:8192, vCores:4> [= configuredMaxAllocation ]
numContainers = 0 [= currentNumContainers ]
state = RUNNING [= configuredState ]
acls = SUBMIT_APP:*ADMINISTER_QUEUE:* [= configuredAcls ]
nodeLocalityDelay = 40
labels=*,
reservationsContinueLooking = true
preemptionDisabled = true
defaultAppPriorityPerQueue = 0
2018-09-06 23:48:56,725 INFO org.apache.hadoop.yarn.server.resourcemanager.scheduler.capacity.CapacityScheduler: Initialized queue: default: capacity=1.0, absoluteCapacity=1.0, usedResources=<memory:0, vCores:0>, usedCapacity=0.0, absoluteUsedCapacity=0.0, numApps=0, numContainers=0
2018-09-06 23:48:56,725 INFO org.apache.hadoop.yarn.server.resourcemanager.scheduler.capacity.CapacityScheduler: Initialized queue: root: numChildQueue= 1, capacity=1.0, absoluteCapacity=1.0, usedResources=<memory:0, vCores:0>usedCapacity=0.0, numApps=0, numContainers=0
2018-09-06 23:48:56,726 INFO org.apache.hadoop.yarn.server.resourcemanager.scheduler.capacity.CapacityScheduler: Initialized root queue root: numChildQueue= 1, capacity=1.0, absoluteCapacity=1.0, usedResources=<memory:0, vCores:0>usedCapacity=0.0, numApps=0, numContainers=0
2018-09-06 23:48:56,726 INFO org.apache.hadoop.yarn.server.resourcemanager.scheduler.capacity.CapacityScheduler: Initialized queue mappings, override: false
2018-09-06 23:48:56,727 INFO org.apache.hadoop.yarn.server.resourcemanager.scheduler.capacity.CapacityScheduler: Initialized CapacityScheduler with calculator=class org.apache.hadoop.yarn.util.resource.DefaultResourceCalculator, minimumAllocation=<<memory:1024, vCores:1>>, maximumAllocation=<<memory:8192, vCores:4>>, asynchronousScheduling=false, asyncScheduleInterval=5ms
2018-09-06 23:48:56,730 INFO org.apache.hadoop.conf.Configuration: dynamic-resources.xml not found
2018-09-06 23:48:56,740 INFO org.apache.hadoop.yarn.server.resourcemanager.metrics.SystemMetricsPublisher: YARN system metrics publishing service is not enabled
2018-09-06 23:48:56,740 INFO org.apache.hadoop.yarn.server.resourcemanager.ResourceManager: Transitioning to active state
2018-09-06 23:48:56,747 INFO org.apache.hadoop.util.JvmPauseMonitor: Starting JVM pause monitor
2018-09-06 23:48:56,762 INFO org.apache.hadoop.yarn.server.resourcemanager.recovery.RMStateStore: Updating AMRMToken
2018-09-06 23:48:56,762 INFO org.apache.hadoop.yarn.server.resourcemanager.security.RMContainerTokenSecretManager: Rolling master-key for container-tokens
2018-09-06 23:48:56,762 INFO org.apache.hadoop.yarn.server.resourcemanager.security.NMTokenSecretManagerInRM: Rolling master-key for nm-tokens
2018-09-06 23:48:56,763 INFO org.apache.hadoop.security.token.delegation.AbstractDelegationTokenSecretManager: Updating the current master key for generating delegation tokens
2018-09-06 23:48:56,763 INFO org.apache.hadoop.yarn.server.resourcemanager.security.RMDelegationTokenSecretManager: storing master key with keyID 1
2018-09-06 23:48:56,763 INFO org.apache.hadoop.yarn.server.resourcemanager.recovery.RMStateStore: Storing RMDTMasterKey.
2018-09-06 23:48:56,765 INFO org.apache.hadoop.security.token.delegation.AbstractDelegationTokenSecretManager: Starting expired delegation token remover thread, tokenRemoverScanInterval=60 min(s)
2018-09-06 23:48:56,765 INFO org.apache.hadoop.security.token.delegation.AbstractDelegationTokenSecretManager: Updating the current master key for generating delegation tokens
2018-09-06 23:48:56,767 INFO org.apache.hadoop.yarn.server.resourcemanager.security.RMDelegationTokenSecretManager: storing master key with keyID 2
2018-09-06 23:48:56,767 INFO org.apache.hadoop.yarn.server.resourcemanager.recovery.RMStateStore: Storing RMDTMasterKey.
2018-09-06 23:48:56,769 INFO org.apache.hadoop.yarn.event.AsyncDispatcher: Registering class org.apache.hadoop.yarn.nodelabels.event.NodeLabelsStoreEventType for class org.apache.hadoop.yarn.nodelabels.CommonNodeLabelsManager$ForwardingEventHandler
2018-09-06 23:48:56,799 INFO org.apache.hadoop.ipc.CallQueueManager: Using callQueue: class java.util.concurrent.LinkedBlockingQueue queueCapacity: 5000 scheduler: class org.apache.hadoop.ipc.DefaultRpcScheduler
2018-09-06 23:48:56,814 INFO org.apache.hadoop.ipc.Server: Starting Socket Reader #1 for port 8031
2018-09-06 23:48:56,949 INFO org.apache.hadoop.yarn.factories.impl.pb.RpcServerFactoryPBImpl: Adding protocol org.apache.hadoop.yarn.server.api.ResourceTrackerPB to the server
2018-09-06 23:48:56,950 INFO org.apache.hadoop.ipc.Server: IPC Server Responder: starting
2018-09-06 23:48:56,950 INFO org.apache.hadoop.ipc.Server: IPC Server listener on 8031: starting
2018-09-06 23:48:56,980 INFO org.apache.hadoop.ipc.CallQueueManager: Using callQueue: class java.util.concurrent.LinkedBlockingQueue queueCapacity: 5000 scheduler: class org.apache.hadoop.ipc.DefaultRpcScheduler
2018-09-06 23:48:56,984 INFO org.apache.hadoop.ipc.Server: Starting Socket Reader #1 for port 8030
2018-09-06 23:48:56,995 INFO org.apache.hadoop.yarn.factories.impl.pb.RpcServerFactoryPBImpl: Adding protocol org.apache.hadoop.yarn.api.ApplicationMasterProtocolPB to the server
2018-09-06 23:48:56,995 INFO org.apache.hadoop.ipc.Server: IPC Server Responder: starting
2018-09-06 23:48:56,995 INFO org.apache.hadoop.ipc.Server: IPC Server listener on 8030: starting
2018-09-06 23:48:57,067 INFO org.apache.hadoop.ipc.CallQueueManager: Using callQueue: class java.util.concurrent.LinkedBlockingQueue queueCapacity: 5000 scheduler: class org.apache.hadoop.ipc.DefaultRpcScheduler
2018-09-06 23:48:57,067 INFO org.apache.hadoop.ipc.Server: Starting Socket Reader #1 for port 8032
2018-09-06 23:48:57,071 INFO org.apache.hadoop.yarn.factories.impl.pb.RpcServerFactoryPBImpl: Adding protocol org.apache.hadoop.yarn.api.ApplicationClientProtocolPB to the server
2018-09-06 23:48:57,072 INFO org.apache.hadoop.ipc.Server: IPC Server Responder: starting
2018-09-06 23:48:57,072 INFO org.apache.hadoop.ipc.Server: IPC Server listener on 8032: starting
2018-09-06 23:48:57,077 INFO org.apache.hadoop.yarn.server.resourcemanager.ResourceManager: Transitioned to active state
2018-09-06 23:48:57,144 INFO org.mortbay.log: Logging to org.slf4j.impl.Log4jLoggerAdapter(org.mortbay.log) via org.mortbay.log.Slf4jLog
2018-09-06 23:48:57,150 INFO org.apache.hadoop.security.authentication.server.AuthenticationFilter: Unable to initialize FileSignerSecretProvider, falling back to use random secrets.
2018-09-06 23:48:57,155 INFO org.apache.hadoop.http.HttpRequestLog: Http request log for http.requests.resourcemanager is not defined
2018-09-06 23:48:57,161 INFO org.apache.hadoop.http.HttpServer2: Added global filter 'safety' (class=org.apache.hadoop.http.HttpServer2$QuotingInputFilter)
2018-09-06 23:48:57,165 INFO org.apache.hadoop.http.HttpServer2: Added filter RMAuthenticationFilter (class=org.apache.hadoop.yarn.server.security.http.RMAuthenticationFilter) to context cluster
2018-09-06 23:48:57,165 INFO org.apache.hadoop.http.HttpServer2: Added filter RMAuthenticationFilter (class=org.apache.hadoop.yarn.server.security.http.RMAuthenticationFilter) to context static
2018-09-06 23:48:57,165 INFO org.apache.hadoop.http.HttpServer2: Added filter RMAuthenticationFilter (class=org.apache.hadoop.yarn.server.security.http.RMAuthenticationFilter) to context logs
2018-09-06 23:48:57,165 INFO org.apache.hadoop.http.HttpServer2: Added filter static_user_filter (class=org.apache.hadoop.http.lib.StaticUserWebFilter$StaticUserFilter) to context cluster
2018-09-06 23:48:57,165 INFO org.apache.hadoop.http.HttpServer2: Added filter static_user_filter (class=org.apache.hadoop.http.lib.StaticUserWebFilter$StaticUserFilter) to context static
2018-09-06 23:48:57,166 INFO org.apache.hadoop.http.HttpServer2: Added filter static_user_filter (class=org.apache.hadoop.http.lib.StaticUserWebFilter$StaticUserFilter) to context logs
2018-09-06 23:48:57,168 INFO org.apache.hadoop.http.HttpServer2: adding path spec: /cluster/*
2018-09-06 23:48:57,168 INFO org.apache.hadoop.http.HttpServer2: adding path spec: /ws/*
2018-09-06 23:48:57,496 INFO org.apache.hadoop.yarn.webapp.WebApps: Registered webapp guice modules
2018-09-06 23:48:57,498 INFO org.apache.hadoop.http.HttpServer2: Jetty bound to port 8088
2018-09-06 23:48:57,498 INFO org.mortbay.log: jetty-6.1.26
2018-09-06 23:48:57,527 INFO org.mortbay.log: Extract jar:file:/Users/jason/hadoop-2.8.1/share/hadoop/yarn/hadoop-yarn-common-2.8.1.jar!/webapps/cluster to /var/folders/7r/3c0pxtpd0rg5hjs32v2rrz_00000gn/T/Jetty_0_0_0_0_8088_cluster____u0rgz3/webapp
2018-09-06 23:48:57,618 INFO org.apache.hadoop.security.token.delegation.AbstractDelegationTokenSecretManager: Updating the current master key for generating delegation tokens
2018-09-06 23:48:57,618 INFO org.apache.hadoop.security.token.delegation.AbstractDelegationTokenSecretManager: Starting expired delegation token remover thread, tokenRemoverScanInterval=60 min(s)
2018-09-06 23:48:57,619 INFO org.apache.hadoop.security.token.delegation.AbstractDelegationTokenSecretManager: Updating the current master key for generating delegation tokens
2018-09-06 23:48:58,389 INFO org.mortbay.log: Started HttpServer2$SelectChannelConnectorWithSafeStartup@0.0.0.0:8088
2018-09-06 23:48:58,389 INFO org.apache.hadoop.yarn.webapp.WebApps: Web app cluster started at 8088
2018-09-06 23:48:58,437 INFO org.apache.hadoop.ipc.CallQueueManager: Using callQueue: class java.util.concurrent.LinkedBlockingQueue queueCapacity: 100 scheduler: class org.apache.hadoop.ipc.DefaultRpcScheduler
2018-09-06 23:48:58,437 INFO org.apache.hadoop.ipc.Server: Starting Socket Reader #1 for port 8033
2018-09-06 23:48:58,441 INFO org.apache.hadoop.yarn.factories.impl.pb.RpcServerFactoryPBImpl: Adding protocol org.apache.hadoop.yarn.server.api.ResourceManagerAdministrationProtocolPB to the server
2018-09-06 23:48:58,441 INFO org.apache.hadoop.ipc.Server: IPC Server Responder: starting
2018-09-06 23:48:58,441 INFO org.apache.hadoop.ipc.Server: IPC Server listener on 8033: starting
2018-09-06 23:49:03,000 INFO org.apache.hadoop.yarn.server.resourcemanager.ResourceTrackerService: NodeManager from node 192.168.1.103(cmPort: 60731 httpPort: 8042) registered with capability: <memory:8192, vCores:8>, assigned nodeId 192.168.1.103:60731
2018-09-06 23:49:03,011 INFO org.apache.hadoop.yarn.server.resourcemanager.rmnode.RMNodeImpl: 192.168.1.103:60731 Node Transitioned from NEW to RUNNING
2018-09-06 23:49:03,022 INFO org.apache.hadoop.yarn.server.resourcemanager.scheduler.capacity.CapacityScheduler: Added node 192.168.1.103:60731 clusterResource: <memory:8192, vCores:8>
2018-09-06 23:58:56,667 INFO org.apache.hadoop.yarn.server.resourcemanager.scheduler.AbstractYarnScheduler: Release request cache is cleaned up
2018-09-07 13:12:27,827 WARN org.apache.hadoop.util.JvmPauseMonitor: Detected pause in JVM or host machine (eg GC): pause of approximately 41443ms
No GCs detected
2018-09-07 15:16:45,275 WARN org.apache.hadoop.util.JvmPauseMonitor: Detected pause in JVM or host machine (eg GC): pause of approximately 18839ms
No GCs detected
2018-09-07 16:21:01,267 WARN org.apache.hadoop.util.JvmPauseMonitor: Detected pause in JVM or host machine (eg GC): pause of approximately 18918ms
No GCs detected
2018-09-07 18:00:02,249 INFO org.apache.hadoop.yarn.server.resourcemanager.ClientRMService: Allocated new applicationId: 1
2018-09-07 18:00:07,759 INFO org.apache.hadoop.ipc.Server: IPC Server handler 14 on 8032, call Call#52 Retry#0 org.apache.hadoop.yarn.api.ApplicationClientProtocolPB.getApplicationReport from 192.168.1.103:62791
org.apache.hadoop.yarn.exceptions.ApplicationNotFoundException: Application with id 'application_1536295736741_0001' doesn't exist in RM.
	at org.apache.hadoop.yarn.server.resourcemanager.ClientRMService.getApplicationReport(ClientRMService.java:358)
	at org.apache.hadoop.yarn.api.impl.pb.service.ApplicationClientProtocolPBServiceImpl.getApplicationReport(ApplicationClientProtocolPBServiceImpl.java:214)
	at org.apache.hadoop.yarn.proto.ApplicationClientProtocol$ApplicationClientProtocolService$2.callBlockingMethod(ApplicationClientProtocol.java:497)
	at org.apache.hadoop.ipc.ProtobufRpcEngine$Server$ProtoBufRpcInvoker.call(ProtobufRpcEngine.java:447)
	at org.apache.hadoop.ipc.RPC$Server.call(RPC.java:989)
	at org.apache.hadoop.ipc.Server$RpcCall.run(Server.java:845)
	at org.apache.hadoop.ipc.Server$RpcCall.run(Server.java:788)
	at java.base/java.security.AccessController.doPrivileged(Native Method)
	at java.base/javax.security.auth.Subject.doAs(Subject.java:423)
	at org.apache.hadoop.security.UserGroupInformation.doAs(UserGroupInformation.java:1807)
	at org.apache.hadoop.ipc.Server$Handler.run(Server.java:2455)
2018-09-07 18:17:01,381 INFO org.apache.hadoop.ipc.Server: Socket Reader #1 for port 8031: readAndProcess from client 192.168.1.103 threw exception [java.io.IOException: Connection reset by peer]
java.io.IOException: Connection reset by peer
	at java.base/sun.nio.ch.FileDispatcherImpl.read0(Native Method)
	at java.base/sun.nio.ch.SocketDispatcher.read(SocketDispatcher.java:39)
	at java.base/sun.nio.ch.IOUtil.readIntoNativeBuffer(IOUtil.java:283)
	at java.base/sun.nio.ch.IOUtil.read(IOUtil.java:250)
	at java.base/sun.nio.ch.IOUtil.read(IOUtil.java:226)
	at java.base/sun.nio.ch.SocketChannelImpl.read(SocketChannelImpl.java:382)
	at org.apache.hadoop.ipc.Server.channelRead(Server.java:3020)
	at org.apache.hadoop.ipc.Server.access$2400(Server.java:134)
	at org.apache.hadoop.ipc.Server$Connection.readAndProcess(Server.java:1869)
	at org.apache.hadoop.ipc.Server$Listener.doRead(Server.java:1125)
	at org.apache.hadoop.ipc.Server$Listener$Reader.doRunLoop(Server.java:982)
	at org.apache.hadoop.ipc.Server$Listener$Reader.run(Server.java:953)
2018-09-07 19:30:20,474 INFO org.apache.hadoop.ipc.Server: Socket Reader #1 for port 8031: readAndProcess from client 10.159.0.148 threw exception [java.io.IOException: Operation timed out]
java.io.IOException: Operation timed out
	at java.base/sun.nio.ch.FileDispatcherImpl.read0(Native Method)
	at java.base/sun.nio.ch.SocketDispatcher.read(SocketDispatcher.java:39)
	at java.base/sun.nio.ch.IOUtil.readIntoNativeBuffer(IOUtil.java:283)
	at java.base/sun.nio.ch.IOUtil.read(IOUtil.java:250)
	at java.base/sun.nio.ch.IOUtil.read(IOUtil.java:226)
	at java.base/sun.nio.ch.SocketChannelImpl.read(SocketChannelImpl.java:382)
	at org.apache.hadoop.ipc.Server.channelRead(Server.java:3020)
	at org.apache.hadoop.ipc.Server.access$2400(Server.java:134)
	at org.apache.hadoop.ipc.Server$Connection.readAndProcess(Server.java:1869)
	at org.apache.hadoop.ipc.Server$Listener.doRead(Server.java:1125)
	at org.apache.hadoop.ipc.Server$Listener$Reader.doRunLoop(Server.java:982)
	at org.apache.hadoop.ipc.Server$Listener$Reader.run(Server.java:953)
2018-09-07 23:48:57,877 INFO org.apache.hadoop.security.token.delegation.AbstractDelegationTokenSecretManager: Updating the current master key for generating delegation tokens
2018-09-07 23:48:57,877 INFO org.apache.hadoop.security.token.delegation.AbstractDelegationTokenSecretManager: Updating the current master key for generating delegation tokens
2018-09-07 23:48:57,889 INFO org.apache.hadoop.yarn.server.resourcemanager.security.RMDelegationTokenSecretManager: storing master key with keyID 3
2018-09-07 23:48:57,892 INFO org.apache.hadoop.yarn.server.resourcemanager.recovery.RMStateStore: Storing RMDTMasterKey.
2018-09-08 16:55:37,043 INFO org.apache.hadoop.util.JvmPauseMonitor: Detected pause in JVM or host machine (eg GC): pause of approximately 1019ms
No GCs detected
2018-09-08 17:16:02,720 INFO org.apache.hadoop.yarn.server.resourcemanager.security.RMContainerTokenSecretManager: Rolling master-key for container-tokens
2018-09-08 17:16:02,721 INFO org.apache.hadoop.yarn.server.resourcemanager.security.NMTokenSecretManagerInRM: Rolling master-key for nm-tokens
2018-09-08 17:16:02,720 INFO org.apache.hadoop.yarn.server.resourcemanager.security.AMRMTokenSecretManager: Rolling master-key for amrm-tokens
2018-09-08 17:16:02,727 INFO org.apache.hadoop.yarn.server.resourcemanager.security.RMContainerTokenSecretManager: Going to activate master-key with key-id -1565937169 in 900000ms
2018-09-08 17:16:02,727 INFO org.apache.hadoop.yarn.server.resourcemanager.security.NMTokenSecretManagerInRM: Going to activate master-key with key-id 611851469 in 900000ms
2018-09-08 17:16:02,727 INFO org.apache.hadoop.yarn.server.resourcemanager.recovery.RMStateStore: Updating AMRMToken
2018-09-08 17:31:02,740 INFO org.apache.hadoop.yarn.server.resourcemanager.security.AMRMTokenSecretManager: Activating next master key with id: 562181277
2018-09-08 17:31:02,740 INFO org.apache.hadoop.yarn.server.resourcemanager.recovery.RMStateStore: Updating AMRMToken
2018-09-08 17:31:02,743 INFO org.apache.hadoop.yarn.server.resourcemanager.security.NMTokenSecretManagerInRM: Activating next master key with id: 611851469
2018-09-08 17:31:02,743 INFO org.apache.hadoop.yarn.server.resourcemanager.security.RMContainerTokenSecretManager: Activating next master key with id: -1565937169
2018-09-09 00:33:16,774 INFO org.apache.hadoop.security.token.delegation.AbstractDelegationTokenSecretManager: Updating the current master key for generating delegation tokens
2018-09-09 00:33:16,774 INFO org.apache.hadoop.security.token.delegation.AbstractDelegationTokenSecretManager: Updating the current master key for generating delegation tokens
2018-09-09 00:33:16,777 INFO org.apache.hadoop.yarn.server.resourcemanager.security.RMDelegationTokenSecretManager: storing master key with keyID 4
2018-09-09 00:33:16,777 INFO org.apache.hadoop.yarn.server.resourcemanager.recovery.RMStateStore: Storing RMDTMasterKey.
2018-09-09 05:48:14,773 INFO org.apache.hadoop.yarn.server.resourcemanager.security.RMContainerTokenSecretManager: Rolling master-key for container-tokens
2018-09-09 05:48:14,773 INFO org.apache.hadoop.yarn.server.resourcemanager.security.NMTokenSecretManagerInRM: Rolling master-key for nm-tokens
2018-09-09 05:48:14,773 INFO org.apache.hadoop.yarn.server.resourcemanager.security.AMRMTokenSecretManager: Rolling master-key for amrm-tokens
2018-09-09 05:48:14,780 INFO org.apache.hadoop.yarn.server.resourcemanager.security.NMTokenSecretManagerInRM: Going to activate master-key with key-id 611851470 in 900000ms
2018-09-09 05:48:14,780 INFO org.apache.hadoop.yarn.server.resourcemanager.security.RMContainerTokenSecretManager: Going to activate master-key with key-id -1565937168 in 900000ms
2018-09-09 05:48:14,780 INFO org.apache.hadoop.yarn.server.resourcemanager.recovery.RMStateStore: Updating AMRMToken
2018-09-09 06:03:14,792 INFO org.apache.hadoop.yarn.server.resourcemanager.security.AMRMTokenSecretManager: Activating next master key with id: 562181278
2018-09-09 06:03:14,792 INFO org.apache.hadoop.yarn.server.resourcemanager.security.RMContainerTokenSecretManager: Activating next master key with id: -1565937168
2018-09-09 06:03:14,792 INFO org.apache.hadoop.yarn.server.resourcemanager.security.NMTokenSecretManagerInRM: Activating next master key with id: 611851470
2018-09-09 06:03:14,792 INFO org.apache.hadoop.yarn.server.resourcemanager.recovery.RMStateStore: Updating AMRMToken
2018-09-09 15:07:23,046 INFO org.apache.hadoop.util.JvmPauseMonitor: Detected pause in JVM or host machine (eg GC): pause of approximately 1056ms
No GCs detected
2018-09-10 00:55:03,068 INFO org.apache.hadoop.util.JvmPauseMonitor: Detected pause in JVM or host machine (eg GC): pause of approximately 1028ms
No GCs detected
2018-09-10 00:55:04,682 INFO org.apache.hadoop.security.token.delegation.AbstractDelegationTokenSecretManager: Updating the current master key for generating delegation tokens
2018-09-10 00:55:04,682 INFO org.apache.hadoop.security.token.delegation.AbstractDelegationTokenSecretManager: Updating the current master key for generating delegation tokens
2018-09-10 00:55:04,685 INFO org.apache.hadoop.yarn.server.resourcemanager.security.RMDelegationTokenSecretManager: storing master key with keyID 5
2018-09-10 00:55:04,689 INFO org.apache.hadoop.yarn.server.resourcemanager.recovery.RMStateStore: Storing RMDTMasterKey.
2018-09-10 04:39:54,011 INFO org.apache.hadoop.util.JvmPauseMonitor: Detected pause in JVM or host machine (eg GC): pause of approximately 1019ms
No GCs detected
2018-09-10 11:53:25,052 INFO org.apache.hadoop.util.JvmPauseMonitor: Detected pause in JVM or host machine (eg GC): pause of approximately 1495ms
No GCs detected
2018-09-10 12:22:25,067 INFO org.apache.hadoop.yarn.server.resourcemanager.security.NMTokenSecretManagerInRM: Rolling master-key for nm-tokens
2018-09-10 12:22:25,068 INFO org.apache.hadoop.yarn.server.resourcemanager.security.AMRMTokenSecretManager: Rolling master-key for amrm-tokens
2018-09-10 12:22:25,067 INFO org.apache.hadoop.yarn.server.resourcemanager.security.RMContainerTokenSecretManager: Rolling master-key for container-tokens
2018-09-10 12:22:25,079 INFO org.apache.hadoop.yarn.server.resourcemanager.security.RMContainerTokenSecretManager: Going to activate master-key with key-id -1565937167 in 900000ms
2018-09-10 12:22:25,079 INFO org.apache.hadoop.yarn.server.resourcemanager.security.NMTokenSecretManagerInRM: Going to activate master-key with key-id 611851471 in 900000ms
2018-09-10 12:22:25,082 INFO org.apache.hadoop.yarn.server.resourcemanager.recovery.RMStateStore: Updating AMRMToken
2018-09-10 13:00:25,866 INFO org.apache.hadoop.yarn.server.resourcemanager.security.RMContainerTokenSecretManager: Activating next master key with id: -1565937167
2018-09-10 13:00:25,866 INFO org.apache.hadoop.yarn.server.resourcemanager.security.AMRMTokenSecretManager: Activating next master key with id: 562181279
2018-09-10 13:00:25,866 INFO org.apache.hadoop.yarn.server.resourcemanager.security.NMTokenSecretManagerInRM: Activating next master key with id: 611851471
2018-09-10 13:00:25,868 INFO org.apache.hadoop.yarn.server.resourcemanager.recovery.RMStateStore: Updating AMRMToken
2018-09-10 15:27:51,023 INFO org.apache.hadoop.ipc.Server: Socket Reader #1 for port 8031: readAndProcess from client 192.168.1.103 threw exception [java.io.IOException: Operation timed out]
java.io.IOException: Operation timed out
	at java.base/sun.nio.ch.FileDispatcherImpl.read0(Native Method)
	at java.base/sun.nio.ch.SocketDispatcher.read(SocketDispatcher.java:39)
	at java.base/sun.nio.ch.IOUtil.readIntoNativeBuffer(IOUtil.java:283)
	at java.base/sun.nio.ch.IOUtil.read(IOUtil.java:250)
	at java.base/sun.nio.ch.IOUtil.read(IOUtil.java:226)
	at java.base/sun.nio.ch.SocketChannelImpl.read(SocketChannelImpl.java:382)
	at org.apache.hadoop.ipc.Server.channelRead(Server.java:3020)
	at org.apache.hadoop.ipc.Server.access$2400(Server.java:134)
	at org.apache.hadoop.ipc.Server$Connection.readAndProcess(Server.java:1869)
	at org.apache.hadoop.ipc.Server$Listener.doRead(Server.java:1125)
	at org.apache.hadoop.ipc.Server$Listener$Reader.doRunLoop(Server.java:982)
	at org.apache.hadoop.ipc.Server$Listener$Reader.run(Server.java:953)
2018-09-10 17:59:06,321 ERROR org.apache.hadoop.yarn.server.resourcemanager.ResourceManager: RECEIVED SIGNAL 15: SIGTERM
2018-09-10 17:59:06,484 ERROR org.apache.hadoop.security.token.delegation.AbstractDelegationTokenSecretManager: ExpiredTokenRemover received java.lang.InterruptedException: sleep interrupted
2018-09-10 17:59:06,502 INFO org.mortbay.log: Stopped HttpServer2$SelectChannelConnectorWithSafeStartup@0.0.0.0:8088
2018-09-10 17:59:06,616 INFO org.apache.hadoop.ipc.Server: Stopping server on 8032
2018-09-10 17:59:06,627 INFO org.apache.hadoop.ipc.Server: Stopping IPC Server listener on 8032
2018-09-10 17:59:06,636 INFO org.apache.hadoop.ipc.Server: Stopping IPC Server Responder
2018-09-10 17:59:06,644 INFO org.apache.hadoop.ipc.Server: Stopping server on 8033
2018-09-10 17:59:06,646 INFO org.apache.hadoop.ipc.Server: Stopping IPC Server listener on 8033
2018-09-10 17:59:06,648 INFO org.apache.hadoop.ipc.Server: Stopping IPC Server Responder
2018-09-10 17:59:06,650 INFO org.apache.hadoop.yarn.server.resourcemanager.ResourceManager: Transitioning to standby state
2018-09-10 17:59:06,653 WARN org.apache.hadoop.yarn.server.resourcemanager.amlauncher.ApplicationMasterLauncher: org.apache.hadoop.yarn.server.resourcemanager.amlauncher.ApplicationMasterLauncher$LauncherThread interrupted. Returning.
2018-09-10 17:59:06,654 INFO org.apache.hadoop.ipc.Server: Stopping server on 8030
2018-09-10 17:59:06,659 INFO org.apache.hadoop.ipc.Server: Stopping IPC Server listener on 8030
2018-09-10 17:59:06,660 INFO org.apache.hadoop.ipc.Server: Stopping IPC Server Responder
2018-09-10 17:59:06,660 INFO org.apache.hadoop.ipc.Server: Stopping server on 8031
2018-09-10 17:59:06,664 INFO org.apache.hadoop.ipc.Server: Stopping IPC Server listener on 8031
2018-09-10 17:59:06,666 INFO org.apache.hadoop.ipc.Server: Stopping IPC Server Responder
2018-09-10 17:59:06,666 INFO org.apache.hadoop.yarn.util.AbstractLivelinessMonitor: NMLivelinessMonitor thread interrupted
2018-09-10 17:59:06,668 ERROR org.apache.hadoop.yarn.server.resourcemanager.ResourceManager: Returning, interrupted : java.lang.InterruptedException
2018-09-10 17:59:06,674 INFO org.apache.hadoop.yarn.event.AsyncDispatcher: AsyncDispatcher is draining to stop, igonring any new events.
2018-09-10 17:59:06,677 INFO org.apache.hadoop.yarn.util.AbstractLivelinessMonitor: AMLivelinessMonitor thread interrupted
2018-09-10 17:59:06,680 INFO org.apache.hadoop.yarn.util.AbstractLivelinessMonitor: AMLivelinessMonitor thread interrupted
2018-09-10 17:59:06,681 INFO org.apache.hadoop.yarn.util.AbstractLivelinessMonitor: org.apache.hadoop.yarn.server.resourcemanager.rmcontainer.ContainerAllocationExpirer thread interrupted
2018-09-10 17:59:06,681 ERROR org.apache.hadoop.security.token.delegation.AbstractDelegationTokenSecretManager: ExpiredTokenRemover received java.lang.InterruptedException: sleep interrupted
2018-09-10 17:59:06,685 INFO org.apache.hadoop.metrics2.impl.MetricsSystemImpl: Stopping ResourceManager metrics system...
2018-09-10 17:59:06,704 INFO org.apache.hadoop.metrics2.impl.MetricsSystemImpl: ResourceManager metrics system stopped.
2018-09-10 17:59:06,706 INFO org.apache.hadoop.metrics2.impl.MetricsSystemImpl: ResourceManager metrics system shutdown complete.
2018-09-10 17:59:06,706 INFO org.apache.hadoop.yarn.event.AsyncDispatcher: AsyncDispatcher is draining to stop, igonring any new events.
2018-09-10 17:59:06,708 INFO org.apache.hadoop.yarn.server.resourcemanager.ResourceManager: Transitioned to standby state
2018-09-10 17:59:06,710 INFO org.apache.hadoop.yarn.server.resourcemanager.ResourceManager: SHUTDOWN_MSG: 
/************************************************************
SHUTDOWN_MSG: Shutting down ResourceManager at Jasons-MacBook-Pro.local/192.168.1.103
************************************************************/
2018-09-10 18:00:41,289 INFO org.apache.hadoop.yarn.server.resourcemanager.ResourceManager: STARTUP_MSG: 
/************************************************************
STARTUP_MSG: Starting ResourceManager
STARTUP_MSG:   user = jason
STARTUP_MSG:   host = Jasons-MacBook-Pro.local/192.168.1.103
STARTUP_MSG:   args = []
STARTUP_MSG:   version = 2.8.1
STARTUP_MSG:   build = https://git-wip-us.apache.org/repos/asf/hadoop.git -r 20fe5304904fc2f5a18053c389e43cd26f7a70fe; compiled by 'vinodkv' on 2017-06-02T06:14Z
STARTUP_MSG:   java = 1.8.0_181
************************************************************/
2018-09-10 18:00:41,296 INFO org.apache.hadoop.yarn.server.resourcemanager.ResourceManager: registered UNIX signal handlers for [TERM, HUP, INT]
2018-09-10 18:00:41,518 INFO org.apache.hadoop.conf.Configuration: found resource core-site.xml at file:/Users/jason/hadoop-2.8.1/etc/hadoop/core-site.xml
2018-09-10 18:00:41,547 WARN org.apache.hadoop.util.NativeCodeLoader: Unable to load native-hadoop library for your platform... using builtin-java classes where applicable
2018-09-10 18:00:41,566 INFO org.apache.hadoop.security.Groups: clearing userToGroupsMap cache
2018-09-10 18:00:41,620 INFO org.apache.hadoop.conf.Configuration: found resource yarn-site.xml at file:/Users/jason/hadoop-2.8.1/etc/hadoop/yarn-site.xml
2018-09-10 18:00:41,763 INFO org.apache.hadoop.yarn.event.AsyncDispatcher: Registering class org.apache.hadoop.yarn.server.resourcemanager.RMFatalEventType for class org.apache.hadoop.yarn.server.resourcemanager.ResourceManager$RMFatalEventDispatcher
2018-09-10 18:00:41,919 INFO org.apache.hadoop.yarn.server.resourcemanager.security.NMTokenSecretManagerInRM: NMTokenKeyRollingInterval: 86400000ms and NMTokenKeyActivationDelay: 900000ms
2018-09-10 18:00:41,923 INFO org.apache.hadoop.yarn.server.resourcemanager.security.RMContainerTokenSecretManager: ContainerTokenKeyRollingInterval: 86400000ms and ContainerTokenKeyActivationDelay: 900000ms
2018-09-10 18:00:41,927 INFO org.apache.hadoop.yarn.server.resourcemanager.security.AMRMTokenSecretManager: AMRMTokenKeyRollingInterval: 86400000ms and AMRMTokenKeyActivationDelay: 900000 ms
2018-09-10 18:00:41,956 INFO org.apache.hadoop.yarn.event.AsyncDispatcher: Registering class org.apache.hadoop.yarn.server.resourcemanager.recovery.RMStateStoreEventType for class org.apache.hadoop.yarn.server.resourcemanager.recovery.RMStateStore$ForwardingEventHandler
2018-09-10 18:00:41,958 INFO org.apache.hadoop.yarn.event.AsyncDispatcher: Registering class org.apache.hadoop.yarn.server.resourcemanager.NodesListManagerEventType for class org.apache.hadoop.yarn.server.resourcemanager.NodesListManager
2018-09-10 18:00:41,958 INFO org.apache.hadoop.yarn.server.resourcemanager.ResourceManager: Using Scheduler: org.apache.hadoop.yarn.server.resourcemanager.scheduler.capacity.CapacityScheduler
2018-09-10 18:00:41,980 INFO org.apache.hadoop.yarn.event.AsyncDispatcher: Registering class org.apache.hadoop.yarn.server.resourcemanager.scheduler.event.SchedulerEventType for class org.apache.hadoop.yarn.server.resourcemanager.ResourceManager$SchedulerEventDispatcher
2018-09-10 18:00:41,981 INFO org.apache.hadoop.yarn.event.AsyncDispatcher: Registering class org.apache.hadoop.yarn.server.resourcemanager.rmapp.RMAppEventType for class org.apache.hadoop.yarn.server.resourcemanager.ResourceManager$ApplicationEventDispatcher
2018-09-10 18:00:41,982 INFO org.apache.hadoop.yarn.event.AsyncDispatcher: Registering class org.apache.hadoop.yarn.server.resourcemanager.rmapp.attempt.RMAppAttemptEventType for class org.apache.hadoop.yarn.server.resourcemanager.ResourceManager$ApplicationAttemptEventDispatcher
2018-09-10 18:00:41,983 INFO org.apache.hadoop.yarn.event.AsyncDispatcher: Registering class org.apache.hadoop.yarn.server.resourcemanager.rmnode.RMNodeEventType for class org.apache.hadoop.yarn.server.resourcemanager.ResourceManager$NodeEventDispatcher
2018-09-10 18:00:42,016 INFO org.apache.hadoop.metrics2.impl.MetricsConfig: loaded properties from hadoop-metrics2.properties
2018-09-10 18:00:42,069 INFO org.apache.hadoop.metrics2.impl.MetricsSystemImpl: Scheduled Metric snapshot period at 10 second(s).
2018-09-10 18:00:42,069 INFO org.apache.hadoop.metrics2.impl.MetricsSystemImpl: ResourceManager metrics system started
2018-09-10 18:00:42,082 INFO org.apache.hadoop.yarn.event.AsyncDispatcher: Registering class org.apache.hadoop.yarn.server.resourcemanager.RMAppManagerEventType for class org.apache.hadoop.yarn.server.resourcemanager.RMAppManager
2018-09-10 18:00:42,089 INFO org.apache.hadoop.yarn.event.AsyncDispatcher: Registering class org.apache.hadoop.yarn.server.resourcemanager.amlauncher.AMLauncherEventType for class org.apache.hadoop.yarn.server.resourcemanager.amlauncher.ApplicationMasterLauncher
2018-09-10 18:00:42,091 INFO org.apache.hadoop.yarn.server.resourcemanager.RMNMInfo: Registered RMNMInfo MBean
2018-09-10 18:00:42,097 INFO org.apache.hadoop.yarn.security.YarnAuthorizationProvider: org.apache.hadoop.yarn.security.ConfiguredYarnAuthorizer is instiantiated.
2018-09-10 18:00:42,098 INFO org.apache.hadoop.util.HostsFileReader: Refreshing hosts (include/exclude) list
2018-09-10 18:00:42,103 INFO org.apache.hadoop.conf.Configuration: found resource capacity-scheduler.xml at file:/Users/jason/hadoop-2.8.1/etc/hadoop/capacity-scheduler.xml
2018-09-10 18:00:42,140 INFO org.apache.hadoop.yarn.server.resourcemanager.scheduler.capacity.CapacitySchedulerConfiguration: max alloc mb per queue for root is undefined
2018-09-10 18:00:42,140 INFO org.apache.hadoop.yarn.server.resourcemanager.scheduler.capacity.CapacitySchedulerConfiguration: max alloc vcore per queue for root is undefined
2018-09-10 18:00:42,146 INFO org.apache.hadoop.yarn.server.resourcemanager.scheduler.capacity.ParentQueue: root, capacity=1.0, asboluteCapacity=1.0, maxCapacity=1.0, asboluteMaxCapacity=1.0, state=RUNNING, acls=ADMINISTER_QUEUE:*SUBMIT_APP:*, labels=*,, offswitchPerHeartbeatLimit = 1, reservationsContinueLooking=true
2018-09-10 18:00:42,147 INFO org.apache.hadoop.yarn.server.resourcemanager.scheduler.capacity.ParentQueue: Initialized parent-queue root name=root, fullname=root
2018-09-10 18:00:42,154 INFO org.apache.hadoop.yarn.server.resourcemanager.scheduler.capacity.CapacitySchedulerConfiguration: max alloc mb per queue for root.default is undefined
2018-09-10 18:00:42,154 INFO org.apache.hadoop.yarn.server.resourcemanager.scheduler.capacity.CapacitySchedulerConfiguration: max alloc vcore per queue for root.default is undefined
2018-09-10 18:00:42,156 INFO org.apache.hadoop.yarn.server.resourcemanager.scheduler.capacity.LeafQueue: Initializing default
capacity = 1.0 [= (float) configuredCapacity / 100 ]
asboluteCapacity = 1.0 [= parentAbsoluteCapacity * capacity ]
maxCapacity = 1.0 [= configuredMaxCapacity ]
absoluteMaxCapacity = 1.0 [= 1.0 maximumCapacity undefined, (parentAbsoluteMaxCapacity * maximumCapacity) / 100 otherwise ]
userLimit = 100 [= configuredUserLimit ]
userLimitFactor = 1.0 [= configuredUserLimitFactor ]
maxApplications = 10000 [= configuredMaximumSystemApplicationsPerQueue or (int)(configuredMaximumSystemApplications * absoluteCapacity)]
maxApplicationsPerUser = 10000 [= (int)(maxApplications * (userLimit / 100.0f) * userLimitFactor) ]
usedCapacity = 0.0 [= usedResourcesMemory / (clusterResourceMemory * absoluteCapacity)]
absoluteUsedCapacity = 0.0 [= usedResourcesMemory / clusterResourceMemory]
maxAMResourcePerQueuePercent = 0.1 [= configuredMaximumAMResourcePercent ]
minimumAllocationFactor = 0.875 [= (float)(maximumAllocationMemory - minimumAllocationMemory) / maximumAllocationMemory ]
maximumAllocation = <memory:8192, vCores:4> [= configuredMaxAllocation ]
numContainers = 0 [= currentNumContainers ]
state = RUNNING [= configuredState ]
acls = ADMINISTER_QUEUE:*SUBMIT_APP:* [= configuredAcls ]
nodeLocalityDelay = 40
labels=*,
reservationsContinueLooking = true
preemptionDisabled = true
defaultAppPriorityPerQueue = 0
2018-09-10 18:00:42,156 INFO org.apache.hadoop.yarn.server.resourcemanager.scheduler.capacity.CapacityScheduler: Initialized queue: default: capacity=1.0, absoluteCapacity=1.0, usedResources=<memory:0, vCores:0>, usedCapacity=0.0, absoluteUsedCapacity=0.0, numApps=0, numContainers=0
2018-09-10 18:00:42,157 INFO org.apache.hadoop.yarn.server.resourcemanager.scheduler.capacity.CapacityScheduler: Initialized queue: root: numChildQueue= 1, capacity=1.0, absoluteCapacity=1.0, usedResources=<memory:0, vCores:0>usedCapacity=0.0, numApps=0, numContainers=0
2018-09-10 18:00:42,157 INFO org.apache.hadoop.yarn.server.resourcemanager.scheduler.capacity.CapacityScheduler: Initialized root queue root: numChildQueue= 1, capacity=1.0, absoluteCapacity=1.0, usedResources=<memory:0, vCores:0>usedCapacity=0.0, numApps=0, numContainers=0
2018-09-10 18:00:42,157 INFO org.apache.hadoop.yarn.server.resourcemanager.scheduler.capacity.CapacityScheduler: Initialized queue mappings, override: false
2018-09-10 18:00:42,158 INFO org.apache.hadoop.yarn.server.resourcemanager.scheduler.capacity.CapacityScheduler: Initialized CapacityScheduler with calculator=class org.apache.hadoop.yarn.util.resource.DefaultResourceCalculator, minimumAllocation=<<memory:1024, vCores:1>>, maximumAllocation=<<memory:8192, vCores:4>>, asynchronousScheduling=false, asyncScheduleInterval=5ms
2018-09-10 18:00:42,161 INFO org.apache.hadoop.conf.Configuration: dynamic-resources.xml not found
2018-09-10 18:00:42,171 INFO org.apache.hadoop.yarn.server.resourcemanager.metrics.SystemMetricsPublisher: YARN system metrics publishing service is not enabled
2018-09-10 18:00:42,171 INFO org.apache.hadoop.yarn.server.resourcemanager.ResourceManager: Transitioning to active state
2018-09-10 18:00:42,184 INFO org.apache.hadoop.util.JvmPauseMonitor: Starting JVM pause monitor
2018-09-10 18:00:42,198 INFO org.apache.hadoop.yarn.server.resourcemanager.recovery.RMStateStore: Updating AMRMToken
2018-09-10 18:00:42,198 INFO org.apache.hadoop.yarn.server.resourcemanager.security.RMContainerTokenSecretManager: Rolling master-key for container-tokens
2018-09-10 18:00:42,199 INFO org.apache.hadoop.yarn.server.resourcemanager.security.NMTokenSecretManagerInRM: Rolling master-key for nm-tokens
2018-09-10 18:00:42,199 INFO org.apache.hadoop.security.token.delegation.AbstractDelegationTokenSecretManager: Updating the current master key for generating delegation tokens
2018-09-10 18:00:42,199 INFO org.apache.hadoop.yarn.server.resourcemanager.security.RMDelegationTokenSecretManager: storing master key with keyID 1
2018-09-10 18:00:42,199 INFO org.apache.hadoop.yarn.server.resourcemanager.recovery.RMStateStore: Storing RMDTMasterKey.
2018-09-10 18:00:42,200 INFO org.apache.hadoop.security.token.delegation.AbstractDelegationTokenSecretManager: Starting expired delegation token remover thread, tokenRemoverScanInterval=60 min(s)
2018-09-10 18:00:42,200 INFO org.apache.hadoop.security.token.delegation.AbstractDelegationTokenSecretManager: Updating the current master key for generating delegation tokens
2018-09-10 18:00:42,200 INFO org.apache.hadoop.yarn.server.resourcemanager.security.RMDelegationTokenSecretManager: storing master key with keyID 2
2018-09-10 18:00:42,200 INFO org.apache.hadoop.yarn.server.resourcemanager.recovery.RMStateStore: Storing RMDTMasterKey.
2018-09-10 18:00:42,201 INFO org.apache.hadoop.yarn.event.AsyncDispatcher: Registering class org.apache.hadoop.yarn.nodelabels.event.NodeLabelsStoreEventType for class org.apache.hadoop.yarn.nodelabels.CommonNodeLabelsManager$ForwardingEventHandler
2018-09-10 18:00:42,229 INFO org.apache.hadoop.ipc.CallQueueManager: Using callQueue: class java.util.concurrent.LinkedBlockingQueue queueCapacity: 5000 scheduler: class org.apache.hadoop.ipc.DefaultRpcScheduler
2018-09-10 18:00:42,252 INFO org.apache.hadoop.ipc.Server: Starting Socket Reader #1 for port 8031
2018-09-10 18:00:42,356 INFO org.apache.hadoop.yarn.factories.impl.pb.RpcServerFactoryPBImpl: Adding protocol org.apache.hadoop.yarn.server.api.ResourceTrackerPB to the server
2018-09-10 18:00:42,356 INFO org.apache.hadoop.ipc.Server: IPC Server Responder: starting
2018-09-10 18:00:42,356 INFO org.apache.hadoop.ipc.Server: IPC Server listener on 8031: starting
2018-09-10 18:00:42,375 INFO org.apache.hadoop.ipc.CallQueueManager: Using callQueue: class java.util.concurrent.LinkedBlockingQueue queueCapacity: 5000 scheduler: class org.apache.hadoop.ipc.DefaultRpcScheduler
2018-09-10 18:00:42,380 INFO org.apache.hadoop.ipc.Server: Starting Socket Reader #1 for port 8030
2018-09-10 18:00:42,392 INFO org.apache.hadoop.yarn.factories.impl.pb.RpcServerFactoryPBImpl: Adding protocol org.apache.hadoop.yarn.api.ApplicationMasterProtocolPB to the server
2018-09-10 18:00:42,393 INFO org.apache.hadoop.ipc.Server: IPC Server Responder: starting
2018-09-10 18:00:42,393 INFO org.apache.hadoop.ipc.Server: IPC Server listener on 8030: starting
2018-09-10 18:00:42,474 INFO org.apache.hadoop.ipc.CallQueueManager: Using callQueue: class java.util.concurrent.LinkedBlockingQueue queueCapacity: 5000 scheduler: class org.apache.hadoop.ipc.DefaultRpcScheduler
2018-09-10 18:00:42,475 INFO org.apache.hadoop.ipc.Server: Starting Socket Reader #1 for port 8032
2018-09-10 18:00:42,478 INFO org.apache.hadoop.yarn.factories.impl.pb.RpcServerFactoryPBImpl: Adding protocol org.apache.hadoop.yarn.api.ApplicationClientProtocolPB to the server
2018-09-10 18:00:42,479 INFO org.apache.hadoop.ipc.Server: IPC Server Responder: starting
2018-09-10 18:00:42,479 INFO org.apache.hadoop.ipc.Server: IPC Server listener on 8032: starting
2018-09-10 18:00:42,484 INFO org.apache.hadoop.yarn.server.resourcemanager.ResourceManager: Transitioned to active state
2018-09-10 18:00:42,539 INFO org.mortbay.log: Logging to org.slf4j.impl.Log4jLoggerAdapter(org.mortbay.log) via org.mortbay.log.Slf4jLog
2018-09-10 18:00:42,545 INFO org.apache.hadoop.security.authentication.server.AuthenticationFilter: Unable to initialize FileSignerSecretProvider, falling back to use random secrets.
2018-09-10 18:00:42,549 INFO org.apache.hadoop.http.HttpRequestLog: Http request log for http.requests.resourcemanager is not defined
2018-09-10 18:00:42,554 INFO org.apache.hadoop.http.HttpServer2: Added global filter 'safety' (class=org.apache.hadoop.http.HttpServer2$QuotingInputFilter)
2018-09-10 18:00:42,559 INFO org.apache.hadoop.http.HttpServer2: Added filter RMAuthenticationFilter (class=org.apache.hadoop.yarn.server.security.http.RMAuthenticationFilter) to context cluster
2018-09-10 18:00:42,559 INFO org.apache.hadoop.http.HttpServer2: Added filter RMAuthenticationFilter (class=org.apache.hadoop.yarn.server.security.http.RMAuthenticationFilter) to context logs
2018-09-10 18:00:42,559 INFO org.apache.hadoop.http.HttpServer2: Added filter RMAuthenticationFilter (class=org.apache.hadoop.yarn.server.security.http.RMAuthenticationFilter) to context static
2018-09-10 18:00:42,559 INFO org.apache.hadoop.http.HttpServer2: Added filter static_user_filter (class=org.apache.hadoop.http.lib.StaticUserWebFilter$StaticUserFilter) to context cluster
2018-09-10 18:00:42,559 INFO org.apache.hadoop.http.HttpServer2: Added filter static_user_filter (class=org.apache.hadoop.http.lib.StaticUserWebFilter$StaticUserFilter) to context logs
2018-09-10 18:00:42,559 INFO org.apache.hadoop.http.HttpServer2: Added filter static_user_filter (class=org.apache.hadoop.http.lib.StaticUserWebFilter$StaticUserFilter) to context static
2018-09-10 18:00:42,561 INFO org.apache.hadoop.http.HttpServer2: adding path spec: /cluster/*
2018-09-10 18:00:42,562 INFO org.apache.hadoop.http.HttpServer2: adding path spec: /ws/*
2018-09-10 18:00:42,815 INFO org.apache.hadoop.yarn.webapp.WebApps: Registered webapp guice modules
2018-09-10 18:00:42,818 INFO org.apache.hadoop.http.HttpServer2: Jetty bound to port 8088
2018-09-10 18:00:42,818 INFO org.mortbay.log: jetty-6.1.26
2018-09-10 18:00:42,836 INFO org.mortbay.log: Extract jar:file:/Users/jason/hadoop-2.8.1/share/hadoop/yarn/hadoop-yarn-common-2.8.1.jar!/webapps/cluster to /var/folders/7r/3c0pxtpd0rg5hjs32v2rrz_00000gn/T/Jetty_0_0_0_0_8088_cluster____u0rgz3/webapp
2018-09-10 18:00:42,972 INFO org.apache.hadoop.security.token.delegation.AbstractDelegationTokenSecretManager: Updating the current master key for generating delegation tokens
2018-09-10 18:00:42,972 INFO org.apache.hadoop.security.token.delegation.AbstractDelegationTokenSecretManager: Starting expired delegation token remover thread, tokenRemoverScanInterval=60 min(s)
2018-09-10 18:00:42,972 INFO org.apache.hadoop.security.token.delegation.AbstractDelegationTokenSecretManager: Updating the current master key for generating delegation tokens
2018-09-10 18:00:43,700 INFO org.mortbay.log: Started HttpServer2$SelectChannelConnectorWithSafeStartup@0.0.0.0:8088
2018-09-10 18:00:43,701 INFO org.apache.hadoop.yarn.webapp.WebApps: Web app cluster started at 8088
2018-09-10 18:00:43,734 INFO org.apache.hadoop.ipc.CallQueueManager: Using callQueue: class java.util.concurrent.LinkedBlockingQueue queueCapacity: 100 scheduler: class org.apache.hadoop.ipc.DefaultRpcScheduler
2018-09-10 18:00:43,735 INFO org.apache.hadoop.ipc.Server: Starting Socket Reader #1 for port 8033
2018-09-10 18:00:43,737 INFO org.apache.hadoop.yarn.factories.impl.pb.RpcServerFactoryPBImpl: Adding protocol org.apache.hadoop.yarn.server.api.ResourceManagerAdministrationProtocolPB to the server
2018-09-10 18:00:43,737 INFO org.apache.hadoop.ipc.Server: IPC Server Responder: starting
2018-09-10 18:00:43,737 INFO org.apache.hadoop.ipc.Server: IPC Server listener on 8033: starting
2018-09-10 18:00:49,530 INFO org.apache.hadoop.yarn.server.resourcemanager.ResourceTrackerService: NodeManager from node 192.168.1.103(cmPort: 55724 httpPort: 8042) registered with capability: <memory:8192, vCores:8>, assigned nodeId 192.168.1.103:55724
2018-09-10 18:00:49,534 INFO org.apache.hadoop.yarn.server.resourcemanager.rmnode.RMNodeImpl: 192.168.1.103:55724 Node Transitioned from NEW to RUNNING
2018-09-10 18:00:49,541 INFO org.apache.hadoop.yarn.server.resourcemanager.scheduler.capacity.CapacityScheduler: Added node 192.168.1.103:55724 clusterResource: <memory:8192, vCores:8>
2018-09-10 18:10:42,109 INFO org.apache.hadoop.yarn.server.resourcemanager.scheduler.AbstractYarnScheduler: Release request cache is cleaned up
2018-09-10 18:39:17,988 ERROR org.apache.hadoop.yarn.server.resourcemanager.ResourceManager: RECEIVED SIGNAL 15: SIGTERM
2018-09-10 18:39:17,998 ERROR org.apache.hadoop.security.token.delegation.AbstractDelegationTokenSecretManager: ExpiredTokenRemover received java.lang.InterruptedException: sleep interrupted
2018-09-10 18:39:18,001 INFO org.mortbay.log: Stopped HttpServer2$SelectChannelConnectorWithSafeStartup@0.0.0.0:8088
2018-09-10 18:39:18,106 INFO org.apache.hadoop.ipc.Server: Stopping server on 8032
2018-09-10 18:39:18,107 INFO org.apache.hadoop.ipc.Server: Stopping IPC Server Responder
2018-09-10 18:39:18,107 INFO org.apache.hadoop.ipc.Server: Stopping IPC Server listener on 8032
2018-09-10 18:39:18,108 INFO org.apache.hadoop.ipc.Server: Stopping server on 8033
2018-09-10 18:39:18,108 INFO org.apache.hadoop.ipc.Server: Stopping IPC Server listener on 8033
2018-09-10 18:39:18,108 INFO org.apache.hadoop.ipc.Server: Stopping IPC Server Responder
2018-09-10 18:39:18,111 INFO org.apache.hadoop.yarn.server.resourcemanager.ResourceManager: Transitioning to standby state
2018-09-10 18:39:18,112 WARN org.apache.hadoop.yarn.server.resourcemanager.amlauncher.ApplicationMasterLauncher: org.apache.hadoop.yarn.server.resourcemanager.amlauncher.ApplicationMasterLauncher$LauncherThread interrupted. Returning.
2018-09-10 18:39:18,112 INFO org.apache.hadoop.ipc.Server: Stopping server on 8030
2018-09-10 18:39:18,113 INFO org.apache.hadoop.ipc.Server: Stopping IPC Server Responder
2018-09-10 18:39:18,113 INFO org.apache.hadoop.ipc.Server: Stopping server on 8031
2018-09-10 18:39:18,116 INFO org.apache.hadoop.ipc.Server: Stopping IPC Server listener on 8030
2018-09-10 18:39:18,117 INFO org.apache.hadoop.ipc.Server: Stopping IPC Server listener on 8031
2018-09-10 18:39:18,117 INFO org.apache.hadoop.ipc.Server: Stopping IPC Server Responder
2018-09-10 18:39:18,117 INFO org.apache.hadoop.yarn.util.AbstractLivelinessMonitor: NMLivelinessMonitor thread interrupted
2018-09-10 18:39:18,118 ERROR org.apache.hadoop.yarn.server.resourcemanager.ResourceManager: Returning, interrupted : java.lang.InterruptedException
2018-09-10 18:39:18,119 INFO org.apache.hadoop.yarn.event.AsyncDispatcher: AsyncDispatcher is draining to stop, igonring any new events.
2018-09-10 18:39:18,119 INFO org.apache.hadoop.yarn.util.AbstractLivelinessMonitor: AMLivelinessMonitor thread interrupted
2018-09-10 18:39:18,119 INFO org.apache.hadoop.yarn.util.AbstractLivelinessMonitor: AMLivelinessMonitor thread interrupted
2018-09-10 18:39:18,119 INFO org.apache.hadoop.yarn.util.AbstractLivelinessMonitor: org.apache.hadoop.yarn.server.resourcemanager.rmcontainer.ContainerAllocationExpirer thread interrupted
2018-09-10 18:39:18,119 ERROR org.apache.hadoop.security.token.delegation.AbstractDelegationTokenSecretManager: ExpiredTokenRemover received java.lang.InterruptedException: sleep interrupted
2018-09-10 18:39:18,120 INFO org.apache.hadoop.metrics2.impl.MetricsSystemImpl: Stopping ResourceManager metrics system...
2018-09-10 18:39:18,122 INFO org.apache.hadoop.metrics2.impl.MetricsSystemImpl: ResourceManager metrics system stopped.
2018-09-10 18:39:18,122 INFO org.apache.hadoop.metrics2.impl.MetricsSystemImpl: ResourceManager metrics system shutdown complete.
2018-09-10 18:39:18,122 INFO org.apache.hadoop.yarn.event.AsyncDispatcher: AsyncDispatcher is draining to stop, igonring any new events.
2018-09-10 18:39:18,123 INFO org.apache.hadoop.yarn.server.resourcemanager.ResourceManager: Transitioned to standby state
2018-09-10 18:39:18,123 INFO org.apache.hadoop.yarn.server.resourcemanager.ResourceManager: SHUTDOWN_MSG: 
/************************************************************
SHUTDOWN_MSG: Shutting down ResourceManager at Jasons-MacBook-Pro.local/192.168.1.103
************************************************************/
2018-09-10 18:39:50,799 INFO org.apache.hadoop.yarn.server.resourcemanager.ResourceManager: STARTUP_MSG: 
/************************************************************
STARTUP_MSG: Starting ResourceManager
STARTUP_MSG:   user = jason
STARTUP_MSG:   host = Jasons-MacBook-Pro.local/192.168.1.103
STARTUP_MSG:   args = []
STARTUP_MSG:   version = 2.8.1
STARTUP_MSG:   build = https://git-wip-us.apache.org/repos/asf/hadoop.git -r 20fe5304904fc2f5a18053c389e43cd26f7a70fe; compiled by 'vinodkv' on 2017-06-02T06:14Z
STARTUP_MSG:   java = 1.8.0_181
************************************************************/
2018-09-10 18:39:50,807 INFO org.apache.hadoop.yarn.server.resourcemanager.ResourceManager: registered UNIX signal handlers for [TERM, HUP, INT]
2018-09-10 18:39:51,028 INFO org.apache.hadoop.conf.Configuration: found resource core-site.xml at file:/Users/jason/hadoop-2.8.1/etc/hadoop/core-site.xml
2018-09-10 18:39:51,057 WARN org.apache.hadoop.util.NativeCodeLoader: Unable to load native-hadoop library for your platform... using builtin-java classes where applicable
2018-09-10 18:39:51,075 INFO org.apache.hadoop.security.Groups: clearing userToGroupsMap cache
2018-09-10 18:39:51,126 INFO org.apache.hadoop.conf.Configuration: found resource yarn-site.xml at file:/Users/jason/hadoop-2.8.1/etc/hadoop/yarn-site.xml
2018-09-10 18:39:51,312 INFO org.apache.hadoop.yarn.event.AsyncDispatcher: Registering class org.apache.hadoop.yarn.server.resourcemanager.RMFatalEventType for class org.apache.hadoop.yarn.server.resourcemanager.ResourceManager$RMFatalEventDispatcher
2018-09-10 18:39:51,486 INFO org.apache.hadoop.yarn.server.resourcemanager.security.NMTokenSecretManagerInRM: NMTokenKeyRollingInterval: 86400000ms and NMTokenKeyActivationDelay: 900000ms
2018-09-10 18:39:51,490 INFO org.apache.hadoop.yarn.server.resourcemanager.security.RMContainerTokenSecretManager: ContainerTokenKeyRollingInterval: 86400000ms and ContainerTokenKeyActivationDelay: 900000ms
2018-09-10 18:39:51,495 INFO org.apache.hadoop.yarn.server.resourcemanager.security.AMRMTokenSecretManager: AMRMTokenKeyRollingInterval: 86400000ms and AMRMTokenKeyActivationDelay: 900000 ms
2018-09-10 18:39:51,525 INFO org.apache.hadoop.yarn.event.AsyncDispatcher: Registering class org.apache.hadoop.yarn.server.resourcemanager.recovery.RMStateStoreEventType for class org.apache.hadoop.yarn.server.resourcemanager.recovery.RMStateStore$ForwardingEventHandler
2018-09-10 18:39:51,527 INFO org.apache.hadoop.yarn.event.AsyncDispatcher: Registering class org.apache.hadoop.yarn.server.resourcemanager.NodesListManagerEventType for class org.apache.hadoop.yarn.server.resourcemanager.NodesListManager
2018-09-10 18:39:51,527 INFO org.apache.hadoop.yarn.server.resourcemanager.ResourceManager: Using Scheduler: org.apache.hadoop.yarn.server.resourcemanager.scheduler.capacity.CapacityScheduler
2018-09-10 18:39:51,547 INFO org.apache.hadoop.yarn.event.AsyncDispatcher: Registering class org.apache.hadoop.yarn.server.resourcemanager.scheduler.event.SchedulerEventType for class org.apache.hadoop.yarn.server.resourcemanager.ResourceManager$SchedulerEventDispatcher
2018-09-10 18:39:51,548 INFO org.apache.hadoop.yarn.event.AsyncDispatcher: Registering class org.apache.hadoop.yarn.server.resourcemanager.rmapp.RMAppEventType for class org.apache.hadoop.yarn.server.resourcemanager.ResourceManager$ApplicationEventDispatcher
2018-09-10 18:39:51,549 INFO org.apache.hadoop.yarn.event.AsyncDispatcher: Registering class org.apache.hadoop.yarn.server.resourcemanager.rmapp.attempt.RMAppAttemptEventType for class org.apache.hadoop.yarn.server.resourcemanager.ResourceManager$ApplicationAttemptEventDispatcher
2018-09-10 18:39:51,550 INFO org.apache.hadoop.yarn.event.AsyncDispatcher: Registering class org.apache.hadoop.yarn.server.resourcemanager.rmnode.RMNodeEventType for class org.apache.hadoop.yarn.server.resourcemanager.ResourceManager$NodeEventDispatcher
2018-09-10 18:39:51,589 INFO org.apache.hadoop.metrics2.impl.MetricsConfig: loaded properties from hadoop-metrics2.properties
2018-09-10 18:39:51,647 INFO org.apache.hadoop.metrics2.impl.MetricsSystemImpl: Scheduled Metric snapshot period at 10 second(s).
2018-09-10 18:39:51,647 INFO org.apache.hadoop.metrics2.impl.MetricsSystemImpl: ResourceManager metrics system started
2018-09-10 18:39:51,660 INFO org.apache.hadoop.yarn.event.AsyncDispatcher: Registering class org.apache.hadoop.yarn.server.resourcemanager.RMAppManagerEventType for class org.apache.hadoop.yarn.server.resourcemanager.RMAppManager
2018-09-10 18:39:51,666 INFO org.apache.hadoop.yarn.event.AsyncDispatcher: Registering class org.apache.hadoop.yarn.server.resourcemanager.amlauncher.AMLauncherEventType for class org.apache.hadoop.yarn.server.resourcemanager.amlauncher.ApplicationMasterLauncher
2018-09-10 18:39:51,668 INFO org.apache.hadoop.yarn.server.resourcemanager.RMNMInfo: Registered RMNMInfo MBean
2018-09-10 18:39:51,673 INFO org.apache.hadoop.yarn.security.YarnAuthorizationProvider: org.apache.hadoop.yarn.security.ConfiguredYarnAuthorizer is instiantiated.
2018-09-10 18:39:51,674 INFO org.apache.hadoop.util.HostsFileReader: Refreshing hosts (include/exclude) list
2018-09-10 18:39:51,679 INFO org.apache.hadoop.conf.Configuration: found resource capacity-scheduler.xml at file:/Users/jason/hadoop-2.8.1/etc/hadoop/capacity-scheduler.xml
2018-09-10 18:39:51,722 INFO org.apache.hadoop.yarn.server.resourcemanager.scheduler.capacity.CapacitySchedulerConfiguration: max alloc mb per queue for root is undefined
2018-09-10 18:39:51,722 INFO org.apache.hadoop.yarn.server.resourcemanager.scheduler.capacity.CapacitySchedulerConfiguration: max alloc vcore per queue for root is undefined
2018-09-10 18:39:51,729 INFO org.apache.hadoop.yarn.server.resourcemanager.scheduler.capacity.ParentQueue: root, capacity=1.0, asboluteCapacity=1.0, maxCapacity=1.0, asboluteMaxCapacity=1.0, state=RUNNING, acls=ADMINISTER_QUEUE:*SUBMIT_APP:*, labels=*,, offswitchPerHeartbeatLimit = 1, reservationsContinueLooking=true
2018-09-10 18:39:51,729 INFO org.apache.hadoop.yarn.server.resourcemanager.scheduler.capacity.ParentQueue: Initialized parent-queue root name=root, fullname=root
2018-09-10 18:39:51,740 INFO org.apache.hadoop.yarn.server.resourcemanager.scheduler.capacity.CapacitySchedulerConfiguration: max alloc mb per queue for root.default is undefined
2018-09-10 18:39:51,740 INFO org.apache.hadoop.yarn.server.resourcemanager.scheduler.capacity.CapacitySchedulerConfiguration: max alloc vcore per queue for root.default is undefined
2018-09-10 18:39:51,742 INFO org.apache.hadoop.yarn.server.resourcemanager.scheduler.capacity.LeafQueue: Initializing default
capacity = 1.0 [= (float) configuredCapacity / 100 ]
asboluteCapacity = 1.0 [= parentAbsoluteCapacity * capacity ]
maxCapacity = 1.0 [= configuredMaxCapacity ]
absoluteMaxCapacity = 1.0 [= 1.0 maximumCapacity undefined, (parentAbsoluteMaxCapacity * maximumCapacity) / 100 otherwise ]
userLimit = 100 [= configuredUserLimit ]
userLimitFactor = 1.0 [= configuredUserLimitFactor ]
maxApplications = 10000 [= configuredMaximumSystemApplicationsPerQueue or (int)(configuredMaximumSystemApplications * absoluteCapacity)]
maxApplicationsPerUser = 10000 [= (int)(maxApplications * (userLimit / 100.0f) * userLimitFactor) ]
usedCapacity = 0.0 [= usedResourcesMemory / (clusterResourceMemory * absoluteCapacity)]
absoluteUsedCapacity = 0.0 [= usedResourcesMemory / clusterResourceMemory]
maxAMResourcePerQueuePercent = 0.1 [= configuredMaximumAMResourcePercent ]
minimumAllocationFactor = 0.875 [= (float)(maximumAllocationMemory - minimumAllocationMemory) / maximumAllocationMemory ]
maximumAllocation = <memory:8192, vCores:4> [= configuredMaxAllocation ]
numContainers = 0 [= currentNumContainers ]
state = RUNNING [= configuredState ]
acls = ADMINISTER_QUEUE:*SUBMIT_APP:* [= configuredAcls ]
nodeLocalityDelay = 40
labels=*,
reservationsContinueLooking = true
preemptionDisabled = true
defaultAppPriorityPerQueue = 0
2018-09-10 18:39:51,742 INFO org.apache.hadoop.yarn.server.resourcemanager.scheduler.capacity.CapacityScheduler: Initialized queue: default: capacity=1.0, absoluteCapacity=1.0, usedResources=<memory:0, vCores:0>, usedCapacity=0.0, absoluteUsedCapacity=0.0, numApps=0, numContainers=0
2018-09-10 18:39:51,743 INFO org.apache.hadoop.yarn.server.resourcemanager.scheduler.capacity.CapacityScheduler: Initialized queue: root: numChildQueue= 1, capacity=1.0, absoluteCapacity=1.0, usedResources=<memory:0, vCores:0>usedCapacity=0.0, numApps=0, numContainers=0
2018-09-10 18:39:51,743 INFO org.apache.hadoop.yarn.server.resourcemanager.scheduler.capacity.CapacityScheduler: Initialized root queue root: numChildQueue= 1, capacity=1.0, absoluteCapacity=1.0, usedResources=<memory:0, vCores:0>usedCapacity=0.0, numApps=0, numContainers=0
2018-09-10 18:39:51,743 INFO org.apache.hadoop.yarn.server.resourcemanager.scheduler.capacity.CapacityScheduler: Initialized queue mappings, override: false
2018-09-10 18:39:51,744 INFO org.apache.hadoop.yarn.server.resourcemanager.scheduler.capacity.CapacityScheduler: Initialized CapacityScheduler with calculator=class org.apache.hadoop.yarn.util.resource.DefaultResourceCalculator, minimumAllocation=<<memory:1024, vCores:1>>, maximumAllocation=<<memory:8192, vCores:4>>, asynchronousScheduling=false, asyncScheduleInterval=5ms
2018-09-10 18:39:51,747 INFO org.apache.hadoop.conf.Configuration: dynamic-resources.xml not found
2018-09-10 18:39:51,755 INFO org.apache.hadoop.yarn.server.resourcemanager.metrics.SystemMetricsPublisher: YARN system metrics publishing service is not enabled
2018-09-10 18:39:51,755 INFO org.apache.hadoop.yarn.server.resourcemanager.ResourceManager: Transitioning to active state
2018-09-10 18:39:51,769 INFO org.apache.hadoop.util.JvmPauseMonitor: Starting JVM pause monitor
2018-09-10 18:39:51,779 INFO org.apache.hadoop.yarn.server.resourcemanager.recovery.RMStateStore: Updating AMRMToken
2018-09-10 18:39:51,780 INFO org.apache.hadoop.yarn.server.resourcemanager.security.RMContainerTokenSecretManager: Rolling master-key for container-tokens
2018-09-10 18:39:51,780 INFO org.apache.hadoop.yarn.server.resourcemanager.security.NMTokenSecretManagerInRM: Rolling master-key for nm-tokens
2018-09-10 18:39:51,780 INFO org.apache.hadoop.security.token.delegation.AbstractDelegationTokenSecretManager: Updating the current master key for generating delegation tokens
2018-09-10 18:39:51,780 INFO org.apache.hadoop.yarn.server.resourcemanager.security.RMDelegationTokenSecretManager: storing master key with keyID 1
2018-09-10 18:39:51,780 INFO org.apache.hadoop.yarn.server.resourcemanager.recovery.RMStateStore: Storing RMDTMasterKey.
2018-09-10 18:39:51,781 INFO org.apache.hadoop.security.token.delegation.AbstractDelegationTokenSecretManager: Starting expired delegation token remover thread, tokenRemoverScanInterval=60 min(s)
2018-09-10 18:39:51,781 INFO org.apache.hadoop.security.token.delegation.AbstractDelegationTokenSecretManager: Updating the current master key for generating delegation tokens
2018-09-10 18:39:51,781 INFO org.apache.hadoop.yarn.server.resourcemanager.security.RMDelegationTokenSecretManager: storing master key with keyID 2
2018-09-10 18:39:51,781 INFO org.apache.hadoop.yarn.server.resourcemanager.recovery.RMStateStore: Storing RMDTMasterKey.
2018-09-10 18:39:51,783 INFO org.apache.hadoop.yarn.event.AsyncDispatcher: Registering class org.apache.hadoop.yarn.nodelabels.event.NodeLabelsStoreEventType for class org.apache.hadoop.yarn.nodelabels.CommonNodeLabelsManager$ForwardingEventHandler
2018-09-10 18:39:51,805 INFO org.apache.hadoop.ipc.CallQueueManager: Using callQueue: class java.util.concurrent.LinkedBlockingQueue queueCapacity: 5000 scheduler: class org.apache.hadoop.ipc.DefaultRpcScheduler
2018-09-10 18:39:51,833 INFO org.apache.hadoop.ipc.Server: Starting Socket Reader #1 for port 8031
2018-09-10 18:39:51,969 INFO org.apache.hadoop.yarn.factories.impl.pb.RpcServerFactoryPBImpl: Adding protocol org.apache.hadoop.yarn.server.api.ResourceTrackerPB to the server
2018-09-10 18:39:51,969 INFO org.apache.hadoop.ipc.Server: IPC Server Responder: starting
2018-09-10 18:39:51,969 INFO org.apache.hadoop.ipc.Server: IPC Server listener on 8031: starting
2018-09-10 18:39:51,997 INFO org.apache.hadoop.ipc.CallQueueManager: Using callQueue: class java.util.concurrent.LinkedBlockingQueue queueCapacity: 5000 scheduler: class org.apache.hadoop.ipc.DefaultRpcScheduler
2018-09-10 18:39:52,004 INFO org.apache.hadoop.ipc.Server: Starting Socket Reader #1 for port 8030
2018-09-10 18:39:52,025 INFO org.apache.hadoop.yarn.factories.impl.pb.RpcServerFactoryPBImpl: Adding protocol org.apache.hadoop.yarn.api.ApplicationMasterProtocolPB to the server
2018-09-10 18:39:52,026 INFO org.apache.hadoop.ipc.Server: IPC Server Responder: starting
2018-09-10 18:39:52,026 INFO org.apache.hadoop.ipc.Server: IPC Server listener on 8030: starting
2018-09-10 18:39:52,185 INFO org.apache.hadoop.ipc.CallQueueManager: Using callQueue: class java.util.concurrent.LinkedBlockingQueue queueCapacity: 5000 scheduler: class org.apache.hadoop.ipc.DefaultRpcScheduler
2018-09-10 18:39:52,185 INFO org.apache.hadoop.ipc.Server: Starting Socket Reader #1 for port 8032
2018-09-10 18:39:52,191 INFO org.apache.hadoop.yarn.factories.impl.pb.RpcServerFactoryPBImpl: Adding protocol org.apache.hadoop.yarn.api.ApplicationClientProtocolPB to the server
2018-09-10 18:39:52,191 INFO org.apache.hadoop.ipc.Server: IPC Server Responder: starting
2018-09-10 18:39:52,191 INFO org.apache.hadoop.ipc.Server: IPC Server listener on 8032: starting
2018-09-10 18:39:52,197 INFO org.apache.hadoop.yarn.server.resourcemanager.ResourceManager: Transitioned to active state
2018-09-10 18:39:52,276 INFO org.mortbay.log: Logging to org.slf4j.impl.Log4jLoggerAdapter(org.mortbay.log) via org.mortbay.log.Slf4jLog
2018-09-10 18:39:52,286 INFO org.apache.hadoop.security.authentication.server.AuthenticationFilter: Unable to initialize FileSignerSecretProvider, falling back to use random secrets.
2018-09-10 18:39:52,294 INFO org.apache.hadoop.http.HttpRequestLog: Http request log for http.requests.resourcemanager is not defined
2018-09-10 18:39:52,303 INFO org.apache.hadoop.http.HttpServer2: Added global filter 'safety' (class=org.apache.hadoop.http.HttpServer2$QuotingInputFilter)
2018-09-10 18:39:52,308 INFO org.apache.hadoop.http.HttpServer2: Added filter RMAuthenticationFilter (class=org.apache.hadoop.yarn.server.security.http.RMAuthenticationFilter) to context cluster
2018-09-10 18:39:52,308 INFO org.apache.hadoop.http.HttpServer2: Added filter RMAuthenticationFilter (class=org.apache.hadoop.yarn.server.security.http.RMAuthenticationFilter) to context logs
2018-09-10 18:39:52,308 INFO org.apache.hadoop.http.HttpServer2: Added filter RMAuthenticationFilter (class=org.apache.hadoop.yarn.server.security.http.RMAuthenticationFilter) to context static
2018-09-10 18:39:52,310 INFO org.apache.hadoop.http.HttpServer2: Added filter static_user_filter (class=org.apache.hadoop.http.lib.StaticUserWebFilter$StaticUserFilter) to context cluster
2018-09-10 18:39:52,310 INFO org.apache.hadoop.http.HttpServer2: Added filter static_user_filter (class=org.apache.hadoop.http.lib.StaticUserWebFilter$StaticUserFilter) to context logs
2018-09-10 18:39:52,310 INFO org.apache.hadoop.http.HttpServer2: Added filter static_user_filter (class=org.apache.hadoop.http.lib.StaticUserWebFilter$StaticUserFilter) to context static
2018-09-10 18:39:52,314 INFO org.apache.hadoop.http.HttpServer2: adding path spec: /cluster/*
2018-09-10 18:39:52,314 INFO org.apache.hadoop.http.HttpServer2: adding path spec: /ws/*
2018-09-10 18:39:52,688 INFO org.apache.hadoop.yarn.webapp.WebApps: Registered webapp guice modules
2018-09-10 18:39:52,696 INFO org.apache.hadoop.http.HttpServer2: Jetty bound to port 8088
2018-09-10 18:39:52,696 INFO org.mortbay.log: jetty-6.1.26
2018-09-10 18:39:52,745 INFO org.mortbay.log: Extract jar:file:/Users/jason/hadoop-2.8.1/share/hadoop/yarn/hadoop-yarn-common-2.8.1.jar!/webapps/cluster to /var/folders/7r/3c0pxtpd0rg5hjs32v2rrz_00000gn/T/Jetty_0_0_0_0_8088_cluster____u0rgz3/webapp
2018-09-10 18:39:53,013 INFO org.apache.hadoop.security.token.delegation.AbstractDelegationTokenSecretManager: Updating the current master key for generating delegation tokens
2018-09-10 18:39:53,013 INFO org.apache.hadoop.security.token.delegation.AbstractDelegationTokenSecretManager: Starting expired delegation token remover thread, tokenRemoverScanInterval=60 min(s)
2018-09-10 18:39:53,013 INFO org.apache.hadoop.security.token.delegation.AbstractDelegationTokenSecretManager: Updating the current master key for generating delegation tokens
2018-09-10 18:39:54,166 INFO org.mortbay.log: Started HttpServer2$SelectChannelConnectorWithSafeStartup@0.0.0.0:8088
2018-09-10 18:39:54,166 INFO org.apache.hadoop.yarn.webapp.WebApps: Web app cluster started at 8088
2018-09-10 18:39:54,213 INFO org.apache.hadoop.ipc.CallQueueManager: Using callQueue: class java.util.concurrent.LinkedBlockingQueue queueCapacity: 100 scheduler: class org.apache.hadoop.ipc.DefaultRpcScheduler
2018-09-10 18:39:54,213 INFO org.apache.hadoop.ipc.Server: Starting Socket Reader #1 for port 8033
2018-09-10 18:39:54,223 INFO org.apache.hadoop.yarn.factories.impl.pb.RpcServerFactoryPBImpl: Adding protocol org.apache.hadoop.yarn.server.api.ResourceManagerAdministrationProtocolPB to the server
2018-09-10 18:39:54,224 INFO org.apache.hadoop.ipc.Server: IPC Server Responder: starting
2018-09-10 18:39:54,224 INFO org.apache.hadoop.ipc.Server: IPC Server listener on 8033: starting
2018-09-10 18:39:55,781 INFO org.apache.hadoop.yarn.server.resourcemanager.ResourceTrackerService: NodeManager from node 192.168.1.103(cmPort: 56045 httpPort: 8042) registered with capability: <memory:8192, vCores:8>, assigned nodeId 192.168.1.103:56045
2018-09-10 18:39:55,785 INFO org.apache.hadoop.yarn.server.resourcemanager.rmnode.RMNodeImpl: 192.168.1.103:56045 Node Transitioned from NEW to RUNNING
2018-09-10 18:39:55,794 INFO org.apache.hadoop.yarn.server.resourcemanager.scheduler.capacity.CapacityScheduler: Added node 192.168.1.103:56045 clusterResource: <memory:8192, vCores:8>
2018-09-10 18:49:14,894 ERROR org.apache.hadoop.yarn.server.resourcemanager.ResourceManager: RECEIVED SIGNAL 15: SIGTERM
2018-09-10 18:49:14,903 ERROR org.apache.hadoop.security.token.delegation.AbstractDelegationTokenSecretManager: ExpiredTokenRemover received java.lang.InterruptedException: sleep interrupted
2018-09-10 18:49:14,905 INFO org.mortbay.log: Stopped HttpServer2$SelectChannelConnectorWithSafeStartup@0.0.0.0:8088
2018-09-10 18:49:15,007 INFO org.apache.hadoop.ipc.Server: Stopping server on 8032
2018-09-10 18:49:15,008 INFO org.apache.hadoop.ipc.Server: Stopping IPC Server listener on 8032
2018-09-10 18:49:15,009 INFO org.apache.hadoop.ipc.Server: Stopping server on 8033
2018-09-10 18:49:15,009 INFO org.apache.hadoop.ipc.Server: Stopping IPC Server Responder
2018-09-10 18:49:15,009 INFO org.apache.hadoop.ipc.Server: Stopping IPC Server listener on 8033
2018-09-10 18:49:15,009 INFO org.apache.hadoop.ipc.Server: Stopping IPC Server Responder
2018-09-10 18:49:15,009 INFO org.apache.hadoop.yarn.server.resourcemanager.ResourceManager: Transitioning to standby state
2018-09-10 18:49:15,010 WARN org.apache.hadoop.yarn.server.resourcemanager.amlauncher.ApplicationMasterLauncher: org.apache.hadoop.yarn.server.resourcemanager.amlauncher.ApplicationMasterLauncher$LauncherThread interrupted. Returning.
2018-09-10 18:49:15,010 INFO org.apache.hadoop.ipc.Server: Stopping server on 8030
2018-09-10 18:49:15,011 INFO org.apache.hadoop.ipc.Server: Stopping IPC Server listener on 8030
2018-09-10 18:49:15,011 INFO org.apache.hadoop.ipc.Server: Stopping server on 8031
2018-09-10 18:49:15,011 INFO org.apache.hadoop.ipc.Server: Stopping IPC Server Responder
2018-09-10 18:49:15,017 INFO org.apache.hadoop.ipc.Server: Stopping IPC Server listener on 8031
2018-09-10 18:49:15,018 INFO org.apache.hadoop.yarn.util.AbstractLivelinessMonitor: NMLivelinessMonitor thread interrupted
2018-09-10 18:49:15,018 ERROR org.apache.hadoop.yarn.server.resourcemanager.ResourceManager: Returning, interrupted : java.lang.InterruptedException
2018-09-10 18:49:15,018 INFO org.apache.hadoop.ipc.Server: Stopping IPC Server Responder
2018-09-10 18:49:15,018 INFO org.apache.hadoop.yarn.event.AsyncDispatcher: AsyncDispatcher is draining to stop, igonring any new events.
2018-09-10 18:49:15,018 INFO org.apache.hadoop.yarn.util.AbstractLivelinessMonitor: AMLivelinessMonitor thread interrupted
2018-09-10 18:49:15,018 INFO org.apache.hadoop.yarn.util.AbstractLivelinessMonitor: AMLivelinessMonitor thread interrupted
2018-09-10 18:49:15,018 INFO org.apache.hadoop.yarn.util.AbstractLivelinessMonitor: org.apache.hadoop.yarn.server.resourcemanager.rmcontainer.ContainerAllocationExpirer thread interrupted
2018-09-10 18:49:15,018 ERROR org.apache.hadoop.security.token.delegation.AbstractDelegationTokenSecretManager: ExpiredTokenRemover received java.lang.InterruptedException: sleep interrupted
2018-09-10 18:49:15,021 INFO org.apache.hadoop.metrics2.impl.MetricsSystemImpl: Stopping ResourceManager metrics system...
2018-09-10 18:49:15,022 INFO org.apache.hadoop.metrics2.impl.MetricsSystemImpl: ResourceManager metrics system stopped.
2018-09-10 18:49:15,022 INFO org.apache.hadoop.metrics2.impl.MetricsSystemImpl: ResourceManager metrics system shutdown complete.
2018-09-10 18:49:15,023 INFO org.apache.hadoop.yarn.event.AsyncDispatcher: AsyncDispatcher is draining to stop, igonring any new events.
2018-09-10 18:49:15,023 INFO org.apache.hadoop.yarn.server.resourcemanager.ResourceManager: Transitioned to standby state
2018-09-10 18:49:15,023 INFO org.apache.hadoop.yarn.server.resourcemanager.ResourceManager: SHUTDOWN_MSG: 
/************************************************************
SHUTDOWN_MSG: Shutting down ResourceManager at Jasons-MacBook-Pro.local/192.168.1.103
************************************************************/
2018-09-13 13:03:40,146 INFO org.apache.hadoop.yarn.server.resourcemanager.ResourceManager: STARTUP_MSG: 
/************************************************************
STARTUP_MSG: Starting ResourceManager
STARTUP_MSG:   user = jason
STARTUP_MSG:   host = Jasons-MacBook-Pro.local/10.169.0.233
STARTUP_MSG:   args = []
STARTUP_MSG:   version = 2.8.1
STARTUP_MSG:   build = https://git-wip-us.apache.org/repos/asf/hadoop.git -r 20fe5304904fc2f5a18053c389e43cd26f7a70fe; compiled by 'vinodkv' on 2017-06-02T06:14Z
STARTUP_MSG:   java = 1.8.0_181
************************************************************/
2018-09-13 13:03:40,158 INFO org.apache.hadoop.yarn.server.resourcemanager.ResourceManager: registered UNIX signal handlers for [TERM, HUP, INT]
2018-09-13 13:03:40,398 INFO org.apache.hadoop.conf.Configuration: found resource core-site.xml at file:/Users/jason/hadoop-2.8.1/etc/hadoop/core-site.xml
2018-09-13 13:03:40,427 WARN org.apache.hadoop.util.NativeCodeLoader: Unable to load native-hadoop library for your platform... using builtin-java classes where applicable
2018-09-13 13:03:40,446 INFO org.apache.hadoop.security.Groups: clearing userToGroupsMap cache
2018-09-13 13:03:40,506 INFO org.apache.hadoop.conf.Configuration: found resource yarn-site.xml at file:/Users/jason/hadoop-2.8.1/etc/hadoop/yarn-site.xml
2018-09-13 13:03:40,651 INFO org.apache.hadoop.yarn.event.AsyncDispatcher: Registering class org.apache.hadoop.yarn.server.resourcemanager.RMFatalEventType for class org.apache.hadoop.yarn.server.resourcemanager.ResourceManager$RMFatalEventDispatcher
2018-09-13 13:03:40,900 INFO org.apache.hadoop.yarn.server.resourcemanager.security.NMTokenSecretManagerInRM: NMTokenKeyRollingInterval: 86400000ms and NMTokenKeyActivationDelay: 900000ms
2018-09-13 13:03:40,903 INFO org.apache.hadoop.yarn.server.resourcemanager.security.RMContainerTokenSecretManager: ContainerTokenKeyRollingInterval: 86400000ms and ContainerTokenKeyActivationDelay: 900000ms
2018-09-13 13:03:40,908 INFO org.apache.hadoop.yarn.server.resourcemanager.security.AMRMTokenSecretManager: AMRMTokenKeyRollingInterval: 86400000ms and AMRMTokenKeyActivationDelay: 900000 ms
2018-09-13 13:03:40,944 INFO org.apache.hadoop.yarn.event.AsyncDispatcher: Registering class org.apache.hadoop.yarn.server.resourcemanager.recovery.RMStateStoreEventType for class org.apache.hadoop.yarn.server.resourcemanager.recovery.RMStateStore$ForwardingEventHandler
2018-09-13 13:03:40,946 INFO org.apache.hadoop.yarn.event.AsyncDispatcher: Registering class org.apache.hadoop.yarn.server.resourcemanager.NodesListManagerEventType for class org.apache.hadoop.yarn.server.resourcemanager.NodesListManager
2018-09-13 13:03:40,947 INFO org.apache.hadoop.yarn.server.resourcemanager.ResourceManager: Using Scheduler: org.apache.hadoop.yarn.server.resourcemanager.scheduler.capacity.CapacityScheduler
2018-09-13 13:03:40,974 INFO org.apache.hadoop.yarn.event.AsyncDispatcher: Registering class org.apache.hadoop.yarn.server.resourcemanager.scheduler.event.SchedulerEventType for class org.apache.hadoop.yarn.server.resourcemanager.ResourceManager$SchedulerEventDispatcher
2018-09-13 13:03:40,975 INFO org.apache.hadoop.yarn.event.AsyncDispatcher: Registering class org.apache.hadoop.yarn.server.resourcemanager.rmapp.RMAppEventType for class org.apache.hadoop.yarn.server.resourcemanager.ResourceManager$ApplicationEventDispatcher
2018-09-13 13:03:40,976 INFO org.apache.hadoop.yarn.event.AsyncDispatcher: Registering class org.apache.hadoop.yarn.server.resourcemanager.rmapp.attempt.RMAppAttemptEventType for class org.apache.hadoop.yarn.server.resourcemanager.ResourceManager$ApplicationAttemptEventDispatcher
2018-09-13 13:03:40,977 INFO org.apache.hadoop.yarn.event.AsyncDispatcher: Registering class org.apache.hadoop.yarn.server.resourcemanager.rmnode.RMNodeEventType for class org.apache.hadoop.yarn.server.resourcemanager.ResourceManager$NodeEventDispatcher
2018-09-13 13:03:41,035 INFO org.apache.hadoop.metrics2.impl.MetricsConfig: loaded properties from hadoop-metrics2.properties
2018-09-13 13:03:46,161 INFO org.apache.hadoop.metrics2.impl.MetricsSystemImpl: Scheduled Metric snapshot period at 10 second(s).
2018-09-13 13:03:46,162 INFO org.apache.hadoop.metrics2.impl.MetricsSystemImpl: ResourceManager metrics system started
2018-09-13 13:03:46,190 INFO org.apache.hadoop.yarn.event.AsyncDispatcher: Registering class org.apache.hadoop.yarn.server.resourcemanager.RMAppManagerEventType for class org.apache.hadoop.yarn.server.resourcemanager.RMAppManager
2018-09-13 13:03:46,198 INFO org.apache.hadoop.yarn.event.AsyncDispatcher: Registering class org.apache.hadoop.yarn.server.resourcemanager.amlauncher.AMLauncherEventType for class org.apache.hadoop.yarn.server.resourcemanager.amlauncher.ApplicationMasterLauncher
2018-09-13 13:03:46,200 INFO org.apache.hadoop.yarn.server.resourcemanager.RMNMInfo: Registered RMNMInfo MBean
2018-09-13 13:03:46,206 INFO org.apache.hadoop.yarn.security.YarnAuthorizationProvider: org.apache.hadoop.yarn.security.ConfiguredYarnAuthorizer is instiantiated.
2018-09-13 13:03:46,207 INFO org.apache.hadoop.util.HostsFileReader: Refreshing hosts (include/exclude) list
2018-09-13 13:03:46,214 INFO org.apache.hadoop.conf.Configuration: found resource capacity-scheduler.xml at file:/Users/jason/hadoop-2.8.1/etc/hadoop/capacity-scheduler.xml
2018-09-13 13:03:46,252 INFO org.apache.hadoop.yarn.server.resourcemanager.scheduler.capacity.CapacitySchedulerConfiguration: max alloc mb per queue for root is undefined
2018-09-13 13:03:46,252 INFO org.apache.hadoop.yarn.server.resourcemanager.scheduler.capacity.CapacitySchedulerConfiguration: max alloc vcore per queue for root is undefined
2018-09-13 13:03:46,261 INFO org.apache.hadoop.yarn.server.resourcemanager.scheduler.capacity.ParentQueue: root, capacity=1.0, asboluteCapacity=1.0, maxCapacity=1.0, asboluteMaxCapacity=1.0, state=RUNNING, acls=ADMINISTER_QUEUE:*SUBMIT_APP:*, labels=*,, offswitchPerHeartbeatLimit = 1, reservationsContinueLooking=true
2018-09-13 13:03:46,261 INFO org.apache.hadoop.yarn.server.resourcemanager.scheduler.capacity.ParentQueue: Initialized parent-queue root name=root, fullname=root
2018-09-13 13:03:46,269 INFO org.apache.hadoop.yarn.server.resourcemanager.scheduler.capacity.CapacitySchedulerConfiguration: max alloc mb per queue for root.default is undefined
2018-09-13 13:03:46,269 INFO org.apache.hadoop.yarn.server.resourcemanager.scheduler.capacity.CapacitySchedulerConfiguration: max alloc vcore per queue for root.default is undefined
2018-09-13 13:03:46,271 INFO org.apache.hadoop.yarn.server.resourcemanager.scheduler.capacity.LeafQueue: Initializing default
capacity = 1.0 [= (float) configuredCapacity / 100 ]
asboluteCapacity = 1.0 [= parentAbsoluteCapacity * capacity ]
maxCapacity = 1.0 [= configuredMaxCapacity ]
absoluteMaxCapacity = 1.0 [= 1.0 maximumCapacity undefined, (parentAbsoluteMaxCapacity * maximumCapacity) / 100 otherwise ]
userLimit = 100 [= configuredUserLimit ]
userLimitFactor = 1.0 [= configuredUserLimitFactor ]
maxApplications = 10000 [= configuredMaximumSystemApplicationsPerQueue or (int)(configuredMaximumSystemApplications * absoluteCapacity)]
maxApplicationsPerUser = 10000 [= (int)(maxApplications * (userLimit / 100.0f) * userLimitFactor) ]
usedCapacity = 0.0 [= usedResourcesMemory / (clusterResourceMemory * absoluteCapacity)]
absoluteUsedCapacity = 0.0 [= usedResourcesMemory / clusterResourceMemory]
maxAMResourcePerQueuePercent = 0.1 [= configuredMaximumAMResourcePercent ]
minimumAllocationFactor = 0.875 [= (float)(maximumAllocationMemory - minimumAllocationMemory) / maximumAllocationMemory ]
maximumAllocation = <memory:8192, vCores:4> [= configuredMaxAllocation ]
numContainers = 0 [= currentNumContainers ]
state = RUNNING [= configuredState ]
acls = ADMINISTER_QUEUE:*SUBMIT_APP:* [= configuredAcls ]
nodeLocalityDelay = 40
labels=*,
reservationsContinueLooking = true
preemptionDisabled = true
defaultAppPriorityPerQueue = 0
2018-09-13 13:03:46,272 INFO org.apache.hadoop.yarn.server.resourcemanager.scheduler.capacity.CapacityScheduler: Initialized queue: default: capacity=1.0, absoluteCapacity=1.0, usedResources=<memory:0, vCores:0>, usedCapacity=0.0, absoluteUsedCapacity=0.0, numApps=0, numContainers=0
2018-09-13 13:03:46,272 INFO org.apache.hadoop.yarn.server.resourcemanager.scheduler.capacity.CapacityScheduler: Initialized queue: root: numChildQueue= 1, capacity=1.0, absoluteCapacity=1.0, usedResources=<memory:0, vCores:0>usedCapacity=0.0, numApps=0, numContainers=0
2018-09-13 13:03:46,272 INFO org.apache.hadoop.yarn.server.resourcemanager.scheduler.capacity.CapacityScheduler: Initialized root queue root: numChildQueue= 1, capacity=1.0, absoluteCapacity=1.0, usedResources=<memory:0, vCores:0>usedCapacity=0.0, numApps=0, numContainers=0
2018-09-13 13:03:46,272 INFO org.apache.hadoop.yarn.server.resourcemanager.scheduler.capacity.CapacityScheduler: Initialized queue mappings, override: false
2018-09-13 13:03:46,273 INFO org.apache.hadoop.yarn.server.resourcemanager.scheduler.capacity.CapacityScheduler: Initialized CapacityScheduler with calculator=class org.apache.hadoop.yarn.util.resource.DefaultResourceCalculator, minimumAllocation=<<memory:1024, vCores:1>>, maximumAllocation=<<memory:8192, vCores:4>>, asynchronousScheduling=false, asyncScheduleInterval=5ms
2018-09-13 13:03:46,277 INFO org.apache.hadoop.conf.Configuration: dynamic-resources.xml not found
2018-09-13 13:03:46,290 INFO org.apache.hadoop.yarn.server.resourcemanager.metrics.SystemMetricsPublisher: YARN system metrics publishing service is not enabled
2018-09-13 13:03:46,290 INFO org.apache.hadoop.yarn.server.resourcemanager.ResourceManager: Transitioning to active state
2018-09-13 13:03:46,308 INFO org.apache.hadoop.util.JvmPauseMonitor: Starting JVM pause monitor
2018-09-13 13:03:46,325 INFO org.apache.hadoop.yarn.server.resourcemanager.recovery.RMStateStore: Updating AMRMToken
2018-09-13 13:03:46,325 INFO org.apache.hadoop.yarn.server.resourcemanager.security.RMContainerTokenSecretManager: Rolling master-key for container-tokens
2018-09-13 13:03:46,326 INFO org.apache.hadoop.yarn.server.resourcemanager.security.NMTokenSecretManagerInRM: Rolling master-key for nm-tokens
2018-09-13 13:03:46,326 INFO org.apache.hadoop.security.token.delegation.AbstractDelegationTokenSecretManager: Updating the current master key for generating delegation tokens
2018-09-13 13:03:46,326 INFO org.apache.hadoop.yarn.server.resourcemanager.security.RMDelegationTokenSecretManager: storing master key with keyID 1
2018-09-13 13:03:46,326 INFO org.apache.hadoop.yarn.server.resourcemanager.recovery.RMStateStore: Storing RMDTMasterKey.
2018-09-13 13:03:46,327 INFO org.apache.hadoop.security.token.delegation.AbstractDelegationTokenSecretManager: Starting expired delegation token remover thread, tokenRemoverScanInterval=60 min(s)
2018-09-13 13:03:46,328 INFO org.apache.hadoop.security.token.delegation.AbstractDelegationTokenSecretManager: Updating the current master key for generating delegation tokens
2018-09-13 13:03:46,328 INFO org.apache.hadoop.yarn.server.resourcemanager.security.RMDelegationTokenSecretManager: storing master key with keyID 2
2018-09-13 13:03:46,328 INFO org.apache.hadoop.yarn.server.resourcemanager.recovery.RMStateStore: Storing RMDTMasterKey.
2018-09-13 13:03:46,330 INFO org.apache.hadoop.yarn.event.AsyncDispatcher: Registering class org.apache.hadoop.yarn.nodelabels.event.NodeLabelsStoreEventType for class org.apache.hadoop.yarn.nodelabels.CommonNodeLabelsManager$ForwardingEventHandler
2018-09-13 13:03:46,376 INFO org.apache.hadoop.ipc.CallQueueManager: Using callQueue: class java.util.concurrent.LinkedBlockingQueue queueCapacity: 5000 scheduler: class org.apache.hadoop.ipc.DefaultRpcScheduler
2018-09-13 13:03:46,416 INFO org.apache.hadoop.ipc.Server: Starting Socket Reader #1 for port 8031
2018-09-13 13:03:46,648 INFO org.apache.hadoop.yarn.factories.impl.pb.RpcServerFactoryPBImpl: Adding protocol org.apache.hadoop.yarn.server.api.ResourceTrackerPB to the server
2018-09-13 13:03:46,648 INFO org.apache.hadoop.ipc.Server: IPC Server Responder: starting
2018-09-13 13:03:46,648 INFO org.apache.hadoop.ipc.Server: IPC Server listener on 8031: starting
2018-09-13 13:03:51,689 INFO org.apache.hadoop.ipc.CallQueueManager: Using callQueue: class java.util.concurrent.LinkedBlockingQueue queueCapacity: 5000 scheduler: class org.apache.hadoop.ipc.DefaultRpcScheduler
2018-09-13 13:03:51,703 INFO org.apache.hadoop.ipc.Server: Starting Socket Reader #1 for port 8030
2018-09-13 13:03:51,716 INFO org.apache.hadoop.yarn.factories.impl.pb.RpcServerFactoryPBImpl: Adding protocol org.apache.hadoop.yarn.api.ApplicationMasterProtocolPB to the server
2018-09-13 13:03:51,716 INFO org.apache.hadoop.ipc.Server: IPC Server Responder: starting
2018-09-13 13:03:51,716 INFO org.apache.hadoop.ipc.Server: IPC Server listener on 8030: starting
2018-09-13 13:03:56,840 INFO org.apache.hadoop.ipc.CallQueueManager: Using callQueue: class java.util.concurrent.LinkedBlockingQueue queueCapacity: 5000 scheduler: class org.apache.hadoop.ipc.DefaultRpcScheduler
2018-09-13 13:03:56,841 INFO org.apache.hadoop.ipc.Server: Starting Socket Reader #1 for port 8032
2018-09-13 13:03:56,844 INFO org.apache.hadoop.yarn.factories.impl.pb.RpcServerFactoryPBImpl: Adding protocol org.apache.hadoop.yarn.api.ApplicationClientProtocolPB to the server
2018-09-13 13:03:56,845 INFO org.apache.hadoop.ipc.Server: IPC Server Responder: starting
2018-09-13 13:03:56,845 INFO org.apache.hadoop.ipc.Server: IPC Server listener on 8032: starting
2018-09-13 13:04:01,855 INFO org.apache.hadoop.yarn.server.resourcemanager.ResourceManager: Transitioned to active state
2018-09-13 13:04:12,004 INFO org.mortbay.log: Logging to org.slf4j.impl.Log4jLoggerAdapter(org.mortbay.log) via org.mortbay.log.Slf4jLog
2018-09-13 13:04:17,027 INFO org.apache.hadoop.security.authentication.server.AuthenticationFilter: Unable to initialize FileSignerSecretProvider, falling back to use random secrets.
2018-09-13 13:04:17,038 INFO org.apache.hadoop.http.HttpRequestLog: Http request log for http.requests.resourcemanager is not defined
2018-09-13 13:04:17,049 INFO org.apache.hadoop.http.HttpServer2: Added global filter 'safety' (class=org.apache.hadoop.http.HttpServer2$QuotingInputFilter)
2018-09-13 13:04:22,057 INFO org.apache.hadoop.http.HttpServer2: Added filter RMAuthenticationFilter (class=org.apache.hadoop.yarn.server.security.http.RMAuthenticationFilter) to context cluster
2018-09-13 13:04:22,058 INFO org.apache.hadoop.http.HttpServer2: Added filter RMAuthenticationFilter (class=org.apache.hadoop.yarn.server.security.http.RMAuthenticationFilter) to context logs
2018-09-13 13:04:22,058 INFO org.apache.hadoop.http.HttpServer2: Added filter RMAuthenticationFilter (class=org.apache.hadoop.yarn.server.security.http.RMAuthenticationFilter) to context static
2018-09-13 13:04:22,058 INFO org.apache.hadoop.http.HttpServer2: Added filter static_user_filter (class=org.apache.hadoop.http.lib.StaticUserWebFilter$StaticUserFilter) to context cluster
2018-09-13 13:04:22,058 INFO org.apache.hadoop.http.HttpServer2: Added filter static_user_filter (class=org.apache.hadoop.http.lib.StaticUserWebFilter$StaticUserFilter) to context logs
2018-09-13 13:04:22,058 INFO org.apache.hadoop.http.HttpServer2: Added filter static_user_filter (class=org.apache.hadoop.http.lib.StaticUserWebFilter$StaticUserFilter) to context static
2018-09-13 13:04:22,063 INFO org.apache.hadoop.http.HttpServer2: adding path spec: /cluster/*
2018-09-13 13:04:22,063 INFO org.apache.hadoop.http.HttpServer2: adding path spec: /ws/*
2018-09-13 13:04:22,395 INFO org.apache.hadoop.yarn.webapp.WebApps: Registered webapp guice modules
2018-09-13 13:04:22,399 INFO org.apache.hadoop.http.HttpServer2: Jetty bound to port 8088
2018-09-13 13:04:22,399 INFO org.mortbay.log: jetty-6.1.26
2018-09-13 13:04:22,429 INFO org.mortbay.log: Extract jar:file:/Users/jason/hadoop-2.8.1/share/hadoop/yarn/hadoop-yarn-common-2.8.1.jar!/webapps/cluster to /var/folders/7r/3c0pxtpd0rg5hjs32v2rrz_00000gn/T/Jetty_0_0_0_0_8088_cluster____u0rgz3/webapp
2018-09-13 13:04:22,571 INFO org.apache.hadoop.security.token.delegation.AbstractDelegationTokenSecretManager: Updating the current master key for generating delegation tokens
2018-09-13 13:04:22,572 INFO org.apache.hadoop.security.token.delegation.AbstractDelegationTokenSecretManager: Starting expired delegation token remover thread, tokenRemoverScanInterval=60 min(s)
2018-09-13 13:04:22,572 INFO org.apache.hadoop.security.token.delegation.AbstractDelegationTokenSecretManager: Updating the current master key for generating delegation tokens
2018-09-13 13:04:23,412 INFO org.mortbay.log: Started HttpServer2$SelectChannelConnectorWithSafeStartup@0.0.0.0:8088
2018-09-13 13:04:23,413 INFO org.apache.hadoop.yarn.webapp.WebApps: Web app cluster started at 8088
2018-09-13 13:04:23,452 INFO org.apache.hadoop.ipc.CallQueueManager: Using callQueue: class java.util.concurrent.LinkedBlockingQueue queueCapacity: 100 scheduler: class org.apache.hadoop.ipc.DefaultRpcScheduler
2018-09-13 13:04:23,453 INFO org.apache.hadoop.ipc.Server: Starting Socket Reader #1 for port 8033
2018-09-13 13:04:23,455 INFO org.apache.hadoop.yarn.factories.impl.pb.RpcServerFactoryPBImpl: Adding protocol org.apache.hadoop.yarn.server.api.ResourceManagerAdministrationProtocolPB to the server
2018-09-13 13:04:23,455 INFO org.apache.hadoop.ipc.Server: IPC Server Responder: starting
2018-09-13 13:04:23,455 INFO org.apache.hadoop.ipc.Server: IPC Server listener on 8033: starting
2018-09-13 13:04:44,983 INFO org.apache.hadoop.yarn.server.resourcemanager.ResourceTrackerService: NodeManager from node 10.169.0.233(cmPort: 55366 httpPort: 8042) registered with capability: <memory:8192, vCores:8>, assigned nodeId 10.169.0.233:55366
2018-09-13 13:04:44,993 INFO org.apache.hadoop.yarn.server.resourcemanager.rmnode.RMNodeImpl: 10.169.0.233:55366 Node Transitioned from NEW to RUNNING
2018-09-13 13:04:45,003 INFO org.apache.hadoop.yarn.server.resourcemanager.scheduler.capacity.CapacityScheduler: Added node 10.169.0.233:55366 clusterResource: <memory:8192, vCores:8>
2018-09-13 13:06:11,181 ERROR org.apache.hadoop.yarn.server.resourcemanager.ResourceManager: RECEIVED SIGNAL 15: SIGTERM
2018-09-13 13:06:11,189 ERROR org.apache.hadoop.security.token.delegation.AbstractDelegationTokenSecretManager: ExpiredTokenRemover received java.lang.InterruptedException: sleep interrupted
2018-09-13 13:06:11,191 INFO org.mortbay.log: Stopped HttpServer2$SelectChannelConnectorWithSafeStartup@0.0.0.0:8088
2018-09-13 13:06:11,295 INFO org.apache.hadoop.ipc.Server: Stopping server on 8032
2018-09-13 13:06:11,301 INFO org.apache.hadoop.ipc.Server: Stopping IPC Server listener on 8032
2018-09-13 13:06:11,302 INFO org.apache.hadoop.ipc.Server: Stopping IPC Server Responder
2018-09-13 13:06:11,304 INFO org.apache.hadoop.ipc.Server: Stopping server on 8033
2018-09-13 13:06:11,305 INFO org.apache.hadoop.ipc.Server: Stopping IPC Server listener on 8033
2018-09-13 13:06:11,306 INFO org.apache.hadoop.ipc.Server: Stopping IPC Server Responder
2018-09-13 13:06:11,307 INFO org.apache.hadoop.yarn.server.resourcemanager.ResourceManager: Transitioning to standby state
2018-09-13 13:06:11,307 WARN org.apache.hadoop.yarn.server.resourcemanager.amlauncher.ApplicationMasterLauncher: org.apache.hadoop.yarn.server.resourcemanager.amlauncher.ApplicationMasterLauncher$LauncherThread interrupted. Returning.
2018-09-13 13:06:11,308 INFO org.apache.hadoop.ipc.Server: Stopping server on 8030
2018-09-13 13:06:11,309 INFO org.apache.hadoop.ipc.Server: Stopping IPC Server listener on 8030
2018-09-13 13:06:11,309 INFO org.apache.hadoop.ipc.Server: Stopping IPC Server Responder
2018-09-13 13:06:11,310 INFO org.apache.hadoop.ipc.Server: Stopping server on 8031
2018-09-13 13:06:11,311 INFO org.apache.hadoop.ipc.Server: Stopping IPC Server listener on 8031
2018-09-13 13:06:11,311 INFO org.apache.hadoop.ipc.Server: Stopping IPC Server Responder
2018-09-13 13:06:11,312 INFO org.apache.hadoop.yarn.util.AbstractLivelinessMonitor: NMLivelinessMonitor thread interrupted
2018-09-13 13:06:11,312 ERROR org.apache.hadoop.yarn.server.resourcemanager.ResourceManager: Returning, interrupted : java.lang.InterruptedException
2018-09-13 13:06:11,314 INFO org.apache.hadoop.yarn.event.AsyncDispatcher: AsyncDispatcher is draining to stop, igonring any new events.
2018-09-13 13:06:11,315 INFO org.apache.hadoop.yarn.util.AbstractLivelinessMonitor: AMLivelinessMonitor thread interrupted
2018-09-13 13:06:11,315 INFO org.apache.hadoop.yarn.util.AbstractLivelinessMonitor: org.apache.hadoop.yarn.server.resourcemanager.rmcontainer.ContainerAllocationExpirer thread interrupted
2018-09-13 13:06:11,315 INFO org.apache.hadoop.yarn.util.AbstractLivelinessMonitor: AMLivelinessMonitor thread interrupted
2018-09-13 13:06:11,315 ERROR org.apache.hadoop.security.token.delegation.AbstractDelegationTokenSecretManager: ExpiredTokenRemover received java.lang.InterruptedException: sleep interrupted
2018-09-13 13:06:11,316 INFO org.apache.hadoop.metrics2.impl.MetricsSystemImpl: Stopping ResourceManager metrics system...
2018-09-13 13:06:11,317 INFO org.apache.hadoop.metrics2.impl.MetricsSystemImpl: ResourceManager metrics system stopped.
2018-09-13 13:06:11,317 INFO org.apache.hadoop.metrics2.impl.MetricsSystemImpl: ResourceManager metrics system shutdown complete.
2018-09-13 13:06:11,317 INFO org.apache.hadoop.yarn.event.AsyncDispatcher: AsyncDispatcher is draining to stop, igonring any new events.
2018-09-13 13:06:11,317 INFO org.apache.hadoop.yarn.server.resourcemanager.ResourceManager: Transitioned to standby state
2018-09-13 13:06:11,318 INFO org.apache.hadoop.yarn.server.resourcemanager.ResourceManager: SHUTDOWN_MSG: 
/************************************************************
SHUTDOWN_MSG: Shutting down ResourceManager at Jasons-MacBook-Pro.local/10.169.0.233
************************************************************/
2018-09-13 13:14:46,092 INFO org.apache.hadoop.yarn.server.resourcemanager.ResourceManager: STARTUP_MSG: 
/************************************************************
STARTUP_MSG: Starting ResourceManager
STARTUP_MSG:   user = jason
STARTUP_MSG:   host = Jasons-MacBook-Pro.local/10.169.0.233
STARTUP_MSG:   args = []
STARTUP_MSG:   version = 2.8.1
STARTUP_MSG:   build = https://git-wip-us.apache.org/repos/asf/hadoop.git -r 20fe5304904fc2f5a18053c389e43cd26f7a70fe; compiled by 'vinodkv' on 2017-06-02T06:14Z
STARTUP_MSG:   java = 1.8.0_181
************************************************************/
2018-09-13 13:14:46,101 INFO org.apache.hadoop.yarn.server.resourcemanager.ResourceManager: registered UNIX signal handlers for [TERM, HUP, INT]
2018-09-13 13:14:46,321 INFO org.apache.hadoop.conf.Configuration: found resource core-site.xml at file:/Users/jason/hadoop-2.8.1/etc/hadoop/core-site.xml
2018-09-13 13:14:46,348 WARN org.apache.hadoop.util.NativeCodeLoader: Unable to load native-hadoop library for your platform... using builtin-java classes where applicable
2018-09-13 13:14:46,368 INFO org.apache.hadoop.security.Groups: clearing userToGroupsMap cache
2018-09-13 13:14:46,415 INFO org.apache.hadoop.conf.Configuration: found resource yarn-site.xml at file:/Users/jason/hadoop-2.8.1/etc/hadoop/yarn-site.xml
2018-09-13 13:14:46,566 INFO org.apache.hadoop.yarn.event.AsyncDispatcher: Registering class org.apache.hadoop.yarn.server.resourcemanager.RMFatalEventType for class org.apache.hadoop.yarn.server.resourcemanager.ResourceManager$RMFatalEventDispatcher
2018-09-13 13:14:46,716 INFO org.apache.hadoop.yarn.server.resourcemanager.security.NMTokenSecretManagerInRM: NMTokenKeyRollingInterval: 86400000ms and NMTokenKeyActivationDelay: 900000ms
2018-09-13 13:14:46,719 INFO org.apache.hadoop.yarn.server.resourcemanager.security.RMContainerTokenSecretManager: ContainerTokenKeyRollingInterval: 86400000ms and ContainerTokenKeyActivationDelay: 900000ms
2018-09-13 13:14:46,722 INFO org.apache.hadoop.yarn.server.resourcemanager.security.AMRMTokenSecretManager: AMRMTokenKeyRollingInterval: 86400000ms and AMRMTokenKeyActivationDelay: 900000 ms
2018-09-13 13:14:46,745 INFO org.apache.hadoop.yarn.event.AsyncDispatcher: Registering class org.apache.hadoop.yarn.server.resourcemanager.recovery.RMStateStoreEventType for class org.apache.hadoop.yarn.server.resourcemanager.recovery.RMStateStore$ForwardingEventHandler
2018-09-13 13:14:46,747 INFO org.apache.hadoop.yarn.event.AsyncDispatcher: Registering class org.apache.hadoop.yarn.server.resourcemanager.NodesListManagerEventType for class org.apache.hadoop.yarn.server.resourcemanager.NodesListManager
2018-09-13 13:14:46,747 INFO org.apache.hadoop.yarn.server.resourcemanager.ResourceManager: Using Scheduler: org.apache.hadoop.yarn.server.resourcemanager.scheduler.capacity.CapacityScheduler
2018-09-13 13:14:46,763 INFO org.apache.hadoop.yarn.event.AsyncDispatcher: Registering class org.apache.hadoop.yarn.server.resourcemanager.scheduler.event.SchedulerEventType for class org.apache.hadoop.yarn.server.resourcemanager.ResourceManager$SchedulerEventDispatcher
2018-09-13 13:14:46,764 INFO org.apache.hadoop.yarn.event.AsyncDispatcher: Registering class org.apache.hadoop.yarn.server.resourcemanager.rmapp.RMAppEventType for class org.apache.hadoop.yarn.server.resourcemanager.ResourceManager$ApplicationEventDispatcher
2018-09-13 13:14:46,765 INFO org.apache.hadoop.yarn.event.AsyncDispatcher: Registering class org.apache.hadoop.yarn.server.resourcemanager.rmapp.attempt.RMAppAttemptEventType for class org.apache.hadoop.yarn.server.resourcemanager.ResourceManager$ApplicationAttemptEventDispatcher
2018-09-13 13:14:46,765 INFO org.apache.hadoop.yarn.event.AsyncDispatcher: Registering class org.apache.hadoop.yarn.server.resourcemanager.rmnode.RMNodeEventType for class org.apache.hadoop.yarn.server.resourcemanager.ResourceManager$NodeEventDispatcher
2018-09-13 13:14:46,797 INFO org.apache.hadoop.metrics2.impl.MetricsConfig: loaded properties from hadoop-metrics2.properties
2018-09-13 13:14:46,851 INFO org.apache.hadoop.metrics2.impl.MetricsSystemImpl: Scheduled Metric snapshot period at 10 second(s).
2018-09-13 13:14:46,851 INFO org.apache.hadoop.metrics2.impl.MetricsSystemImpl: ResourceManager metrics system started
2018-09-13 13:14:46,864 INFO org.apache.hadoop.yarn.event.AsyncDispatcher: Registering class org.apache.hadoop.yarn.server.resourcemanager.RMAppManagerEventType for class org.apache.hadoop.yarn.server.resourcemanager.RMAppManager
2018-09-13 13:14:46,870 INFO org.apache.hadoop.yarn.event.AsyncDispatcher: Registering class org.apache.hadoop.yarn.server.resourcemanager.amlauncher.AMLauncherEventType for class org.apache.hadoop.yarn.server.resourcemanager.amlauncher.ApplicationMasterLauncher
2018-09-13 13:14:46,872 INFO org.apache.hadoop.yarn.server.resourcemanager.RMNMInfo: Registered RMNMInfo MBean
2018-09-13 13:14:46,877 INFO org.apache.hadoop.yarn.security.YarnAuthorizationProvider: org.apache.hadoop.yarn.security.ConfiguredYarnAuthorizer is instiantiated.
2018-09-13 13:14:46,878 INFO org.apache.hadoop.util.HostsFileReader: Refreshing hosts (include/exclude) list
2018-09-13 13:14:46,884 INFO org.apache.hadoop.conf.Configuration: found resource capacity-scheduler.xml at file:/Users/jason/hadoop-2.8.1/etc/hadoop/capacity-scheduler.xml
2018-09-13 13:14:46,926 INFO org.apache.hadoop.yarn.server.resourcemanager.scheduler.capacity.CapacitySchedulerConfiguration: max alloc mb per queue for root is undefined
2018-09-13 13:14:46,927 INFO org.apache.hadoop.yarn.server.resourcemanager.scheduler.capacity.CapacitySchedulerConfiguration: max alloc vcore per queue for root is undefined
2018-09-13 13:14:46,933 INFO org.apache.hadoop.yarn.server.resourcemanager.scheduler.capacity.ParentQueue: root, capacity=1.0, asboluteCapacity=1.0, maxCapacity=1.0, asboluteMaxCapacity=1.0, state=RUNNING, acls=ADMINISTER_QUEUE:*SUBMIT_APP:*, labels=*,, offswitchPerHeartbeatLimit = 1, reservationsContinueLooking=true
2018-09-13 13:14:46,934 INFO org.apache.hadoop.yarn.server.resourcemanager.scheduler.capacity.ParentQueue: Initialized parent-queue root name=root, fullname=root
2018-09-13 13:14:46,943 INFO org.apache.hadoop.yarn.server.resourcemanager.scheduler.capacity.CapacitySchedulerConfiguration: max alloc mb per queue for root.default is undefined
2018-09-13 13:14:46,943 INFO org.apache.hadoop.yarn.server.resourcemanager.scheduler.capacity.CapacitySchedulerConfiguration: max alloc vcore per queue for root.default is undefined
2018-09-13 13:14:46,945 INFO org.apache.hadoop.yarn.server.resourcemanager.scheduler.capacity.LeafQueue: Initializing default
capacity = 1.0 [= (float) configuredCapacity / 100 ]
asboluteCapacity = 1.0 [= parentAbsoluteCapacity * capacity ]
maxCapacity = 1.0 [= configuredMaxCapacity ]
absoluteMaxCapacity = 1.0 [= 1.0 maximumCapacity undefined, (parentAbsoluteMaxCapacity * maximumCapacity) / 100 otherwise ]
userLimit = 100 [= configuredUserLimit ]
userLimitFactor = 1.0 [= configuredUserLimitFactor ]
maxApplications = 10000 [= configuredMaximumSystemApplicationsPerQueue or (int)(configuredMaximumSystemApplications * absoluteCapacity)]
maxApplicationsPerUser = 10000 [= (int)(maxApplications * (userLimit / 100.0f) * userLimitFactor) ]
usedCapacity = 0.0 [= usedResourcesMemory / (clusterResourceMemory * absoluteCapacity)]
absoluteUsedCapacity = 0.0 [= usedResourcesMemory / clusterResourceMemory]
maxAMResourcePerQueuePercent = 0.1 [= configuredMaximumAMResourcePercent ]
minimumAllocationFactor = 0.875 [= (float)(maximumAllocationMemory - minimumAllocationMemory) / maximumAllocationMemory ]
maximumAllocation = <memory:8192, vCores:4> [= configuredMaxAllocation ]
numContainers = 0 [= currentNumContainers ]
state = RUNNING [= configuredState ]
acls = ADMINISTER_QUEUE:*SUBMIT_APP:* [= configuredAcls ]
nodeLocalityDelay = 40
labels=*,
reservationsContinueLooking = true
preemptionDisabled = true
defaultAppPriorityPerQueue = 0
2018-09-13 13:14:46,945 INFO org.apache.hadoop.yarn.server.resourcemanager.scheduler.capacity.CapacityScheduler: Initialized queue: default: capacity=1.0, absoluteCapacity=1.0, usedResources=<memory:0, vCores:0>, usedCapacity=0.0, absoluteUsedCapacity=0.0, numApps=0, numContainers=0
2018-09-13 13:14:46,946 INFO org.apache.hadoop.yarn.server.resourcemanager.scheduler.capacity.CapacityScheduler: Initialized queue: root: numChildQueue= 1, capacity=1.0, absoluteCapacity=1.0, usedResources=<memory:0, vCores:0>usedCapacity=0.0, numApps=0, numContainers=0
2018-09-13 13:14:46,946 INFO org.apache.hadoop.yarn.server.resourcemanager.scheduler.capacity.CapacityScheduler: Initialized root queue root: numChildQueue= 1, capacity=1.0, absoluteCapacity=1.0, usedResources=<memory:0, vCores:0>usedCapacity=0.0, numApps=0, numContainers=0
2018-09-13 13:14:46,946 INFO org.apache.hadoop.yarn.server.resourcemanager.scheduler.capacity.CapacityScheduler: Initialized queue mappings, override: false
2018-09-13 13:14:46,947 INFO org.apache.hadoop.yarn.server.resourcemanager.scheduler.capacity.CapacityScheduler: Initialized CapacityScheduler with calculator=class org.apache.hadoop.yarn.util.resource.DefaultResourceCalculator, minimumAllocation=<<memory:1024, vCores:1>>, maximumAllocation=<<memory:8192, vCores:4>>, asynchronousScheduling=false, asyncScheduleInterval=5ms
2018-09-13 13:14:46,949 INFO org.apache.hadoop.conf.Configuration: dynamic-resources.xml not found
2018-09-13 13:14:46,957 INFO org.apache.hadoop.yarn.server.resourcemanager.metrics.SystemMetricsPublisher: YARN system metrics publishing service is not enabled
2018-09-13 13:14:46,957 INFO org.apache.hadoop.yarn.server.resourcemanager.ResourceManager: Transitioning to active state
2018-09-13 13:14:46,971 INFO org.apache.hadoop.util.JvmPauseMonitor: Starting JVM pause monitor
2018-09-13 13:14:46,980 INFO org.apache.hadoop.yarn.server.resourcemanager.recovery.RMStateStore: Updating AMRMToken
2018-09-13 13:14:46,980 INFO org.apache.hadoop.yarn.server.resourcemanager.security.RMContainerTokenSecretManager: Rolling master-key for container-tokens
2018-09-13 13:14:46,981 INFO org.apache.hadoop.yarn.server.resourcemanager.security.NMTokenSecretManagerInRM: Rolling master-key for nm-tokens
2018-09-13 13:14:46,981 INFO org.apache.hadoop.security.token.delegation.AbstractDelegationTokenSecretManager: Updating the current master key for generating delegation tokens
2018-09-13 13:14:46,981 INFO org.apache.hadoop.yarn.server.resourcemanager.security.RMDelegationTokenSecretManager: storing master key with keyID 1
2018-09-13 13:14:46,981 INFO org.apache.hadoop.yarn.server.resourcemanager.recovery.RMStateStore: Storing RMDTMasterKey.
2018-09-13 13:14:46,982 INFO org.apache.hadoop.security.token.delegation.AbstractDelegationTokenSecretManager: Starting expired delegation token remover thread, tokenRemoverScanInterval=60 min(s)
2018-09-13 13:14:46,982 INFO org.apache.hadoop.security.token.delegation.AbstractDelegationTokenSecretManager: Updating the current master key for generating delegation tokens
2018-09-13 13:14:46,982 INFO org.apache.hadoop.yarn.server.resourcemanager.security.RMDelegationTokenSecretManager: storing master key with keyID 2
2018-09-13 13:14:46,982 INFO org.apache.hadoop.yarn.server.resourcemanager.recovery.RMStateStore: Storing RMDTMasterKey.
2018-09-13 13:14:46,983 INFO org.apache.hadoop.yarn.event.AsyncDispatcher: Registering class org.apache.hadoop.yarn.nodelabels.event.NodeLabelsStoreEventType for class org.apache.hadoop.yarn.nodelabels.CommonNodeLabelsManager$ForwardingEventHandler
2018-09-13 13:14:47,006 INFO org.apache.hadoop.ipc.CallQueueManager: Using callQueue: class java.util.concurrent.LinkedBlockingQueue queueCapacity: 5000 scheduler: class org.apache.hadoop.ipc.DefaultRpcScheduler
2018-09-13 13:14:47,034 INFO org.apache.hadoop.ipc.Server: Starting Socket Reader #1 for port 8031
2018-09-13 13:14:47,156 INFO org.apache.hadoop.yarn.factories.impl.pb.RpcServerFactoryPBImpl: Adding protocol org.apache.hadoop.yarn.server.api.ResourceTrackerPB to the server
2018-09-13 13:14:47,156 INFO org.apache.hadoop.ipc.Server: IPC Server Responder: starting
2018-09-13 13:14:47,156 INFO org.apache.hadoop.ipc.Server: IPC Server listener on 8031: starting
2018-09-13 13:14:47,174 INFO org.apache.hadoop.ipc.CallQueueManager: Using callQueue: class java.util.concurrent.LinkedBlockingQueue queueCapacity: 5000 scheduler: class org.apache.hadoop.ipc.DefaultRpcScheduler
2018-09-13 13:14:47,178 INFO org.apache.hadoop.ipc.Server: Starting Socket Reader #1 for port 8030
2018-09-13 13:14:47,188 INFO org.apache.hadoop.yarn.factories.impl.pb.RpcServerFactoryPBImpl: Adding protocol org.apache.hadoop.yarn.api.ApplicationMasterProtocolPB to the server
2018-09-13 13:14:47,189 INFO org.apache.hadoop.ipc.Server: IPC Server Responder: starting
2018-09-13 13:14:47,189 INFO org.apache.hadoop.ipc.Server: IPC Server listener on 8030: starting
2018-09-13 13:14:47,298 INFO org.apache.hadoop.ipc.CallQueueManager: Using callQueue: class java.util.concurrent.LinkedBlockingQueue queueCapacity: 5000 scheduler: class org.apache.hadoop.ipc.DefaultRpcScheduler
2018-09-13 13:14:47,298 INFO org.apache.hadoop.ipc.Server: Starting Socket Reader #1 for port 8032
2018-09-13 13:14:47,303 INFO org.apache.hadoop.yarn.factories.impl.pb.RpcServerFactoryPBImpl: Adding protocol org.apache.hadoop.yarn.api.ApplicationClientProtocolPB to the server
2018-09-13 13:14:47,303 INFO org.apache.hadoop.ipc.Server: IPC Server Responder: starting
2018-09-13 13:14:47,303 INFO org.apache.hadoop.ipc.Server: IPC Server listener on 8032: starting
2018-09-13 13:14:47,308 INFO org.apache.hadoop.yarn.server.resourcemanager.ResourceManager: Transitioned to active state
2018-09-13 13:14:47,376 INFO org.mortbay.log: Logging to org.slf4j.impl.Log4jLoggerAdapter(org.mortbay.log) via org.mortbay.log.Slf4jLog
2018-09-13 13:14:47,383 INFO org.apache.hadoop.security.authentication.server.AuthenticationFilter: Unable to initialize FileSignerSecretProvider, falling back to use random secrets.
2018-09-13 13:14:47,388 INFO org.apache.hadoop.http.HttpRequestLog: Http request log for http.requests.resourcemanager is not defined
2018-09-13 13:14:47,395 INFO org.apache.hadoop.http.HttpServer2: Added global filter 'safety' (class=org.apache.hadoop.http.HttpServer2$QuotingInputFilter)
2018-09-13 13:14:47,398 INFO org.apache.hadoop.http.HttpServer2: Added filter RMAuthenticationFilter (class=org.apache.hadoop.yarn.server.security.http.RMAuthenticationFilter) to context cluster
2018-09-13 13:14:47,398 INFO org.apache.hadoop.http.HttpServer2: Added filter RMAuthenticationFilter (class=org.apache.hadoop.yarn.server.security.http.RMAuthenticationFilter) to context logs
2018-09-13 13:14:47,398 INFO org.apache.hadoop.http.HttpServer2: Added filter RMAuthenticationFilter (class=org.apache.hadoop.yarn.server.security.http.RMAuthenticationFilter) to context static
2018-09-13 13:14:47,398 INFO org.apache.hadoop.http.HttpServer2: Added filter static_user_filter (class=org.apache.hadoop.http.lib.StaticUserWebFilter$StaticUserFilter) to context cluster
2018-09-13 13:14:47,398 INFO org.apache.hadoop.http.HttpServer2: Added filter static_user_filter (class=org.apache.hadoop.http.lib.StaticUserWebFilter$StaticUserFilter) to context logs
2018-09-13 13:14:47,398 INFO org.apache.hadoop.http.HttpServer2: Added filter static_user_filter (class=org.apache.hadoop.http.lib.StaticUserWebFilter$StaticUserFilter) to context static
2018-09-13 13:14:47,401 INFO org.apache.hadoop.http.HttpServer2: adding path spec: /cluster/*
2018-09-13 13:14:47,401 INFO org.apache.hadoop.http.HttpServer2: adding path spec: /ws/*
2018-09-13 13:14:47,675 INFO org.apache.hadoop.yarn.webapp.WebApps: Registered webapp guice modules
2018-09-13 13:14:47,678 INFO org.apache.hadoop.http.HttpServer2: Jetty bound to port 8088
2018-09-13 13:14:47,678 INFO org.mortbay.log: jetty-6.1.26
2018-09-13 13:14:47,698 INFO org.mortbay.log: Extract jar:file:/Users/jason/hadoop-2.8.1/share/hadoop/yarn/hadoop-yarn-common-2.8.1.jar!/webapps/cluster to /var/folders/7r/3c0pxtpd0rg5hjs32v2rrz_00000gn/T/Jetty_0_0_0_0_8088_cluster____u0rgz3/webapp
2018-09-13 13:14:47,882 INFO org.apache.hadoop.security.token.delegation.AbstractDelegationTokenSecretManager: Updating the current master key for generating delegation tokens
2018-09-13 13:14:47,882 INFO org.apache.hadoop.security.token.delegation.AbstractDelegationTokenSecretManager: Starting expired delegation token remover thread, tokenRemoverScanInterval=60 min(s)
2018-09-13 13:14:47,882 INFO org.apache.hadoop.security.token.delegation.AbstractDelegationTokenSecretManager: Updating the current master key for generating delegation tokens
2018-09-13 13:14:48,852 INFO org.mortbay.log: Started HttpServer2$SelectChannelConnectorWithSafeStartup@0.0.0.0:8088
2018-09-13 13:14:48,852 INFO org.apache.hadoop.yarn.webapp.WebApps: Web app cluster started at 8088
2018-09-13 13:14:48,888 INFO org.apache.hadoop.ipc.CallQueueManager: Using callQueue: class java.util.concurrent.LinkedBlockingQueue queueCapacity: 100 scheduler: class org.apache.hadoop.ipc.DefaultRpcScheduler
2018-09-13 13:14:48,888 INFO org.apache.hadoop.ipc.Server: Starting Socket Reader #1 for port 8033
2018-09-13 13:14:48,892 INFO org.apache.hadoop.yarn.factories.impl.pb.RpcServerFactoryPBImpl: Adding protocol org.apache.hadoop.yarn.server.api.ResourceManagerAdministrationProtocolPB to the server
2018-09-13 13:14:48,892 INFO org.apache.hadoop.ipc.Server: IPC Server Responder: starting
2018-09-13 13:14:48,892 INFO org.apache.hadoop.ipc.Server: IPC Server listener on 8033: starting
2018-09-13 13:14:50,377 INFO org.apache.hadoop.yarn.server.resourcemanager.ResourceTrackerService: NodeManager from node 10.169.0.233(cmPort: 55415 httpPort: 8042) registered with capability: <memory:8192, vCores:8>, assigned nodeId 10.169.0.233:55415
2018-09-13 13:14:50,380 INFO org.apache.hadoop.yarn.server.resourcemanager.rmnode.RMNodeImpl: 10.169.0.233:55415 Node Transitioned from NEW to RUNNING
2018-09-13 13:14:50,387 INFO org.apache.hadoop.yarn.server.resourcemanager.scheduler.capacity.CapacityScheduler: Added node 10.169.0.233:55415 clusterResource: <memory:8192, vCores:8>
2018-09-13 13:24:46,886 INFO org.apache.hadoop.yarn.server.resourcemanager.scheduler.AbstractYarnScheduler: Release request cache is cleaned up
2018-09-13 14:30:19,444 ERROR org.apache.hadoop.yarn.server.resourcemanager.ResourceManager: RECEIVED SIGNAL 15: SIGTERM
2018-09-13 14:30:19,450 ERROR org.apache.hadoop.security.token.delegation.AbstractDelegationTokenSecretManager: ExpiredTokenRemover received java.lang.InterruptedException: sleep interrupted
2018-09-13 14:30:19,451 INFO org.mortbay.log: Stopped HttpServer2$SelectChannelConnectorWithSafeStartup@0.0.0.0:8088
2018-09-13 14:30:19,556 INFO org.apache.hadoop.ipc.Server: Stopping server on 8032
2018-09-13 14:30:19,557 INFO org.apache.hadoop.ipc.Server: Stopping IPC Server listener on 8032
2018-09-13 14:30:19,557 INFO org.apache.hadoop.ipc.Server: Stopping server on 8033
2018-09-13 14:30:19,557 INFO org.apache.hadoop.ipc.Server: Stopping IPC Server listener on 8033
2018-09-13 14:30:19,560 INFO org.apache.hadoop.ipc.Server: Stopping IPC Server Responder
2018-09-13 14:30:19,560 INFO org.apache.hadoop.ipc.Server: Stopping IPC Server Responder
2018-09-13 14:30:19,560 INFO org.apache.hadoop.yarn.server.resourcemanager.ResourceManager: Transitioning to standby state
2018-09-13 14:30:19,561 WARN org.apache.hadoop.yarn.server.resourcemanager.amlauncher.ApplicationMasterLauncher: org.apache.hadoop.yarn.server.resourcemanager.amlauncher.ApplicationMasterLauncher$LauncherThread interrupted. Returning.
2018-09-13 14:30:19,561 INFO org.apache.hadoop.ipc.Server: Stopping server on 8030
2018-09-13 14:30:19,562 INFO org.apache.hadoop.ipc.Server: Stopping IPC Server listener on 8030
2018-09-13 14:30:19,562 INFO org.apache.hadoop.ipc.Server: Stopping server on 8031
2018-09-13 14:30:19,564 INFO org.apache.hadoop.ipc.Server: Stopping IPC Server Responder
2018-09-13 14:30:19,566 INFO org.apache.hadoop.ipc.Server: Stopping IPC Server listener on 8031
2018-09-13 14:30:19,566 INFO org.apache.hadoop.ipc.Server: Stopping IPC Server Responder
2018-09-13 14:30:19,567 ERROR org.apache.hadoop.yarn.server.resourcemanager.ResourceManager: Returning, interrupted : java.lang.InterruptedException
2018-09-13 14:30:19,567 INFO org.apache.hadoop.yarn.util.AbstractLivelinessMonitor: NMLivelinessMonitor thread interrupted
2018-09-13 14:30:19,567 INFO org.apache.hadoop.yarn.event.AsyncDispatcher: AsyncDispatcher is draining to stop, igonring any new events.
2018-09-13 14:30:19,567 INFO org.apache.hadoop.yarn.util.AbstractLivelinessMonitor: AMLivelinessMonitor thread interrupted
2018-09-13 14:30:19,567 ERROR org.apache.hadoop.security.token.delegation.AbstractDelegationTokenSecretManager: ExpiredTokenRemover received java.lang.InterruptedException: sleep interrupted
2018-09-13 14:30:19,567 INFO org.apache.hadoop.yarn.util.AbstractLivelinessMonitor: org.apache.hadoop.yarn.server.resourcemanager.rmcontainer.ContainerAllocationExpirer thread interrupted
2018-09-13 14:30:19,567 INFO org.apache.hadoop.yarn.util.AbstractLivelinessMonitor: AMLivelinessMonitor thread interrupted
2018-09-13 14:30:19,567 INFO org.apache.hadoop.metrics2.impl.MetricsSystemImpl: Stopping ResourceManager metrics system...
2018-09-13 14:30:19,568 INFO org.apache.hadoop.metrics2.impl.MetricsSystemImpl: ResourceManager metrics system stopped.
2018-09-13 14:30:19,568 INFO org.apache.hadoop.metrics2.impl.MetricsSystemImpl: ResourceManager metrics system shutdown complete.
2018-09-13 14:30:19,568 INFO org.apache.hadoop.yarn.event.AsyncDispatcher: AsyncDispatcher is draining to stop, igonring any new events.
2018-09-13 14:30:19,569 INFO org.apache.hadoop.yarn.server.resourcemanager.ResourceManager: Transitioned to standby state
2018-09-13 14:30:19,569 INFO org.apache.hadoop.yarn.server.resourcemanager.ResourceManager: SHUTDOWN_MSG: 
/************************************************************
SHUTDOWN_MSG: Shutting down ResourceManager at Jasons-MacBook-Pro.local/10.169.0.233
************************************************************/
2018-09-13 17:47:08,673 INFO org.apache.hadoop.yarn.server.resourcemanager.ResourceManager: STARTUP_MSG: 
/************************************************************
STARTUP_MSG: Starting ResourceManager
STARTUP_MSG:   user = jason
STARTUP_MSG:   host = Jasons-MacBook-Pro.local/192.168.1.103
STARTUP_MSG:   args = []
STARTUP_MSG:   version = 2.8.1
STARTUP_MSG:   build = https://git-wip-us.apache.org/repos/asf/hadoop.git -r 20fe5304904fc2f5a18053c389e43cd26f7a70fe; compiled by 'vinodkv' on 2017-06-02T06:14Z
STARTUP_MSG:   java = 1.8.0_181
************************************************************/
2018-09-13 17:47:08,687 INFO org.apache.hadoop.yarn.server.resourcemanager.ResourceManager: registered UNIX signal handlers for [TERM, HUP, INT]
2018-09-13 17:47:08,902 INFO org.apache.hadoop.conf.Configuration: found resource core-site.xml at file:/Users/jason/hadoop-2.8.1/etc/hadoop/core-site.xml
2018-09-13 17:47:08,930 WARN org.apache.hadoop.util.NativeCodeLoader: Unable to load native-hadoop library for your platform... using builtin-java classes where applicable
2018-09-13 17:47:08,948 INFO org.apache.hadoop.security.Groups: clearing userToGroupsMap cache
2018-09-13 17:47:08,995 INFO org.apache.hadoop.conf.Configuration: found resource yarn-site.xml at file:/Users/jason/hadoop-2.8.1/etc/hadoop/yarn-site.xml
2018-09-13 17:47:09,142 INFO org.apache.hadoop.yarn.event.AsyncDispatcher: Registering class org.apache.hadoop.yarn.server.resourcemanager.RMFatalEventType for class org.apache.hadoop.yarn.server.resourcemanager.ResourceManager$RMFatalEventDispatcher
2018-09-13 17:47:09,286 INFO org.apache.hadoop.yarn.server.resourcemanager.security.NMTokenSecretManagerInRM: NMTokenKeyRollingInterval: 86400000ms and NMTokenKeyActivationDelay: 900000ms
2018-09-13 17:47:09,289 INFO org.apache.hadoop.yarn.server.resourcemanager.security.RMContainerTokenSecretManager: ContainerTokenKeyRollingInterval: 86400000ms and ContainerTokenKeyActivationDelay: 900000ms
2018-09-13 17:47:09,292 INFO org.apache.hadoop.yarn.server.resourcemanager.security.AMRMTokenSecretManager: AMRMTokenKeyRollingInterval: 86400000ms and AMRMTokenKeyActivationDelay: 900000 ms
2018-09-13 17:47:09,316 INFO org.apache.hadoop.yarn.event.AsyncDispatcher: Registering class org.apache.hadoop.yarn.server.resourcemanager.recovery.RMStateStoreEventType for class org.apache.hadoop.yarn.server.resourcemanager.recovery.RMStateStore$ForwardingEventHandler
2018-09-13 17:47:09,318 INFO org.apache.hadoop.yarn.event.AsyncDispatcher: Registering class org.apache.hadoop.yarn.server.resourcemanager.NodesListManagerEventType for class org.apache.hadoop.yarn.server.resourcemanager.NodesListManager
2018-09-13 17:47:09,318 INFO org.apache.hadoop.yarn.server.resourcemanager.ResourceManager: Using Scheduler: org.apache.hadoop.yarn.server.resourcemanager.scheduler.capacity.CapacityScheduler
2018-09-13 17:47:09,335 INFO org.apache.hadoop.yarn.event.AsyncDispatcher: Registering class org.apache.hadoop.yarn.server.resourcemanager.scheduler.event.SchedulerEventType for class org.apache.hadoop.yarn.server.resourcemanager.ResourceManager$SchedulerEventDispatcher
2018-09-13 17:47:09,336 INFO org.apache.hadoop.yarn.event.AsyncDispatcher: Registering class org.apache.hadoop.yarn.server.resourcemanager.rmapp.RMAppEventType for class org.apache.hadoop.yarn.server.resourcemanager.ResourceManager$ApplicationEventDispatcher
2018-09-13 17:47:09,337 INFO org.apache.hadoop.yarn.event.AsyncDispatcher: Registering class org.apache.hadoop.yarn.server.resourcemanager.rmapp.attempt.RMAppAttemptEventType for class org.apache.hadoop.yarn.server.resourcemanager.ResourceManager$ApplicationAttemptEventDispatcher
2018-09-13 17:47:09,338 INFO org.apache.hadoop.yarn.event.AsyncDispatcher: Registering class org.apache.hadoop.yarn.server.resourcemanager.rmnode.RMNodeEventType for class org.apache.hadoop.yarn.server.resourcemanager.ResourceManager$NodeEventDispatcher
2018-09-13 17:47:09,371 INFO org.apache.hadoop.metrics2.impl.MetricsConfig: loaded properties from hadoop-metrics2.properties
2018-09-13 17:47:09,421 INFO org.apache.hadoop.metrics2.impl.MetricsSystemImpl: Scheduled Metric snapshot period at 10 second(s).
2018-09-13 17:47:09,421 INFO org.apache.hadoop.metrics2.impl.MetricsSystemImpl: ResourceManager metrics system started
2018-09-13 17:47:09,434 INFO org.apache.hadoop.yarn.event.AsyncDispatcher: Registering class org.apache.hadoop.yarn.server.resourcemanager.RMAppManagerEventType for class org.apache.hadoop.yarn.server.resourcemanager.RMAppManager
2018-09-13 17:47:09,441 INFO org.apache.hadoop.yarn.event.AsyncDispatcher: Registering class org.apache.hadoop.yarn.server.resourcemanager.amlauncher.AMLauncherEventType for class org.apache.hadoop.yarn.server.resourcemanager.amlauncher.ApplicationMasterLauncher
2018-09-13 17:47:09,443 INFO org.apache.hadoop.yarn.server.resourcemanager.RMNMInfo: Registered RMNMInfo MBean
2018-09-13 17:47:09,448 INFO org.apache.hadoop.yarn.security.YarnAuthorizationProvider: org.apache.hadoop.yarn.security.ConfiguredYarnAuthorizer is instiantiated.
2018-09-13 17:47:09,449 INFO org.apache.hadoop.util.HostsFileReader: Refreshing hosts (include/exclude) list
2018-09-13 17:47:09,456 INFO org.apache.hadoop.conf.Configuration: found resource capacity-scheduler.xml at file:/Users/jason/hadoop-2.8.1/etc/hadoop/capacity-scheduler.xml
2018-09-13 17:47:09,499 INFO org.apache.hadoop.yarn.server.resourcemanager.scheduler.capacity.CapacitySchedulerConfiguration: max alloc mb per queue for root is undefined
2018-09-13 17:47:09,499 INFO org.apache.hadoop.yarn.server.resourcemanager.scheduler.capacity.CapacitySchedulerConfiguration: max alloc vcore per queue for root is undefined
2018-09-13 17:47:09,506 INFO org.apache.hadoop.yarn.server.resourcemanager.scheduler.capacity.ParentQueue: root, capacity=1.0, asboluteCapacity=1.0, maxCapacity=1.0, asboluteMaxCapacity=1.0, state=RUNNING, acls=ADMINISTER_QUEUE:*SUBMIT_APP:*, labels=*,, offswitchPerHeartbeatLimit = 1, reservationsContinueLooking=true
2018-09-13 17:47:09,506 INFO org.apache.hadoop.yarn.server.resourcemanager.scheduler.capacity.ParentQueue: Initialized parent-queue root name=root, fullname=root
2018-09-13 17:47:09,516 INFO org.apache.hadoop.yarn.server.resourcemanager.scheduler.capacity.CapacitySchedulerConfiguration: max alloc mb per queue for root.default is undefined
2018-09-13 17:47:09,516 INFO org.apache.hadoop.yarn.server.resourcemanager.scheduler.capacity.CapacitySchedulerConfiguration: max alloc vcore per queue for root.default is undefined
2018-09-13 17:47:09,518 INFO org.apache.hadoop.yarn.server.resourcemanager.scheduler.capacity.LeafQueue: Initializing default
capacity = 1.0 [= (float) configuredCapacity / 100 ]
asboluteCapacity = 1.0 [= parentAbsoluteCapacity * capacity ]
maxCapacity = 1.0 [= configuredMaxCapacity ]
absoluteMaxCapacity = 1.0 [= 1.0 maximumCapacity undefined, (parentAbsoluteMaxCapacity * maximumCapacity) / 100 otherwise ]
userLimit = 100 [= configuredUserLimit ]
userLimitFactor = 1.0 [= configuredUserLimitFactor ]
maxApplications = 10000 [= configuredMaximumSystemApplicationsPerQueue or (int)(configuredMaximumSystemApplications * absoluteCapacity)]
maxApplicationsPerUser = 10000 [= (int)(maxApplications * (userLimit / 100.0f) * userLimitFactor) ]
usedCapacity = 0.0 [= usedResourcesMemory / (clusterResourceMemory * absoluteCapacity)]
absoluteUsedCapacity = 0.0 [= usedResourcesMemory / clusterResourceMemory]
maxAMResourcePerQueuePercent = 0.1 [= configuredMaximumAMResourcePercent ]
minimumAllocationFactor = 0.875 [= (float)(maximumAllocationMemory - minimumAllocationMemory) / maximumAllocationMemory ]
maximumAllocation = <memory:8192, vCores:4> [= configuredMaxAllocation ]
numContainers = 0 [= currentNumContainers ]
state = RUNNING [= configuredState ]
acls = ADMINISTER_QUEUE:*SUBMIT_APP:* [= configuredAcls ]
nodeLocalityDelay = 40
labels=*,
reservationsContinueLooking = true
preemptionDisabled = true
defaultAppPriorityPerQueue = 0
2018-09-13 17:47:09,519 INFO org.apache.hadoop.yarn.server.resourcemanager.scheduler.capacity.CapacityScheduler: Initialized queue: default: capacity=1.0, absoluteCapacity=1.0, usedResources=<memory:0, vCores:0>, usedCapacity=0.0, absoluteUsedCapacity=0.0, numApps=0, numContainers=0
2018-09-13 17:47:09,519 INFO org.apache.hadoop.yarn.server.resourcemanager.scheduler.capacity.CapacityScheduler: Initialized queue: root: numChildQueue= 1, capacity=1.0, absoluteCapacity=1.0, usedResources=<memory:0, vCores:0>usedCapacity=0.0, numApps=0, numContainers=0
2018-09-13 17:47:09,520 INFO org.apache.hadoop.yarn.server.resourcemanager.scheduler.capacity.CapacityScheduler: Initialized root queue root: numChildQueue= 1, capacity=1.0, absoluteCapacity=1.0, usedResources=<memory:0, vCores:0>usedCapacity=0.0, numApps=0, numContainers=0
2018-09-13 17:47:09,520 INFO org.apache.hadoop.yarn.server.resourcemanager.scheduler.capacity.CapacityScheduler: Initialized queue mappings, override: false
2018-09-13 17:47:09,521 INFO org.apache.hadoop.yarn.server.resourcemanager.scheduler.capacity.CapacityScheduler: Initialized CapacityScheduler with calculator=class org.apache.hadoop.yarn.util.resource.DefaultResourceCalculator, minimumAllocation=<<memory:1024, vCores:1>>, maximumAllocation=<<memory:8192, vCores:4>>, asynchronousScheduling=false, asyncScheduleInterval=5ms
2018-09-13 17:47:09,524 INFO org.apache.hadoop.conf.Configuration: dynamic-resources.xml not found
2018-09-13 17:47:09,532 INFO org.apache.hadoop.yarn.server.resourcemanager.metrics.SystemMetricsPublisher: YARN system metrics publishing service is not enabled
2018-09-13 17:47:09,532 INFO org.apache.hadoop.yarn.server.resourcemanager.ResourceManager: Transitioning to active state
2018-09-13 17:47:09,547 INFO org.apache.hadoop.util.JvmPauseMonitor: Starting JVM pause monitor
2018-09-13 17:47:09,559 INFO org.apache.hadoop.yarn.server.resourcemanager.recovery.RMStateStore: Updating AMRMToken
2018-09-13 17:47:09,559 INFO org.apache.hadoop.yarn.server.resourcemanager.security.RMContainerTokenSecretManager: Rolling master-key for container-tokens
2018-09-13 17:47:09,559 INFO org.apache.hadoop.yarn.server.resourcemanager.security.NMTokenSecretManagerInRM: Rolling master-key for nm-tokens
2018-09-13 17:47:09,559 INFO org.apache.hadoop.security.token.delegation.AbstractDelegationTokenSecretManager: Updating the current master key for generating delegation tokens
2018-09-13 17:47:09,560 INFO org.apache.hadoop.yarn.server.resourcemanager.security.RMDelegationTokenSecretManager: storing master key with keyID 1
2018-09-13 17:47:09,560 INFO org.apache.hadoop.yarn.server.resourcemanager.recovery.RMStateStore: Storing RMDTMasterKey.
2018-09-13 17:47:09,561 INFO org.apache.hadoop.security.token.delegation.AbstractDelegationTokenSecretManager: Starting expired delegation token remover thread, tokenRemoverScanInterval=60 min(s)
2018-09-13 17:47:09,561 INFO org.apache.hadoop.security.token.delegation.AbstractDelegationTokenSecretManager: Updating the current master key for generating delegation tokens
2018-09-13 17:47:09,561 INFO org.apache.hadoop.yarn.server.resourcemanager.security.RMDelegationTokenSecretManager: storing master key with keyID 2
2018-09-13 17:47:09,561 INFO org.apache.hadoop.yarn.server.resourcemanager.recovery.RMStateStore: Storing RMDTMasterKey.
2018-09-13 17:47:09,563 INFO org.apache.hadoop.yarn.event.AsyncDispatcher: Registering class org.apache.hadoop.yarn.nodelabels.event.NodeLabelsStoreEventType for class org.apache.hadoop.yarn.nodelabels.CommonNodeLabelsManager$ForwardingEventHandler
2018-09-13 17:47:09,587 INFO org.apache.hadoop.ipc.CallQueueManager: Using callQueue: class java.util.concurrent.LinkedBlockingQueue queueCapacity: 5000 scheduler: class org.apache.hadoop.ipc.DefaultRpcScheduler
2018-09-13 17:47:09,614 INFO org.apache.hadoop.ipc.Server: Starting Socket Reader #1 for port 8031
2018-09-13 17:47:09,731 INFO org.apache.hadoop.yarn.factories.impl.pb.RpcServerFactoryPBImpl: Adding protocol org.apache.hadoop.yarn.server.api.ResourceTrackerPB to the server
2018-09-13 17:47:09,731 INFO org.apache.hadoop.ipc.Server: IPC Server Responder: starting
2018-09-13 17:47:09,731 INFO org.apache.hadoop.ipc.Server: IPC Server listener on 8031: starting
2018-09-13 17:47:09,745 INFO org.apache.hadoop.ipc.CallQueueManager: Using callQueue: class java.util.concurrent.LinkedBlockingQueue queueCapacity: 5000 scheduler: class org.apache.hadoop.ipc.DefaultRpcScheduler
2018-09-13 17:47:09,749 INFO org.apache.hadoop.ipc.Server: Starting Socket Reader #1 for port 8030
2018-09-13 17:47:09,767 INFO org.apache.hadoop.yarn.factories.impl.pb.RpcServerFactoryPBImpl: Adding protocol org.apache.hadoop.yarn.api.ApplicationMasterProtocolPB to the server
2018-09-13 17:47:09,767 INFO org.apache.hadoop.ipc.Server: IPC Server Responder: starting
2018-09-13 17:47:09,767 INFO org.apache.hadoop.ipc.Server: IPC Server listener on 8030: starting
2018-09-13 17:47:09,869 INFO org.apache.hadoop.ipc.CallQueueManager: Using callQueue: class java.util.concurrent.LinkedBlockingQueue queueCapacity: 5000 scheduler: class org.apache.hadoop.ipc.DefaultRpcScheduler
2018-09-13 17:47:09,869 INFO org.apache.hadoop.ipc.Server: Starting Socket Reader #1 for port 8032
2018-09-13 17:47:09,873 INFO org.apache.hadoop.yarn.factories.impl.pb.RpcServerFactoryPBImpl: Adding protocol org.apache.hadoop.yarn.api.ApplicationClientProtocolPB to the server
2018-09-13 17:47:09,873 INFO org.apache.hadoop.ipc.Server: IPC Server Responder: starting
2018-09-13 17:47:09,874 INFO org.apache.hadoop.ipc.Server: IPC Server listener on 8032: starting
2018-09-13 17:47:09,879 INFO org.apache.hadoop.yarn.server.resourcemanager.ResourceManager: Transitioned to active state
2018-09-13 17:47:09,945 INFO org.mortbay.log: Logging to org.slf4j.impl.Log4jLoggerAdapter(org.mortbay.log) via org.mortbay.log.Slf4jLog
2018-09-13 17:47:09,953 INFO org.apache.hadoop.security.authentication.server.AuthenticationFilter: Unable to initialize FileSignerSecretProvider, falling back to use random secrets.
2018-09-13 17:47:09,958 INFO org.apache.hadoop.http.HttpRequestLog: Http request log for http.requests.resourcemanager is not defined
2018-09-13 17:47:09,964 INFO org.apache.hadoop.http.HttpServer2: Added global filter 'safety' (class=org.apache.hadoop.http.HttpServer2$QuotingInputFilter)
2018-09-13 17:47:09,966 INFO org.apache.hadoop.http.HttpServer2: Added filter RMAuthenticationFilter (class=org.apache.hadoop.yarn.server.security.http.RMAuthenticationFilter) to context cluster
2018-09-13 17:47:09,966 INFO org.apache.hadoop.http.HttpServer2: Added filter RMAuthenticationFilter (class=org.apache.hadoop.yarn.server.security.http.RMAuthenticationFilter) to context logs
2018-09-13 17:47:09,966 INFO org.apache.hadoop.http.HttpServer2: Added filter RMAuthenticationFilter (class=org.apache.hadoop.yarn.server.security.http.RMAuthenticationFilter) to context static
2018-09-13 17:47:09,967 INFO org.apache.hadoop.http.HttpServer2: Added filter static_user_filter (class=org.apache.hadoop.http.lib.StaticUserWebFilter$StaticUserFilter) to context cluster
2018-09-13 17:47:09,967 INFO org.apache.hadoop.http.HttpServer2: Added filter static_user_filter (class=org.apache.hadoop.http.lib.StaticUserWebFilter$StaticUserFilter) to context logs
2018-09-13 17:47:09,967 INFO org.apache.hadoop.http.HttpServer2: Added filter static_user_filter (class=org.apache.hadoop.http.lib.StaticUserWebFilter$StaticUserFilter) to context static
2018-09-13 17:47:09,969 INFO org.apache.hadoop.http.HttpServer2: adding path spec: /cluster/*
2018-09-13 17:47:09,969 INFO org.apache.hadoop.http.HttpServer2: adding path spec: /ws/*
2018-09-13 17:47:10,242 INFO org.apache.hadoop.yarn.webapp.WebApps: Registered webapp guice modules
2018-09-13 17:47:10,244 INFO org.apache.hadoop.http.HttpServer2: Jetty bound to port 8088
2018-09-13 17:47:10,245 INFO org.mortbay.log: jetty-6.1.26
2018-09-13 17:47:10,264 INFO org.mortbay.log: Extract jar:file:/Users/jason/hadoop-2.8.1/share/hadoop/yarn/hadoop-yarn-common-2.8.1.jar!/webapps/cluster to /var/folders/7r/3c0pxtpd0rg5hjs32v2rrz_00000gn/T/Jetty_0_0_0_0_8088_cluster____u0rgz3/webapp
2018-09-13 17:47:10,408 INFO org.apache.hadoop.security.token.delegation.AbstractDelegationTokenSecretManager: Updating the current master key for generating delegation tokens
2018-09-13 17:47:10,409 INFO org.apache.hadoop.security.token.delegation.AbstractDelegationTokenSecretManager: Starting expired delegation token remover thread, tokenRemoverScanInterval=60 min(s)
2018-09-13 17:47:10,409 INFO org.apache.hadoop.security.token.delegation.AbstractDelegationTokenSecretManager: Updating the current master key for generating delegation tokens
2018-09-13 17:47:11,375 INFO org.mortbay.log: Started HttpServer2$SelectChannelConnectorWithSafeStartup@0.0.0.0:8088
2018-09-13 17:47:11,375 INFO org.apache.hadoop.yarn.webapp.WebApps: Web app cluster started at 8088
2018-09-13 17:47:11,403 INFO org.apache.hadoop.ipc.CallQueueManager: Using callQueue: class java.util.concurrent.LinkedBlockingQueue queueCapacity: 100 scheduler: class org.apache.hadoop.ipc.DefaultRpcScheduler
2018-09-13 17:47:11,403 INFO org.apache.hadoop.ipc.Server: Starting Socket Reader #1 for port 8033
2018-09-13 17:47:11,407 INFO org.apache.hadoop.yarn.factories.impl.pb.RpcServerFactoryPBImpl: Adding protocol org.apache.hadoop.yarn.server.api.ResourceManagerAdministrationProtocolPB to the server
2018-09-13 17:47:11,407 INFO org.apache.hadoop.ipc.Server: IPC Server Responder: starting
2018-09-13 17:47:11,407 INFO org.apache.hadoop.ipc.Server: IPC Server listener on 8033: starting
2018-09-13 17:47:12,824 INFO org.apache.hadoop.yarn.server.resourcemanager.ResourceTrackerService: NodeManager from node 192.168.1.103(cmPort: 56395 httpPort: 8042) registered with capability: <memory:8192, vCores:8>, assigned nodeId 192.168.1.103:56395
2018-09-13 17:47:12,827 INFO org.apache.hadoop.yarn.server.resourcemanager.rmnode.RMNodeImpl: 192.168.1.103:56395 Node Transitioned from NEW to RUNNING
2018-09-13 17:47:12,834 INFO org.apache.hadoop.yarn.server.resourcemanager.scheduler.capacity.CapacityScheduler: Added node 192.168.1.103:56395 clusterResource: <memory:8192, vCores:8>
2018-09-13 17:57:09,458 INFO org.apache.hadoop.yarn.server.resourcemanager.scheduler.AbstractYarnScheduler: Release request cache is cleaned up
2018-09-14 17:47:12,059 INFO org.apache.hadoop.security.token.delegation.AbstractDelegationTokenSecretManager: Updating the current master key for generating delegation tokens
2018-09-14 17:47:12,066 INFO org.apache.hadoop.yarn.server.resourcemanager.security.RMDelegationTokenSecretManager: storing master key with keyID 3
2018-09-14 17:47:12,067 INFO org.apache.hadoop.yarn.server.resourcemanager.recovery.RMStateStore: Storing RMDTMasterKey.
2018-09-14 17:47:13,343 INFO org.apache.hadoop.security.token.delegation.AbstractDelegationTokenSecretManager: Updating the current master key for generating delegation tokens
2018-09-15 18:15:24,008 INFO org.apache.hadoop.security.token.delegation.AbstractDelegationTokenSecretManager: Updating the current master key for generating delegation tokens
2018-09-15 18:15:27,579 INFO org.apache.hadoop.security.token.delegation.AbstractDelegationTokenSecretManager: Updating the current master key for generating delegation tokens
2018-09-15 18:15:27,579 INFO org.apache.hadoop.yarn.server.resourcemanager.security.RMDelegationTokenSecretManager: storing master key with keyID 4
2018-09-15 18:15:27,580 INFO org.apache.hadoop.yarn.server.resourcemanager.recovery.RMStateStore: Storing RMDTMasterKey.
2018-09-16 18:48:10,567 INFO org.apache.hadoop.security.token.delegation.AbstractDelegationTokenSecretManager: Updating the current master key for generating delegation tokens
2018-09-16 18:48:12,498 INFO org.apache.hadoop.security.token.delegation.AbstractDelegationTokenSecretManager: Updating the current master key for generating delegation tokens
2018-09-16 18:48:12,498 INFO org.apache.hadoop.yarn.server.resourcemanager.security.RMDelegationTokenSecretManager: storing master key with keyID 5
2018-09-16 18:48:12,498 INFO org.apache.hadoop.yarn.server.resourcemanager.recovery.RMStateStore: Storing RMDTMasterKey.
2018-09-17 19:27:44,002 INFO org.apache.hadoop.security.token.delegation.AbstractDelegationTokenSecretManager: Updating the current master key for generating delegation tokens
2018-09-17 19:27:44,042 INFO org.apache.hadoop.yarn.server.resourcemanager.security.RMDelegationTokenSecretManager: storing master key with keyID 6
2018-09-17 19:27:44,042 INFO org.apache.hadoop.yarn.server.resourcemanager.recovery.RMStateStore: Storing RMDTMasterKey.
2018-09-17 19:27:47,739 INFO org.apache.hadoop.security.token.delegation.AbstractDelegationTokenSecretManager: Updating the current master key for generating delegation tokens
2018-09-17 21:27:57,787 WARN org.apache.hadoop.util.JvmPauseMonitor: Detected pause in JVM or host machine (eg GC): pause of approximately 32033ms
No GCs detected
2018-09-17 23:28:11,333 WARN org.apache.hadoop.util.JvmPauseMonitor: Detected pause in JVM or host machine (eg GC): pause of approximately 10099ms
No GCs detected
2018-09-18 01:28:24,206 INFO org.apache.hadoop.util.JvmPauseMonitor: Detected pause in JVM or host machine (eg GC): pause of approximately 7793ms
No GCs detected
2018-09-18 03:28:37,254 INFO org.apache.hadoop.util.JvmPauseMonitor: Detected pause in JVM or host machine (eg GC): pause of approximately 9383ms
No GCs detected
2018-09-18 04:28:12,119 INFO org.apache.hadoop.util.JvmPauseMonitor: Detected pause in JVM or host machine (eg GC): pause of approximately 7547ms
No GCs detected
2018-09-18 09:38:59,249 INFO org.apache.hadoop.util.JvmPauseMonitor: Detected pause in JVM or host machine (eg GC): pause of approximately 6625ms
No GCs detected
2018-09-18 10:01:12,991 INFO org.apache.hadoop.yarn.server.resourcemanager.ClientRMService: Allocated new applicationId: 1
2018-09-18 10:01:13,801 INFO org.apache.hadoop.yarn.server.resourcemanager.scheduler.capacity.CapacityScheduler: Application 'application_1536878829533_0001' is submitted without priority hence considering default queue/cluster priority: 0
2018-09-18 10:01:13,801 INFO org.apache.hadoop.yarn.server.resourcemanager.scheduler.capacity.CapacityScheduler: Priority '0' is acceptable in queue : default for application: application_1536878829533_0001 for the user: jason
2018-09-18 10:01:13,834 INFO org.apache.hadoop.yarn.server.resourcemanager.ClientRMService: Application with id 1 submitted by user jason
2018-09-18 10:01:13,834 INFO org.apache.hadoop.yarn.server.resourcemanager.rmapp.RMAppImpl: Storing application with id application_1536878829533_0001
2018-09-18 10:01:13,842 INFO org.apache.hadoop.yarn.server.resourcemanager.RMAuditLogger: USER=jason	IP=192.168.1.103	OPERATION=Submit Application Request	TARGET=ClientRMService	RESULT=SUCCESS	APPID=application_1536878829533_0001
2018-09-18 10:01:13,853 INFO org.apache.hadoop.yarn.server.resourcemanager.rmapp.RMAppImpl: application_1536878829533_0001 State change from NEW to NEW_SAVING on event=START
2018-09-18 10:01:13,853 INFO org.apache.hadoop.yarn.server.resourcemanager.recovery.RMStateStore: Storing info for app: application_1536878829533_0001
2018-09-18 10:01:13,854 INFO org.apache.hadoop.yarn.server.resourcemanager.rmapp.RMAppImpl: application_1536878829533_0001 State change from NEW_SAVING to SUBMITTED on event=APP_NEW_SAVED
2018-09-18 10:01:13,857 INFO org.apache.hadoop.yarn.server.resourcemanager.scheduler.capacity.ParentQueue: Application added - appId: application_1536878829533_0001 user: jason leaf-queue of parent: root #applications: 1
2018-09-18 10:01:13,858 INFO org.apache.hadoop.yarn.server.resourcemanager.scheduler.capacity.CapacityScheduler: Accepted application application_1536878829533_0001 from user: jason, in queue: default
2018-09-18 10:01:13,893 INFO org.apache.hadoop.yarn.server.resourcemanager.rmapp.RMAppImpl: application_1536878829533_0001 State change from SUBMITTED to ACCEPTED on event=APP_ACCEPTED
2018-09-18 10:01:13,932 INFO org.apache.hadoop.yarn.server.resourcemanager.ApplicationMasterService: Registering app attempt : appattempt_1536878829533_0001_000001
2018-09-18 10:01:13,934 INFO org.apache.hadoop.yarn.server.resourcemanager.rmapp.attempt.RMAppAttemptImpl: appattempt_1536878829533_0001_000001 State change from NEW to SUBMITTED
2018-09-18 10:01:13,961 WARN org.apache.hadoop.yarn.server.resourcemanager.scheduler.capacity.LeafQueue: maximum-am-resource-percent is insufficient to start a single application in queue, it is likely set too low. skipping enforcement to allow at least one application to start
2018-09-18 10:01:13,961 WARN org.apache.hadoop.yarn.server.resourcemanager.scheduler.capacity.LeafQueue: maximum-am-resource-percent is insufficient to start a single application in queue for user, it is likely set too low. skipping enforcement to allow at least one application to start
2018-09-18 10:01:13,965 INFO org.apache.hadoop.yarn.server.resourcemanager.scheduler.capacity.LeafQueue: Application application_1536878829533_0001 from user: jason activated in queue: default
2018-09-18 10:01:13,965 INFO org.apache.hadoop.yarn.server.resourcemanager.scheduler.capacity.LeafQueue: Application added - appId: application_1536878829533_0001 user: jason, leaf-queue: default #user-pending-applications: 0 #user-active-applications: 1 #queue-pending-applications: 0 #queue-active-applications: 1
2018-09-18 10:01:13,965 INFO org.apache.hadoop.yarn.server.resourcemanager.scheduler.capacity.CapacityScheduler: Added Application Attempt appattempt_1536878829533_0001_000001 to scheduler from user jason in queue default
2018-09-18 10:01:13,968 INFO org.apache.hadoop.yarn.server.resourcemanager.rmapp.attempt.RMAppAttemptImpl: appattempt_1536878829533_0001_000001 State change from SUBMITTED to SCHEDULED
2018-09-18 10:01:14,917 INFO org.apache.hadoop.yarn.server.resourcemanager.rmcontainer.RMContainerImpl: container_1536878829533_0001_01_000001 Container Transitioned from NEW to ALLOCATED
2018-09-18 10:01:14,918 INFO org.apache.hadoop.yarn.server.resourcemanager.RMAuditLogger: USER=jason	OPERATION=AM Allocated Container	TARGET=SchedulerApp	RESULT=SUCCESS	APPID=application_1536878829533_0001	CONTAINERID=container_1536878829533_0001_01_000001
2018-09-18 10:01:14,919 INFO org.apache.hadoop.yarn.server.resourcemanager.scheduler.SchedulerNode: Assigned container container_1536878829533_0001_01_000001 of capacity <memory:2048, vCores:1> on host 192.168.1.103:56395, which has 1 containers, <memory:2048, vCores:1> used and <memory:6144, vCores:7> available after allocation
2018-09-18 10:01:14,919 INFO org.apache.hadoop.yarn.server.resourcemanager.scheduler.capacity.allocator.AbstractContainerAllocator: assignedContainer application attempt=appattempt_1536878829533_0001_000001 container=container_1536878829533_0001_01_000001 queue=org.apache.hadoop.yarn.server.resourcemanager.scheduler.capacity.allocator.RegularContainerAllocator@616798c1 clusterResource=<memory:8192, vCores:8> type=OFF_SWITCH
2018-09-18 10:01:14,952 INFO org.apache.hadoop.yarn.server.resourcemanager.security.NMTokenSecretManagerInRM: Sending NMToken for nodeId : 192.168.1.103:56395 for container : container_1536878829533_0001_01_000001
2018-09-18 10:01:14,965 INFO org.apache.hadoop.yarn.server.resourcemanager.rmcontainer.RMContainerImpl: container_1536878829533_0001_01_000001 Container Transitioned from ALLOCATED to ACQUIRED
2018-09-18 10:01:14,965 INFO org.apache.hadoop.yarn.server.resourcemanager.security.NMTokenSecretManagerInRM: Clear node set for appattempt_1536878829533_0001_000001
2018-09-18 10:01:14,966 INFO org.apache.hadoop.yarn.server.resourcemanager.rmapp.attempt.RMAppAttemptImpl: Storing attempt: AppId: application_1536878829533_0001 AttemptId: appattempt_1536878829533_0001_000001 MasterContainer: Container: [ContainerId: container_1536878829533_0001_01_000001, Version: 0, NodeId: 192.168.1.103:56395, NodeHttpAddress: 192.168.1.103:8042, Resource: <memory:2048, vCores:1>, Priority: 0, Token: Token { kind: ContainerToken, service: 192.168.1.103:56395 }, ]
2018-09-18 10:01:14,966 INFO org.apache.hadoop.yarn.server.resourcemanager.scheduler.capacity.ParentQueue: Re-sorting assigned queue: root.default stats: default: capacity=1.0, absoluteCapacity=1.0, usedResources=<memory:2048, vCores:1>, usedCapacity=0.25, absoluteUsedCapacity=0.25, numApps=1, numContainers=1
2018-09-18 10:01:14,966 INFO org.apache.hadoop.yarn.server.resourcemanager.scheduler.capacity.ParentQueue: assignedContainer queue=root usedCapacity=0.25 absoluteUsedCapacity=0.25 used=<memory:2048, vCores:1> cluster=<memory:8192, vCores:8>
2018-09-18 10:01:14,977 INFO org.apache.hadoop.yarn.server.resourcemanager.rmapp.attempt.RMAppAttemptImpl: appattempt_1536878829533_0001_000001 State change from SCHEDULED to ALLOCATED_SAVING
2018-09-18 10:01:14,983 INFO org.apache.hadoop.yarn.server.resourcemanager.rmapp.attempt.RMAppAttemptImpl: appattempt_1536878829533_0001_000001 State change from ALLOCATED_SAVING to ALLOCATED
2018-09-18 10:01:14,987 INFO org.apache.hadoop.yarn.server.resourcemanager.amlauncher.AMLauncher: Launching masterappattempt_1536878829533_0001_000001
2018-09-18 10:01:15,047 INFO org.apache.hadoop.yarn.server.resourcemanager.amlauncher.AMLauncher: Setting up container Container: [ContainerId: container_1536878829533_0001_01_000001, Version: 0, NodeId: 192.168.1.103:56395, NodeHttpAddress: 192.168.1.103:8042, Resource: <memory:2048, vCores:1>, Priority: 0, Token: Token { kind: ContainerToken, service: 192.168.1.103:56395 }, ] for AM appattempt_1536878829533_0001_000001
2018-09-18 10:01:15,047 INFO org.apache.hadoop.yarn.server.resourcemanager.security.AMRMTokenSecretManager: Create AMRMToken for ApplicationAttempt: appattempt_1536878829533_0001_000001
2018-09-18 10:01:15,051 INFO org.apache.hadoop.yarn.server.resourcemanager.security.AMRMTokenSecretManager: Creating password for appattempt_1536878829533_0001_000001
2018-09-18 10:01:15,456 INFO org.apache.hadoop.yarn.server.resourcemanager.amlauncher.AMLauncher: Done launching container Container: [ContainerId: container_1536878829533_0001_01_000001, Version: 0, NodeId: 192.168.1.103:56395, NodeHttpAddress: 192.168.1.103:8042, Resource: <memory:2048, vCores:1>, Priority: 0, Token: Token { kind: ContainerToken, service: 192.168.1.103:56395 }, ] for AM appattempt_1536878829533_0001_000001
2018-09-18 10:01:15,456 INFO org.apache.hadoop.yarn.server.resourcemanager.rmapp.attempt.RMAppAttemptImpl: appattempt_1536878829533_0001_000001 State change from ALLOCATED to LAUNCHED
2018-09-18 10:01:15,890 INFO org.apache.hadoop.yarn.server.resourcemanager.rmcontainer.RMContainerImpl: container_1536878829533_0001_01_000001 Container Transitioned from ACQUIRED to RUNNING
2018-09-18 10:01:20,038 INFO SecurityLogger.org.apache.hadoop.ipc.Server: Auth successful for appattempt_1536878829533_0001_000001 (auth:SIMPLE)
2018-09-18 10:01:20,046 INFO org.apache.hadoop.yarn.server.resourcemanager.ApplicationMasterService: AM registration appattempt_1536878829533_0001_000001
2018-09-18 10:01:20,046 INFO org.apache.hadoop.yarn.server.resourcemanager.RMAuditLogger: USER=jason	IP=192.168.1.103	OPERATION=Register App Master	TARGET=ApplicationMasterService	RESULT=SUCCESS	APPID=application_1536878829533_0001	APPATTEMPTID=appattempt_1536878829533_0001_000001
2018-09-18 10:01:20,046 INFO org.apache.hadoop.yarn.server.resourcemanager.rmapp.attempt.RMAppAttemptImpl: appattempt_1536878829533_0001_000001 State change from LAUNCHED to RUNNING
2018-09-18 10:01:20,047 INFO org.apache.hadoop.yarn.server.resourcemanager.rmapp.RMAppImpl: application_1536878829533_0001 State change from ACCEPTED to RUNNING on event=ATTEMPT_REGISTERED
2018-09-18 10:01:21,909 INFO org.apache.hadoop.yarn.server.resourcemanager.rmcontainer.RMContainerImpl: container_1536878829533_0001_01_000002 Container Transitioned from NEW to ALLOCATED
2018-09-18 10:01:21,909 INFO org.apache.hadoop.yarn.server.resourcemanager.RMAuditLogger: USER=jason	OPERATION=AM Allocated Container	TARGET=SchedulerApp	RESULT=SUCCESS	APPID=application_1536878829533_0001	CONTAINERID=container_1536878829533_0001_01_000002
2018-09-18 10:01:21,909 INFO org.apache.hadoop.yarn.server.resourcemanager.scheduler.SchedulerNode: Assigned container container_1536878829533_0001_01_000002 of capacity <memory:1024, vCores:1> on host 192.168.1.103:56395, which has 2 containers, <memory:3072, vCores:2> used and <memory:5120, vCores:6> available after allocation
2018-09-18 10:01:21,909 INFO org.apache.hadoop.yarn.server.resourcemanager.scheduler.capacity.allocator.AbstractContainerAllocator: assignedContainer application attempt=appattempt_1536878829533_0001_000001 container=container_1536878829533_0001_01_000002 queue=org.apache.hadoop.yarn.server.resourcemanager.scheduler.capacity.allocator.RegularContainerAllocator@616798c1 clusterResource=<memory:8192, vCores:8> type=NODE_LOCAL
2018-09-18 10:01:21,909 INFO org.apache.hadoop.yarn.server.resourcemanager.scheduler.capacity.ParentQueue: Re-sorting assigned queue: root.default stats: default: capacity=1.0, absoluteCapacity=1.0, usedResources=<memory:3072, vCores:2>, usedCapacity=0.375, absoluteUsedCapacity=0.375, numApps=1, numContainers=2
2018-09-18 10:01:21,909 INFO org.apache.hadoop.yarn.server.resourcemanager.scheduler.capacity.ParentQueue: assignedContainer queue=root usedCapacity=0.375 absoluteUsedCapacity=0.375 used=<memory:3072, vCores:2> cluster=<memory:8192, vCores:8>
2018-09-18 10:01:22,122 INFO org.apache.hadoop.yarn.server.resourcemanager.security.NMTokenSecretManagerInRM: Sending NMToken for nodeId : 192.168.1.103:56395 for container : container_1536878829533_0001_01_000002
2018-09-18 10:01:22,123 INFO org.apache.hadoop.yarn.server.resourcemanager.rmcontainer.RMContainerImpl: container_1536878829533_0001_01_000002 Container Transitioned from ALLOCATED to ACQUIRED
2018-09-18 10:01:22,909 INFO org.apache.hadoop.yarn.server.resourcemanager.rmcontainer.RMContainerImpl: container_1536878829533_0001_01_000002 Container Transitioned from ACQUIRED to RUNNING
2018-09-18 10:01:23,142 INFO org.apache.hadoop.yarn.server.resourcemanager.scheduler.AppSchedulingInfo: checking for deactivate of application :application_1536878829533_0001
2018-09-18 10:01:24,603 INFO org.apache.hadoop.yarn.server.resourcemanager.rmcontainer.RMContainerImpl: container_1536878829533_0001_01_000002 Container Transitioned from RUNNING to COMPLETED
2018-09-18 10:01:24,603 INFO org.apache.hadoop.yarn.server.resourcemanager.RMAuditLogger: USER=jason	OPERATION=AM Released Container	TARGET=SchedulerApp	RESULT=SUCCESS	APPID=application_1536878829533_0001	CONTAINERID=container_1536878829533_0001_01_000002
2018-09-18 10:01:24,604 INFO org.apache.hadoop.yarn.server.resourcemanager.scheduler.SchedulerNode: Released container container_1536878829533_0001_01_000002 of capacity <memory:1024, vCores:1> on host 192.168.1.103:56395, which currently has 1 containers, <memory:2048, vCores:1> used and <memory:6144, vCores:7> available, release resources=true
2018-09-18 10:01:26,616 INFO org.apache.hadoop.yarn.server.resourcemanager.rmcontainer.RMContainerImpl: container_1536878829533_0001_01_000003 Container Transitioned from NEW to ALLOCATED
2018-09-18 10:01:26,616 INFO org.apache.hadoop.yarn.server.resourcemanager.RMAuditLogger: USER=jason	OPERATION=AM Allocated Container	TARGET=SchedulerApp	RESULT=SUCCESS	APPID=application_1536878829533_0001	CONTAINERID=container_1536878829533_0001_01_000003
2018-09-18 10:01:26,616 INFO org.apache.hadoop.yarn.server.resourcemanager.scheduler.SchedulerNode: Assigned container container_1536878829533_0001_01_000003 of capacity <memory:1024, vCores:1> on host 192.168.1.103:56395, which has 2 containers, <memory:3072, vCores:2> used and <memory:5120, vCores:6> available after allocation
2018-09-18 10:01:26,616 INFO org.apache.hadoop.yarn.server.resourcemanager.scheduler.capacity.allocator.AbstractContainerAllocator: assignedContainer application attempt=appattempt_1536878829533_0001_000001 container=container_1536878829533_0001_01_000003 queue=org.apache.hadoop.yarn.server.resourcemanager.scheduler.capacity.allocator.RegularContainerAllocator@616798c1 clusterResource=<memory:8192, vCores:8> type=OFF_SWITCH
2018-09-18 10:01:26,616 INFO org.apache.hadoop.yarn.server.resourcemanager.scheduler.capacity.ParentQueue: Re-sorting assigned queue: root.default stats: default: capacity=1.0, absoluteCapacity=1.0, usedResources=<memory:3072, vCores:2>, usedCapacity=0.375, absoluteUsedCapacity=0.375, numApps=1, numContainers=2
2018-09-18 10:01:26,616 INFO org.apache.hadoop.yarn.server.resourcemanager.scheduler.capacity.ParentQueue: assignedContainer queue=root usedCapacity=0.375 absoluteUsedCapacity=0.375 used=<memory:3072, vCores:2> cluster=<memory:8192, vCores:8>
2018-09-18 10:01:27,173 INFO org.apache.hadoop.yarn.server.resourcemanager.rmcontainer.RMContainerImpl: container_1536878829533_0001_01_000003 Container Transitioned from ALLOCATED to ACQUIRED
2018-09-18 10:01:27,622 INFO org.apache.hadoop.yarn.server.resourcemanager.rmcontainer.RMContainerImpl: container_1536878829533_0001_01_000003 Container Transitioned from ACQUIRED to RUNNING
2018-09-18 10:01:28,177 INFO org.apache.hadoop.yarn.server.resourcemanager.scheduler.AppSchedulingInfo: checking for deactivate of application :application_1536878829533_0001
2018-09-18 10:01:29,477 INFO org.apache.hadoop.yarn.server.resourcemanager.rmapp.attempt.RMAppAttemptImpl: Updating application attempt appattempt_1536878829533_0001_000001 with final state: FINISHING, and exit status: -1000
2018-09-18 10:01:29,478 INFO org.apache.hadoop.yarn.server.resourcemanager.rmapp.attempt.RMAppAttemptImpl: appattempt_1536878829533_0001_000001 State change from RUNNING to FINAL_SAVING
2018-09-18 10:01:29,478 INFO org.apache.hadoop.yarn.server.resourcemanager.rmapp.RMAppImpl: Updating application application_1536878829533_0001 with final state: FINISHING
2018-09-18 10:01:29,478 INFO org.apache.hadoop.yarn.server.resourcemanager.rmapp.RMAppImpl: application_1536878829533_0001 State change from RUNNING to FINAL_SAVING on event=ATTEMPT_UNREGISTERED
2018-09-18 10:01:29,478 INFO org.apache.hadoop.yarn.server.resourcemanager.recovery.RMStateStore: Updating info for app: application_1536878829533_0001
2018-09-18 10:01:29,478 INFO org.apache.hadoop.yarn.server.resourcemanager.rmapp.attempt.RMAppAttemptImpl: appattempt_1536878829533_0001_000001 State change from FINAL_SAVING to FINISHING
2018-09-18 10:01:29,478 INFO org.apache.hadoop.yarn.server.resourcemanager.rmapp.RMAppImpl: application_1536878829533_0001 State change from FINAL_SAVING to FINISHING on event=APP_UPDATE_SAVED
2018-09-18 10:01:29,488 INFO org.apache.hadoop.yarn.server.resourcemanager.rmcontainer.RMContainerImpl: container_1536878829533_0001_01_000003 Container Transitioned from RUNNING to COMPLETED
2018-09-18 10:01:29,488 INFO org.apache.hadoop.yarn.server.resourcemanager.RMAuditLogger: USER=jason	OPERATION=AM Released Container	TARGET=SchedulerApp	RESULT=SUCCESS	APPID=application_1536878829533_0001	CONTAINERID=container_1536878829533_0001_01_000003
2018-09-18 10:01:29,489 INFO org.apache.hadoop.yarn.server.resourcemanager.scheduler.SchedulerNode: Released container container_1536878829533_0001_01_000003 of capacity <memory:1024, vCores:1> on host 192.168.1.103:56395, which currently has 1 containers, <memory:2048, vCores:1> used and <memory:6144, vCores:7> available, release resources=true
2018-09-18 10:01:30,485 INFO org.apache.hadoop.yarn.server.resourcemanager.ApplicationMasterService: application_1536878829533_0001 unregistered successfully. 
2018-09-18 10:01:35,676 INFO org.apache.hadoop.yarn.server.resourcemanager.rmcontainer.RMContainerImpl: container_1536878829533_0001_01_000001 Container Transitioned from RUNNING to COMPLETED
2018-09-18 10:01:35,676 INFO org.apache.hadoop.yarn.server.resourcemanager.ApplicationMasterService: Unregistering app attempt : appattempt_1536878829533_0001_000001
2018-09-18 10:01:35,676 INFO org.apache.hadoop.yarn.server.resourcemanager.RMAuditLogger: USER=jason	OPERATION=AM Released Container	TARGET=SchedulerApp	RESULT=SUCCESS	APPID=application_1536878829533_0001	CONTAINERID=container_1536878829533_0001_01_000001
2018-09-18 10:01:35,677 INFO org.apache.hadoop.yarn.server.resourcemanager.scheduler.SchedulerNode: Released container container_1536878829533_0001_01_000001 of capacity <memory:2048, vCores:1> on host 192.168.1.103:56395, which currently has 0 containers, <memory:0, vCores:0> used and <memory:8192, vCores:8> available, release resources=true
2018-09-18 10:01:35,677 INFO org.apache.hadoop.yarn.server.resourcemanager.security.AMRMTokenSecretManager: Application finished, removing password for appattempt_1536878829533_0001_000001
2018-09-18 10:01:35,678 INFO org.apache.hadoop.yarn.server.resourcemanager.rmapp.attempt.RMAppAttemptImpl: appattempt_1536878829533_0001_000001 State change from FINISHING to FINISHED
2018-09-18 10:01:35,680 INFO org.apache.hadoop.yarn.server.resourcemanager.rmapp.RMAppImpl: application_1536878829533_0001 State change from FINISHING to FINISHED on event=ATTEMPT_FINISHED
2018-09-18 10:01:35,680 INFO org.apache.hadoop.yarn.server.resourcemanager.scheduler.capacity.CapacityScheduler: Application Attempt appattempt_1536878829533_0001_000001 is done. finalState=FINISHED
2018-09-18 10:01:35,681 INFO org.apache.hadoop.yarn.server.resourcemanager.scheduler.AppSchedulingInfo: Application application_1536878829533_0001 requests cleared
2018-09-18 10:01:35,681 INFO org.apache.hadoop.yarn.server.resourcemanager.amlauncher.AMLauncher: Cleaning master appattempt_1536878829533_0001_000001
2018-09-18 10:01:35,681 INFO org.apache.hadoop.yarn.server.resourcemanager.scheduler.capacity.LeafQueue: Application removed - appId: application_1536878829533_0001 user: jason queue: default #user-pending-applications: 0 #user-active-applications: 0 #queue-pending-applications: 0 #queue-active-applications: 0
2018-09-18 10:01:35,681 INFO org.apache.hadoop.yarn.server.resourcemanager.scheduler.capacity.ParentQueue: Application removed - appId: application_1536878829533_0001 user: jason leaf-queue of parent: root #applications: 0
2018-09-18 10:01:35,681 INFO org.apache.hadoop.yarn.server.resourcemanager.RMAuditLogger: USER=jason	OPERATION=Application Finished - Succeeded	TARGET=RMAppManager	RESULT=SUCCESS	APPID=application_1536878829533_0001
2018-09-18 10:01:35,684 INFO org.apache.hadoop.yarn.server.resourcemanager.RMAppManager$ApplicationSummary: appId=application_1536878829533_0001,name=word count,user=jason,queue=default,state=FINISHED,trackingUrl=http://Jasons-MacBook-Pro.local:8088/proxy/application_1536878829533_0001/,appMasterHost=192.168.1.103,startTime=1537282873821,finishTime=1537282889478,finalStatus=SUCCEEDED,memorySeconds=48216,vcoreSeconds=24,preemptedMemorySeconds=0,preemptedVcoreSeconds=0,preemptedAMContainers=0,preemptedNonAMContainers=0,preemptedResources=<memory:0\, vCores:0>,applicationType=MAPREDUCE
2018-09-18 10:01:37,691 INFO org.apache.hadoop.yarn.server.resourcemanager.scheduler.AbstractYarnScheduler: Container container_1536878829533_0001_01_000003 completed with event FINISHED, but corresponding RMContainer doesn't exist.
2018-09-18 13:08:14,928 INFO org.apache.hadoop.yarn.util.AbstractLivelinessMonitor: Expired:192.168.1.103:56395 Timed out after 600 secs
2018-09-18 13:08:14,936 INFO org.apache.hadoop.yarn.server.resourcemanager.rmnode.RMNodeImpl: Deactivating Node 192.168.1.103:56395 as it is now LOST
2018-09-18 13:08:14,936 INFO org.apache.hadoop.yarn.server.resourcemanager.rmnode.RMNodeImpl: 192.168.1.103:56395 Node Transitioned from RUNNING to LOST
2018-09-18 13:08:14,937 INFO org.apache.hadoop.yarn.server.resourcemanager.scheduler.capacity.CapacityScheduler: Removed node 192.168.1.103:56395 clusterResource: <memory:0, vCores:0>
2018-09-18 13:11:55,574 INFO org.apache.hadoop.yarn.server.resourcemanager.ResourceTrackerService: Node not found resyncing 192.168.1.103:56395
2018-09-18 13:11:55,584 INFO org.apache.hadoop.yarn.server.resourcemanager.ResourceTrackerService: NodeManager from node 192.168.1.103(cmPort: 56395 httpPort: 8042) registered with capability: <memory:8192, vCores:8>, assigned nodeId 192.168.1.103:56395
2018-09-18 13:11:55,584 INFO org.apache.hadoop.yarn.server.resourcemanager.rmnode.RMNodeImpl: 192.168.1.103:56395 Node Transitioned from NEW to RUNNING
2018-09-18 13:11:55,585 INFO org.apache.hadoop.yarn.server.resourcemanager.scheduler.capacity.CapacityScheduler: Added node 192.168.1.103:56395 clusterResource: <memory:8192, vCores:8>
2018-09-18 13:13:10,399 INFO org.apache.hadoop.yarn.server.resourcemanager.ClientRMService: Allocated new applicationId: 2
2018-09-18 13:13:10,891 INFO org.apache.hadoop.yarn.server.resourcemanager.scheduler.capacity.CapacityScheduler: Application 'application_1536878829533_0002' is submitted without priority hence considering default queue/cluster priority: 0
2018-09-18 13:13:10,891 INFO org.apache.hadoop.yarn.server.resourcemanager.scheduler.capacity.CapacityScheduler: Priority '0' is acceptable in queue : default for application: application_1536878829533_0002 for the user: jason
2018-09-18 13:13:10,891 INFO org.apache.hadoop.yarn.server.resourcemanager.ClientRMService: Application with id 2 submitted by user jason
2018-09-18 13:13:10,891 INFO org.apache.hadoop.yarn.server.resourcemanager.RMAuditLogger: USER=jason	IP=10.169.1.149	OPERATION=Submit Application Request	TARGET=ClientRMService	RESULT=SUCCESS	APPID=application_1536878829533_0002
2018-09-18 13:13:10,891 INFO org.apache.hadoop.yarn.server.resourcemanager.rmapp.RMAppImpl: Storing application with id application_1536878829533_0002
2018-09-18 13:13:10,892 INFO org.apache.hadoop.yarn.server.resourcemanager.rmapp.RMAppImpl: application_1536878829533_0002 State change from NEW to NEW_SAVING on event=START
2018-09-18 13:13:10,892 INFO org.apache.hadoop.yarn.server.resourcemanager.recovery.RMStateStore: Storing info for app: application_1536878829533_0002
2018-09-18 13:13:10,892 INFO org.apache.hadoop.yarn.server.resourcemanager.rmapp.RMAppImpl: application_1536878829533_0002 State change from NEW_SAVING to SUBMITTED on event=APP_NEW_SAVED
2018-09-18 13:13:10,892 INFO org.apache.hadoop.yarn.server.resourcemanager.scheduler.capacity.ParentQueue: Application added - appId: application_1536878829533_0002 user: jason leaf-queue of parent: root #applications: 1
2018-09-18 13:13:10,892 INFO org.apache.hadoop.yarn.server.resourcemanager.scheduler.capacity.CapacityScheduler: Accepted application application_1536878829533_0002 from user: jason, in queue: default
2018-09-18 13:13:10,894 INFO org.apache.hadoop.yarn.server.resourcemanager.rmapp.RMAppImpl: application_1536878829533_0002 State change from SUBMITTED to ACCEPTED on event=APP_ACCEPTED
2018-09-18 13:13:10,894 INFO org.apache.hadoop.yarn.server.resourcemanager.ApplicationMasterService: Registering app attempt : appattempt_1536878829533_0002_000001
2018-09-18 13:13:10,894 INFO org.apache.hadoop.yarn.server.resourcemanager.rmapp.attempt.RMAppAttemptImpl: appattempt_1536878829533_0002_000001 State change from NEW to SUBMITTED
2018-09-18 13:13:10,895 WARN org.apache.hadoop.yarn.server.resourcemanager.scheduler.capacity.LeafQueue: maximum-am-resource-percent is insufficient to start a single application in queue, it is likely set too low. skipping enforcement to allow at least one application to start
2018-09-18 13:13:10,895 WARN org.apache.hadoop.yarn.server.resourcemanager.scheduler.capacity.LeafQueue: maximum-am-resource-percent is insufficient to start a single application in queue for user, it is likely set too low. skipping enforcement to allow at least one application to start
2018-09-18 13:13:10,895 INFO org.apache.hadoop.yarn.server.resourcemanager.scheduler.capacity.LeafQueue: Application application_1536878829533_0002 from user: jason activated in queue: default
2018-09-18 13:13:10,895 INFO org.apache.hadoop.yarn.server.resourcemanager.scheduler.capacity.LeafQueue: Application added - appId: application_1536878829533_0002 user: jason, leaf-queue: default #user-pending-applications: 0 #user-active-applications: 1 #queue-pending-applications: 0 #queue-active-applications: 1
2018-09-18 13:13:10,895 INFO org.apache.hadoop.yarn.server.resourcemanager.scheduler.capacity.CapacityScheduler: Added Application Attempt appattempt_1536878829533_0002_000001 to scheduler from user jason in queue default
2018-09-18 13:13:10,896 INFO org.apache.hadoop.yarn.server.resourcemanager.rmapp.attempt.RMAppAttemptImpl: appattempt_1536878829533_0002_000001 State change from SUBMITTED to SCHEDULED
2018-09-18 13:13:11,808 INFO org.apache.hadoop.yarn.server.resourcemanager.rmcontainer.RMContainerImpl: container_1536878829533_0002_01_000001 Container Transitioned from NEW to ALLOCATED
2018-09-18 13:13:11,808 INFO org.apache.hadoop.yarn.server.resourcemanager.RMAuditLogger: USER=jason	OPERATION=AM Allocated Container	TARGET=SchedulerApp	RESULT=SUCCESS	APPID=application_1536878829533_0002	CONTAINERID=container_1536878829533_0002_01_000001
2018-09-18 13:13:11,808 INFO org.apache.hadoop.yarn.server.resourcemanager.scheduler.SchedulerNode: Assigned container container_1536878829533_0002_01_000001 of capacity <memory:2048, vCores:1> on host 192.168.1.103:56395, which has 1 containers, <memory:2048, vCores:1> used and <memory:6144, vCores:7> available after allocation
2018-09-18 13:13:11,808 INFO org.apache.hadoop.yarn.server.resourcemanager.scheduler.capacity.allocator.AbstractContainerAllocator: assignedContainer application attempt=appattempt_1536878829533_0002_000001 container=container_1536878829533_0002_01_000001 queue=org.apache.hadoop.yarn.server.resourcemanager.scheduler.capacity.allocator.RegularContainerAllocator@2595a1cc clusterResource=<memory:8192, vCores:8> type=OFF_SWITCH
2018-09-18 13:13:11,811 INFO org.apache.hadoop.yarn.server.resourcemanager.security.NMTokenSecretManagerInRM: Sending NMToken for nodeId : 192.168.1.103:56395 for container : container_1536878829533_0002_01_000001
2018-09-18 13:13:11,812 INFO org.apache.hadoop.yarn.server.resourcemanager.rmcontainer.RMContainerImpl: container_1536878829533_0002_01_000001 Container Transitioned from ALLOCATED to ACQUIRED
2018-09-18 13:13:11,812 INFO org.apache.hadoop.yarn.server.resourcemanager.security.NMTokenSecretManagerInRM: Clear node set for appattempt_1536878829533_0002_000001
2018-09-18 13:13:11,812 INFO org.apache.hadoop.yarn.server.resourcemanager.rmapp.attempt.RMAppAttemptImpl: Storing attempt: AppId: application_1536878829533_0002 AttemptId: appattempt_1536878829533_0002_000001 MasterContainer: Container: [ContainerId: container_1536878829533_0002_01_000001, Version: 0, NodeId: 192.168.1.103:56395, NodeHttpAddress: 192.168.1.103:8042, Resource: <memory:2048, vCores:1>, Priority: 0, Token: Token { kind: ContainerToken, service: 192.168.1.103:56395 }, ]
2018-09-18 13:13:11,812 INFO org.apache.hadoop.yarn.server.resourcemanager.scheduler.capacity.ParentQueue: Re-sorting assigned queue: root.default stats: default: capacity=1.0, absoluteCapacity=1.0, usedResources=<memory:2048, vCores:1>, usedCapacity=0.25, absoluteUsedCapacity=0.25, numApps=1, numContainers=1
2018-09-18 13:13:11,813 INFO org.apache.hadoop.yarn.server.resourcemanager.rmapp.attempt.RMAppAttemptImpl: appattempt_1536878829533_0002_000001 State change from SCHEDULED to ALLOCATED_SAVING
2018-09-18 13:13:11,813 INFO org.apache.hadoop.yarn.server.resourcemanager.rmapp.attempt.RMAppAttemptImpl: appattempt_1536878829533_0002_000001 State change from ALLOCATED_SAVING to ALLOCATED
2018-09-18 13:13:11,813 INFO org.apache.hadoop.yarn.server.resourcemanager.scheduler.capacity.ParentQueue: assignedContainer queue=root usedCapacity=0.25 absoluteUsedCapacity=0.25 used=<memory:2048, vCores:1> cluster=<memory:8192, vCores:8>
2018-09-18 13:13:11,813 INFO org.apache.hadoop.yarn.server.resourcemanager.amlauncher.AMLauncher: Launching masterappattempt_1536878829533_0002_000001
2018-09-18 13:13:11,815 INFO org.apache.hadoop.yarn.server.resourcemanager.amlauncher.AMLauncher: Setting up container Container: [ContainerId: container_1536878829533_0002_01_000001, Version: 0, NodeId: 192.168.1.103:56395, NodeHttpAddress: 192.168.1.103:8042, Resource: <memory:2048, vCores:1>, Priority: 0, Token: Token { kind: ContainerToken, service: 192.168.1.103:56395 }, ] for AM appattempt_1536878829533_0002_000001
2018-09-18 13:13:11,815 INFO org.apache.hadoop.yarn.server.resourcemanager.security.AMRMTokenSecretManager: Create AMRMToken for ApplicationAttempt: appattempt_1536878829533_0002_000001
2018-09-18 13:13:11,815 INFO org.apache.hadoop.yarn.server.resourcemanager.security.AMRMTokenSecretManager: Creating password for appattempt_1536878829533_0002_000001
2018-09-18 13:22:31,955 INFO org.apache.hadoop.yarn.server.resourcemanager.amlauncher.AMLauncher: Error launching appattempt_1536878829533_0002_000001. Got exception: org.apache.hadoop.net.ConnectTimeoutException: Call From Jasons-MBP.kc.umkc.edu/10.169.1.149 to 192.168.1.103:56395 failed on socket timeout exception: org.apache.hadoop.net.ConnectTimeoutException: 20000 millis timeout while waiting for channel to be ready for connect. ch : java.nio.channels.SocketChannel[connection-pending remote=192.168.1.103/192.168.1.103:56395]; For more details see:  http://wiki.apache.org/hadoop/SocketTimeout
	at sun.reflect.GeneratedConstructorAccessor54.newInstance(Unknown Source)
	at sun.reflect.DelegatingConstructorAccessorImpl.newInstance(DelegatingConstructorAccessorImpl.java:45)
	at java.lang.reflect.Constructor.newInstance(Constructor.java:423)
	at org.apache.hadoop.net.NetUtils.wrapWithMessage(NetUtils.java:801)
	at org.apache.hadoop.net.NetUtils.wrapException(NetUtils.java:751)
	at org.apache.hadoop.ipc.Client.getRpcResponse(Client.java:1485)
	at org.apache.hadoop.ipc.Client.call(Client.java:1427)
	at org.apache.hadoop.ipc.Client.call(Client.java:1337)
	at org.apache.hadoop.ipc.ProtobufRpcEngine$Invoker.invoke(ProtobufRpcEngine.java:227)
	at org.apache.hadoop.ipc.ProtobufRpcEngine$Invoker.invoke(ProtobufRpcEngine.java:116)
	at com.sun.proxy.$Proxy86.startContainers(Unknown Source)
	at org.apache.hadoop.yarn.api.impl.pb.client.ContainerManagementProtocolPBClientImpl.startContainers(ContainerManagementProtocolPBClientImpl.java:106)
	at sun.reflect.GeneratedMethodAccessor26.invoke(Unknown Source)
	at sun.reflect.DelegatingMethodAccessorImpl.invoke(DelegatingMethodAccessorImpl.java:43)
	at java.lang.reflect.Method.invoke(Method.java:498)
	at org.apache.hadoop.io.retry.RetryInvocationHandler.invokeMethod(RetryInvocationHandler.java:398)
	at org.apache.hadoop.io.retry.RetryInvocationHandler$Call.invokeMethod(RetryInvocationHandler.java:163)
	at org.apache.hadoop.io.retry.RetryInvocationHandler$Call.invoke(RetryInvocationHandler.java:155)
	at org.apache.hadoop.io.retry.RetryInvocationHandler$Call.invokeOnce(RetryInvocationHandler.java:95)
	at org.apache.hadoop.io.retry.RetryInvocationHandler.invoke(RetryInvocationHandler.java:335)
	at com.sun.proxy.$Proxy87.startContainers(Unknown Source)
	at org.apache.hadoop.yarn.server.resourcemanager.amlauncher.AMLauncher.launch(AMLauncher.java:119)
	at org.apache.hadoop.yarn.server.resourcemanager.amlauncher.AMLauncher.run(AMLauncher.java:250)
	at java.util.concurrent.ThreadPoolExecutor.runWorker(ThreadPoolExecutor.java:1149)
	at java.util.concurrent.ThreadPoolExecutor$Worker.run(ThreadPoolExecutor.java:624)
	at java.lang.Thread.run(Thread.java:748)
Caused by: org.apache.hadoop.net.ConnectTimeoutException: 20000 millis timeout while waiting for channel to be ready for connect. ch : java.nio.channels.SocketChannel[connection-pending remote=192.168.1.103/192.168.1.103:56395]
	at org.apache.hadoop.net.NetUtils.connect(NetUtils.java:534)
	at org.apache.hadoop.net.NetUtils.connect(NetUtils.java:495)
	at org.apache.hadoop.ipc.Client$Connection.setupConnection(Client.java:681)
	at org.apache.hadoop.ipc.Client$Connection.setupIOstreams(Client.java:777)
	at org.apache.hadoop.ipc.Client$Connection.access$3500(Client.java:409)
	at org.apache.hadoop.ipc.Client.getConnection(Client.java:1542)
	at org.apache.hadoop.ipc.Client.call(Client.java:1373)
	... 19 more

2018-09-18 13:22:31,961 INFO org.apache.hadoop.yarn.server.resourcemanager.rmapp.attempt.RMAppAttemptImpl: Updating application attempt appattempt_1536878829533_0002_000001 with final state: FAILED, and exit status: -1000
2018-09-18 13:22:31,961 INFO org.apache.hadoop.yarn.server.resourcemanager.rmapp.attempt.RMAppAttemptImpl: appattempt_1536878829533_0002_000001 State change from ALLOCATED to FINAL_SAVING
2018-09-18 13:22:31,961 INFO org.apache.hadoop.yarn.server.resourcemanager.ApplicationMasterService: Unregistering app attempt : appattempt_1536878829533_0002_000001
2018-09-18 13:22:31,961 INFO org.apache.hadoop.yarn.server.resourcemanager.security.AMRMTokenSecretManager: Application finished, removing password for appattempt_1536878829533_0002_000001
2018-09-18 13:22:31,961 INFO org.apache.hadoop.yarn.server.resourcemanager.rmapp.attempt.RMAppAttemptImpl: appattempt_1536878829533_0002_000001 State change from FINAL_SAVING to FAILED
2018-09-18 13:22:31,962 INFO org.apache.hadoop.yarn.server.resourcemanager.rmapp.RMAppImpl: The number of failed attempts is 1. The max attempts is 2
2018-09-18 13:22:31,962 INFO org.apache.hadoop.yarn.server.resourcemanager.ApplicationMasterService: Registering app attempt : appattempt_1536878829533_0002_000002
2018-09-18 13:22:31,962 INFO org.apache.hadoop.yarn.server.resourcemanager.rmapp.attempt.RMAppAttemptImpl: appattempt_1536878829533_0002_000002 State change from NEW to SUBMITTED
2018-09-18 13:22:31,962 INFO org.apache.hadoop.yarn.server.resourcemanager.scheduler.capacity.CapacityScheduler: Application Attempt appattempt_1536878829533_0002_000001 is done. finalState=FAILED
2018-09-18 13:22:31,963 INFO org.apache.hadoop.yarn.server.resourcemanager.rmcontainer.RMContainerImpl: container_1536878829533_0002_01_000001 Container Transitioned from ACQUIRED to KILLED
2018-09-18 13:22:31,963 INFO org.apache.hadoop.yarn.server.resourcemanager.RMAuditLogger: USER=jason	OPERATION=AM Released Container	TARGET=SchedulerApp	RESULT=SUCCESS	APPID=application_1536878829533_0002	CONTAINERID=container_1536878829533_0002_01_000001
2018-09-18 13:22:31,963 INFO org.apache.hadoop.yarn.server.resourcemanager.scheduler.SchedulerNode: Released container container_1536878829533_0002_01_000001 of capacity <memory:2048, vCores:1> on host 192.168.1.103:56395, which currently has 0 containers, <memory:0, vCores:0> used and <memory:8192, vCores:8> available, release resources=true
2018-09-18 13:22:31,964 INFO org.apache.hadoop.yarn.server.resourcemanager.scheduler.AppSchedulingInfo: Application application_1536878829533_0002 requests cleared
2018-09-18 13:22:31,964 INFO org.apache.hadoop.yarn.server.resourcemanager.scheduler.capacity.LeafQueue: Application removed - appId: application_1536878829533_0002 user: jason queue: default #user-pending-applications: 0 #user-active-applications: 0 #queue-pending-applications: 0 #queue-active-applications: 0
2018-09-18 13:22:31,964 WARN org.apache.hadoop.yarn.server.resourcemanager.scheduler.capacity.LeafQueue: maximum-am-resource-percent is insufficient to start a single application in queue, it is likely set too low. skipping enforcement to allow at least one application to start
2018-09-18 13:22:31,964 WARN org.apache.hadoop.yarn.server.resourcemanager.scheduler.capacity.LeafQueue: maximum-am-resource-percent is insufficient to start a single application in queue for user, it is likely set too low. skipping enforcement to allow at least one application to start
2018-09-18 13:22:31,964 INFO org.apache.hadoop.yarn.server.resourcemanager.scheduler.capacity.LeafQueue: Application application_1536878829533_0002 from user: jason activated in queue: default
2018-09-18 13:22:31,964 INFO org.apache.hadoop.yarn.server.resourcemanager.scheduler.capacity.LeafQueue: Application added - appId: application_1536878829533_0002 user: jason, leaf-queue: default #user-pending-applications: 0 #user-active-applications: 1 #queue-pending-applications: 0 #queue-active-applications: 1
2018-09-18 13:22:31,964 INFO org.apache.hadoop.yarn.server.resourcemanager.scheduler.capacity.CapacityScheduler: Added Application Attempt appattempt_1536878829533_0002_000002 to scheduler from user jason in queue default
2018-09-18 13:22:31,965 INFO org.apache.hadoop.yarn.server.resourcemanager.rmapp.attempt.RMAppAttemptImpl: appattempt_1536878829533_0002_000002 State change from SUBMITTED to SCHEDULED
2018-09-18 13:22:32,491 INFO org.apache.hadoop.yarn.server.resourcemanager.rmcontainer.RMContainerImpl: container_1536878829533_0002_02_000001 Container Transitioned from NEW to ALLOCATED
2018-09-18 13:22:32,492 INFO org.apache.hadoop.yarn.server.resourcemanager.RMAuditLogger: USER=jason	OPERATION=AM Allocated Container	TARGET=SchedulerApp	RESULT=SUCCESS	APPID=application_1536878829533_0002	CONTAINERID=container_1536878829533_0002_02_000001
2018-09-18 13:22:32,492 INFO org.apache.hadoop.yarn.server.resourcemanager.scheduler.SchedulerNode: Assigned container container_1536878829533_0002_02_000001 of capacity <memory:2048, vCores:1> on host 192.168.1.103:56395, which has 1 containers, <memory:2048, vCores:1> used and <memory:6144, vCores:7> available after allocation
2018-09-18 13:22:32,492 INFO org.apache.hadoop.yarn.server.resourcemanager.scheduler.capacity.allocator.AbstractContainerAllocator: assignedContainer application attempt=appattempt_1536878829533_0002_000002 container=container_1536878829533_0002_02_000001 queue=org.apache.hadoop.yarn.server.resourcemanager.scheduler.capacity.allocator.RegularContainerAllocator@427c8b6f clusterResource=<memory:8192, vCores:8> type=OFF_SWITCH
2018-09-18 13:22:32,493 INFO org.apache.hadoop.yarn.server.resourcemanager.security.NMTokenSecretManagerInRM: Sending NMToken for nodeId : 192.168.1.103:56395 for container : container_1536878829533_0002_02_000001
2018-09-18 13:22:32,494 INFO org.apache.hadoop.yarn.server.resourcemanager.rmcontainer.RMContainerImpl: container_1536878829533_0002_02_000001 Container Transitioned from ALLOCATED to ACQUIRED
2018-09-18 13:22:32,494 INFO org.apache.hadoop.yarn.server.resourcemanager.security.NMTokenSecretManagerInRM: Clear node set for appattempt_1536878829533_0002_000002
2018-09-18 13:22:32,494 INFO org.apache.hadoop.yarn.server.resourcemanager.rmapp.attempt.RMAppAttemptImpl: Storing attempt: AppId: application_1536878829533_0002 AttemptId: appattempt_1536878829533_0002_000002 MasterContainer: Container: [ContainerId: container_1536878829533_0002_02_000001, Version: 0, NodeId: 192.168.1.103:56395, NodeHttpAddress: 192.168.1.103:8042, Resource: <memory:2048, vCores:1>, Priority: 0, Token: Token { kind: ContainerToken, service: 192.168.1.103:56395 }, ]
2018-09-18 13:22:32,494 INFO org.apache.hadoop.yarn.server.resourcemanager.scheduler.capacity.ParentQueue: Re-sorting assigned queue: root.default stats: default: capacity=1.0, absoluteCapacity=1.0, usedResources=<memory:2048, vCores:1>, usedCapacity=0.25, absoluteUsedCapacity=0.25, numApps=1, numContainers=1
2018-09-18 13:22:32,494 INFO org.apache.hadoop.yarn.server.resourcemanager.rmapp.attempt.RMAppAttemptImpl: appattempt_1536878829533_0002_000002 State change from SCHEDULED to ALLOCATED_SAVING
2018-09-18 13:22:32,495 INFO org.apache.hadoop.yarn.server.resourcemanager.scheduler.capacity.ParentQueue: assignedContainer queue=root usedCapacity=0.25 absoluteUsedCapacity=0.25 used=<memory:2048, vCores:1> cluster=<memory:8192, vCores:8>
2018-09-18 13:22:32,495 INFO org.apache.hadoop.yarn.server.resourcemanager.rmapp.attempt.RMAppAttemptImpl: appattempt_1536878829533_0002_000002 State change from ALLOCATED_SAVING to ALLOCATED
2018-09-18 13:22:32,495 INFO org.apache.hadoop.yarn.server.resourcemanager.amlauncher.AMLauncher: Launching masterappattempt_1536878829533_0002_000002
2018-09-18 13:22:32,499 INFO org.apache.hadoop.yarn.server.resourcemanager.amlauncher.AMLauncher: Setting up container Container: [ContainerId: container_1536878829533_0002_02_000001, Version: 0, NodeId: 192.168.1.103:56395, NodeHttpAddress: 192.168.1.103:8042, Resource: <memory:2048, vCores:1>, Priority: 0, Token: Token { kind: ContainerToken, service: 192.168.1.103:56395 }, ] for AM appattempt_1536878829533_0002_000002
2018-09-18 13:22:32,500 INFO org.apache.hadoop.yarn.server.resourcemanager.security.AMRMTokenSecretManager: Create AMRMToken for ApplicationAttempt: appattempt_1536878829533_0002_000002
2018-09-18 13:22:32,500 INFO org.apache.hadoop.yarn.server.resourcemanager.security.AMRMTokenSecretManager: Creating password for appattempt_1536878829533_0002_000002
2018-09-18 13:26:30,600 INFO org.apache.hadoop.ipc.Server: Socket Reader #1 for port 8031: readAndProcess from client 192.168.1.103 threw exception [java.io.IOException: Operation timed out]
java.io.IOException: Operation timed out
	at sun.nio.ch.FileDispatcherImpl.read0(Native Method)
	at sun.nio.ch.SocketDispatcher.read(SocketDispatcher.java:39)
	at sun.nio.ch.IOUtil.readIntoNativeBuffer(IOUtil.java:223)
	at sun.nio.ch.IOUtil.read(IOUtil.java:197)
	at sun.nio.ch.SocketChannelImpl.read(SocketChannelImpl.java:380)
	at org.apache.hadoop.ipc.Server.channelRead(Server.java:3020)
	at org.apache.hadoop.ipc.Server.access$2400(Server.java:134)
	at org.apache.hadoop.ipc.Server$Connection.readAndProcess(Server.java:1869)
	at org.apache.hadoop.ipc.Server$Listener.doRead(Server.java:1125)
	at org.apache.hadoop.ipc.Server$Listener$Reader.doRunLoop(Server.java:982)
	at org.apache.hadoop.ipc.Server$Listener$Reader.run(Server.java:953)
2018-09-18 13:31:52,622 INFO org.apache.hadoop.yarn.server.resourcemanager.amlauncher.AMLauncher: Error launching appattempt_1536878829533_0002_000002. Got exception: org.apache.hadoop.net.ConnectTimeoutException: Call From Jasons-MBP.kc.umkc.edu/10.169.1.149 to 192.168.1.103:56395 failed on socket timeout exception: org.apache.hadoop.net.ConnectTimeoutException: 20000 millis timeout while waiting for channel to be ready for connect. ch : java.nio.channels.SocketChannel[connection-pending remote=192.168.1.103/192.168.1.103:56395]; For more details see:  http://wiki.apache.org/hadoop/SocketTimeout
	at sun.reflect.GeneratedConstructorAccessor54.newInstance(Unknown Source)
	at sun.reflect.DelegatingConstructorAccessorImpl.newInstance(DelegatingConstructorAccessorImpl.java:45)
	at java.lang.reflect.Constructor.newInstance(Constructor.java:423)
	at org.apache.hadoop.net.NetUtils.wrapWithMessage(NetUtils.java:801)
	at org.apache.hadoop.net.NetUtils.wrapException(NetUtils.java:751)
	at org.apache.hadoop.ipc.Client.getRpcResponse(Client.java:1485)
	at org.apache.hadoop.ipc.Client.call(Client.java:1427)
	at org.apache.hadoop.ipc.Client.call(Client.java:1337)
	at org.apache.hadoop.ipc.ProtobufRpcEngine$Invoker.invoke(ProtobufRpcEngine.java:227)
	at org.apache.hadoop.ipc.ProtobufRpcEngine$Invoker.invoke(ProtobufRpcEngine.java:116)
	at com.sun.proxy.$Proxy86.startContainers(Unknown Source)
	at org.apache.hadoop.yarn.api.impl.pb.client.ContainerManagementProtocolPBClientImpl.startContainers(ContainerManagementProtocolPBClientImpl.java:106)
	at sun.reflect.GeneratedMethodAccessor26.invoke(Unknown Source)
	at sun.reflect.DelegatingMethodAccessorImpl.invoke(DelegatingMethodAccessorImpl.java:43)
	at java.lang.reflect.Method.invoke(Method.java:498)
	at org.apache.hadoop.io.retry.RetryInvocationHandler.invokeMethod(RetryInvocationHandler.java:398)
	at org.apache.hadoop.io.retry.RetryInvocationHandler$Call.invokeMethod(RetryInvocationHandler.java:163)
	at org.apache.hadoop.io.retry.RetryInvocationHandler$Call.invoke(RetryInvocationHandler.java:155)
	at org.apache.hadoop.io.retry.RetryInvocationHandler$Call.invokeOnce(RetryInvocationHandler.java:95)
	at org.apache.hadoop.io.retry.RetryInvocationHandler.invoke(RetryInvocationHandler.java:335)
	at com.sun.proxy.$Proxy87.startContainers(Unknown Source)
	at org.apache.hadoop.yarn.server.resourcemanager.amlauncher.AMLauncher.launch(AMLauncher.java:119)
	at org.apache.hadoop.yarn.server.resourcemanager.amlauncher.AMLauncher.run(AMLauncher.java:250)
	at java.util.concurrent.ThreadPoolExecutor.runWorker(ThreadPoolExecutor.java:1149)
	at java.util.concurrent.ThreadPoolExecutor$Worker.run(ThreadPoolExecutor.java:624)
	at java.lang.Thread.run(Thread.java:748)
Caused by: org.apache.hadoop.net.ConnectTimeoutException: 20000 millis timeout while waiting for channel to be ready for connect. ch : java.nio.channels.SocketChannel[connection-pending remote=192.168.1.103/192.168.1.103:56395]
	at org.apache.hadoop.net.NetUtils.connect(NetUtils.java:534)
	at org.apache.hadoop.net.NetUtils.connect(NetUtils.java:495)
	at org.apache.hadoop.ipc.Client$Connection.setupConnection(Client.java:681)
	at org.apache.hadoop.ipc.Client$Connection.setupIOstreams(Client.java:777)
	at org.apache.hadoop.ipc.Client$Connection.access$3500(Client.java:409)
	at org.apache.hadoop.ipc.Client.getConnection(Client.java:1542)
	at org.apache.hadoop.ipc.Client.call(Client.java:1373)
	... 19 more

2018-09-18 13:31:52,623 INFO org.apache.hadoop.yarn.server.resourcemanager.rmapp.attempt.RMAppAttemptImpl: Updating application attempt appattempt_1536878829533_0002_000002 with final state: FAILED, and exit status: -1000
2018-09-18 13:31:52,623 INFO org.apache.hadoop.yarn.server.resourcemanager.rmapp.attempt.RMAppAttemptImpl: appattempt_1536878829533_0002_000002 State change from ALLOCATED to FINAL_SAVING
2018-09-18 13:31:52,623 INFO org.apache.hadoop.yarn.server.resourcemanager.ApplicationMasterService: Unregistering app attempt : appattempt_1536878829533_0002_000002
2018-09-18 13:31:52,623 INFO org.apache.hadoop.yarn.server.resourcemanager.security.AMRMTokenSecretManager: Application finished, removing password for appattempt_1536878829533_0002_000002
2018-09-18 13:31:52,623 INFO org.apache.hadoop.yarn.server.resourcemanager.rmapp.attempt.RMAppAttemptImpl: appattempt_1536878829533_0002_000002 State change from FINAL_SAVING to FAILED
2018-09-18 13:31:52,623 INFO org.apache.hadoop.yarn.server.resourcemanager.rmapp.RMAppImpl: The number of failed attempts is 2. The max attempts is 2
2018-09-18 13:31:52,624 INFO org.apache.hadoop.yarn.server.resourcemanager.rmapp.RMAppImpl: Updating application application_1536878829533_0002 with final state: FAILED
2018-09-18 13:31:52,624 INFO org.apache.hadoop.yarn.server.resourcemanager.rmapp.RMAppImpl: application_1536878829533_0002 State change from ACCEPTED to FINAL_SAVING on event=ATTEMPT_FAILED
2018-09-18 13:31:52,624 INFO org.apache.hadoop.yarn.server.resourcemanager.recovery.RMStateStore: Updating info for app: application_1536878829533_0002
2018-09-18 13:31:52,624 INFO org.apache.hadoop.yarn.server.resourcemanager.scheduler.capacity.CapacityScheduler: Application Attempt appattempt_1536878829533_0002_000002 is done. finalState=FAILED
2018-09-18 13:31:52,625 INFO org.apache.hadoop.yarn.server.resourcemanager.rmcontainer.RMContainerImpl: container_1536878829533_0002_02_000001 Container Transitioned from ACQUIRED to KILLED
2018-09-18 13:31:52,625 INFO org.apache.hadoop.yarn.server.resourcemanager.RMAuditLogger: USER=jason	OPERATION=AM Released Container	TARGET=SchedulerApp	RESULT=SUCCESS	APPID=application_1536878829533_0002	CONTAINERID=container_1536878829533_0002_02_000001
2018-09-18 13:31:52,625 INFO org.apache.hadoop.yarn.server.resourcemanager.rmapp.RMAppImpl: Application application_1536878829533_0002 failed 2 times due to Error launching appattempt_1536878829533_0002_000002. Got exception: org.apache.hadoop.net.ConnectTimeoutException: Call From Jasons-MBP.kc.umkc.edu/10.169.1.149 to 192.168.1.103:56395 failed on socket timeout exception: org.apache.hadoop.net.ConnectTimeoutException: 20000 millis timeout while waiting for channel to be ready for connect. ch : java.nio.channels.SocketChannel[connection-pending remote=192.168.1.103/192.168.1.103:56395]; For more details see:  http://wiki.apache.org/hadoop/SocketTimeout
	at sun.reflect.GeneratedConstructorAccessor54.newInstance(Unknown Source)
	at sun.reflect.DelegatingConstructorAccessorImpl.newInstance(DelegatingConstructorAccessorImpl.java:45)
	at java.lang.reflect.Constructor.newInstance(Constructor.java:423)
	at org.apache.hadoop.net.NetUtils.wrapWithMessage(NetUtils.java:801)
	at org.apache.hadoop.net.NetUtils.wrapException(NetUtils.java:751)
	at org.apache.hadoop.ipc.Client.getRpcResponse(Client.java:1485)
	at org.apache.hadoop.ipc.Client.call(Client.java:1427)
	at org.apache.hadoop.ipc.Client.call(Client.java:1337)
	at org.apache.hadoop.ipc.ProtobufRpcEngine$Invoker.invoke(ProtobufRpcEngine.java:227)
	at org.apache.hadoop.ipc.ProtobufRpcEngine$Invoker.invoke(ProtobufRpcEngine.java:116)
	at com.sun.proxy.$Proxy86.startContainers(Unknown Source)
	at org.apache.hadoop.yarn.api.impl.pb.client.ContainerManagementProtocolPBClientImpl.startContainers(ContainerManagementProtocolPBClientImpl.java:106)
	at sun.reflect.GeneratedMethodAccessor26.invoke(Unknown Source)
	at sun.reflect.DelegatingMethodAccessorImpl.invoke(DelegatingMethodAccessorImpl.java:43)
	at java.lang.reflect.Method.invoke(Method.java:498)
	at org.apache.hadoop.io.retry.RetryInvocationHandler.invokeMethod(RetryInvocationHandler.java:398)
	at org.apache.hadoop.io.retry.RetryInvocationHandler$Call.invokeMethod(RetryInvocationHandler.java:163)
	at org.apache.hadoop.io.retry.RetryInvocationHandler$Call.invoke(RetryInvocationHandler.java:155)
	at org.apache.hadoop.io.retry.RetryInvocationHandler$Call.invokeOnce(RetryInvocationHandler.java:95)
	at org.apache.hadoop.io.retry.RetryInvocationHandler.invoke(RetryInvocationHandler.java:335)
	at com.sun.proxy.$Proxy87.startContainers(Unknown Source)
	at org.apache.hadoop.yarn.server.resourcemanager.amlauncher.AMLauncher.launch(AMLauncher.java:119)
	at org.apache.hadoop.yarn.server.resourcemanager.amlauncher.AMLauncher.run(AMLauncher.java:250)
	at java.util.concurrent.ThreadPoolExecutor.runWorker(ThreadPoolExecutor.java:1149)
	at java.util.concurrent.ThreadPoolExecutor$Worker.run(ThreadPoolExecutor.java:624)
	at java.lang.Thread.run(Thread.java:748)
Caused by: org.apache.hadoop.net.ConnectTimeoutException: 20000 millis timeout while waiting for channel to be ready for connect. ch : java.nio.channels.SocketChannel[connection-pending remote=192.168.1.103/192.168.1.103:56395]
	at org.apache.hadoop.net.NetUtils.connect(NetUtils.java:534)
	at org.apache.hadoop.net.NetUtils.connect(NetUtils.java:495)
	at org.apache.hadoop.ipc.Client$Connection.setupConnection(Client.java:681)
	at org.apache.hadoop.ipc.Client$Connection.setupIOstreams(Client.java:777)
	at org.apache.hadoop.ipc.Client$Connection.access$3500(Client.java:409)
	at org.apache.hadoop.ipc.Client.getConnection(Client.java:1542)
	at org.apache.hadoop.ipc.Client.call(Client.java:1373)
	... 19 more
. Failing the application.
2018-09-18 13:31:52,625 INFO org.apache.hadoop.yarn.server.resourcemanager.scheduler.SchedulerNode: Released container container_1536878829533_0002_02_000001 of capacity <memory:2048, vCores:1> on host 192.168.1.103:56395, which currently has 0 containers, <memory:0, vCores:0> used and <memory:8192, vCores:8> available, release resources=true
2018-09-18 13:31:52,625 INFO org.apache.hadoop.yarn.server.resourcemanager.rmapp.RMAppImpl: application_1536878829533_0002 State change from FINAL_SAVING to FAILED on event=APP_UPDATE_SAVED
2018-09-18 13:31:52,626 INFO org.apache.hadoop.yarn.server.resourcemanager.scheduler.AppSchedulingInfo: Application application_1536878829533_0002 requests cleared
2018-09-18 13:31:52,626 WARN org.apache.hadoop.yarn.server.resourcemanager.RMAuditLogger: USER=jason	OPERATION=Application Finished - Failed	TARGET=RMAppManager	RESULT=FAILURE	DESCRIPTION=App failed with state: FAILED	PERMISSIONS=Application application_1536878829533_0002 failed 2 times due to Error launching appattempt_1536878829533_0002_000002. Got exception: org.apache.hadoop.net.ConnectTimeoutException: Call From Jasons-MBP.kc.umkc.edu/10.169.1.149 to 192.168.1.103:56395 failed on socket timeout exception: org.apache.hadoop.net.ConnectTimeoutException: 20000 millis timeout while waiting for channel to be ready for connect. ch : java.nio.channels.SocketChannel[connection-pending remote=192.168.1.103/192.168.1.103:56395]; For more details see:  http://wiki.apache.org/hadoop/SocketTimeout
	at sun.reflect.GeneratedConstructorAccessor54.newInstance(Unknown Source)
	at sun.reflect.DelegatingConstructorAccessorImpl.newInstance(DelegatingConstructorAccessorImpl.java:45)
	at java.lang.reflect.Constructor.newInstance(Constructor.java:423)
	at org.apache.hadoop.net.NetUtils.wrapWithMessage(NetUtils.java:801)
	at org.apache.hadoop.net.NetUtils.wrapException(NetUtils.java:751)
	at org.apache.hadoop.ipc.Client.getRpcResponse(Client.java:1485)
	at org.apache.hadoop.ipc.Client.call(Client.java:1427)
	at org.apache.hadoop.ipc.Client.call(Client.java:1337)
	at org.apache.hadoop.ipc.ProtobufRpcEngine$Invoker.invoke(ProtobufRpcEngine.java:227)
	at org.apache.hadoop.ipc.ProtobufRpcEngine$Invoker.invoke(ProtobufRpcEngine.java:116)
	at com.sun.proxy.$Proxy86.startContainers(Unknown Source)
	at org.apache.hadoop.yarn.api.impl.pb.client.ContainerManagementProtocolPBClientImpl.startContainers(ContainerManagementProtocolPBClientImpl.java:106)
	at sun.reflect.GeneratedMethodAccessor26.invoke(Unknown Source)
	at sun.reflect.DelegatingMethodAccessorImpl.invoke(DelegatingMethodAccessorImpl.java:43)
	at java.lang.reflect.Method.invoke(Method.java:498)
	at org.apache.hadoop.io.retry.RetryInvocationHandler.invokeMethod(RetryInvocationHandler.java:398)
	at org.apache.hadoop.io.retry.RetryInvocationHandler$Call.invokeMethod(RetryInvocationHandler.java:163)
	at org.apache.hadoop.io.retry.RetryInvocationHandler$Call.invoke(RetryInvocationHandler.java:155)
	at org.apache.hadoop.io.retry.RetryInvocationHandler$Call.invokeOnce(RetryInvocationHandler.java:95)
	at org.apache.hadoop.io.retry.RetryInvocationHandler.invoke(RetryInvocationHandler.java:335)
	at com.sun.proxy.$Proxy87.startContainers(Unknown Source)
	at org.apache.hadoop.yarn.server.resourcemanager.amlauncher.AMLauncher.launch(AMLauncher.java:119)
	at org.apache.hadoop.yarn.server.resourcemanager.amlauncher.AMLauncher.run(AMLauncher.java:250)
	at java.util.concurrent.ThreadPoolExecutor.runWorker(ThreadPoolExecutor.java:1149)
	at java.util.concurrent.ThreadPoolExecutor$Worker.run(ThreadPoolExecutor.java:624)
	at java.lang.Thread.run(Thread.java:748)
Caused by: org.apache.hadoop.net.ConnectTimeoutException: 20000 millis timeout while waiting for channel to be ready for connect. ch : java.nio.channels.SocketChannel[connection-pending remote=192.168.1.103/192.168.1.103:56395]
	at org.apache.hadoop.net.NetUtils.connect(NetUtils.java:534)
	at org.apache.hadoop.net.NetUtils.connect(NetUtils.java:495)
	at org.apache.hadoop.ipc.Client$Connection.setupConnection(Client.java:681)
	at org.apache.hadoop.ipc.Client$Connection.setupIOstreams(Client.java:777)
	at org.apache.hadoop.ipc.Client$Connection.access$3500(Client.java:409)
	at org.apache.hadoop.ipc.Client.getConnection(Client.java:1542)
	at org.apache.hadoop.ipc.Client.call(Client.java:1373)
	... 19 more
. Failing the application.	APPID=application_1536878829533_0002
2018-09-18 13:31:52,626 INFO org.apache.hadoop.yarn.server.resourcemanager.scheduler.capacity.LeafQueue: Application removed - appId: application_1536878829533_0002 user: jason queue: default #user-pending-applications: 0 #user-active-applications: 0 #queue-pending-applications: 0 #queue-active-applications: 0
2018-09-18 13:31:52,626 INFO org.apache.hadoop.yarn.server.resourcemanager.scheduler.capacity.ParentQueue: Application removed - appId: application_1536878829533_0002 user: jason leaf-queue of parent: root #applications: 0
2018-09-18 13:31:52,626 INFO org.apache.hadoop.yarn.server.resourcemanager.RMAppManager$ApplicationSummary: appId=application_1536878829533_0002,name=word count,user=jason,queue=default,state=FAILED,trackingUrl=http://Jasons-MBP.kc.umkc.edu:8088/cluster/app/application_1536878829533_0002,appMasterHost=N/A,startTime=1537294390891,finishTime=1537295512624,finalStatus=FAILED,memorySeconds=2294353,vcoreSeconds=1120,preemptedMemorySeconds=0,preemptedVcoreSeconds=0,preemptedAMContainers=0,preemptedNonAMContainers=0,preemptedResources=<memory:0\, vCores:0>,applicationType=MAPREDUCE
2018-09-18 13:33:30,620 INFO org.apache.hadoop.yarn.server.resourcemanager.ClientRMService: Allocated new applicationId: 3
2018-09-18 13:33:31,111 INFO org.apache.hadoop.yarn.server.resourcemanager.scheduler.capacity.CapacityScheduler: Application 'application_1536878829533_0003' is submitted without priority hence considering default queue/cluster priority: 0
2018-09-18 13:33:31,111 INFO org.apache.hadoop.yarn.server.resourcemanager.scheduler.capacity.CapacityScheduler: Priority '0' is acceptable in queue : default for application: application_1536878829533_0003 for the user: jason
2018-09-18 13:33:31,111 INFO org.apache.hadoop.yarn.server.resourcemanager.ClientRMService: Application with id 3 submitted by user jason
2018-09-18 13:33:31,111 INFO org.apache.hadoop.yarn.server.resourcemanager.RMAuditLogger: USER=jason	IP=10.169.1.149	OPERATION=Submit Application Request	TARGET=ClientRMService	RESULT=SUCCESS	APPID=application_1536878829533_0003
2018-09-18 13:33:31,111 INFO org.apache.hadoop.yarn.server.resourcemanager.rmapp.RMAppImpl: Storing application with id application_1536878829533_0003
2018-09-18 13:33:31,111 INFO org.apache.hadoop.yarn.server.resourcemanager.rmapp.RMAppImpl: application_1536878829533_0003 State change from NEW to NEW_SAVING on event=START
2018-09-18 13:33:31,111 INFO org.apache.hadoop.yarn.server.resourcemanager.recovery.RMStateStore: Storing info for app: application_1536878829533_0003
2018-09-18 13:33:31,112 INFO org.apache.hadoop.yarn.server.resourcemanager.rmapp.RMAppImpl: application_1536878829533_0003 State change from NEW_SAVING to SUBMITTED on event=APP_NEW_SAVED
2018-09-18 13:33:31,112 INFO org.apache.hadoop.yarn.server.resourcemanager.scheduler.capacity.ParentQueue: Application added - appId: application_1536878829533_0003 user: jason leaf-queue of parent: root #applications: 1
2018-09-18 13:33:31,112 INFO org.apache.hadoop.yarn.server.resourcemanager.scheduler.capacity.CapacityScheduler: Accepted application application_1536878829533_0003 from user: jason, in queue: default
2018-09-18 13:33:31,114 INFO org.apache.hadoop.yarn.server.resourcemanager.rmapp.RMAppImpl: application_1536878829533_0003 State change from SUBMITTED to ACCEPTED on event=APP_ACCEPTED
2018-09-18 13:33:31,114 INFO org.apache.hadoop.yarn.server.resourcemanager.ApplicationMasterService: Registering app attempt : appattempt_1536878829533_0003_000001
2018-09-18 13:33:31,114 INFO org.apache.hadoop.yarn.server.resourcemanager.rmapp.attempt.RMAppAttemptImpl: appattempt_1536878829533_0003_000001 State change from NEW to SUBMITTED
2018-09-18 13:33:31,114 WARN org.apache.hadoop.yarn.server.resourcemanager.scheduler.capacity.LeafQueue: maximum-am-resource-percent is insufficient to start a single application in queue, it is likely set too low. skipping enforcement to allow at least one application to start
2018-09-18 13:33:31,114 WARN org.apache.hadoop.yarn.server.resourcemanager.scheduler.capacity.LeafQueue: maximum-am-resource-percent is insufficient to start a single application in queue for user, it is likely set too low. skipping enforcement to allow at least one application to start
2018-09-18 13:33:31,114 INFO org.apache.hadoop.yarn.server.resourcemanager.scheduler.capacity.LeafQueue: Application application_1536878829533_0003 from user: jason activated in queue: default
2018-09-18 13:33:31,114 INFO org.apache.hadoop.yarn.server.resourcemanager.scheduler.capacity.LeafQueue: Application added - appId: application_1536878829533_0003 user: jason, leaf-queue: default #user-pending-applications: 0 #user-active-applications: 1 #queue-pending-applications: 0 #queue-active-applications: 1
2018-09-18 13:33:31,114 INFO org.apache.hadoop.yarn.server.resourcemanager.scheduler.capacity.CapacityScheduler: Added Application Attempt appattempt_1536878829533_0003_000001 to scheduler from user jason in queue default
2018-09-18 13:33:31,115 INFO org.apache.hadoop.yarn.server.resourcemanager.rmapp.attempt.RMAppAttemptImpl: appattempt_1536878829533_0003_000001 State change from SUBMITTED to SCHEDULED
2018-09-18 13:33:31,392 INFO org.apache.hadoop.yarn.server.resourcemanager.rmcontainer.RMContainerImpl: container_1536878829533_0003_01_000001 Container Transitioned from NEW to ALLOCATED
2018-09-18 13:33:31,392 INFO org.apache.hadoop.yarn.server.resourcemanager.RMAuditLogger: USER=jason	OPERATION=AM Allocated Container	TARGET=SchedulerApp	RESULT=SUCCESS	APPID=application_1536878829533_0003	CONTAINERID=container_1536878829533_0003_01_000001
2018-09-18 13:33:31,392 INFO org.apache.hadoop.yarn.server.resourcemanager.scheduler.SchedulerNode: Assigned container container_1536878829533_0003_01_000001 of capacity <memory:2048, vCores:1> on host 192.168.1.103:56395, which has 1 containers, <memory:2048, vCores:1> used and <memory:6144, vCores:7> available after allocation
2018-09-18 13:33:31,393 INFO org.apache.hadoop.yarn.server.resourcemanager.scheduler.capacity.allocator.AbstractContainerAllocator: assignedContainer application attempt=appattempt_1536878829533_0003_000001 container=container_1536878829533_0003_01_000001 queue=org.apache.hadoop.yarn.server.resourcemanager.scheduler.capacity.allocator.RegularContainerAllocator@748bd187 clusterResource=<memory:8192, vCores:8> type=OFF_SWITCH
2018-09-18 13:33:31,393 INFO org.apache.hadoop.yarn.server.resourcemanager.security.NMTokenSecretManagerInRM: Sending NMToken for nodeId : 192.168.1.103:56395 for container : container_1536878829533_0003_01_000001
2018-09-18 13:33:31,394 INFO org.apache.hadoop.yarn.server.resourcemanager.rmcontainer.RMContainerImpl: container_1536878829533_0003_01_000001 Container Transitioned from ALLOCATED to ACQUIRED
2018-09-18 13:33:31,394 INFO org.apache.hadoop.yarn.server.resourcemanager.security.NMTokenSecretManagerInRM: Clear node set for appattempt_1536878829533_0003_000001
2018-09-18 13:33:31,394 INFO org.apache.hadoop.yarn.server.resourcemanager.rmapp.attempt.RMAppAttemptImpl: Storing attempt: AppId: application_1536878829533_0003 AttemptId: appattempt_1536878829533_0003_000001 MasterContainer: Container: [ContainerId: container_1536878829533_0003_01_000001, Version: 0, NodeId: 192.168.1.103:56395, NodeHttpAddress: 192.168.1.103:8042, Resource: <memory:2048, vCores:1>, Priority: 0, Token: Token { kind: ContainerToken, service: 192.168.1.103:56395 }, ]
2018-09-18 13:33:31,394 INFO org.apache.hadoop.yarn.server.resourcemanager.scheduler.capacity.ParentQueue: Re-sorting assigned queue: root.default stats: default: capacity=1.0, absoluteCapacity=1.0, usedResources=<memory:2048, vCores:1>, usedCapacity=0.25, absoluteUsedCapacity=0.25, numApps=1, numContainers=1
2018-09-18 13:33:31,394 INFO org.apache.hadoop.yarn.server.resourcemanager.rmapp.attempt.RMAppAttemptImpl: appattempt_1536878829533_0003_000001 State change from SCHEDULED to ALLOCATED_SAVING
2018-09-18 13:33:31,394 INFO org.apache.hadoop.yarn.server.resourcemanager.scheduler.capacity.ParentQueue: assignedContainer queue=root usedCapacity=0.25 absoluteUsedCapacity=0.25 used=<memory:2048, vCores:1> cluster=<memory:8192, vCores:8>
2018-09-18 13:33:31,394 INFO org.apache.hadoop.yarn.server.resourcemanager.rmapp.attempt.RMAppAttemptImpl: appattempt_1536878829533_0003_000001 State change from ALLOCATED_SAVING to ALLOCATED
2018-09-18 13:33:31,395 INFO org.apache.hadoop.yarn.server.resourcemanager.amlauncher.AMLauncher: Launching masterappattempt_1536878829533_0003_000001
2018-09-18 13:33:31,396 INFO org.apache.hadoop.yarn.server.resourcemanager.amlauncher.AMLauncher: Setting up container Container: [ContainerId: container_1536878829533_0003_01_000001, Version: 0, NodeId: 192.168.1.103:56395, NodeHttpAddress: 192.168.1.103:8042, Resource: <memory:2048, vCores:1>, Priority: 0, Token: Token { kind: ContainerToken, service: 192.168.1.103:56395 }, ] for AM appattempt_1536878829533_0003_000001
2018-09-18 13:33:31,397 INFO org.apache.hadoop.yarn.server.resourcemanager.security.AMRMTokenSecretManager: Create AMRMToken for ApplicationAttempt: appattempt_1536878829533_0003_000001
2018-09-18 13:33:31,397 INFO org.apache.hadoop.yarn.server.resourcemanager.security.AMRMTokenSecretManager: Creating password for appattempt_1536878829533_0003_000001
2018-09-18 13:35:05,816 INFO org.apache.hadoop.yarn.server.resourcemanager.RMAuditLogger: USER=dr.who	OPERATION=Kill Application Request	TARGET=RMAppImpl	RESULT=SUCCESS	APPID=application_1536878829533_0003
2018-09-18 13:35:05,816 INFO org.apache.hadoop.yarn.server.resourcemanager.rmapp.RMAppImpl: application_1536878829533_0003 State change from ACCEPTED to KILLING on event=KILL
2018-09-18 13:35:05,817 INFO org.apache.hadoop.yarn.server.resourcemanager.rmapp.attempt.RMAppAttemptImpl: Updating application attempt appattempt_1536878829533_0003_000001 with final state: KILLED, and exit status: -1000
2018-09-18 13:35:05,817 INFO org.apache.hadoop.yarn.server.resourcemanager.rmapp.attempt.RMAppAttemptImpl: appattempt_1536878829533_0003_000001 State change from ALLOCATED to FINAL_SAVING
2018-09-18 13:35:05,817 INFO org.apache.hadoop.yarn.server.resourcemanager.ApplicationMasterService: Unregistering app attempt : appattempt_1536878829533_0003_000001
2018-09-18 13:35:05,817 INFO org.apache.hadoop.yarn.server.resourcemanager.security.AMRMTokenSecretManager: Application finished, removing password for appattempt_1536878829533_0003_000001
2018-09-18 13:35:05,817 INFO org.apache.hadoop.yarn.server.resourcemanager.rmapp.attempt.RMAppAttemptImpl: appattempt_1536878829533_0003_000001 State change from FINAL_SAVING to KILLED
2018-09-18 13:35:05,817 INFO org.apache.hadoop.yarn.server.resourcemanager.rmapp.RMAppImpl: Updating application application_1536878829533_0003 with final state: KILLED
2018-09-18 13:35:05,817 INFO org.apache.hadoop.yarn.server.resourcemanager.rmapp.RMAppImpl: application_1536878829533_0003 State change from KILLING to FINAL_SAVING on event=ATTEMPT_KILLED
2018-09-18 13:35:05,817 INFO org.apache.hadoop.yarn.server.resourcemanager.recovery.RMStateStore: Updating info for app: application_1536878829533_0003
2018-09-18 13:35:05,817 INFO org.apache.hadoop.yarn.server.resourcemanager.scheduler.capacity.CapacityScheduler: Application Attempt appattempt_1536878829533_0003_000001 is done. finalState=KILLED
2018-09-18 13:35:05,817 INFO org.apache.hadoop.yarn.server.resourcemanager.rmapp.RMAppImpl: application_1536878829533_0003 State change from FINAL_SAVING to KILLED on event=APP_UPDATE_SAVED
2018-09-18 13:35:05,817 INFO org.apache.hadoop.yarn.server.resourcemanager.rmcontainer.RMContainerImpl: container_1536878829533_0003_01_000001 Container Transitioned from ACQUIRED to KILLED
2018-09-18 13:35:05,817 INFO org.apache.hadoop.yarn.server.resourcemanager.RMAuditLogger: USER=jason	OPERATION=Application Finished - Killed	TARGET=RMAppManager	RESULT=SUCCESS	APPID=application_1536878829533_0003
2018-09-18 13:35:05,817 INFO org.apache.hadoop.yarn.server.resourcemanager.RMAuditLogger: USER=jason	OPERATION=AM Released Container	TARGET=SchedulerApp	RESULT=SUCCESS	APPID=application_1536878829533_0003	CONTAINERID=container_1536878829533_0003_01_000001
2018-09-18 13:35:05,817 INFO org.apache.hadoop.yarn.server.resourcemanager.scheduler.SchedulerNode: Released container container_1536878829533_0003_01_000001 of capacity <memory:2048, vCores:1> on host 192.168.1.103:56395, which currently has 0 containers, <memory:0, vCores:0> used and <memory:8192, vCores:8> available, release resources=true
2018-09-18 13:35:05,817 INFO org.apache.hadoop.yarn.server.resourcemanager.amlauncher.AMLauncher: Cleaning master appattempt_1536878829533_0003_000001
2018-09-18 13:35:05,818 INFO org.apache.hadoop.yarn.server.resourcemanager.RMAppManager$ApplicationSummary: appId=application_1536878829533_0003,name=word count,user=jason,queue=default,state=KILLED,trackingUrl=http://Jasons-MBP.kc.umkc.edu:8088/cluster/app/application_1536878829533_0003,appMasterHost=N/A,startTime=1537295611111,finishTime=1537295705817,finalStatus=KILLED,memorySeconds=193382,vcoreSeconds=94,preemptedMemorySeconds=0,preemptedVcoreSeconds=0,preemptedAMContainers=0,preemptedNonAMContainers=0,preemptedResources=<memory:0\, vCores:0>,applicationType=MAPREDUCE
2018-09-18 13:35:05,818 INFO org.apache.hadoop.yarn.server.resourcemanager.scheduler.AppSchedulingInfo: Application application_1536878829533_0003 requests cleared
2018-09-18 13:35:05,818 INFO org.apache.hadoop.yarn.server.resourcemanager.scheduler.capacity.LeafQueue: Application removed - appId: application_1536878829533_0003 user: jason queue: default #user-pending-applications: 0 #user-active-applications: 0 #queue-pending-applications: 0 #queue-active-applications: 0
2018-09-18 13:35:05,818 INFO org.apache.hadoop.yarn.server.resourcemanager.scheduler.capacity.ParentQueue: Application removed - appId: application_1536878829533_0003 user: jason leaf-queue of parent: root #applications: 0
2018-09-18 13:42:23,880 INFO org.apache.hadoop.ipc.Server: Socket Reader #1 for port 8031: readAndProcess from client 10.159.0.103 threw exception [java.io.IOException: Operation timed out]
java.io.IOException: Operation timed out
	at sun.nio.ch.FileDispatcherImpl.read0(Native Method)
	at sun.nio.ch.SocketDispatcher.read(SocketDispatcher.java:39)
	at sun.nio.ch.IOUtil.readIntoNativeBuffer(IOUtil.java:223)
	at sun.nio.ch.IOUtil.read(IOUtil.java:197)
	at sun.nio.ch.SocketChannelImpl.read(SocketChannelImpl.java:380)
	at org.apache.hadoop.ipc.Server.channelRead(Server.java:3020)
	at org.apache.hadoop.ipc.Server.access$2400(Server.java:134)
	at org.apache.hadoop.ipc.Server$Connection.readAndProcess(Server.java:1869)
	at org.apache.hadoop.ipc.Server$Listener.doRead(Server.java:1125)
	at org.apache.hadoop.ipc.Server$Listener$Reader.doRunLoop(Server.java:982)
	at org.apache.hadoop.ipc.Server$Listener$Reader.run(Server.java:953)
2018-09-18 13:42:51,555 INFO org.apache.hadoop.yarn.server.resourcemanager.amlauncher.AMLauncher: Error launching appattempt_1536878829533_0003_000001. Got exception: org.apache.hadoop.net.ConnectTimeoutException: Call From Jasons-MBP.kc.umkc.edu/10.169.1.149 to 192.168.1.103:56395 failed on socket timeout exception: org.apache.hadoop.net.ConnectTimeoutException: 20000 millis timeout while waiting for channel to be ready for connect. ch : java.nio.channels.SocketChannel[connection-pending remote=192.168.1.103/192.168.1.103:56395]; For more details see:  http://wiki.apache.org/hadoop/SocketTimeout
	at sun.reflect.GeneratedConstructorAccessor54.newInstance(Unknown Source)
	at sun.reflect.DelegatingConstructorAccessorImpl.newInstance(DelegatingConstructorAccessorImpl.java:45)
	at java.lang.reflect.Constructor.newInstance(Constructor.java:423)
	at org.apache.hadoop.net.NetUtils.wrapWithMessage(NetUtils.java:801)
	at org.apache.hadoop.net.NetUtils.wrapException(NetUtils.java:751)
	at org.apache.hadoop.ipc.Client.getRpcResponse(Client.java:1485)
	at org.apache.hadoop.ipc.Client.call(Client.java:1427)
	at org.apache.hadoop.ipc.Client.call(Client.java:1337)
	at org.apache.hadoop.ipc.ProtobufRpcEngine$Invoker.invoke(ProtobufRpcEngine.java:227)
	at org.apache.hadoop.ipc.ProtobufRpcEngine$Invoker.invoke(ProtobufRpcEngine.java:116)
	at com.sun.proxy.$Proxy86.startContainers(Unknown Source)
	at org.apache.hadoop.yarn.api.impl.pb.client.ContainerManagementProtocolPBClientImpl.startContainers(ContainerManagementProtocolPBClientImpl.java:106)
	at sun.reflect.GeneratedMethodAccessor26.invoke(Unknown Source)
	at sun.reflect.DelegatingMethodAccessorImpl.invoke(DelegatingMethodAccessorImpl.java:43)
	at java.lang.reflect.Method.invoke(Method.java:498)
	at org.apache.hadoop.io.retry.RetryInvocationHandler.invokeMethod(RetryInvocationHandler.java:398)
	at org.apache.hadoop.io.retry.RetryInvocationHandler$Call.invokeMethod(RetryInvocationHandler.java:163)
	at org.apache.hadoop.io.retry.RetryInvocationHandler$Call.invoke(RetryInvocationHandler.java:155)
	at org.apache.hadoop.io.retry.RetryInvocationHandler$Call.invokeOnce(RetryInvocationHandler.java:95)
	at org.apache.hadoop.io.retry.RetryInvocationHandler.invoke(RetryInvocationHandler.java:335)
	at com.sun.proxy.$Proxy87.startContainers(Unknown Source)
	at org.apache.hadoop.yarn.server.resourcemanager.amlauncher.AMLauncher.launch(AMLauncher.java:119)
	at org.apache.hadoop.yarn.server.resourcemanager.amlauncher.AMLauncher.run(AMLauncher.java:250)
	at java.util.concurrent.ThreadPoolExecutor.runWorker(ThreadPoolExecutor.java:1149)
	at java.util.concurrent.ThreadPoolExecutor$Worker.run(ThreadPoolExecutor.java:624)
	at java.lang.Thread.run(Thread.java:748)
Caused by: org.apache.hadoop.net.ConnectTimeoutException: 20000 millis timeout while waiting for channel to be ready for connect. ch : java.nio.channels.SocketChannel[connection-pending remote=192.168.1.103/192.168.1.103:56395]
	at org.apache.hadoop.net.NetUtils.connect(NetUtils.java:534)
	at org.apache.hadoop.net.NetUtils.connect(NetUtils.java:495)
	at org.apache.hadoop.ipc.Client$Connection.setupConnection(Client.java:681)
	at org.apache.hadoop.ipc.Client$Connection.setupIOstreams(Client.java:777)
	at org.apache.hadoop.ipc.Client$Connection.access$3500(Client.java:409)
	at org.apache.hadoop.ipc.Client.getConnection(Client.java:1542)
	at org.apache.hadoop.ipc.Client.call(Client.java:1373)
	... 19 more

2018-09-18 13:44:25,921 INFO org.apache.hadoop.yarn.server.resourcemanager.amlauncher.AMLauncher: Error cleaning master 
org.apache.hadoop.net.ConnectTimeoutException: Call From Jasons-MBP.kc.umkc.edu/10.169.1.149 to 192.168.1.103:56395 failed on socket timeout exception: org.apache.hadoop.net.ConnectTimeoutException: 20000 millis timeout while waiting for channel to be ready for connect. ch : java.nio.channels.SocketChannel[connection-pending remote=192.168.1.103/192.168.1.103:56395]; For more details see:  http://wiki.apache.org/hadoop/SocketTimeout
	at sun.reflect.GeneratedConstructorAccessor54.newInstance(Unknown Source)
	at sun.reflect.DelegatingConstructorAccessorImpl.newInstance(DelegatingConstructorAccessorImpl.java:45)
	at java.lang.reflect.Constructor.newInstance(Constructor.java:423)
	at org.apache.hadoop.net.NetUtils.wrapWithMessage(NetUtils.java:801)
	at org.apache.hadoop.net.NetUtils.wrapException(NetUtils.java:751)
	at org.apache.hadoop.ipc.Client.getRpcResponse(Client.java:1485)
	at org.apache.hadoop.ipc.Client.call(Client.java:1427)
	at org.apache.hadoop.ipc.Client.call(Client.java:1337)
	at org.apache.hadoop.ipc.ProtobufRpcEngine$Invoker.invoke(ProtobufRpcEngine.java:227)
	at org.apache.hadoop.ipc.ProtobufRpcEngine$Invoker.invoke(ProtobufRpcEngine.java:116)
	at com.sun.proxy.$Proxy86.stopContainers(Unknown Source)
	at org.apache.hadoop.yarn.api.impl.pb.client.ContainerManagementProtocolPBClientImpl.stopContainers(ContainerManagementProtocolPBClientImpl.java:120)
	at sun.reflect.GeneratedMethodAccessor39.invoke(Unknown Source)
	at sun.reflect.DelegatingMethodAccessorImpl.invoke(DelegatingMethodAccessorImpl.java:43)
	at java.lang.reflect.Method.invoke(Method.java:498)
	at org.apache.hadoop.io.retry.RetryInvocationHandler.invokeMethod(RetryInvocationHandler.java:398)
	at org.apache.hadoop.io.retry.RetryInvocationHandler$Call.invokeMethod(RetryInvocationHandler.java:163)
	at org.apache.hadoop.io.retry.RetryInvocationHandler$Call.invoke(RetryInvocationHandler.java:155)
	at org.apache.hadoop.io.retry.RetryInvocationHandler$Call.invokeOnce(RetryInvocationHandler.java:95)
	at org.apache.hadoop.io.retry.RetryInvocationHandler.invoke(RetryInvocationHandler.java:335)
	at com.sun.proxy.$Proxy87.stopContainers(Unknown Source)
	at org.apache.hadoop.yarn.server.resourcemanager.amlauncher.AMLauncher.cleanup(AMLauncher.java:139)
	at org.apache.hadoop.yarn.server.resourcemanager.amlauncher.AMLauncher.run(AMLauncher.java:264)
	at java.util.concurrent.ThreadPoolExecutor.runWorker(ThreadPoolExecutor.java:1149)
	at java.util.concurrent.ThreadPoolExecutor$Worker.run(ThreadPoolExecutor.java:624)
	at java.lang.Thread.run(Thread.java:748)
Caused by: org.apache.hadoop.net.ConnectTimeoutException: 20000 millis timeout while waiting for channel to be ready for connect. ch : java.nio.channels.SocketChannel[connection-pending remote=192.168.1.103/192.168.1.103:56395]
	at org.apache.hadoop.net.NetUtils.connect(NetUtils.java:534)
	at org.apache.hadoop.net.NetUtils.connect(NetUtils.java:495)
	at org.apache.hadoop.ipc.Client$Connection.setupConnection(Client.java:681)
	at org.apache.hadoop.ipc.Client$Connection.setupIOstreams(Client.java:777)
	at org.apache.hadoop.ipc.Client$Connection.access$3500(Client.java:409)
	at org.apache.hadoop.ipc.Client.getConnection(Client.java:1542)
	at org.apache.hadoop.ipc.Client.call(Client.java:1373)
	... 19 more
2018-09-18 20:05:53,448 INFO org.apache.hadoop.security.token.delegation.AbstractDelegationTokenSecretManager: Updating the current master key for generating delegation tokens
2018-09-18 20:05:54,060 WARN org.apache.hadoop.util.JvmPauseMonitor: Detected pause in JVM or host machine (eg GC): pause of approximately 24928ms
No GCs detected
2018-09-18 20:05:53,448 INFO org.apache.hadoop.security.token.delegation.AbstractDelegationTokenSecretManager: Updating the current master key for generating delegation tokens
2018-09-18 20:05:54,091 INFO org.apache.hadoop.yarn.server.resourcemanager.security.RMDelegationTokenSecretManager: storing master key with keyID 7
2018-09-18 20:05:54,096 INFO org.apache.hadoop.yarn.server.resourcemanager.recovery.RMStateStore: Storing RMDTMasterKey.
2018-09-18 20:06:21,104 INFO org.apache.hadoop.yarn.server.resourcemanager.ClientRMService: Allocated new applicationId: 4
2018-09-18 20:06:22,791 INFO org.apache.hadoop.yarn.server.resourcemanager.scheduler.capacity.CapacityScheduler: Application 'application_1536878829533_0004' is submitted without priority hence considering default queue/cluster priority: 0
2018-09-18 20:06:22,791 INFO org.apache.hadoop.yarn.server.resourcemanager.scheduler.capacity.CapacityScheduler: Priority '0' is acceptable in queue : default for application: application_1536878829533_0004 for the user: jason
2018-09-18 20:06:22,795 INFO org.apache.hadoop.yarn.server.resourcemanager.ClientRMService: Application with id 4 submitted by user jason
2018-09-18 20:06:22,796 INFO org.apache.hadoop.yarn.server.resourcemanager.rmapp.RMAppImpl: Storing application with id application_1536878829533_0004
2018-09-18 20:06:22,796 INFO org.apache.hadoop.yarn.server.resourcemanager.RMAuditLogger: USER=jason	IP=192.168.1.103	OPERATION=Submit Application Request	TARGET=ClientRMService	RESULT=SUCCESS	APPID=application_1536878829533_0004
2018-09-18 20:06:22,796 INFO org.apache.hadoop.yarn.server.resourcemanager.recovery.RMStateStore: Storing info for app: application_1536878829533_0004
2018-09-18 20:06:22,797 INFO org.apache.hadoop.yarn.server.resourcemanager.rmapp.RMAppImpl: application_1536878829533_0004 State change from NEW to NEW_SAVING on event=START
2018-09-18 20:06:22,798 INFO org.apache.hadoop.yarn.server.resourcemanager.rmapp.RMAppImpl: application_1536878829533_0004 State change from NEW_SAVING to SUBMITTED on event=APP_NEW_SAVED
2018-09-18 20:06:22,798 INFO org.apache.hadoop.yarn.server.resourcemanager.scheduler.capacity.ParentQueue: Application added - appId: application_1536878829533_0004 user: jason leaf-queue of parent: root #applications: 1
2018-09-18 20:06:22,798 INFO org.apache.hadoop.yarn.server.resourcemanager.scheduler.capacity.CapacityScheduler: Accepted application application_1536878829533_0004 from user: jason, in queue: default
2018-09-18 20:06:22,805 INFO org.apache.hadoop.yarn.server.resourcemanager.rmapp.RMAppImpl: application_1536878829533_0004 State change from SUBMITTED to ACCEPTED on event=APP_ACCEPTED
2018-09-18 20:06:22,821 INFO org.apache.hadoop.yarn.server.resourcemanager.ApplicationMasterService: Registering app attempt : appattempt_1536878829533_0004_000001
2018-09-18 20:06:22,821 INFO org.apache.hadoop.yarn.server.resourcemanager.rmapp.attempt.RMAppAttemptImpl: appattempt_1536878829533_0004_000001 State change from NEW to SUBMITTED
2018-09-18 20:06:22,823 WARN org.apache.hadoop.yarn.server.resourcemanager.scheduler.capacity.LeafQueue: maximum-am-resource-percent is insufficient to start a single application in queue, it is likely set too low. skipping enforcement to allow at least one application to start
2018-09-18 20:06:22,823 WARN org.apache.hadoop.yarn.server.resourcemanager.scheduler.capacity.LeafQueue: maximum-am-resource-percent is insufficient to start a single application in queue for user, it is likely set too low. skipping enforcement to allow at least one application to start
2018-09-18 20:06:22,825 INFO org.apache.hadoop.yarn.server.resourcemanager.scheduler.capacity.LeafQueue: Application application_1536878829533_0004 from user: jason activated in queue: default
2018-09-18 20:06:22,825 INFO org.apache.hadoop.yarn.server.resourcemanager.scheduler.capacity.LeafQueue: Application added - appId: application_1536878829533_0004 user: jason, leaf-queue: default #user-pending-applications: 0 #user-active-applications: 1 #queue-pending-applications: 0 #queue-active-applications: 1
2018-09-18 20:06:22,825 INFO org.apache.hadoop.yarn.server.resourcemanager.scheduler.capacity.CapacityScheduler: Added Application Attempt appattempt_1536878829533_0004_000001 to scheduler from user jason in queue default
2018-09-18 20:06:22,826 INFO org.apache.hadoop.yarn.server.resourcemanager.rmapp.attempt.RMAppAttemptImpl: appattempt_1536878829533_0004_000001 State change from SUBMITTED to SCHEDULED
2018-09-18 20:06:26,573 INFO org.apache.hadoop.yarn.server.resourcemanager.rmcontainer.RMContainerImpl: container_1536878829533_0004_01_000001 Container Transitioned from NEW to ALLOCATED
2018-09-18 20:06:26,573 INFO org.apache.hadoop.yarn.server.resourcemanager.RMAuditLogger: USER=jason	OPERATION=AM Allocated Container	TARGET=SchedulerApp	RESULT=SUCCESS	APPID=application_1536878829533_0004	CONTAINERID=container_1536878829533_0004_01_000001
2018-09-18 20:06:26,573 INFO org.apache.hadoop.yarn.server.resourcemanager.scheduler.SchedulerNode: Assigned container container_1536878829533_0004_01_000001 of capacity <memory:2048, vCores:1> on host 192.168.1.103:56395, which has 1 containers, <memory:2048, vCores:1> used and <memory:6144, vCores:7> available after allocation
2018-09-18 20:06:26,574 INFO org.apache.hadoop.yarn.server.resourcemanager.scheduler.capacity.allocator.AbstractContainerAllocator: assignedContainer application attempt=appattempt_1536878829533_0004_000001 container=container_1536878829533_0004_01_000001 queue=org.apache.hadoop.yarn.server.resourcemanager.scheduler.capacity.allocator.RegularContainerAllocator@23986f8e clusterResource=<memory:8192, vCores:8> type=OFF_SWITCH
2018-09-18 20:06:26,580 INFO org.apache.hadoop.yarn.server.resourcemanager.security.NMTokenSecretManagerInRM: Sending NMToken for nodeId : 192.168.1.103:56395 for container : container_1536878829533_0004_01_000001
2018-09-18 20:06:26,583 INFO org.apache.hadoop.yarn.server.resourcemanager.rmcontainer.RMContainerImpl: container_1536878829533_0004_01_000001 Container Transitioned from ALLOCATED to ACQUIRED
2018-09-18 20:06:26,583 INFO org.apache.hadoop.yarn.server.resourcemanager.security.NMTokenSecretManagerInRM: Clear node set for appattempt_1536878829533_0004_000001
2018-09-18 20:06:26,583 INFO org.apache.hadoop.yarn.server.resourcemanager.rmapp.attempt.RMAppAttemptImpl: Storing attempt: AppId: application_1536878829533_0004 AttemptId: appattempt_1536878829533_0004_000001 MasterContainer: Container: [ContainerId: container_1536878829533_0004_01_000001, Version: 0, NodeId: 192.168.1.103:56395, NodeHttpAddress: 192.168.1.103:8042, Resource: <memory:2048, vCores:1>, Priority: 0, Token: Token { kind: ContainerToken, service: 192.168.1.103:56395 }, ]
2018-09-18 20:06:26,583 INFO org.apache.hadoop.yarn.server.resourcemanager.scheduler.capacity.ParentQueue: Re-sorting assigned queue: root.default stats: default: capacity=1.0, absoluteCapacity=1.0, usedResources=<memory:2048, vCores:1>, usedCapacity=0.25, absoluteUsedCapacity=0.25, numApps=1, numContainers=1
2018-09-18 20:06:26,584 INFO org.apache.hadoop.yarn.server.resourcemanager.rmapp.attempt.RMAppAttemptImpl: appattempt_1536878829533_0004_000001 State change from SCHEDULED to ALLOCATED_SAVING
2018-09-18 20:06:26,584 INFO org.apache.hadoop.yarn.server.resourcemanager.scheduler.capacity.ParentQueue: assignedContainer queue=root usedCapacity=0.25 absoluteUsedCapacity=0.25 used=<memory:2048, vCores:1> cluster=<memory:8192, vCores:8>
2018-09-18 20:06:26,585 INFO org.apache.hadoop.yarn.server.resourcemanager.rmapp.attempt.RMAppAttemptImpl: appattempt_1536878829533_0004_000001 State change from ALLOCATED_SAVING to ALLOCATED
2018-09-18 20:06:26,587 INFO org.apache.hadoop.yarn.server.resourcemanager.amlauncher.AMLauncher: Launching masterappattempt_1536878829533_0004_000001
2018-09-18 20:06:26,608 INFO org.apache.hadoop.yarn.server.resourcemanager.amlauncher.AMLauncher: Setting up container Container: [ContainerId: container_1536878829533_0004_01_000001, Version: 0, NodeId: 192.168.1.103:56395, NodeHttpAddress: 192.168.1.103:8042, Resource: <memory:2048, vCores:1>, Priority: 0, Token: Token { kind: ContainerToken, service: 192.168.1.103:56395 }, ] for AM appattempt_1536878829533_0004_000001
2018-09-18 20:06:26,608 INFO org.apache.hadoop.yarn.server.resourcemanager.security.AMRMTokenSecretManager: Create AMRMToken for ApplicationAttempt: appattempt_1536878829533_0004_000001
2018-09-18 20:06:26,608 INFO org.apache.hadoop.yarn.server.resourcemanager.security.AMRMTokenSecretManager: Creating password for appattempt_1536878829533_0004_000001
2018-09-18 20:06:26,695 INFO org.apache.hadoop.yarn.server.resourcemanager.amlauncher.AMLauncher: Done launching container Container: [ContainerId: container_1536878829533_0004_01_000001, Version: 0, NodeId: 192.168.1.103:56395, NodeHttpAddress: 192.168.1.103:8042, Resource: <memory:2048, vCores:1>, Priority: 0, Token: Token { kind: ContainerToken, service: 192.168.1.103:56395 }, ] for AM appattempt_1536878829533_0004_000001
2018-09-18 20:06:26,696 INFO org.apache.hadoop.yarn.server.resourcemanager.rmapp.attempt.RMAppAttemptImpl: appattempt_1536878829533_0004_000001 State change from ALLOCATED to LAUNCHED
2018-09-18 20:06:27,581 INFO org.apache.hadoop.yarn.server.resourcemanager.rmcontainer.RMContainerImpl: container_1536878829533_0004_01_000001 Container Transitioned from ACQUIRED to RUNNING
2018-09-18 20:06:30,890 INFO SecurityLogger.org.apache.hadoop.ipc.Server: Auth successful for appattempt_1536878829533_0004_000001 (auth:SIMPLE)
2018-09-18 20:06:30,895 INFO org.apache.hadoop.yarn.server.resourcemanager.ApplicationMasterService: AM registration appattempt_1536878829533_0004_000001
2018-09-18 20:06:30,895 INFO org.apache.hadoop.yarn.server.resourcemanager.rmapp.attempt.RMAppAttemptImpl: appattempt_1536878829533_0004_000001 State change from LAUNCHED to RUNNING
2018-09-18 20:06:30,895 INFO org.apache.hadoop.yarn.server.resourcemanager.rmapp.RMAppImpl: application_1536878829533_0004 State change from ACCEPTED to RUNNING on event=ATTEMPT_REGISTERED
2018-09-18 20:06:30,896 INFO org.apache.hadoop.yarn.server.resourcemanager.RMAuditLogger: USER=jason	IP=192.168.1.103	OPERATION=Register App Master	TARGET=ApplicationMasterService	RESULT=SUCCESS	APPID=application_1536878829533_0004	APPATTEMPTID=appattempt_1536878829533_0004_000001
2018-09-18 20:06:32,605 INFO org.apache.hadoop.yarn.server.resourcemanager.rmcontainer.RMContainerImpl: container_1536878829533_0004_01_000002 Container Transitioned from NEW to ALLOCATED
2018-09-18 20:06:32,605 INFO org.apache.hadoop.yarn.server.resourcemanager.RMAuditLogger: USER=jason	OPERATION=AM Allocated Container	TARGET=SchedulerApp	RESULT=SUCCESS	APPID=application_1536878829533_0004	CONTAINERID=container_1536878829533_0004_01_000002
2018-09-18 20:06:32,605 INFO org.apache.hadoop.yarn.server.resourcemanager.scheduler.SchedulerNode: Assigned container container_1536878829533_0004_01_000002 of capacity <memory:1024, vCores:1> on host 192.168.1.103:56395, which has 2 containers, <memory:3072, vCores:2> used and <memory:5120, vCores:6> available after allocation
2018-09-18 20:06:32,605 INFO org.apache.hadoop.yarn.server.resourcemanager.scheduler.capacity.allocator.AbstractContainerAllocator: assignedContainer application attempt=appattempt_1536878829533_0004_000001 container=container_1536878829533_0004_01_000002 queue=org.apache.hadoop.yarn.server.resourcemanager.scheduler.capacity.allocator.RegularContainerAllocator@23986f8e clusterResource=<memory:8192, vCores:8> type=NODE_LOCAL
2018-09-18 20:06:32,605 INFO org.apache.hadoop.yarn.server.resourcemanager.scheduler.capacity.ParentQueue: Re-sorting assigned queue: root.default stats: default: capacity=1.0, absoluteCapacity=1.0, usedResources=<memory:3072, vCores:2>, usedCapacity=0.375, absoluteUsedCapacity=0.375, numApps=1, numContainers=2
2018-09-18 20:06:32,605 INFO org.apache.hadoop.yarn.server.resourcemanager.scheduler.capacity.ParentQueue: assignedContainer queue=root usedCapacity=0.375 absoluteUsedCapacity=0.375 used=<memory:3072, vCores:2> cluster=<memory:8192, vCores:8>
2018-09-18 20:06:32,970 INFO org.apache.hadoop.yarn.server.resourcemanager.security.NMTokenSecretManagerInRM: Sending NMToken for nodeId : 192.168.1.103:56395 for container : container_1536878829533_0004_01_000002
2018-09-18 20:06:32,971 INFO org.apache.hadoop.yarn.server.resourcemanager.rmcontainer.RMContainerImpl: container_1536878829533_0004_01_000002 Container Transitioned from ALLOCATED to ACQUIRED
2018-09-18 20:06:33,607 INFO org.apache.hadoop.yarn.server.resourcemanager.rmcontainer.RMContainerImpl: container_1536878829533_0004_01_000002 Container Transitioned from ACQUIRED to RUNNING
2018-09-18 20:06:33,996 INFO org.apache.hadoop.yarn.server.resourcemanager.scheduler.AppSchedulingInfo: checking for deactivate of application :application_1536878829533_0004
2018-09-18 20:06:35,491 INFO org.apache.hadoop.yarn.server.resourcemanager.rmcontainer.RMContainerImpl: container_1536878829533_0004_01_000002 Container Transitioned from RUNNING to COMPLETED
2018-09-18 20:06:35,491 INFO org.apache.hadoop.yarn.server.resourcemanager.RMAuditLogger: USER=jason	OPERATION=AM Released Container	TARGET=SchedulerApp	RESULT=SUCCESS	APPID=application_1536878829533_0004	CONTAINERID=container_1536878829533_0004_01_000002
2018-09-18 20:06:35,492 INFO org.apache.hadoop.yarn.server.resourcemanager.scheduler.SchedulerNode: Released container container_1536878829533_0004_01_000002 of capacity <memory:1024, vCores:1> on host 192.168.1.103:56395, which currently has 1 containers, <memory:2048, vCores:1> used and <memory:6144, vCores:7> available, release resources=true
2018-09-18 20:06:37,511 INFO org.apache.hadoop.yarn.server.resourcemanager.rmcontainer.RMContainerImpl: container_1536878829533_0004_01_000003 Container Transitioned from NEW to ALLOCATED
2018-09-18 20:06:37,511 INFO org.apache.hadoop.yarn.server.resourcemanager.RMAuditLogger: USER=jason	OPERATION=AM Allocated Container	TARGET=SchedulerApp	RESULT=SUCCESS	APPID=application_1536878829533_0004	CONTAINERID=container_1536878829533_0004_01_000003
2018-09-18 20:06:37,512 INFO org.apache.hadoop.yarn.server.resourcemanager.scheduler.SchedulerNode: Assigned container container_1536878829533_0004_01_000003 of capacity <memory:1024, vCores:1> on host 192.168.1.103:56395, which has 2 containers, <memory:3072, vCores:2> used and <memory:5120, vCores:6> available after allocation
2018-09-18 20:06:37,512 INFO org.apache.hadoop.yarn.server.resourcemanager.scheduler.capacity.allocator.AbstractContainerAllocator: assignedContainer application attempt=appattempt_1536878829533_0004_000001 container=container_1536878829533_0004_01_000003 queue=org.apache.hadoop.yarn.server.resourcemanager.scheduler.capacity.allocator.RegularContainerAllocator@23986f8e clusterResource=<memory:8192, vCores:8> type=OFF_SWITCH
2018-09-18 20:06:37,512 INFO org.apache.hadoop.yarn.server.resourcemanager.scheduler.capacity.ParentQueue: Re-sorting assigned queue: root.default stats: default: capacity=1.0, absoluteCapacity=1.0, usedResources=<memory:3072, vCores:2>, usedCapacity=0.375, absoluteUsedCapacity=0.375, numApps=1, numContainers=2
2018-09-18 20:06:37,512 INFO org.apache.hadoop.yarn.server.resourcemanager.scheduler.capacity.ParentQueue: assignedContainer queue=root usedCapacity=0.375 absoluteUsedCapacity=0.375 used=<memory:3072, vCores:2> cluster=<memory:8192, vCores:8>
2018-09-18 20:06:38,040 INFO org.apache.hadoop.yarn.server.resourcemanager.rmcontainer.RMContainerImpl: container_1536878829533_0004_01_000003 Container Transitioned from ALLOCATED to ACQUIRED
2018-09-18 20:06:38,522 INFO org.apache.hadoop.yarn.server.resourcemanager.rmcontainer.RMContainerImpl: container_1536878829533_0004_01_000003 Container Transitioned from ACQUIRED to RUNNING
2018-09-18 20:06:39,044 INFO org.apache.hadoop.yarn.server.resourcemanager.scheduler.AppSchedulingInfo: checking for deactivate of application :application_1536878829533_0004
2018-09-18 20:06:40,286 INFO org.apache.hadoop.yarn.server.resourcemanager.rmcontainer.RMContainerImpl: container_1536878829533_0004_01_000003 Container Transitioned from RUNNING to COMPLETED
2018-09-18 20:06:40,286 INFO org.apache.hadoop.yarn.server.resourcemanager.RMAuditLogger: USER=jason	OPERATION=AM Released Container	TARGET=SchedulerApp	RESULT=SUCCESS	APPID=application_1536878829533_0004	CONTAINERID=container_1536878829533_0004_01_000003
2018-09-18 20:06:40,286 INFO org.apache.hadoop.yarn.server.resourcemanager.scheduler.SchedulerNode: Released container container_1536878829533_0004_01_000003 of capacity <memory:1024, vCores:1> on host 192.168.1.103:56395, which currently has 1 containers, <memory:2048, vCores:1> used and <memory:6144, vCores:7> available, release resources=true
2018-09-18 20:06:40,602 INFO org.apache.hadoop.yarn.server.resourcemanager.rmapp.attempt.RMAppAttemptImpl: Updating application attempt appattempt_1536878829533_0004_000001 with final state: FINISHING, and exit status: -1000
2018-09-18 20:06:40,602 INFO org.apache.hadoop.yarn.server.resourcemanager.rmapp.attempt.RMAppAttemptImpl: appattempt_1536878829533_0004_000001 State change from RUNNING to FINAL_SAVING
2018-09-18 20:06:40,603 INFO org.apache.hadoop.yarn.server.resourcemanager.rmapp.RMAppImpl: Updating application application_1536878829533_0004 with final state: FINISHING
2018-09-18 20:06:40,603 INFO org.apache.hadoop.yarn.server.resourcemanager.rmapp.RMAppImpl: application_1536878829533_0004 State change from RUNNING to FINAL_SAVING on event=ATTEMPT_UNREGISTERED
2018-09-18 20:06:40,603 INFO org.apache.hadoop.yarn.server.resourcemanager.rmapp.attempt.RMAppAttemptImpl: appattempt_1536878829533_0004_000001 State change from FINAL_SAVING to FINISHING
2018-09-18 20:06:40,603 INFO org.apache.hadoop.yarn.server.resourcemanager.recovery.RMStateStore: Updating info for app: application_1536878829533_0004
2018-09-18 20:06:40,603 INFO org.apache.hadoop.yarn.server.resourcemanager.rmapp.RMAppImpl: application_1536878829533_0004 State change from FINAL_SAVING to FINISHING on event=APP_UPDATE_SAVED
2018-09-18 20:06:41,603 INFO org.apache.hadoop.yarn.server.resourcemanager.ApplicationMasterService: application_1536878829533_0004 unregistered successfully. 
2018-09-18 20:06:46,790 INFO org.apache.hadoop.yarn.server.resourcemanager.rmcontainer.RMContainerImpl: container_1536878829533_0004_01_000001 Container Transitioned from RUNNING to COMPLETED
2018-09-18 20:06:46,790 INFO org.apache.hadoop.yarn.server.resourcemanager.RMAuditLogger: USER=jason	OPERATION=AM Released Container	TARGET=SchedulerApp	RESULT=SUCCESS	APPID=application_1536878829533_0004	CONTAINERID=container_1536878829533_0004_01_000001
2018-09-18 20:06:46,790 INFO org.apache.hadoop.yarn.server.resourcemanager.ApplicationMasterService: Unregistering app attempt : appattempt_1536878829533_0004_000001
2018-09-18 20:06:46,790 INFO org.apache.hadoop.yarn.server.resourcemanager.security.AMRMTokenSecretManager: Application finished, removing password for appattempt_1536878829533_0004_000001
2018-09-18 20:06:46,791 INFO org.apache.hadoop.yarn.server.resourcemanager.rmapp.attempt.RMAppAttemptImpl: appattempt_1536878829533_0004_000001 State change from FINISHING to FINISHED
2018-09-18 20:06:46,791 INFO org.apache.hadoop.yarn.server.resourcemanager.rmapp.RMAppImpl: application_1536878829533_0004 State change from FINISHING to FINISHED on event=ATTEMPT_FINISHED
2018-09-18 20:06:46,791 INFO org.apache.hadoop.yarn.server.resourcemanager.scheduler.SchedulerNode: Released container container_1536878829533_0004_01_000001 of capacity <memory:2048, vCores:1> on host 192.168.1.103:56395, which currently has 0 containers, <memory:0, vCores:0> used and <memory:8192, vCores:8> available, release resources=true
2018-09-18 20:06:46,791 INFO org.apache.hadoop.yarn.server.resourcemanager.scheduler.capacity.CapacityScheduler: Application Attempt appattempt_1536878829533_0004_000001 is done. finalState=FINISHED
2018-09-18 20:06:46,791 INFO org.apache.hadoop.yarn.server.resourcemanager.RMAuditLogger: USER=jason	OPERATION=Application Finished - Succeeded	TARGET=RMAppManager	RESULT=SUCCESS	APPID=application_1536878829533_0004
2018-09-18 20:06:46,792 INFO org.apache.hadoop.yarn.server.resourcemanager.scheduler.AppSchedulingInfo: Application application_1536878829533_0004 requests cleared
2018-09-18 20:06:46,792 INFO org.apache.hadoop.yarn.server.resourcemanager.amlauncher.AMLauncher: Cleaning master appattempt_1536878829533_0004_000001
2018-09-18 20:06:46,792 INFO org.apache.hadoop.yarn.server.resourcemanager.scheduler.capacity.LeafQueue: Application removed - appId: application_1536878829533_0004 user: jason queue: default #user-pending-applications: 0 #user-active-applications: 0 #queue-pending-applications: 0 #queue-active-applications: 0
2018-09-18 20:06:46,792 INFO org.apache.hadoop.yarn.server.resourcemanager.scheduler.capacity.ParentQueue: Application removed - appId: application_1536878829533_0004 user: jason leaf-queue of parent: root #applications: 0
2018-09-18 20:06:46,793 INFO org.apache.hadoop.yarn.server.resourcemanager.RMAppManager$ApplicationSummary: appId=application_1536878829533_0004,name=word count,user=jason,queue=default,state=FINISHED,trackingUrl=http://Jasons-MacBook-Pro.local:8088/proxy/application_1536878829533_0004/,appMasterHost=192.168.1.103,startTime=1537319182792,finishTime=1537319200602,finalStatus=SUCCEEDED,memorySeconds=47203,vcoreSeconds=24,preemptedMemorySeconds=0,preemptedVcoreSeconds=0,preemptedAMContainers=0,preemptedNonAMContainers=0,preemptedResources=<memory:0\, vCores:0>,applicationType=MAPREDUCE
2018-09-18 20:06:48,797 INFO org.apache.hadoop.yarn.server.resourcemanager.scheduler.AbstractYarnScheduler: Container container_1536878829533_0004_01_000003 completed with event FINISHED, but corresponding RMContainer doesn't exist.
2018-09-18 20:07:08,298 INFO org.apache.hadoop.ipc.Server: Socket Reader #1 for port 8031: readAndProcess from client 192.168.1.103 threw exception [java.io.IOException: Connection reset by peer]
java.io.IOException: Connection reset by peer
	at sun.nio.ch.FileDispatcherImpl.read0(Native Method)
	at sun.nio.ch.SocketDispatcher.read(SocketDispatcher.java:39)
	at sun.nio.ch.IOUtil.readIntoNativeBuffer(IOUtil.java:223)
	at sun.nio.ch.IOUtil.read(IOUtil.java:197)
	at sun.nio.ch.SocketChannelImpl.read(SocketChannelImpl.java:380)
	at org.apache.hadoop.ipc.Server.channelRead(Server.java:3020)
	at org.apache.hadoop.ipc.Server.access$2400(Server.java:134)
	at org.apache.hadoop.ipc.Server$Connection.readAndProcess(Server.java:1869)
	at org.apache.hadoop.ipc.Server$Listener.doRead(Server.java:1125)
	at org.apache.hadoop.ipc.Server$Listener$Reader.doRunLoop(Server.java:982)
	at org.apache.hadoop.ipc.Server$Listener$Reader.run(Server.java:953)
2018-09-18 20:15:11,207 INFO org.apache.hadoop.ipc.Server: Socket Reader #1 for port 8031: readAndProcess from client 10.159.0.246 threw exception [java.io.IOException: Operation timed out]
java.io.IOException: Operation timed out
	at sun.nio.ch.FileDispatcherImpl.read0(Native Method)
	at sun.nio.ch.SocketDispatcher.read(SocketDispatcher.java:39)
	at sun.nio.ch.IOUtil.readIntoNativeBuffer(IOUtil.java:223)
	at sun.nio.ch.IOUtil.read(IOUtil.java:197)
	at sun.nio.ch.SocketChannelImpl.read(SocketChannelImpl.java:380)
	at org.apache.hadoop.ipc.Server.channelRead(Server.java:3020)
	at org.apache.hadoop.ipc.Server.access$2400(Server.java:134)
	at org.apache.hadoop.ipc.Server$Connection.readAndProcess(Server.java:1869)
	at org.apache.hadoop.ipc.Server$Listener.doRead(Server.java:1125)
	at org.apache.hadoop.ipc.Server$Listener$Reader.doRunLoop(Server.java:982)
	at org.apache.hadoop.ipc.Server$Listener$Reader.run(Server.java:953)
2018-09-18 20:16:56,871 INFO org.apache.hadoop.ipc.Server: Socket Reader #1 for port 8031: readAndProcess from client 10.43.0.124 threw exception [java.io.IOException: Operation timed out]
java.io.IOException: Operation timed out
	at sun.nio.ch.FileDispatcherImpl.read0(Native Method)
	at sun.nio.ch.SocketDispatcher.read(SocketDispatcher.java:39)
	at sun.nio.ch.IOUtil.readIntoNativeBuffer(IOUtil.java:223)
	at sun.nio.ch.IOUtil.read(IOUtil.java:197)
	at sun.nio.ch.SocketChannelImpl.read(SocketChannelImpl.java:380)
	at org.apache.hadoop.ipc.Server.channelRead(Server.java:3020)
	at org.apache.hadoop.ipc.Server.access$2400(Server.java:134)
	at org.apache.hadoop.ipc.Server$Connection.readAndProcess(Server.java:1869)
	at org.apache.hadoop.ipc.Server$Listener.doRead(Server.java:1125)
	at org.apache.hadoop.ipc.Server$Listener$Reader.doRunLoop(Server.java:982)
	at org.apache.hadoop.ipc.Server$Listener$Reader.run(Server.java:953)
2018-09-18 21:37:51,103 INFO org.apache.hadoop.ipc.Server: Socket Reader #1 for port 8031: readAndProcess from client 10.169.1.149 threw exception [java.io.IOException: Operation timed out]
java.io.IOException: Operation timed out
	at sun.nio.ch.FileDispatcherImpl.read0(Native Method)
	at sun.nio.ch.SocketDispatcher.read(SocketDispatcher.java:39)
	at sun.nio.ch.IOUtil.readIntoNativeBuffer(IOUtil.java:223)
	at sun.nio.ch.IOUtil.read(IOUtil.java:197)
	at sun.nio.ch.SocketChannelImpl.read(SocketChannelImpl.java:380)
	at org.apache.hadoop.ipc.Server.channelRead(Server.java:3020)
	at org.apache.hadoop.ipc.Server.access$2400(Server.java:134)
	at org.apache.hadoop.ipc.Server$Connection.readAndProcess(Server.java:1869)
	at org.apache.hadoop.ipc.Server$Listener.doRead(Server.java:1125)
	at org.apache.hadoop.ipc.Server$Listener$Reader.doRunLoop(Server.java:982)
	at org.apache.hadoop.ipc.Server$Listener$Reader.run(Server.java:953)
2018-09-18 22:15:37,873 INFO org.apache.hadoop.ipc.Server: Socket Reader #1 for port 8031: readAndProcess from client 10.159.0.40 threw exception [java.io.IOException: Operation timed out]
java.io.IOException: Operation timed out
	at sun.nio.ch.FileDispatcherImpl.read0(Native Method)
	at sun.nio.ch.SocketDispatcher.read(SocketDispatcher.java:39)
	at sun.nio.ch.IOUtil.readIntoNativeBuffer(IOUtil.java:223)
	at sun.nio.ch.IOUtil.read(IOUtil.java:197)
	at sun.nio.ch.SocketChannelImpl.read(SocketChannelImpl.java:380)
	at org.apache.hadoop.ipc.Server.channelRead(Server.java:3020)
	at org.apache.hadoop.ipc.Server.access$2400(Server.java:134)
	at org.apache.hadoop.ipc.Server$Connection.readAndProcess(Server.java:1869)
	at org.apache.hadoop.ipc.Server$Listener.doRead(Server.java:1125)
	at org.apache.hadoop.ipc.Server$Listener$Reader.doRunLoop(Server.java:982)
	at org.apache.hadoop.ipc.Server$Listener$Reader.run(Server.java:953)
2018-09-19 11:51:35,511 INFO org.apache.hadoop.yarn.server.resourcemanager.ClientRMService: Allocated new applicationId: 5
2018-09-19 11:51:36,021 INFO org.apache.hadoop.yarn.server.resourcemanager.scheduler.capacity.CapacityScheduler: Application 'application_1536878829533_0005' is submitted without priority hence considering default queue/cluster priority: 0
2018-09-19 11:51:36,021 INFO org.apache.hadoop.yarn.server.resourcemanager.scheduler.capacity.CapacityScheduler: Priority '0' is acceptable in queue : default for application: application_1536878829533_0005 for the user: jason
2018-09-19 11:51:36,022 INFO org.apache.hadoop.yarn.server.resourcemanager.ClientRMService: Application with id 5 submitted by user jason
2018-09-19 11:51:36,022 INFO org.apache.hadoop.yarn.server.resourcemanager.RMAuditLogger: USER=jason	IP=192.168.1.103	OPERATION=Submit Application Request	TARGET=ClientRMService	RESULT=SUCCESS	APPID=application_1536878829533_0005
2018-09-19 11:51:36,022 INFO org.apache.hadoop.yarn.server.resourcemanager.rmapp.RMAppImpl: Storing application with id application_1536878829533_0005
2018-09-19 11:51:36,022 INFO org.apache.hadoop.yarn.server.resourcemanager.rmapp.RMAppImpl: application_1536878829533_0005 State change from NEW to NEW_SAVING on event=START
2018-09-19 11:51:36,022 INFO org.apache.hadoop.yarn.server.resourcemanager.recovery.RMStateStore: Storing info for app: application_1536878829533_0005
2018-09-19 11:51:36,022 INFO org.apache.hadoop.yarn.server.resourcemanager.rmapp.RMAppImpl: application_1536878829533_0005 State change from NEW_SAVING to SUBMITTED on event=APP_NEW_SAVED
2018-09-19 11:51:36,022 INFO org.apache.hadoop.yarn.server.resourcemanager.scheduler.capacity.ParentQueue: Application added - appId: application_1536878829533_0005 user: jason leaf-queue of parent: root #applications: 1
2018-09-19 11:51:36,022 INFO org.apache.hadoop.yarn.server.resourcemanager.scheduler.capacity.CapacityScheduler: Accepted application application_1536878829533_0005 from user: jason, in queue: default
2018-09-19 11:51:36,023 INFO org.apache.hadoop.yarn.server.resourcemanager.rmapp.RMAppImpl: application_1536878829533_0005 State change from SUBMITTED to ACCEPTED on event=APP_ACCEPTED
2018-09-19 11:51:36,024 INFO org.apache.hadoop.yarn.server.resourcemanager.ApplicationMasterService: Registering app attempt : appattempt_1536878829533_0005_000001
2018-09-19 11:51:36,024 INFO org.apache.hadoop.yarn.server.resourcemanager.rmapp.attempt.RMAppAttemptImpl: appattempt_1536878829533_0005_000001 State change from NEW to SUBMITTED
2018-09-19 11:51:36,024 WARN org.apache.hadoop.yarn.server.resourcemanager.scheduler.capacity.LeafQueue: maximum-am-resource-percent is insufficient to start a single application in queue, it is likely set too low. skipping enforcement to allow at least one application to start
2018-09-19 11:51:36,024 WARN org.apache.hadoop.yarn.server.resourcemanager.scheduler.capacity.LeafQueue: maximum-am-resource-percent is insufficient to start a single application in queue for user, it is likely set too low. skipping enforcement to allow at least one application to start
2018-09-19 11:51:36,024 INFO org.apache.hadoop.yarn.server.resourcemanager.scheduler.capacity.LeafQueue: Application application_1536878829533_0005 from user: jason activated in queue: default
2018-09-19 11:51:36,024 INFO org.apache.hadoop.yarn.server.resourcemanager.scheduler.capacity.LeafQueue: Application added - appId: application_1536878829533_0005 user: jason, leaf-queue: default #user-pending-applications: 0 #user-active-applications: 1 #queue-pending-applications: 0 #queue-active-applications: 1
2018-09-19 11:51:36,024 INFO org.apache.hadoop.yarn.server.resourcemanager.scheduler.capacity.CapacityScheduler: Added Application Attempt appattempt_1536878829533_0005_000001 to scheduler from user jason in queue default
2018-09-19 11:51:36,025 INFO org.apache.hadoop.yarn.server.resourcemanager.rmapp.attempt.RMAppAttemptImpl: appattempt_1536878829533_0005_000001 State change from SUBMITTED to SCHEDULED
2018-09-19 11:51:36,148 INFO org.apache.hadoop.yarn.server.resourcemanager.rmcontainer.RMContainerImpl: container_1536878829533_0005_01_000001 Container Transitioned from NEW to ALLOCATED
2018-09-19 11:51:36,148 INFO org.apache.hadoop.yarn.server.resourcemanager.RMAuditLogger: USER=jason	OPERATION=AM Allocated Container	TARGET=SchedulerApp	RESULT=SUCCESS	APPID=application_1536878829533_0005	CONTAINERID=container_1536878829533_0005_01_000001
2018-09-19 11:51:36,148 INFO org.apache.hadoop.yarn.server.resourcemanager.scheduler.SchedulerNode: Assigned container container_1536878829533_0005_01_000001 of capacity <memory:2048, vCores:1> on host 192.168.1.103:56395, which has 1 containers, <memory:2048, vCores:1> used and <memory:6144, vCores:7> available after allocation
2018-09-19 11:51:36,148 INFO org.apache.hadoop.yarn.server.resourcemanager.scheduler.capacity.allocator.AbstractContainerAllocator: assignedContainer application attempt=appattempt_1536878829533_0005_000001 container=container_1536878829533_0005_01_000001 queue=org.apache.hadoop.yarn.server.resourcemanager.scheduler.capacity.allocator.RegularContainerAllocator@66312ccb clusterResource=<memory:8192, vCores:8> type=OFF_SWITCH
2018-09-19 11:51:36,149 INFO org.apache.hadoop.yarn.server.resourcemanager.security.NMTokenSecretManagerInRM: Sending NMToken for nodeId : 192.168.1.103:56395 for container : container_1536878829533_0005_01_000001
2018-09-19 11:51:36,150 INFO org.apache.hadoop.yarn.server.resourcemanager.rmcontainer.RMContainerImpl: container_1536878829533_0005_01_000001 Container Transitioned from ALLOCATED to ACQUIRED
2018-09-19 11:51:36,150 INFO org.apache.hadoop.yarn.server.resourcemanager.security.NMTokenSecretManagerInRM: Clear node set for appattempt_1536878829533_0005_000001
2018-09-19 11:51:36,150 INFO org.apache.hadoop.yarn.server.resourcemanager.rmapp.attempt.RMAppAttemptImpl: Storing attempt: AppId: application_1536878829533_0005 AttemptId: appattempt_1536878829533_0005_000001 MasterContainer: Container: [ContainerId: container_1536878829533_0005_01_000001, Version: 0, NodeId: 192.168.1.103:56395, NodeHttpAddress: 192.168.1.103:8042, Resource: <memory:2048, vCores:1>, Priority: 0, Token: Token { kind: ContainerToken, service: 192.168.1.103:56395 }, ]
2018-09-19 11:51:36,150 INFO org.apache.hadoop.yarn.server.resourcemanager.scheduler.capacity.ParentQueue: Re-sorting assigned queue: root.default stats: default: capacity=1.0, absoluteCapacity=1.0, usedResources=<memory:2048, vCores:1>, usedCapacity=0.25, absoluteUsedCapacity=0.25, numApps=1, numContainers=1
2018-09-19 11:51:36,150 INFO org.apache.hadoop.yarn.server.resourcemanager.rmapp.attempt.RMAppAttemptImpl: appattempt_1536878829533_0005_000001 State change from SCHEDULED to ALLOCATED_SAVING
2018-09-19 11:51:36,150 INFO org.apache.hadoop.yarn.server.resourcemanager.scheduler.capacity.ParentQueue: assignedContainer queue=root usedCapacity=0.25 absoluteUsedCapacity=0.25 used=<memory:2048, vCores:1> cluster=<memory:8192, vCores:8>
2018-09-19 11:51:36,150 INFO org.apache.hadoop.yarn.server.resourcemanager.rmapp.attempt.RMAppAttemptImpl: appattempt_1536878829533_0005_000001 State change from ALLOCATED_SAVING to ALLOCATED
2018-09-19 11:51:36,150 INFO org.apache.hadoop.yarn.server.resourcemanager.amlauncher.AMLauncher: Launching masterappattempt_1536878829533_0005_000001
2018-09-19 11:51:36,163 INFO org.apache.hadoop.yarn.server.resourcemanager.amlauncher.AMLauncher: Setting up container Container: [ContainerId: container_1536878829533_0005_01_000001, Version: 0, NodeId: 192.168.1.103:56395, NodeHttpAddress: 192.168.1.103:8042, Resource: <memory:2048, vCores:1>, Priority: 0, Token: Token { kind: ContainerToken, service: 192.168.1.103:56395 }, ] for AM appattempt_1536878829533_0005_000001
2018-09-19 11:51:36,163 INFO org.apache.hadoop.yarn.server.resourcemanager.security.AMRMTokenSecretManager: Create AMRMToken for ApplicationAttempt: appattempt_1536878829533_0005_000001
2018-09-19 11:51:36,163 INFO org.apache.hadoop.yarn.server.resourcemanager.security.AMRMTokenSecretManager: Creating password for appattempt_1536878829533_0005_000001
2018-09-19 11:51:36,175 INFO org.apache.hadoop.yarn.server.resourcemanager.amlauncher.AMLauncher: Done launching container Container: [ContainerId: container_1536878829533_0005_01_000001, Version: 0, NodeId: 192.168.1.103:56395, NodeHttpAddress: 192.168.1.103:8042, Resource: <memory:2048, vCores:1>, Priority: 0, Token: Token { kind: ContainerToken, service: 192.168.1.103:56395 }, ] for AM appattempt_1536878829533_0005_000001
2018-09-19 11:51:36,175 INFO org.apache.hadoop.yarn.server.resourcemanager.rmapp.attempt.RMAppAttemptImpl: appattempt_1536878829533_0005_000001 State change from ALLOCATED to LAUNCHED
2018-09-19 11:51:37,151 INFO org.apache.hadoop.yarn.server.resourcemanager.rmcontainer.RMContainerImpl: container_1536878829533_0005_01_000001 Container Transitioned from ACQUIRED to RUNNING
2018-09-19 11:51:39,711 INFO SecurityLogger.org.apache.hadoop.ipc.Server: Auth successful for appattempt_1536878829533_0005_000001 (auth:SIMPLE)
2018-09-19 11:51:39,716 INFO org.apache.hadoop.yarn.server.resourcemanager.ApplicationMasterService: AM registration appattempt_1536878829533_0005_000001
2018-09-19 11:51:39,716 INFO org.apache.hadoop.yarn.server.resourcemanager.RMAuditLogger: USER=jason	IP=192.168.1.103	OPERATION=Register App Master	TARGET=ApplicationMasterService	RESULT=SUCCESS	APPID=application_1536878829533_0005	APPATTEMPTID=appattempt_1536878829533_0005_000001
2018-09-19 11:51:39,716 INFO org.apache.hadoop.yarn.server.resourcemanager.rmapp.attempt.RMAppAttemptImpl: appattempt_1536878829533_0005_000001 State change from LAUNCHED to RUNNING
2018-09-19 11:51:39,716 INFO org.apache.hadoop.yarn.server.resourcemanager.rmapp.RMAppImpl: application_1536878829533_0005 State change from ACCEPTED to RUNNING on event=ATTEMPT_REGISTERED
2018-09-19 11:51:41,164 INFO org.apache.hadoop.yarn.server.resourcemanager.rmcontainer.RMContainerImpl: container_1536878829533_0005_01_000002 Container Transitioned from NEW to ALLOCATED
2018-09-19 11:51:41,164 INFO org.apache.hadoop.yarn.server.resourcemanager.RMAuditLogger: USER=jason	OPERATION=AM Allocated Container	TARGET=SchedulerApp	RESULT=SUCCESS	APPID=application_1536878829533_0005	CONTAINERID=container_1536878829533_0005_01_000002
2018-09-19 11:51:41,164 INFO org.apache.hadoop.yarn.server.resourcemanager.scheduler.SchedulerNode: Assigned container container_1536878829533_0005_01_000002 of capacity <memory:1024, vCores:1> on host 192.168.1.103:56395, which has 2 containers, <memory:3072, vCores:2> used and <memory:5120, vCores:6> available after allocation
2018-09-19 11:51:41,164 INFO org.apache.hadoop.yarn.server.resourcemanager.scheduler.capacity.allocator.AbstractContainerAllocator: assignedContainer application attempt=appattempt_1536878829533_0005_000001 container=container_1536878829533_0005_01_000002 queue=org.apache.hadoop.yarn.server.resourcemanager.scheduler.capacity.allocator.RegularContainerAllocator@66312ccb clusterResource=<memory:8192, vCores:8> type=NODE_LOCAL
2018-09-19 11:51:41,165 INFO org.apache.hadoop.yarn.server.resourcemanager.scheduler.capacity.ParentQueue: Re-sorting assigned queue: root.default stats: default: capacity=1.0, absoluteCapacity=1.0, usedResources=<memory:3072, vCores:2>, usedCapacity=0.375, absoluteUsedCapacity=0.375, numApps=1, numContainers=2
2018-09-19 11:51:41,165 INFO org.apache.hadoop.yarn.server.resourcemanager.scheduler.capacity.ParentQueue: assignedContainer queue=root usedCapacity=0.375 absoluteUsedCapacity=0.375 used=<memory:3072, vCores:2> cluster=<memory:8192, vCores:8>
2018-09-19 11:51:41,165 INFO org.apache.hadoop.yarn.server.resourcemanager.rmcontainer.RMContainerImpl: container_1536878829533_0005_01_000003 Container Transitioned from NEW to ALLOCATED
2018-09-19 11:51:41,165 INFO org.apache.hadoop.yarn.server.resourcemanager.RMAuditLogger: USER=jason	OPERATION=AM Allocated Container	TARGET=SchedulerApp	RESULT=SUCCESS	APPID=application_1536878829533_0005	CONTAINERID=container_1536878829533_0005_01_000003
2018-09-19 11:51:41,165 INFO org.apache.hadoop.yarn.server.resourcemanager.scheduler.SchedulerNode: Assigned container container_1536878829533_0005_01_000003 of capacity <memory:1024, vCores:1> on host 192.168.1.103:56395, which has 3 containers, <memory:4096, vCores:3> used and <memory:4096, vCores:5> available after allocation
2018-09-19 11:51:41,165 INFO org.apache.hadoop.yarn.server.resourcemanager.scheduler.capacity.allocator.AbstractContainerAllocator: assignedContainer application attempt=appattempt_1536878829533_0005_000001 container=container_1536878829533_0005_01_000003 queue=org.apache.hadoop.yarn.server.resourcemanager.scheduler.capacity.allocator.RegularContainerAllocator@66312ccb clusterResource=<memory:8192, vCores:8> type=NODE_LOCAL
2018-09-19 11:51:41,165 INFO org.apache.hadoop.yarn.server.resourcemanager.scheduler.capacity.ParentQueue: Re-sorting assigned queue: root.default stats: default: capacity=1.0, absoluteCapacity=1.0, usedResources=<memory:4096, vCores:3>, usedCapacity=0.5, absoluteUsedCapacity=0.5, numApps=1, numContainers=3
2018-09-19 11:51:41,165 INFO org.apache.hadoop.yarn.server.resourcemanager.scheduler.capacity.ParentQueue: assignedContainer queue=root usedCapacity=0.5 absoluteUsedCapacity=0.5 used=<memory:4096, vCores:3> cluster=<memory:8192, vCores:8>
2018-09-19 11:51:41,165 INFO org.apache.hadoop.yarn.server.resourcemanager.rmcontainer.RMContainerImpl: container_1536878829533_0005_01_000004 Container Transitioned from NEW to ALLOCATED
2018-09-19 11:51:41,166 INFO org.apache.hadoop.yarn.server.resourcemanager.RMAuditLogger: USER=jason	OPERATION=AM Allocated Container	TARGET=SchedulerApp	RESULT=SUCCESS	APPID=application_1536878829533_0005	CONTAINERID=container_1536878829533_0005_01_000004
2018-09-19 11:51:41,166 INFO org.apache.hadoop.yarn.server.resourcemanager.scheduler.SchedulerNode: Assigned container container_1536878829533_0005_01_000004 of capacity <memory:1024, vCores:1> on host 192.168.1.103:56395, which has 4 containers, <memory:5120, vCores:4> used and <memory:3072, vCores:4> available after allocation
2018-09-19 11:51:41,166 INFO org.apache.hadoop.yarn.server.resourcemanager.scheduler.capacity.allocator.AbstractContainerAllocator: assignedContainer application attempt=appattempt_1536878829533_0005_000001 container=container_1536878829533_0005_01_000004 queue=org.apache.hadoop.yarn.server.resourcemanager.scheduler.capacity.allocator.RegularContainerAllocator@66312ccb clusterResource=<memory:8192, vCores:8> type=NODE_LOCAL
2018-09-19 11:51:41,166 INFO org.apache.hadoop.yarn.server.resourcemanager.scheduler.capacity.ParentQueue: Re-sorting assigned queue: root.default stats: default: capacity=1.0, absoluteCapacity=1.0, usedResources=<memory:5120, vCores:4>, usedCapacity=0.625, absoluteUsedCapacity=0.625, numApps=1, numContainers=4
2018-09-19 11:51:41,166 INFO org.apache.hadoop.yarn.server.resourcemanager.scheduler.capacity.ParentQueue: assignedContainer queue=root usedCapacity=0.625 absoluteUsedCapacity=0.625 used=<memory:5120, vCores:4> cluster=<memory:8192, vCores:8>
2018-09-19 11:51:41,172 INFO org.apache.hadoop.yarn.server.resourcemanager.rmcontainer.RMContainerImpl: container_1536878829533_0005_01_000005 Container Transitioned from NEW to ALLOCATED
2018-09-19 11:51:41,172 INFO org.apache.hadoop.yarn.server.resourcemanager.RMAuditLogger: USER=jason	OPERATION=AM Allocated Container	TARGET=SchedulerApp	RESULT=SUCCESS	APPID=application_1536878829533_0005	CONTAINERID=container_1536878829533_0005_01_000005
2018-09-19 11:51:41,172 INFO org.apache.hadoop.yarn.server.resourcemanager.scheduler.SchedulerNode: Assigned container container_1536878829533_0005_01_000005 of capacity <memory:1024, vCores:1> on host 192.168.1.103:56395, which has 5 containers, <memory:6144, vCores:5> used and <memory:2048, vCores:3> available after allocation
2018-09-19 11:51:41,173 INFO org.apache.hadoop.yarn.server.resourcemanager.scheduler.capacity.allocator.AbstractContainerAllocator: assignedContainer application attempt=appattempt_1536878829533_0005_000001 container=container_1536878829533_0005_01_000005 queue=org.apache.hadoop.yarn.server.resourcemanager.scheduler.capacity.allocator.RegularContainerAllocator@66312ccb clusterResource=<memory:8192, vCores:8> type=NODE_LOCAL
2018-09-19 11:51:41,173 INFO org.apache.hadoop.yarn.server.resourcemanager.scheduler.capacity.ParentQueue: Re-sorting assigned queue: root.default stats: default: capacity=1.0, absoluteCapacity=1.0, usedResources=<memory:6144, vCores:5>, usedCapacity=0.75, absoluteUsedCapacity=0.75, numApps=1, numContainers=5
2018-09-19 11:51:41,173 INFO org.apache.hadoop.yarn.server.resourcemanager.scheduler.capacity.ParentQueue: assignedContainer queue=root usedCapacity=0.75 absoluteUsedCapacity=0.75 used=<memory:6144, vCores:5> cluster=<memory:8192, vCores:8>
2018-09-19 11:51:41,174 INFO org.apache.hadoop.yarn.server.resourcemanager.rmcontainer.RMContainerImpl: container_1536878829533_0005_01_000006 Container Transitioned from NEW to ALLOCATED
2018-09-19 11:51:41,174 INFO org.apache.hadoop.yarn.server.resourcemanager.RMAuditLogger: USER=jason	OPERATION=AM Allocated Container	TARGET=SchedulerApp	RESULT=SUCCESS	APPID=application_1536878829533_0005	CONTAINERID=container_1536878829533_0005_01_000006
2018-09-19 11:51:41,174 INFO org.apache.hadoop.yarn.server.resourcemanager.scheduler.SchedulerNode: Assigned container container_1536878829533_0005_01_000006 of capacity <memory:1024, vCores:1> on host 192.168.1.103:56395, which has 6 containers, <memory:7168, vCores:6> used and <memory:1024, vCores:2> available after allocation
2018-09-19 11:51:41,174 INFO org.apache.hadoop.yarn.server.resourcemanager.scheduler.capacity.allocator.AbstractContainerAllocator: assignedContainer application attempt=appattempt_1536878829533_0005_000001 container=container_1536878829533_0005_01_000006 queue=org.apache.hadoop.yarn.server.resourcemanager.scheduler.capacity.allocator.RegularContainerAllocator@66312ccb clusterResource=<memory:8192, vCores:8> type=NODE_LOCAL
2018-09-19 11:51:41,174 INFO org.apache.hadoop.yarn.server.resourcemanager.scheduler.capacity.ParentQueue: Re-sorting assigned queue: root.default stats: default: capacity=1.0, absoluteCapacity=1.0, usedResources=<memory:7168, vCores:6>, usedCapacity=0.875, absoluteUsedCapacity=0.875, numApps=1, numContainers=6
2018-09-19 11:51:41,174 INFO org.apache.hadoop.yarn.server.resourcemanager.scheduler.capacity.ParentQueue: assignedContainer queue=root usedCapacity=0.875 absoluteUsedCapacity=0.875 used=<memory:7168, vCores:6> cluster=<memory:8192, vCores:8>
2018-09-19 11:51:41,175 INFO org.apache.hadoop.yarn.server.resourcemanager.rmcontainer.RMContainerImpl: container_1536878829533_0005_01_000007 Container Transitioned from NEW to ALLOCATED
2018-09-19 11:51:41,175 INFO org.apache.hadoop.yarn.server.resourcemanager.RMAuditLogger: USER=jason	OPERATION=AM Allocated Container	TARGET=SchedulerApp	RESULT=SUCCESS	APPID=application_1536878829533_0005	CONTAINERID=container_1536878829533_0005_01_000007
2018-09-19 11:51:41,175 INFO org.apache.hadoop.yarn.server.resourcemanager.scheduler.SchedulerNode: Assigned container container_1536878829533_0005_01_000007 of capacity <memory:1024, vCores:1> on host 192.168.1.103:56395, which has 7 containers, <memory:8192, vCores:7> used and <memory:0, vCores:1> available after allocation
2018-09-19 11:51:41,175 INFO org.apache.hadoop.yarn.server.resourcemanager.scheduler.capacity.allocator.AbstractContainerAllocator: assignedContainer application attempt=appattempt_1536878829533_0005_000001 container=container_1536878829533_0005_01_000007 queue=org.apache.hadoop.yarn.server.resourcemanager.scheduler.capacity.allocator.RegularContainerAllocator@66312ccb clusterResource=<memory:8192, vCores:8> type=NODE_LOCAL
2018-09-19 11:51:41,176 INFO org.apache.hadoop.yarn.server.resourcemanager.scheduler.capacity.ParentQueue: Re-sorting assigned queue: root.default stats: default: capacity=1.0, absoluteCapacity=1.0, usedResources=<memory:8192, vCores:7>, usedCapacity=1.0, absoluteUsedCapacity=1.0, numApps=1, numContainers=7
2018-09-19 11:51:41,176 INFO org.apache.hadoop.yarn.server.resourcemanager.scheduler.capacity.ParentQueue: assignedContainer queue=root usedCapacity=1.0 absoluteUsedCapacity=1.0 used=<memory:8192, vCores:7> cluster=<memory:8192, vCores:8>
2018-09-19 11:51:41,772 INFO org.apache.hadoop.yarn.server.resourcemanager.security.NMTokenSecretManagerInRM: Sending NMToken for nodeId : 192.168.1.103:56395 for container : container_1536878829533_0005_01_000002
2018-09-19 11:51:41,773 INFO org.apache.hadoop.yarn.server.resourcemanager.rmcontainer.RMContainerImpl: container_1536878829533_0005_01_000002 Container Transitioned from ALLOCATED to ACQUIRED
2018-09-19 11:51:41,774 INFO org.apache.hadoop.yarn.server.resourcemanager.rmcontainer.RMContainerImpl: container_1536878829533_0005_01_000003 Container Transitioned from ALLOCATED to ACQUIRED
2018-09-19 11:51:41,775 INFO org.apache.hadoop.yarn.server.resourcemanager.rmcontainer.RMContainerImpl: container_1536878829533_0005_01_000004 Container Transitioned from ALLOCATED to ACQUIRED
2018-09-19 11:51:41,776 INFO org.apache.hadoop.yarn.server.resourcemanager.rmcontainer.RMContainerImpl: container_1536878829533_0005_01_000005 Container Transitioned from ALLOCATED to ACQUIRED
2018-09-19 11:51:41,777 INFO org.apache.hadoop.yarn.server.resourcemanager.rmcontainer.RMContainerImpl: container_1536878829533_0005_01_000006 Container Transitioned from ALLOCATED to ACQUIRED
2018-09-19 11:51:41,778 INFO org.apache.hadoop.yarn.server.resourcemanager.rmcontainer.RMContainerImpl: container_1536878829533_0005_01_000007 Container Transitioned from ALLOCATED to ACQUIRED
2018-09-19 11:51:42,168 INFO org.apache.hadoop.yarn.server.resourcemanager.rmcontainer.RMContainerImpl: container_1536878829533_0005_01_000002 Container Transitioned from ACQUIRED to RUNNING
2018-09-19 11:51:42,169 INFO org.apache.hadoop.yarn.server.resourcemanager.rmcontainer.RMContainerImpl: container_1536878829533_0005_01_000003 Container Transitioned from ACQUIRED to RUNNING
2018-09-19 11:51:42,170 INFO org.apache.hadoop.yarn.server.resourcemanager.rmcontainer.RMContainerImpl: container_1536878829533_0005_01_000004 Container Transitioned from ACQUIRED to RUNNING
2018-09-19 11:51:42,170 INFO org.apache.hadoop.yarn.server.resourcemanager.rmcontainer.RMContainerImpl: container_1536878829533_0005_01_000005 Container Transitioned from ACQUIRED to RUNNING
2018-09-19 11:51:42,172 INFO org.apache.hadoop.yarn.server.resourcemanager.rmcontainer.RMContainerImpl: container_1536878829533_0005_01_000006 Container Transitioned from ACQUIRED to RUNNING
2018-09-19 11:51:42,172 INFO org.apache.hadoop.yarn.server.resourcemanager.rmcontainer.RMContainerImpl: container_1536878829533_0005_01_000007 Container Transitioned from ACQUIRED to RUNNING
2018-09-19 11:51:48,188 INFO org.apache.hadoop.yarn.server.resourcemanager.rmcontainer.RMContainerImpl: container_1536878829533_0005_01_000002 Container Transitioned from RUNNING to COMPLETED
2018-09-19 11:51:48,188 INFO org.apache.hadoop.yarn.server.resourcemanager.RMAuditLogger: USER=jason	OPERATION=AM Released Container	TARGET=SchedulerApp	RESULT=SUCCESS	APPID=application_1536878829533_0005	CONTAINERID=container_1536878829533_0005_01_000002
2018-09-19 11:51:48,188 INFO org.apache.hadoop.yarn.server.resourcemanager.scheduler.SchedulerNode: Released container container_1536878829533_0005_01_000002 of capacity <memory:1024, vCores:1> on host 192.168.1.103:56395, which currently has 6 containers, <memory:7168, vCores:6> used and <memory:1024, vCores:2> available, release resources=true
2018-09-19 11:51:48,189 INFO org.apache.hadoop.yarn.server.resourcemanager.rmcontainer.RMContainerImpl: container_1536878829533_0005_01_000008 Container Transitioned from NEW to ALLOCATED
2018-09-19 11:51:48,189 INFO org.apache.hadoop.yarn.server.resourcemanager.RMAuditLogger: USER=jason	OPERATION=AM Allocated Container	TARGET=SchedulerApp	RESULT=SUCCESS	APPID=application_1536878829533_0005	CONTAINERID=container_1536878829533_0005_01_000008
2018-09-19 11:51:48,189 INFO org.apache.hadoop.yarn.server.resourcemanager.scheduler.SchedulerNode: Assigned container container_1536878829533_0005_01_000008 of capacity <memory:1024, vCores:1> on host 192.168.1.103:56395, which has 7 containers, <memory:8192, vCores:7> used and <memory:0, vCores:1> available after allocation
2018-09-19 11:51:48,189 INFO org.apache.hadoop.yarn.server.resourcemanager.scheduler.capacity.allocator.AbstractContainerAllocator: assignedContainer application attempt=appattempt_1536878829533_0005_000001 container=container_1536878829533_0005_01_000008 queue=org.apache.hadoop.yarn.server.resourcemanager.scheduler.capacity.allocator.RegularContainerAllocator@66312ccb clusterResource=<memory:8192, vCores:8> type=NODE_LOCAL
2018-09-19 11:51:48,189 INFO org.apache.hadoop.yarn.server.resourcemanager.scheduler.capacity.ParentQueue: Re-sorting assigned queue: root.default stats: default: capacity=1.0, absoluteCapacity=1.0, usedResources=<memory:8192, vCores:7>, usedCapacity=1.0, absoluteUsedCapacity=1.0, numApps=1, numContainers=7
2018-09-19 11:51:48,189 INFO org.apache.hadoop.yarn.server.resourcemanager.scheduler.capacity.ParentQueue: assignedContainer queue=root usedCapacity=1.0 absoluteUsedCapacity=1.0 used=<memory:8192, vCores:7> cluster=<memory:8192, vCores:8>
2018-09-19 11:51:48,273 INFO org.apache.hadoop.yarn.server.resourcemanager.rmcontainer.RMContainerImpl: container_1536878829533_0005_01_000007 Container Transitioned from RUNNING to COMPLETED
2018-09-19 11:51:48,273 INFO org.apache.hadoop.yarn.server.resourcemanager.RMAuditLogger: USER=jason	OPERATION=AM Released Container	TARGET=SchedulerApp	RESULT=SUCCESS	APPID=application_1536878829533_0005	CONTAINERID=container_1536878829533_0005_01_000007
2018-09-19 11:51:48,274 INFO org.apache.hadoop.yarn.server.resourcemanager.scheduler.SchedulerNode: Released container container_1536878829533_0005_01_000007 of capacity <memory:1024, vCores:1> on host 192.168.1.103:56395, which currently has 6 containers, <memory:7168, vCores:6> used and <memory:1024, vCores:2> available, release resources=true
2018-09-19 11:51:48,275 INFO org.apache.hadoop.yarn.server.resourcemanager.rmcontainer.RMContainerImpl: container_1536878829533_0005_01_000009 Container Transitioned from NEW to ALLOCATED
2018-09-19 11:51:48,275 INFO org.apache.hadoop.yarn.server.resourcemanager.RMAuditLogger: USER=jason	OPERATION=AM Allocated Container	TARGET=SchedulerApp	RESULT=SUCCESS	APPID=application_1536878829533_0005	CONTAINERID=container_1536878829533_0005_01_000009
2018-09-19 11:51:48,275 INFO org.apache.hadoop.yarn.server.resourcemanager.scheduler.SchedulerNode: Assigned container container_1536878829533_0005_01_000009 of capacity <memory:1024, vCores:1> on host 192.168.1.103:56395, which has 7 containers, <memory:8192, vCores:7> used and <memory:0, vCores:1> available after allocation
2018-09-19 11:51:48,275 INFO org.apache.hadoop.yarn.server.resourcemanager.scheduler.capacity.allocator.AbstractContainerAllocator: assignedContainer application attempt=appattempt_1536878829533_0005_000001 container=container_1536878829533_0005_01_000009 queue=org.apache.hadoop.yarn.server.resourcemanager.scheduler.capacity.allocator.RegularContainerAllocator@66312ccb clusterResource=<memory:8192, vCores:8> type=NODE_LOCAL
2018-09-19 11:51:48,275 INFO org.apache.hadoop.yarn.server.resourcemanager.scheduler.capacity.ParentQueue: Re-sorting assigned queue: root.default stats: default: capacity=1.0, absoluteCapacity=1.0, usedResources=<memory:8192, vCores:7>, usedCapacity=1.0, absoluteUsedCapacity=1.0, numApps=1, numContainers=7
2018-09-19 11:51:48,275 INFO org.apache.hadoop.yarn.server.resourcemanager.scheduler.capacity.ParentQueue: assignedContainer queue=root usedCapacity=1.0 absoluteUsedCapacity=1.0 used=<memory:8192, vCores:7> cluster=<memory:8192, vCores:8>
2018-09-19 11:51:48,364 INFO org.apache.hadoop.yarn.server.resourcemanager.rmcontainer.RMContainerImpl: container_1536878829533_0005_01_000006 Container Transitioned from RUNNING to COMPLETED
2018-09-19 11:51:48,364 INFO org.apache.hadoop.yarn.server.resourcemanager.RMAuditLogger: USER=jason	OPERATION=AM Released Container	TARGET=SchedulerApp	RESULT=SUCCESS	APPID=application_1536878829533_0005	CONTAINERID=container_1536878829533_0005_01_000006
2018-09-19 11:51:48,364 INFO org.apache.hadoop.yarn.server.resourcemanager.scheduler.SchedulerNode: Released container container_1536878829533_0005_01_000006 of capacity <memory:1024, vCores:1> on host 192.168.1.103:56395, which currently has 6 containers, <memory:7168, vCores:6> used and <memory:1024, vCores:2> available, release resources=true
2018-09-19 11:51:48,365 INFO org.apache.hadoop.yarn.server.resourcemanager.rmcontainer.RMContainerImpl: container_1536878829533_0005_01_000005 Container Transitioned from RUNNING to COMPLETED
2018-09-19 11:51:48,365 INFO org.apache.hadoop.yarn.server.resourcemanager.RMAuditLogger: USER=jason	OPERATION=AM Released Container	TARGET=SchedulerApp	RESULT=SUCCESS	APPID=application_1536878829533_0005	CONTAINERID=container_1536878829533_0005_01_000005
2018-09-19 11:51:48,365 INFO org.apache.hadoop.yarn.server.resourcemanager.scheduler.SchedulerNode: Released container container_1536878829533_0005_01_000005 of capacity <memory:1024, vCores:1> on host 192.168.1.103:56395, which currently has 5 containers, <memory:6144, vCores:5> used and <memory:2048, vCores:3> available, release resources=true
2018-09-19 11:51:48,365 INFO org.apache.hadoop.yarn.server.resourcemanager.rmcontainer.RMContainerImpl: container_1536878829533_0005_01_000004 Container Transitioned from RUNNING to COMPLETED
2018-09-19 11:51:48,365 INFO org.apache.hadoop.yarn.server.resourcemanager.RMAuditLogger: USER=jason	OPERATION=AM Released Container	TARGET=SchedulerApp	RESULT=SUCCESS	APPID=application_1536878829533_0005	CONTAINERID=container_1536878829533_0005_01_000004
2018-09-19 11:51:48,365 INFO org.apache.hadoop.yarn.server.resourcemanager.scheduler.SchedulerNode: Released container container_1536878829533_0005_01_000004 of capacity <memory:1024, vCores:1> on host 192.168.1.103:56395, which currently has 4 containers, <memory:5120, vCores:4> used and <memory:3072, vCores:4> available, release resources=true
2018-09-19 11:51:48,833 INFO org.apache.hadoop.yarn.server.resourcemanager.rmcontainer.RMContainerImpl: container_1536878829533_0005_01_000008 Container Transitioned from ALLOCATED to ACQUIRED
2018-09-19 11:51:48,834 INFO org.apache.hadoop.yarn.server.resourcemanager.rmcontainer.RMContainerImpl: container_1536878829533_0005_01_000009 Container Transitioned from ALLOCATED to ACQUIRED
2018-09-19 11:51:49,369 INFO org.apache.hadoop.yarn.server.resourcemanager.rmcontainer.RMContainerImpl: container_1536878829533_0005_01_000008 Container Transitioned from ACQUIRED to RUNNING
2018-09-19 11:51:49,369 INFO org.apache.hadoop.yarn.server.resourcemanager.rmcontainer.RMContainerImpl: container_1536878829533_0005_01_000009 Container Transitioned from ACQUIRED to RUNNING
2018-09-19 11:51:49,370 INFO org.apache.hadoop.yarn.server.resourcemanager.rmcontainer.RMContainerImpl: container_1536878829533_0005_01_000003 Container Transitioned from RUNNING to COMPLETED
2018-09-19 11:51:49,370 INFO org.apache.hadoop.yarn.server.resourcemanager.RMAuditLogger: USER=jason	OPERATION=AM Released Container	TARGET=SchedulerApp	RESULT=SUCCESS	APPID=application_1536878829533_0005	CONTAINERID=container_1536878829533_0005_01_000003
2018-09-19 11:51:49,370 INFO org.apache.hadoop.yarn.server.resourcemanager.scheduler.SchedulerNode: Released container container_1536878829533_0005_01_000003 of capacity <memory:1024, vCores:1> on host 192.168.1.103:56395, which currently has 3 containers, <memory:4096, vCores:3> used and <memory:4096, vCores:5> available, release resources=true
2018-09-19 11:51:49,845 INFO org.apache.hadoop.yarn.server.resourcemanager.scheduler.AppSchedulingInfo: checking for deactivate of application :application_1536878829533_0005
2018-09-19 11:51:50,373 INFO org.apache.hadoop.yarn.server.resourcemanager.rmcontainer.RMContainerImpl: container_1536878829533_0005_01_000010 Container Transitioned from NEW to ALLOCATED
2018-09-19 11:51:50,373 INFO org.apache.hadoop.yarn.server.resourcemanager.RMAuditLogger: USER=jason	OPERATION=AM Allocated Container	TARGET=SchedulerApp	RESULT=SUCCESS	APPID=application_1536878829533_0005	CONTAINERID=container_1536878829533_0005_01_000010
2018-09-19 11:51:50,373 INFO org.apache.hadoop.yarn.server.resourcemanager.scheduler.SchedulerNode: Assigned container container_1536878829533_0005_01_000010 of capacity <memory:1024, vCores:1> on host 192.168.1.103:56395, which has 4 containers, <memory:5120, vCores:4> used and <memory:3072, vCores:4> available after allocation
2018-09-19 11:51:50,373 INFO org.apache.hadoop.yarn.server.resourcemanager.scheduler.capacity.allocator.AbstractContainerAllocator: assignedContainer application attempt=appattempt_1536878829533_0005_000001 container=container_1536878829533_0005_01_000010 queue=org.apache.hadoop.yarn.server.resourcemanager.scheduler.capacity.allocator.RegularContainerAllocator@66312ccb clusterResource=<memory:8192, vCores:8> type=OFF_SWITCH
2018-09-19 11:51:50,373 INFO org.apache.hadoop.yarn.server.resourcemanager.scheduler.capacity.ParentQueue: Re-sorting assigned queue: root.default stats: default: capacity=1.0, absoluteCapacity=1.0, usedResources=<memory:5120, vCores:4>, usedCapacity=0.625, absoluteUsedCapacity=0.625, numApps=1, numContainers=4
2018-09-19 11:51:50,373 INFO org.apache.hadoop.yarn.server.resourcemanager.scheduler.capacity.ParentQueue: assignedContainer queue=root usedCapacity=0.625 absoluteUsedCapacity=0.625 used=<memory:5120, vCores:4> cluster=<memory:8192, vCores:8>
2018-09-19 11:51:50,852 INFO org.apache.hadoop.yarn.server.resourcemanager.rmcontainer.RMContainerImpl: container_1536878829533_0005_01_000010 Container Transitioned from ALLOCATED to ACQUIRED
2018-09-19 11:51:51,375 INFO org.apache.hadoop.yarn.server.resourcemanager.rmcontainer.RMContainerImpl: container_1536878829533_0005_01_000010 Container Transitioned from ACQUIRED to RUNNING
2018-09-19 11:51:51,530 INFO org.apache.hadoop.yarn.server.resourcemanager.rmcontainer.RMContainerImpl: container_1536878829533_0005_01_000008 Container Transitioned from RUNNING to COMPLETED
2018-09-19 11:51:51,530 INFO org.apache.hadoop.yarn.server.resourcemanager.RMAuditLogger: USER=jason	OPERATION=AM Released Container	TARGET=SchedulerApp	RESULT=SUCCESS	APPID=application_1536878829533_0005	CONTAINERID=container_1536878829533_0005_01_000008
2018-09-19 11:51:51,530 INFO org.apache.hadoop.yarn.server.resourcemanager.scheduler.SchedulerNode: Released container container_1536878829533_0005_01_000008 of capacity <memory:1024, vCores:1> on host 192.168.1.103:56395, which currently has 3 containers, <memory:4096, vCores:3> used and <memory:4096, vCores:5> available, release resources=true
2018-09-19 11:51:51,577 INFO org.apache.hadoop.yarn.server.resourcemanager.rmcontainer.RMContainerImpl: container_1536878829533_0005_01_000009 Container Transitioned from RUNNING to COMPLETED
2018-09-19 11:51:51,577 INFO org.apache.hadoop.yarn.server.resourcemanager.RMAuditLogger: USER=jason	OPERATION=AM Released Container	TARGET=SchedulerApp	RESULT=SUCCESS	APPID=application_1536878829533_0005	CONTAINERID=container_1536878829533_0005_01_000009
2018-09-19 11:51:51,577 INFO org.apache.hadoop.yarn.server.resourcemanager.scheduler.SchedulerNode: Released container container_1536878829533_0005_01_000009 of capacity <memory:1024, vCores:1> on host 192.168.1.103:56395, which currently has 2 containers, <memory:3072, vCores:2> used and <memory:5120, vCores:6> available, release resources=true
2018-09-19 11:51:51,854 INFO org.apache.hadoop.yarn.server.resourcemanager.scheduler.AppSchedulingInfo: checking for deactivate of application :application_1536878829533_0005
2018-09-19 11:51:53,312 INFO org.apache.hadoop.yarn.server.resourcemanager.rmcontainer.RMContainerImpl: container_1536878829533_0005_01_000010 Container Transitioned from RUNNING to COMPLETED
2018-09-19 11:51:53,312 INFO org.apache.hadoop.yarn.server.resourcemanager.RMAuditLogger: USER=jason	OPERATION=AM Released Container	TARGET=SchedulerApp	RESULT=SUCCESS	APPID=application_1536878829533_0005	CONTAINERID=container_1536878829533_0005_01_000010
2018-09-19 11:51:53,312 INFO org.apache.hadoop.yarn.server.resourcemanager.scheduler.SchedulerNode: Released container container_1536878829533_0005_01_000010 of capacity <memory:1024, vCores:1> on host 192.168.1.103:56395, which currently has 1 containers, <memory:2048, vCores:1> used and <memory:6144, vCores:7> available, release resources=true
2018-09-19 11:51:53,575 INFO org.apache.hadoop.yarn.server.resourcemanager.rmapp.attempt.RMAppAttemptImpl: Updating application attempt appattempt_1536878829533_0005_000001 with final state: FINISHING, and exit status: -1000
2018-09-19 11:51:53,575 INFO org.apache.hadoop.yarn.server.resourcemanager.rmapp.attempt.RMAppAttemptImpl: appattempt_1536878829533_0005_000001 State change from RUNNING to FINAL_SAVING
2018-09-19 11:51:53,575 INFO org.apache.hadoop.yarn.server.resourcemanager.rmapp.RMAppImpl: Updating application application_1536878829533_0005 with final state: FINISHING
2018-09-19 11:51:53,575 INFO org.apache.hadoop.yarn.server.resourcemanager.rmapp.RMAppImpl: application_1536878829533_0005 State change from RUNNING to FINAL_SAVING on event=ATTEMPT_UNREGISTERED
2018-09-19 11:51:53,575 INFO org.apache.hadoop.yarn.server.resourcemanager.recovery.RMStateStore: Updating info for app: application_1536878829533_0005
2018-09-19 11:51:53,575 INFO org.apache.hadoop.yarn.server.resourcemanager.rmapp.attempt.RMAppAttemptImpl: appattempt_1536878829533_0005_000001 State change from FINAL_SAVING to FINISHING
2018-09-19 11:51:53,575 INFO org.apache.hadoop.yarn.server.resourcemanager.rmapp.RMAppImpl: application_1536878829533_0005 State change from FINAL_SAVING to FINISHING on event=APP_UPDATE_SAVED
2018-09-19 11:51:54,577 INFO org.apache.hadoop.yarn.server.resourcemanager.ApplicationMasterService: application_1536878829533_0005 unregistered successfully. 
2018-09-19 11:51:59,760 INFO org.apache.hadoop.yarn.server.resourcemanager.rmcontainer.RMContainerImpl: container_1536878829533_0005_01_000001 Container Transitioned from RUNNING to COMPLETED
2018-09-19 11:51:59,760 INFO org.apache.hadoop.yarn.server.resourcemanager.ApplicationMasterService: Unregistering app attempt : appattempt_1536878829533_0005_000001
2018-09-19 11:51:59,760 INFO org.apache.hadoop.yarn.server.resourcemanager.RMAuditLogger: USER=jason	OPERATION=AM Released Container	TARGET=SchedulerApp	RESULT=SUCCESS	APPID=application_1536878829533_0005	CONTAINERID=container_1536878829533_0005_01_000001
2018-09-19 11:51:59,760 INFO org.apache.hadoop.yarn.server.resourcemanager.security.AMRMTokenSecretManager: Application finished, removing password for appattempt_1536878829533_0005_000001
2018-09-19 11:51:59,760 INFO org.apache.hadoop.yarn.server.resourcemanager.rmapp.attempt.RMAppAttemptImpl: appattempt_1536878829533_0005_000001 State change from FINISHING to FINISHED
2018-09-19 11:51:59,760 INFO org.apache.hadoop.yarn.server.resourcemanager.rmapp.RMAppImpl: application_1536878829533_0005 State change from FINISHING to FINISHED on event=ATTEMPT_FINISHED
2018-09-19 11:51:59,761 INFO org.apache.hadoop.yarn.server.resourcemanager.scheduler.SchedulerNode: Released container container_1536878829533_0005_01_000001 of capacity <memory:2048, vCores:1> on host 192.168.1.103:56395, which currently has 0 containers, <memory:0, vCores:0> used and <memory:8192, vCores:8> available, release resources=true
2018-09-19 11:51:59,761 INFO org.apache.hadoop.yarn.server.resourcemanager.RMAuditLogger: USER=jason	OPERATION=Application Finished - Succeeded	TARGET=RMAppManager	RESULT=SUCCESS	APPID=application_1536878829533_0005
2018-09-19 11:51:59,761 INFO org.apache.hadoop.yarn.server.resourcemanager.scheduler.capacity.CapacityScheduler: Application Attempt appattempt_1536878829533_0005_000001 is done. finalState=FINISHED
2018-09-19 11:51:59,761 INFO org.apache.hadoop.yarn.server.resourcemanager.RMAppManager$ApplicationSummary: appId=application_1536878829533_0005,name=word count,user=jason,queue=default,state=FINISHED,trackingUrl=http://Jasons-MacBook-Pro.local:8088/proxy/application_1536878829533_0005/,appMasterHost=192.168.1.103,startTime=1537375896021,finishTime=1537375913575,finalStatus=SUCCEEDED,memorySeconds=103129,vcoreSeconds=74,preemptedMemorySeconds=0,preemptedVcoreSeconds=0,preemptedAMContainers=0,preemptedNonAMContainers=0,preemptedResources=<memory:0\, vCores:0>,applicationType=MAPREDUCE
2018-09-19 11:51:59,762 INFO org.apache.hadoop.yarn.server.resourcemanager.scheduler.AppSchedulingInfo: Application application_1536878829533_0005 requests cleared
2018-09-19 11:51:59,762 INFO org.apache.hadoop.yarn.server.resourcemanager.amlauncher.AMLauncher: Cleaning master appattempt_1536878829533_0005_000001
2018-09-19 11:51:59,762 INFO org.apache.hadoop.yarn.server.resourcemanager.scheduler.capacity.LeafQueue: Application removed - appId: application_1536878829533_0005 user: jason queue: default #user-pending-applications: 0 #user-active-applications: 0 #queue-pending-applications: 0 #queue-active-applications: 0
2018-09-19 11:51:59,762 INFO org.apache.hadoop.yarn.server.resourcemanager.scheduler.capacity.ParentQueue: Application removed - appId: application_1536878829533_0005 user: jason leaf-queue of parent: root #applications: 0
2018-09-19 11:52:01,768 INFO org.apache.hadoop.yarn.server.resourcemanager.scheduler.AbstractYarnScheduler: Container container_1536878829533_0005_01_000010 completed with event FINISHED, but corresponding RMContainer doesn't exist.
2018-09-19 11:59:35,328 INFO org.apache.hadoop.yarn.server.resourcemanager.ClientRMService: Allocated new applicationId: 6
2018-09-19 11:59:35,829 INFO org.apache.hadoop.yarn.server.resourcemanager.scheduler.capacity.CapacityScheduler: Application 'application_1536878829533_0006' is submitted without priority hence considering default queue/cluster priority: 0
2018-09-19 11:59:35,829 INFO org.apache.hadoop.yarn.server.resourcemanager.scheduler.capacity.CapacityScheduler: Priority '0' is acceptable in queue : default for application: application_1536878829533_0006 for the user: jason
2018-09-19 11:59:35,830 INFO org.apache.hadoop.yarn.server.resourcemanager.ClientRMService: Application with id 6 submitted by user jason
2018-09-19 11:59:35,830 INFO org.apache.hadoop.yarn.server.resourcemanager.RMAuditLogger: USER=jason	IP=192.168.1.103	OPERATION=Submit Application Request	TARGET=ClientRMService	RESULT=SUCCESS	APPID=application_1536878829533_0006
2018-09-19 11:59:35,830 INFO org.apache.hadoop.yarn.server.resourcemanager.rmapp.RMAppImpl: Storing application with id application_1536878829533_0006
2018-09-19 11:59:35,830 INFO org.apache.hadoop.yarn.server.resourcemanager.recovery.RMStateStore: Storing info for app: application_1536878829533_0006
2018-09-19 11:59:35,830 INFO org.apache.hadoop.yarn.server.resourcemanager.rmapp.RMAppImpl: application_1536878829533_0006 State change from NEW to NEW_SAVING on event=START
2018-09-19 11:59:35,830 INFO org.apache.hadoop.yarn.server.resourcemanager.rmapp.RMAppImpl: application_1536878829533_0006 State change from NEW_SAVING to SUBMITTED on event=APP_NEW_SAVED
2018-09-19 11:59:35,831 INFO org.apache.hadoop.yarn.server.resourcemanager.scheduler.capacity.ParentQueue: Application added - appId: application_1536878829533_0006 user: jason leaf-queue of parent: root #applications: 1
2018-09-19 11:59:35,831 INFO org.apache.hadoop.yarn.server.resourcemanager.scheduler.capacity.CapacityScheduler: Accepted application application_1536878829533_0006 from user: jason, in queue: default
2018-09-19 11:59:35,831 INFO org.apache.hadoop.yarn.server.resourcemanager.rmapp.RMAppImpl: application_1536878829533_0006 State change from SUBMITTED to ACCEPTED on event=APP_ACCEPTED
2018-09-19 11:59:35,831 INFO org.apache.hadoop.yarn.server.resourcemanager.ApplicationMasterService: Registering app attempt : appattempt_1536878829533_0006_000001
2018-09-19 11:59:35,831 INFO org.apache.hadoop.yarn.server.resourcemanager.rmapp.attempt.RMAppAttemptImpl: appattempt_1536878829533_0006_000001 State change from NEW to SUBMITTED
2018-09-19 11:59:35,832 WARN org.apache.hadoop.yarn.server.resourcemanager.scheduler.capacity.LeafQueue: maximum-am-resource-percent is insufficient to start a single application in queue, it is likely set too low. skipping enforcement to allow at least one application to start
2018-09-19 11:59:35,832 WARN org.apache.hadoop.yarn.server.resourcemanager.scheduler.capacity.LeafQueue: maximum-am-resource-percent is insufficient to start a single application in queue for user, it is likely set too low. skipping enforcement to allow at least one application to start
2018-09-19 11:59:35,832 INFO org.apache.hadoop.yarn.server.resourcemanager.scheduler.capacity.LeafQueue: Application application_1536878829533_0006 from user: jason activated in queue: default
2018-09-19 11:59:35,832 INFO org.apache.hadoop.yarn.server.resourcemanager.scheduler.capacity.LeafQueue: Application added - appId: application_1536878829533_0006 user: jason, leaf-queue: default #user-pending-applications: 0 #user-active-applications: 1 #queue-pending-applications: 0 #queue-active-applications: 1
2018-09-19 11:59:35,832 INFO org.apache.hadoop.yarn.server.resourcemanager.scheduler.capacity.CapacityScheduler: Added Application Attempt appattempt_1536878829533_0006_000001 to scheduler from user jason in queue default
2018-09-19 11:59:35,833 INFO org.apache.hadoop.yarn.server.resourcemanager.rmapp.attempt.RMAppAttemptImpl: appattempt_1536878829533_0006_000001 State change from SUBMITTED to SCHEDULED
2018-09-19 11:59:35,957 INFO org.apache.hadoop.yarn.server.resourcemanager.rmcontainer.RMContainerImpl: container_1536878829533_0006_01_000001 Container Transitioned from NEW to ALLOCATED
2018-09-19 11:59:35,957 INFO org.apache.hadoop.yarn.server.resourcemanager.RMAuditLogger: USER=jason	OPERATION=AM Allocated Container	TARGET=SchedulerApp	RESULT=SUCCESS	APPID=application_1536878829533_0006	CONTAINERID=container_1536878829533_0006_01_000001
2018-09-19 11:59:35,957 INFO org.apache.hadoop.yarn.server.resourcemanager.scheduler.SchedulerNode: Assigned container container_1536878829533_0006_01_000001 of capacity <memory:2048, vCores:1> on host 192.168.1.103:56395, which has 1 containers, <memory:2048, vCores:1> used and <memory:6144, vCores:7> available after allocation
2018-09-19 11:59:35,957 INFO org.apache.hadoop.yarn.server.resourcemanager.scheduler.capacity.allocator.AbstractContainerAllocator: assignedContainer application attempt=appattempt_1536878829533_0006_000001 container=container_1536878829533_0006_01_000001 queue=org.apache.hadoop.yarn.server.resourcemanager.scheduler.capacity.allocator.RegularContainerAllocator@a99f42b clusterResource=<memory:8192, vCores:8> type=OFF_SWITCH
2018-09-19 11:59:35,957 INFO org.apache.hadoop.yarn.server.resourcemanager.security.NMTokenSecretManagerInRM: Sending NMToken for nodeId : 192.168.1.103:56395 for container : container_1536878829533_0006_01_000001
2018-09-19 11:59:35,958 INFO org.apache.hadoop.yarn.server.resourcemanager.rmcontainer.RMContainerImpl: container_1536878829533_0006_01_000001 Container Transitioned from ALLOCATED to ACQUIRED
2018-09-19 11:59:35,958 INFO org.apache.hadoop.yarn.server.resourcemanager.security.NMTokenSecretManagerInRM: Clear node set for appattempt_1536878829533_0006_000001
2018-09-19 11:59:35,958 INFO org.apache.hadoop.yarn.server.resourcemanager.rmapp.attempt.RMAppAttemptImpl: Storing attempt: AppId: application_1536878829533_0006 AttemptId: appattempt_1536878829533_0006_000001 MasterContainer: Container: [ContainerId: container_1536878829533_0006_01_000001, Version: 0, NodeId: 192.168.1.103:56395, NodeHttpAddress: 192.168.1.103:8042, Resource: <memory:2048, vCores:1>, Priority: 0, Token: Token { kind: ContainerToken, service: 192.168.1.103:56395 }, ]
2018-09-19 11:59:35,958 INFO org.apache.hadoop.yarn.server.resourcemanager.scheduler.capacity.ParentQueue: Re-sorting assigned queue: root.default stats: default: capacity=1.0, absoluteCapacity=1.0, usedResources=<memory:2048, vCores:1>, usedCapacity=0.25, absoluteUsedCapacity=0.25, numApps=1, numContainers=1
2018-09-19 11:59:35,958 INFO org.apache.hadoop.yarn.server.resourcemanager.rmapp.attempt.RMAppAttemptImpl: appattempt_1536878829533_0006_000001 State change from SCHEDULED to ALLOCATED_SAVING
2018-09-19 11:59:35,958 INFO org.apache.hadoop.yarn.server.resourcemanager.scheduler.capacity.ParentQueue: assignedContainer queue=root usedCapacity=0.25 absoluteUsedCapacity=0.25 used=<memory:2048, vCores:1> cluster=<memory:8192, vCores:8>
2018-09-19 11:59:35,958 INFO org.apache.hadoop.yarn.server.resourcemanager.rmapp.attempt.RMAppAttemptImpl: appattempt_1536878829533_0006_000001 State change from ALLOCATED_SAVING to ALLOCATED
2018-09-19 11:59:35,959 INFO org.apache.hadoop.yarn.server.resourcemanager.amlauncher.AMLauncher: Launching masterappattempt_1536878829533_0006_000001
2018-09-19 11:59:35,960 INFO org.apache.hadoop.yarn.server.resourcemanager.amlauncher.AMLauncher: Setting up container Container: [ContainerId: container_1536878829533_0006_01_000001, Version: 0, NodeId: 192.168.1.103:56395, NodeHttpAddress: 192.168.1.103:8042, Resource: <memory:2048, vCores:1>, Priority: 0, Token: Token { kind: ContainerToken, service: 192.168.1.103:56395 }, ] for AM appattempt_1536878829533_0006_000001
2018-09-19 11:59:35,960 INFO org.apache.hadoop.yarn.server.resourcemanager.security.AMRMTokenSecretManager: Create AMRMToken for ApplicationAttempt: appattempt_1536878829533_0006_000001
2018-09-19 11:59:35,960 INFO org.apache.hadoop.yarn.server.resourcemanager.security.AMRMTokenSecretManager: Creating password for appattempt_1536878829533_0006_000001
2018-09-19 11:59:35,973 INFO org.apache.hadoop.yarn.server.resourcemanager.amlauncher.AMLauncher: Done launching container Container: [ContainerId: container_1536878829533_0006_01_000001, Version: 0, NodeId: 192.168.1.103:56395, NodeHttpAddress: 192.168.1.103:8042, Resource: <memory:2048, vCores:1>, Priority: 0, Token: Token { kind: ContainerToken, service: 192.168.1.103:56395 }, ] for AM appattempt_1536878829533_0006_000001
2018-09-19 11:59:35,973 INFO org.apache.hadoop.yarn.server.resourcemanager.rmapp.attempt.RMAppAttemptImpl: appattempt_1536878829533_0006_000001 State change from ALLOCATED to LAUNCHED
2018-09-19 11:59:36,957 INFO org.apache.hadoop.yarn.server.resourcemanager.rmcontainer.RMContainerImpl: container_1536878829533_0006_01_000001 Container Transitioned from ACQUIRED to RUNNING
2018-09-19 11:59:39,409 INFO SecurityLogger.org.apache.hadoop.ipc.Server: Auth successful for appattempt_1536878829533_0006_000001 (auth:SIMPLE)
2018-09-19 11:59:39,411 INFO org.apache.hadoop.yarn.server.resourcemanager.ApplicationMasterService: AM registration appattempt_1536878829533_0006_000001
2018-09-19 11:59:39,411 INFO org.apache.hadoop.yarn.server.resourcemanager.RMAuditLogger: USER=jason	IP=192.168.1.103	OPERATION=Register App Master	TARGET=ApplicationMasterService	RESULT=SUCCESS	APPID=application_1536878829533_0006	APPATTEMPTID=appattempt_1536878829533_0006_000001
2018-09-19 11:59:39,411 INFO org.apache.hadoop.yarn.server.resourcemanager.rmapp.attempt.RMAppAttemptImpl: appattempt_1536878829533_0006_000001 State change from LAUNCHED to RUNNING
2018-09-19 11:59:39,411 INFO org.apache.hadoop.yarn.server.resourcemanager.rmapp.RMAppImpl: application_1536878829533_0006 State change from ACCEPTED to RUNNING on event=ATTEMPT_REGISTERED
2018-09-19 11:59:40,970 INFO org.apache.hadoop.yarn.server.resourcemanager.rmcontainer.RMContainerImpl: container_1536878829533_0006_01_000002 Container Transitioned from NEW to ALLOCATED
2018-09-19 11:59:40,970 INFO org.apache.hadoop.yarn.server.resourcemanager.RMAuditLogger: USER=jason	OPERATION=AM Allocated Container	TARGET=SchedulerApp	RESULT=SUCCESS	APPID=application_1536878829533_0006	CONTAINERID=container_1536878829533_0006_01_000002
2018-09-19 11:59:40,970 INFO org.apache.hadoop.yarn.server.resourcemanager.scheduler.SchedulerNode: Assigned container container_1536878829533_0006_01_000002 of capacity <memory:1024, vCores:1> on host 192.168.1.103:56395, which has 2 containers, <memory:3072, vCores:2> used and <memory:5120, vCores:6> available after allocation
2018-09-19 11:59:40,970 INFO org.apache.hadoop.yarn.server.resourcemanager.scheduler.capacity.allocator.AbstractContainerAllocator: assignedContainer application attempt=appattempt_1536878829533_0006_000001 container=container_1536878829533_0006_01_000002 queue=org.apache.hadoop.yarn.server.resourcemanager.scheduler.capacity.allocator.RegularContainerAllocator@a99f42b clusterResource=<memory:8192, vCores:8> type=NODE_LOCAL
2018-09-19 11:59:40,970 INFO org.apache.hadoop.yarn.server.resourcemanager.scheduler.capacity.ParentQueue: Re-sorting assigned queue: root.default stats: default: capacity=1.0, absoluteCapacity=1.0, usedResources=<memory:3072, vCores:2>, usedCapacity=0.375, absoluteUsedCapacity=0.375, numApps=1, numContainers=2
2018-09-19 11:59:40,970 INFO org.apache.hadoop.yarn.server.resourcemanager.scheduler.capacity.ParentQueue: assignedContainer queue=root usedCapacity=0.375 absoluteUsedCapacity=0.375 used=<memory:3072, vCores:2> cluster=<memory:8192, vCores:8>
2018-09-19 11:59:40,970 INFO org.apache.hadoop.yarn.server.resourcemanager.rmcontainer.RMContainerImpl: container_1536878829533_0006_01_000003 Container Transitioned from NEW to ALLOCATED
2018-09-19 11:59:40,970 INFO org.apache.hadoop.yarn.server.resourcemanager.RMAuditLogger: USER=jason	OPERATION=AM Allocated Container	TARGET=SchedulerApp	RESULT=SUCCESS	APPID=application_1536878829533_0006	CONTAINERID=container_1536878829533_0006_01_000003
2018-09-19 11:59:40,970 INFO org.apache.hadoop.yarn.server.resourcemanager.scheduler.SchedulerNode: Assigned container container_1536878829533_0006_01_000003 of capacity <memory:1024, vCores:1> on host 192.168.1.103:56395, which has 3 containers, <memory:4096, vCores:3> used and <memory:4096, vCores:5> available after allocation
2018-09-19 11:59:40,971 INFO org.apache.hadoop.yarn.server.resourcemanager.scheduler.capacity.allocator.AbstractContainerAllocator: assignedContainer application attempt=appattempt_1536878829533_0006_000001 container=container_1536878829533_0006_01_000003 queue=org.apache.hadoop.yarn.server.resourcemanager.scheduler.capacity.allocator.RegularContainerAllocator@a99f42b clusterResource=<memory:8192, vCores:8> type=NODE_LOCAL
2018-09-19 11:59:40,971 INFO org.apache.hadoop.yarn.server.resourcemanager.scheduler.capacity.ParentQueue: Re-sorting assigned queue: root.default stats: default: capacity=1.0, absoluteCapacity=1.0, usedResources=<memory:4096, vCores:3>, usedCapacity=0.5, absoluteUsedCapacity=0.5, numApps=1, numContainers=3
2018-09-19 11:59:40,971 INFO org.apache.hadoop.yarn.server.resourcemanager.scheduler.capacity.ParentQueue: assignedContainer queue=root usedCapacity=0.5 absoluteUsedCapacity=0.5 used=<memory:4096, vCores:3> cluster=<memory:8192, vCores:8>
2018-09-19 11:59:40,971 INFO org.apache.hadoop.yarn.server.resourcemanager.rmcontainer.RMContainerImpl: container_1536878829533_0006_01_000004 Container Transitioned from NEW to ALLOCATED
2018-09-19 11:59:40,971 INFO org.apache.hadoop.yarn.server.resourcemanager.RMAuditLogger: USER=jason	OPERATION=AM Allocated Container	TARGET=SchedulerApp	RESULT=SUCCESS	APPID=application_1536878829533_0006	CONTAINERID=container_1536878829533_0006_01_000004
2018-09-19 11:59:40,971 INFO org.apache.hadoop.yarn.server.resourcemanager.scheduler.SchedulerNode: Assigned container container_1536878829533_0006_01_000004 of capacity <memory:1024, vCores:1> on host 192.168.1.103:56395, which has 4 containers, <memory:5120, vCores:4> used and <memory:3072, vCores:4> available after allocation
2018-09-19 11:59:40,971 INFO org.apache.hadoop.yarn.server.resourcemanager.scheduler.capacity.allocator.AbstractContainerAllocator: assignedContainer application attempt=appattempt_1536878829533_0006_000001 container=container_1536878829533_0006_01_000004 queue=org.apache.hadoop.yarn.server.resourcemanager.scheduler.capacity.allocator.RegularContainerAllocator@a99f42b clusterResource=<memory:8192, vCores:8> type=NODE_LOCAL
2018-09-19 11:59:40,971 INFO org.apache.hadoop.yarn.server.resourcemanager.scheduler.capacity.ParentQueue: Re-sorting assigned queue: root.default stats: default: capacity=1.0, absoluteCapacity=1.0, usedResources=<memory:5120, vCores:4>, usedCapacity=0.625, absoluteUsedCapacity=0.625, numApps=1, numContainers=4
2018-09-19 11:59:40,971 INFO org.apache.hadoop.yarn.server.resourcemanager.scheduler.capacity.ParentQueue: assignedContainer queue=root usedCapacity=0.625 absoluteUsedCapacity=0.625 used=<memory:5120, vCores:4> cluster=<memory:8192, vCores:8>
2018-09-19 11:59:40,972 INFO org.apache.hadoop.yarn.server.resourcemanager.rmcontainer.RMContainerImpl: container_1536878829533_0006_01_000005 Container Transitioned from NEW to ALLOCATED
2018-09-19 11:59:40,972 INFO org.apache.hadoop.yarn.server.resourcemanager.RMAuditLogger: USER=jason	OPERATION=AM Allocated Container	TARGET=SchedulerApp	RESULT=SUCCESS	APPID=application_1536878829533_0006	CONTAINERID=container_1536878829533_0006_01_000005
2018-09-19 11:59:40,972 INFO org.apache.hadoop.yarn.server.resourcemanager.scheduler.SchedulerNode: Assigned container container_1536878829533_0006_01_000005 of capacity <memory:1024, vCores:1> on host 192.168.1.103:56395, which has 5 containers, <memory:6144, vCores:5> used and <memory:2048, vCores:3> available after allocation
2018-09-19 11:59:40,972 INFO org.apache.hadoop.yarn.server.resourcemanager.scheduler.capacity.allocator.AbstractContainerAllocator: assignedContainer application attempt=appattempt_1536878829533_0006_000001 container=container_1536878829533_0006_01_000005 queue=org.apache.hadoop.yarn.server.resourcemanager.scheduler.capacity.allocator.RegularContainerAllocator@a99f42b clusterResource=<memory:8192, vCores:8> type=NODE_LOCAL
2018-09-19 11:59:40,972 INFO org.apache.hadoop.yarn.server.resourcemanager.scheduler.capacity.ParentQueue: Re-sorting assigned queue: root.default stats: default: capacity=1.0, absoluteCapacity=1.0, usedResources=<memory:6144, vCores:5>, usedCapacity=0.75, absoluteUsedCapacity=0.75, numApps=1, numContainers=5
2018-09-19 11:59:40,972 INFO org.apache.hadoop.yarn.server.resourcemanager.scheduler.capacity.ParentQueue: assignedContainer queue=root usedCapacity=0.75 absoluteUsedCapacity=0.75 used=<memory:6144, vCores:5> cluster=<memory:8192, vCores:8>
2018-09-19 11:59:40,972 INFO org.apache.hadoop.yarn.server.resourcemanager.rmcontainer.RMContainerImpl: container_1536878829533_0006_01_000006 Container Transitioned from NEW to ALLOCATED
2018-09-19 11:59:40,972 INFO org.apache.hadoop.yarn.server.resourcemanager.RMAuditLogger: USER=jason	OPERATION=AM Allocated Container	TARGET=SchedulerApp	RESULT=SUCCESS	APPID=application_1536878829533_0006	CONTAINERID=container_1536878829533_0006_01_000006
2018-09-19 11:59:40,972 INFO org.apache.hadoop.yarn.server.resourcemanager.scheduler.SchedulerNode: Assigned container container_1536878829533_0006_01_000006 of capacity <memory:1024, vCores:1> on host 192.168.1.103:56395, which has 6 containers, <memory:7168, vCores:6> used and <memory:1024, vCores:2> available after allocation
2018-09-19 11:59:40,972 INFO org.apache.hadoop.yarn.server.resourcemanager.scheduler.capacity.allocator.AbstractContainerAllocator: assignedContainer application attempt=appattempt_1536878829533_0006_000001 container=container_1536878829533_0006_01_000006 queue=org.apache.hadoop.yarn.server.resourcemanager.scheduler.capacity.allocator.RegularContainerAllocator@a99f42b clusterResource=<memory:8192, vCores:8> type=NODE_LOCAL
2018-09-19 11:59:40,972 INFO org.apache.hadoop.yarn.server.resourcemanager.scheduler.capacity.ParentQueue: Re-sorting assigned queue: root.default stats: default: capacity=1.0, absoluteCapacity=1.0, usedResources=<memory:7168, vCores:6>, usedCapacity=0.875, absoluteUsedCapacity=0.875, numApps=1, numContainers=6
2018-09-19 11:59:40,973 INFO org.apache.hadoop.yarn.server.resourcemanager.scheduler.capacity.ParentQueue: assignedContainer queue=root usedCapacity=0.875 absoluteUsedCapacity=0.875 used=<memory:7168, vCores:6> cluster=<memory:8192, vCores:8>
2018-09-19 11:59:40,973 INFO org.apache.hadoop.yarn.server.resourcemanager.rmcontainer.RMContainerImpl: container_1536878829533_0006_01_000007 Container Transitioned from NEW to ALLOCATED
2018-09-19 11:59:40,973 INFO org.apache.hadoop.yarn.server.resourcemanager.RMAuditLogger: USER=jason	OPERATION=AM Allocated Container	TARGET=SchedulerApp	RESULT=SUCCESS	APPID=application_1536878829533_0006	CONTAINERID=container_1536878829533_0006_01_000007
2018-09-19 11:59:40,973 INFO org.apache.hadoop.yarn.server.resourcemanager.scheduler.SchedulerNode: Assigned container container_1536878829533_0006_01_000007 of capacity <memory:1024, vCores:1> on host 192.168.1.103:56395, which has 7 containers, <memory:8192, vCores:7> used and <memory:0, vCores:1> available after allocation
2018-09-19 11:59:40,973 INFO org.apache.hadoop.yarn.server.resourcemanager.scheduler.capacity.allocator.AbstractContainerAllocator: assignedContainer application attempt=appattempt_1536878829533_0006_000001 container=container_1536878829533_0006_01_000007 queue=org.apache.hadoop.yarn.server.resourcemanager.scheduler.capacity.allocator.RegularContainerAllocator@a99f42b clusterResource=<memory:8192, vCores:8> type=NODE_LOCAL
2018-09-19 11:59:40,973 INFO org.apache.hadoop.yarn.server.resourcemanager.scheduler.capacity.ParentQueue: Re-sorting assigned queue: root.default stats: default: capacity=1.0, absoluteCapacity=1.0, usedResources=<memory:8192, vCores:7>, usedCapacity=1.0, absoluteUsedCapacity=1.0, numApps=1, numContainers=7
2018-09-19 11:59:40,973 INFO org.apache.hadoop.yarn.server.resourcemanager.scheduler.capacity.ParentQueue: assignedContainer queue=root usedCapacity=1.0 absoluteUsedCapacity=1.0 used=<memory:8192, vCores:7> cluster=<memory:8192, vCores:8>
2018-09-19 11:59:41,457 INFO org.apache.hadoop.yarn.server.resourcemanager.security.NMTokenSecretManagerInRM: Sending NMToken for nodeId : 192.168.1.103:56395 for container : container_1536878829533_0006_01_000002
2018-09-19 11:59:41,458 INFO org.apache.hadoop.yarn.server.resourcemanager.rmcontainer.RMContainerImpl: container_1536878829533_0006_01_000002 Container Transitioned from ALLOCATED to ACQUIRED
2018-09-19 11:59:41,459 INFO org.apache.hadoop.yarn.server.resourcemanager.rmcontainer.RMContainerImpl: container_1536878829533_0006_01_000003 Container Transitioned from ALLOCATED to ACQUIRED
2018-09-19 11:59:41,459 INFO org.apache.hadoop.yarn.server.resourcemanager.rmcontainer.RMContainerImpl: container_1536878829533_0006_01_000004 Container Transitioned from ALLOCATED to ACQUIRED
2018-09-19 11:59:41,460 INFO org.apache.hadoop.yarn.server.resourcemanager.rmcontainer.RMContainerImpl: container_1536878829533_0006_01_000005 Container Transitioned from ALLOCATED to ACQUIRED
2018-09-19 11:59:41,461 INFO org.apache.hadoop.yarn.server.resourcemanager.rmcontainer.RMContainerImpl: container_1536878829533_0006_01_000006 Container Transitioned from ALLOCATED to ACQUIRED
2018-09-19 11:59:41,462 INFO org.apache.hadoop.yarn.server.resourcemanager.rmcontainer.RMContainerImpl: container_1536878829533_0006_01_000007 Container Transitioned from ALLOCATED to ACQUIRED
2018-09-19 11:59:41,969 INFO org.apache.hadoop.yarn.server.resourcemanager.rmcontainer.RMContainerImpl: container_1536878829533_0006_01_000002 Container Transitioned from ACQUIRED to RUNNING
2018-09-19 11:59:41,970 INFO org.apache.hadoop.yarn.server.resourcemanager.rmcontainer.RMContainerImpl: container_1536878829533_0006_01_000003 Container Transitioned from ACQUIRED to RUNNING
2018-09-19 11:59:41,970 INFO org.apache.hadoop.yarn.server.resourcemanager.rmcontainer.RMContainerImpl: container_1536878829533_0006_01_000004 Container Transitioned from ACQUIRED to RUNNING
2018-09-19 11:59:41,970 INFO org.apache.hadoop.yarn.server.resourcemanager.rmcontainer.RMContainerImpl: container_1536878829533_0006_01_000005 Container Transitioned from ACQUIRED to RUNNING
2018-09-19 11:59:41,971 INFO org.apache.hadoop.yarn.server.resourcemanager.rmcontainer.RMContainerImpl: container_1536878829533_0006_01_000006 Container Transitioned from ACQUIRED to RUNNING
2018-09-19 11:59:41,972 INFO org.apache.hadoop.yarn.server.resourcemanager.rmcontainer.RMContainerImpl: container_1536878829533_0006_01_000007 Container Transitioned from ACQUIRED to RUNNING
2018-09-19 11:59:47,628 INFO org.apache.hadoop.yarn.server.resourcemanager.rmcontainer.RMContainerImpl: container_1536878829533_0006_01_000006 Container Transitioned from RUNNING to COMPLETED
2018-09-19 11:59:47,629 INFO org.apache.hadoop.yarn.server.resourcemanager.RMAuditLogger: USER=jason	OPERATION=AM Released Container	TARGET=SchedulerApp	RESULT=SUCCESS	APPID=application_1536878829533_0006	CONTAINERID=container_1536878829533_0006_01_000006
2018-09-19 11:59:47,629 INFO org.apache.hadoop.yarn.server.resourcemanager.scheduler.SchedulerNode: Released container container_1536878829533_0006_01_000006 of capacity <memory:1024, vCores:1> on host 192.168.1.103:56395, which currently has 6 containers, <memory:7168, vCores:6> used and <memory:1024, vCores:2> available, release resources=true
2018-09-19 11:59:47,630 INFO org.apache.hadoop.yarn.server.resourcemanager.rmcontainer.RMContainerImpl: container_1536878829533_0006_01_000008 Container Transitioned from NEW to ALLOCATED
2018-09-19 11:59:47,630 INFO org.apache.hadoop.yarn.server.resourcemanager.RMAuditLogger: USER=jason	OPERATION=AM Allocated Container	TARGET=SchedulerApp	RESULT=SUCCESS	APPID=application_1536878829533_0006	CONTAINERID=container_1536878829533_0006_01_000008
2018-09-19 11:59:47,630 INFO org.apache.hadoop.yarn.server.resourcemanager.scheduler.SchedulerNode: Assigned container container_1536878829533_0006_01_000008 of capacity <memory:1024, vCores:1> on host 192.168.1.103:56395, which has 7 containers, <memory:8192, vCores:7> used and <memory:0, vCores:1> available after allocation
2018-09-19 11:59:47,630 INFO org.apache.hadoop.yarn.server.resourcemanager.scheduler.capacity.allocator.AbstractContainerAllocator: assignedContainer application attempt=appattempt_1536878829533_0006_000001 container=container_1536878829533_0006_01_000008 queue=org.apache.hadoop.yarn.server.resourcemanager.scheduler.capacity.allocator.RegularContainerAllocator@a99f42b clusterResource=<memory:8192, vCores:8> type=NODE_LOCAL
2018-09-19 11:59:47,630 INFO org.apache.hadoop.yarn.server.resourcemanager.scheduler.capacity.ParentQueue: Re-sorting assigned queue: root.default stats: default: capacity=1.0, absoluteCapacity=1.0, usedResources=<memory:8192, vCores:7>, usedCapacity=1.0, absoluteUsedCapacity=1.0, numApps=1, numContainers=7
2018-09-19 11:59:47,630 INFO org.apache.hadoop.yarn.server.resourcemanager.scheduler.capacity.ParentQueue: assignedContainer queue=root usedCapacity=1.0 absoluteUsedCapacity=1.0 used=<memory:8192, vCores:7> cluster=<memory:8192, vCores:8>
2018-09-19 11:59:47,679 INFO org.apache.hadoop.yarn.server.resourcemanager.rmcontainer.RMContainerImpl: container_1536878829533_0006_01_000007 Container Transitioned from RUNNING to COMPLETED
2018-09-19 11:59:47,679 INFO org.apache.hadoop.yarn.server.resourcemanager.RMAuditLogger: USER=jason	OPERATION=AM Released Container	TARGET=SchedulerApp	RESULT=SUCCESS	APPID=application_1536878829533_0006	CONTAINERID=container_1536878829533_0006_01_000007
2018-09-19 11:59:47,680 INFO org.apache.hadoop.yarn.server.resourcemanager.scheduler.SchedulerNode: Released container container_1536878829533_0006_01_000007 of capacity <memory:1024, vCores:1> on host 192.168.1.103:56395, which currently has 6 containers, <memory:7168, vCores:6> used and <memory:1024, vCores:2> available, release resources=true
2018-09-19 11:59:47,680 INFO org.apache.hadoop.yarn.server.resourcemanager.rmcontainer.RMContainerImpl: container_1536878829533_0006_01_000004 Container Transitioned from RUNNING to COMPLETED
2018-09-19 11:59:47,680 INFO org.apache.hadoop.yarn.server.resourcemanager.RMAuditLogger: USER=jason	OPERATION=AM Released Container	TARGET=SchedulerApp	RESULT=SUCCESS	APPID=application_1536878829533_0006	CONTAINERID=container_1536878829533_0006_01_000004
2018-09-19 11:59:47,680 INFO org.apache.hadoop.yarn.server.resourcemanager.scheduler.SchedulerNode: Released container container_1536878829533_0006_01_000004 of capacity <memory:1024, vCores:1> on host 192.168.1.103:56395, which currently has 5 containers, <memory:6144, vCores:5> used and <memory:2048, vCores:3> available, release resources=true
2018-09-19 11:59:47,681 INFO org.apache.hadoop.yarn.server.resourcemanager.rmcontainer.RMContainerImpl: container_1536878829533_0006_01_000005 Container Transitioned from RUNNING to COMPLETED
2018-09-19 11:59:47,681 INFO org.apache.hadoop.yarn.server.resourcemanager.RMAuditLogger: USER=jason	OPERATION=AM Released Container	TARGET=SchedulerApp	RESULT=SUCCESS	APPID=application_1536878829533_0006	CONTAINERID=container_1536878829533_0006_01_000005
2018-09-19 11:59:47,681 INFO org.apache.hadoop.yarn.server.resourcemanager.scheduler.SchedulerNode: Released container container_1536878829533_0006_01_000005 of capacity <memory:1024, vCores:1> on host 192.168.1.103:56395, which currently has 4 containers, <memory:5120, vCores:4> used and <memory:3072, vCores:4> available, release resources=true
2018-09-19 11:59:47,682 INFO org.apache.hadoop.yarn.server.resourcemanager.rmcontainer.RMContainerImpl: container_1536878829533_0006_01_000009 Container Transitioned from NEW to ALLOCATED
2018-09-19 11:59:47,682 INFO org.apache.hadoop.yarn.server.resourcemanager.RMAuditLogger: USER=jason	OPERATION=AM Allocated Container	TARGET=SchedulerApp	RESULT=SUCCESS	APPID=application_1536878829533_0006	CONTAINERID=container_1536878829533_0006_01_000009
2018-09-19 11:59:47,682 INFO org.apache.hadoop.yarn.server.resourcemanager.scheduler.SchedulerNode: Assigned container container_1536878829533_0006_01_000009 of capacity <memory:1024, vCores:1> on host 192.168.1.103:56395, which has 5 containers, <memory:6144, vCores:5> used and <memory:2048, vCores:3> available after allocation
2018-09-19 11:59:47,682 INFO org.apache.hadoop.yarn.server.resourcemanager.scheduler.capacity.allocator.AbstractContainerAllocator: assignedContainer application attempt=appattempt_1536878829533_0006_000001 container=container_1536878829533_0006_01_000009 queue=org.apache.hadoop.yarn.server.resourcemanager.scheduler.capacity.allocator.RegularContainerAllocator@a99f42b clusterResource=<memory:8192, vCores:8> type=NODE_LOCAL
2018-09-19 11:59:47,682 INFO org.apache.hadoop.yarn.server.resourcemanager.scheduler.capacity.ParentQueue: Re-sorting assigned queue: root.default stats: default: capacity=1.0, absoluteCapacity=1.0, usedResources=<memory:6144, vCores:5>, usedCapacity=0.75, absoluteUsedCapacity=0.75, numApps=1, numContainers=5
2018-09-19 11:59:47,682 INFO org.apache.hadoop.yarn.server.resourcemanager.scheduler.capacity.ParentQueue: assignedContainer queue=root usedCapacity=0.75 absoluteUsedCapacity=0.75 used=<memory:6144, vCores:5> cluster=<memory:8192, vCores:8>
2018-09-19 11:59:47,713 INFO org.apache.hadoop.yarn.server.resourcemanager.rmcontainer.RMContainerImpl: container_1536878829533_0006_01_000002 Container Transitioned from RUNNING to COMPLETED
2018-09-19 11:59:47,713 INFO org.apache.hadoop.yarn.server.resourcemanager.RMAuditLogger: USER=jason	OPERATION=AM Released Container	TARGET=SchedulerApp	RESULT=SUCCESS	APPID=application_1536878829533_0006	CONTAINERID=container_1536878829533_0006_01_000002
2018-09-19 11:59:47,713 INFO org.apache.hadoop.yarn.server.resourcemanager.scheduler.SchedulerNode: Released container container_1536878829533_0006_01_000002 of capacity <memory:1024, vCores:1> on host 192.168.1.103:56395, which currently has 4 containers, <memory:5120, vCores:4> used and <memory:3072, vCores:4> available, release resources=true
2018-09-19 11:59:47,714 INFO org.apache.hadoop.yarn.server.resourcemanager.rmcontainer.RMContainerImpl: container_1536878829533_0006_01_000003 Container Transitioned from RUNNING to COMPLETED
2018-09-19 11:59:47,714 INFO org.apache.hadoop.yarn.server.resourcemanager.RMAuditLogger: USER=jason	OPERATION=AM Released Container	TARGET=SchedulerApp	RESULT=SUCCESS	APPID=application_1536878829533_0006	CONTAINERID=container_1536878829533_0006_01_000003
2018-09-19 11:59:47,714 INFO org.apache.hadoop.yarn.server.resourcemanager.scheduler.SchedulerNode: Released container container_1536878829533_0006_01_000003 of capacity <memory:1024, vCores:1> on host 192.168.1.103:56395, which currently has 3 containers, <memory:4096, vCores:3> used and <memory:4096, vCores:5> available, release resources=true
2018-09-19 11:59:48,505 INFO org.apache.hadoop.yarn.server.resourcemanager.rmcontainer.RMContainerImpl: container_1536878829533_0006_01_000008 Container Transitioned from ALLOCATED to ACQUIRED
2018-09-19 11:59:48,506 INFO org.apache.hadoop.yarn.server.resourcemanager.rmcontainer.RMContainerImpl: container_1536878829533_0006_01_000009 Container Transitioned from ALLOCATED to ACQUIRED
2018-09-19 11:59:48,714 INFO org.apache.hadoop.yarn.server.resourcemanager.rmcontainer.RMContainerImpl: container_1536878829533_0006_01_000008 Container Transitioned from ACQUIRED to RUNNING
2018-09-19 11:59:48,714 INFO org.apache.hadoop.yarn.server.resourcemanager.rmcontainer.RMContainerImpl: container_1536878829533_0006_01_000009 Container Transitioned from ACQUIRED to RUNNING
2018-09-19 11:59:48,715 INFO org.apache.hadoop.yarn.server.resourcemanager.rmcontainer.RMContainerImpl: container_1536878829533_0006_01_000010 Container Transitioned from NEW to ALLOCATED
2018-09-19 11:59:48,715 INFO org.apache.hadoop.yarn.server.resourcemanager.RMAuditLogger: USER=jason	OPERATION=AM Allocated Container	TARGET=SchedulerApp	RESULT=SUCCESS	APPID=application_1536878829533_0006	CONTAINERID=container_1536878829533_0006_01_000010
2018-09-19 11:59:48,715 INFO org.apache.hadoop.yarn.server.resourcemanager.scheduler.SchedulerNode: Assigned container container_1536878829533_0006_01_000010 of capacity <memory:1024, vCores:1> on host 192.168.1.103:56395, which has 4 containers, <memory:5120, vCores:4> used and <memory:3072, vCores:4> available after allocation
2018-09-19 11:59:48,715 INFO org.apache.hadoop.yarn.server.resourcemanager.scheduler.capacity.allocator.AbstractContainerAllocator: assignedContainer application attempt=appattempt_1536878829533_0006_000001 container=container_1536878829533_0006_01_000010 queue=org.apache.hadoop.yarn.server.resourcemanager.scheduler.capacity.allocator.RegularContainerAllocator@a99f42b clusterResource=<memory:8192, vCores:8> type=OFF_SWITCH
2018-09-19 11:59:48,715 INFO org.apache.hadoop.yarn.server.resourcemanager.scheduler.capacity.ParentQueue: Re-sorting assigned queue: root.default stats: default: capacity=1.0, absoluteCapacity=1.0, usedResources=<memory:5120, vCores:4>, usedCapacity=0.625, absoluteUsedCapacity=0.625, numApps=1, numContainers=4
2018-09-19 11:59:48,715 INFO org.apache.hadoop.yarn.server.resourcemanager.scheduler.capacity.ParentQueue: assignedContainer queue=root usedCapacity=0.625 absoluteUsedCapacity=0.625 used=<memory:5120, vCores:4> cluster=<memory:8192, vCores:8>
2018-09-19 11:59:49,518 INFO org.apache.hadoop.yarn.server.resourcemanager.scheduler.AppSchedulingInfo: checking for deactivate of application :application_1536878829533_0006
2018-09-19 11:59:49,520 INFO org.apache.hadoop.yarn.server.resourcemanager.rmcontainer.RMContainerImpl: container_1536878829533_0006_01_000010 Container Transitioned from ALLOCATED to ACQUIRED
2018-09-19 11:59:49,717 INFO org.apache.hadoop.yarn.server.resourcemanager.rmcontainer.RMContainerImpl: container_1536878829533_0006_01_000010 Container Transitioned from ACQUIRED to RUNNING
2018-09-19 11:59:50,525 INFO org.apache.hadoop.yarn.server.resourcemanager.scheduler.AppSchedulingInfo: checking for deactivate of application :application_1536878829533_0006
2018-09-19 11:59:51,529 INFO org.apache.hadoop.yarn.server.resourcemanager.scheduler.AppSchedulingInfo: checking for deactivate of application :application_1536878829533_0006
2018-09-19 11:59:51,631 INFO org.apache.hadoop.yarn.server.resourcemanager.rmcontainer.RMContainerImpl: container_1536878829533_0006_01_000009 Container Transitioned from RUNNING to COMPLETED
2018-09-19 11:59:51,632 INFO org.apache.hadoop.yarn.server.resourcemanager.RMAuditLogger: USER=jason	OPERATION=AM Released Container	TARGET=SchedulerApp	RESULT=SUCCESS	APPID=application_1536878829533_0006	CONTAINERID=container_1536878829533_0006_01_000009
2018-09-19 11:59:51,632 INFO org.apache.hadoop.yarn.server.resourcemanager.scheduler.SchedulerNode: Released container container_1536878829533_0006_01_000009 of capacity <memory:1024, vCores:1> on host 192.168.1.103:56395, which currently has 3 containers, <memory:4096, vCores:3> used and <memory:4096, vCores:5> available, release resources=true
2018-09-19 11:59:51,654 INFO org.apache.hadoop.yarn.server.resourcemanager.rmcontainer.RMContainerImpl: container_1536878829533_0006_01_000008 Container Transitioned from RUNNING to COMPLETED
2018-09-19 11:59:51,654 INFO org.apache.hadoop.yarn.server.resourcemanager.RMAuditLogger: USER=jason	OPERATION=AM Released Container	TARGET=SchedulerApp	RESULT=SUCCESS	APPID=application_1536878829533_0006	CONTAINERID=container_1536878829533_0006_01_000008
2018-09-19 11:59:51,655 INFO org.apache.hadoop.yarn.server.resourcemanager.scheduler.SchedulerNode: Released container container_1536878829533_0006_01_000008 of capacity <memory:1024, vCores:1> on host 192.168.1.103:56395, which currently has 2 containers, <memory:3072, vCores:2> used and <memory:5120, vCores:6> available, release resources=true
2018-09-19 11:59:52,384 INFO org.apache.hadoop.yarn.server.resourcemanager.rmapp.attempt.RMAppAttemptImpl: Updating application attempt appattempt_1536878829533_0006_000001 with final state: FINISHING, and exit status: -1000
2018-09-19 11:59:52,384 INFO org.apache.hadoop.yarn.server.resourcemanager.rmapp.attempt.RMAppAttemptImpl: appattempt_1536878829533_0006_000001 State change from RUNNING to FINAL_SAVING
2018-09-19 11:59:52,384 INFO org.apache.hadoop.yarn.server.resourcemanager.rmapp.RMAppImpl: Updating application application_1536878829533_0006 with final state: FINISHING
2018-09-19 11:59:52,384 INFO org.apache.hadoop.yarn.server.resourcemanager.rmapp.RMAppImpl: application_1536878829533_0006 State change from RUNNING to FINAL_SAVING on event=ATTEMPT_UNREGISTERED
2018-09-19 11:59:52,384 INFO org.apache.hadoop.yarn.server.resourcemanager.recovery.RMStateStore: Updating info for app: application_1536878829533_0006
2018-09-19 11:59:52,384 INFO org.apache.hadoop.yarn.server.resourcemanager.rmapp.attempt.RMAppAttemptImpl: appattempt_1536878829533_0006_000001 State change from FINAL_SAVING to FINISHING
2018-09-19 11:59:52,384 INFO org.apache.hadoop.yarn.server.resourcemanager.rmapp.RMAppImpl: application_1536878829533_0006 State change from FINAL_SAVING to FINISHING on event=APP_UPDATE_SAVED
2018-09-19 11:59:52,386 INFO org.apache.hadoop.yarn.server.resourcemanager.rmcontainer.RMContainerImpl: container_1536878829533_0006_01_000010 Container Transitioned from RUNNING to COMPLETED
2018-09-19 11:59:52,386 INFO org.apache.hadoop.yarn.server.resourcemanager.RMAuditLogger: USER=jason	OPERATION=AM Released Container	TARGET=SchedulerApp	RESULT=SUCCESS	APPID=application_1536878829533_0006	CONTAINERID=container_1536878829533_0006_01_000010
2018-09-19 11:59:52,387 INFO org.apache.hadoop.yarn.server.resourcemanager.scheduler.SchedulerNode: Released container container_1536878829533_0006_01_000010 of capacity <memory:1024, vCores:1> on host 192.168.1.103:56395, which currently has 1 containers, <memory:2048, vCores:1> used and <memory:6144, vCores:7> available, release resources=true
2018-09-19 11:59:53,390 INFO org.apache.hadoop.yarn.server.resourcemanager.ApplicationMasterService: application_1536878829533_0006 unregistered successfully. 
2018-09-19 11:59:58,572 INFO org.apache.hadoop.yarn.server.resourcemanager.rmcontainer.RMContainerImpl: container_1536878829533_0006_01_000001 Container Transitioned from RUNNING to COMPLETED
2018-09-19 11:59:58,572 INFO org.apache.hadoop.yarn.server.resourcemanager.RMAuditLogger: USER=jason	OPERATION=AM Released Container	TARGET=SchedulerApp	RESULT=SUCCESS	APPID=application_1536878829533_0006	CONTAINERID=container_1536878829533_0006_01_000001
2018-09-19 11:59:58,573 INFO org.apache.hadoop.yarn.server.resourcemanager.ApplicationMasterService: Unregistering app attempt : appattempt_1536878829533_0006_000001
2018-09-19 11:59:58,573 INFO org.apache.hadoop.yarn.server.resourcemanager.security.AMRMTokenSecretManager: Application finished, removing password for appattempt_1536878829533_0006_000001
2018-09-19 11:59:58,573 INFO org.apache.hadoop.yarn.server.resourcemanager.rmapp.attempt.RMAppAttemptImpl: appattempt_1536878829533_0006_000001 State change from FINISHING to FINISHED
2018-09-19 11:59:58,573 INFO org.apache.hadoop.yarn.server.resourcemanager.scheduler.SchedulerNode: Released container container_1536878829533_0006_01_000001 of capacity <memory:2048, vCores:1> on host 192.168.1.103:56395, which currently has 0 containers, <memory:0, vCores:0> used and <memory:8192, vCores:8> available, release resources=true
2018-09-19 11:59:58,573 INFO org.apache.hadoop.yarn.server.resourcemanager.rmapp.RMAppImpl: application_1536878829533_0006 State change from FINISHING to FINISHED on event=ATTEMPT_FINISHED
2018-09-19 11:59:58,573 INFO org.apache.hadoop.yarn.server.resourcemanager.scheduler.capacity.CapacityScheduler: Application Attempt appattempt_1536878829533_0006_000001 is done. finalState=FINISHED
2018-09-19 11:59:58,573 INFO org.apache.hadoop.yarn.server.resourcemanager.RMAuditLogger: USER=jason	OPERATION=Application Finished - Succeeded	TARGET=RMAppManager	RESULT=SUCCESS	APPID=application_1536878829533_0006
2018-09-19 11:59:58,573 INFO org.apache.hadoop.yarn.server.resourcemanager.scheduler.AppSchedulingInfo: Application application_1536878829533_0006 requests cleared
2018-09-19 11:59:58,574 INFO org.apache.hadoop.yarn.server.resourcemanager.scheduler.capacity.LeafQueue: Application removed - appId: application_1536878829533_0006 user: jason queue: default #user-pending-applications: 0 #user-active-applications: 0 #queue-pending-applications: 0 #queue-active-applications: 0
2018-09-19 11:59:58,574 INFO org.apache.hadoop.yarn.server.resourcemanager.scheduler.capacity.ParentQueue: Application removed - appId: application_1536878829533_0006 user: jason leaf-queue of parent: root #applications: 0
